Workbook

Sheet center-April
A1: Milk Chilling Centre(Ghado) - Monthly Camel Milk Procurement Report - 01-04-2024 TO 30-04-2024
A2: SR. NO. | B2: Farmer Code | C2: Farmer Name | D2: Total Quantity Supplied(Lits) | E2: Camel Milk Price/Lit(OMR) | F2: Total Value Milk (OMR) | G2: Paid | H2: balance | I2: ID No: | J2: Remarks
A3: 1 | B3: 1040 | C3: Ahmed Said Mahad Jamaan Dhishil al Kathiri | D3: 422.1 | E3: 0.4 | F3: =D3*E3 -> 168.84 | G3: =164.9+3.94 -> 168.84 | H3: =F3-G3 -> 0 | I3: 25082374 | J3: 11-08-2024-feeds
A4: 5 | B4: 1728 | C4: MUJEEB MUSALLAM SALIM ALKATINI ALRAWAS | D4: 500.9 | E4: 0.4 | F4: =D4*E4 -> 200.36 | G4: =198.85+1.51 -> 200.36 | H4: =F4-G4 -> 0 | I4: 8977778 | J4: 12-08-2024-feeds
D5: =SUM(D3:D4) -> 923 | F5: =SUM(F3:F4) -> 369.2 | G5: =SUM(G3:G4) -> 369.2 | H5: =SUM(H3:H4) -> 0
A11: Hassan Ghaly | F11: Sakku Mathew

Sheet 05-25
A1: Milk Chilling Centre(Ghado) - Monthly Camel Milk Procurement Report - 01-05-2024 TO 31-05-2024
A2: SR. NO. | B2: Farmer Code | C2: Farmer Name | D2: Total Quantity Supplied(Lits) | E2: Camel Milk Price/Lit(OMR) | F2: Total Value Milk (OMR) | G2: Paid | H2: Balance | I2: ID No: | J2: Account No | K2: Bank Name | L2: BANK SWIFT CODE | M2: Phone No: | N2: Remarks
A3: 1 | B3: 1106 | C3: Badar Said Masood Al Kathiri | D3: 1380 | E3: 0.4 | F3: =D3*E3 -> 552 | G3: =164.9+3.94+383.16 -> 552 | H3: =F3-G3 -> 0 | I3: 5502751 | J3: 10060192223001 | K3: NBO | L3: NBOMOMRX | M3: 99270001 | N3: 26-08-2024-feeds
A4: 4 | B4: 1333 | C4: Suhail Salim Ahmed Al Nubi Al Kathiri | D4: 839.1 | E4: 0.4 | F4: =D4*E4 -> 335.64 | G4: =334.65+0.99 -> 335.64 | H4: =F4-G4 -> 0 | I4: 1736679 | J4: 0401002496140031 | K4: Bank Muscat | L4: BMUSOMRX | M4: 99482212 | N4: 20-08-2024-feeds | O4: 45691
A5: 5 | B5: 1382 | C5: Suhail Mohammed Said Ghawas Al Kathiri | D5: 920 | E5: 0.4 | F5: =D5*E5 -> 368 | G5: =367.75+0.25 -> 368 | H5: =F5-G5 -> 0 | I5: 886492 | J5: 0397003786810019 | K5: Bank Muscat | L5: BMUSOMRX | M5: 99494166 | N5: 12-08-24-feeds | O5: 45600
A6: 6 | B6: 1384 | C6: Abdul Selam Musallam Mohammed Al Rawas | D6: 459 | E6: 0.4 | F6: =D6*E6 -> 183.6 | G6: =183.02+0.58 -> 183.6 | H6: =F6-G6 -> 0 | I6: 4426701 | J6: 0406003017570013 | K6: Bank Muscat | L6: BMUSOMRX | M6: 92634991 | N6: 11-08-2024-feeds | O6: 45658
A7: 7 | B7: 1386 | C7: Omar Salim Ahmed Al Hadi Ba Omar | D7: 924 | E7: 0.4 | F7: =D7*E7 -> 369.6 | G7: =368.6+1 -> 369.6 | H7: =F7-G7 -> 0 | I7: 711799 | J7: 0406003202280013 | K7: Bank Muscat | L7: BMUSOMRX | M7: 92394924 | N7: 26-08-2024- feeds | O7: 45601
A8: 13 | B8: 1417 | C8: Said Bakhit said Al mashikhi | D8: 689.5 | E8: 0.4 | F8: =D8*E8 -> 275.8 | G8: =274.6+1.2 -> 275.8 | H8: =F8-G8 -> 0 | I8: 1252579 | J8: 0397003628950016 | K8: Bank Muscat | L8: BMUSOMRX | M8: 98520912 | N8: 19-08-2024-fceeds | O8: 45635
A9: 14 | B9: 1435 | C9: Salim Said aoubad Ghawas | D9: 1376.5 | E9: 0.4 | F9: =D9*E9 -> 550.6 | G9: =548.8+1.8 -> 550.6 | H9: =F9-G9 -> 0 | I9: 1305522 | J9: 0397003064100017 | K9: Bank Muscat | L9: BMUSOMRX | M9: 93246263 | N9: 13-08-2024-feeds | O9: 45601
A10: 17 | B10: 1462 | C10: Mohammed Suhail Mohammed Ghawas | D10: 460 | E10: 0.4 | F10: =D10*E10 -> 184 | G10: =181.45+2.55 -> 184 | H10: =F10-G10 -> 0 | I10: 9664038 | J10: 132247650084010 | K10: Bank Muscat | L10: BMUSOMRX | M10: 92989674 | N10: 12-08-2024-feeds | O10: 45601
A11: 18 | B11: 1463 | C11: Said Salim Ali Aazad Al Kathiri | D11: 779.9 | E11: 0.4 | F11: =D11*E11 -> 311.96 | G11: =308.94+3.02 -> 311.96 | H11: =F11-G11 -> 0 | I11: 3798072 | J11: 01040280652001 | K11: Bank Dhofar | L11: BDOFOMRU | M11: 99480608 | N11: 19-08-2024-feeds | O11: 45623
A12: 20 | B12: 1711 | C12: MUSALLAM SALIM AHMED AL KATHIRI | D12: 714 | E12: 0.4 | F12: =D12*E12 -> 285.6 | G12: =281.3+4.3 -> 285.6 | H12: =F12-G12 -> 0 | I12: 638353 | J12: 0401059818360018 | K12: Bank Muscat | L12: BMUSOMRX | M12: 99292727 | N12: 20-08-2024-feeds | O12: 45691
A13: 21 | B13: 1712 | C13: SAID MAHAD JAMAAN DHISHLIL AL KATHIRI | D13: 434.6 | E13: 0.4 | F13: =D13*E13 -> 173.84 | G13: =72.75+97+4.09 -> 173.84 | H13: =F13-G13 -> 0 | I13: 788958 | J13: 0397003887980012 | K13: Bank Muscat | L13: BMUSOMRX | N13: 45635 | O13: 45609
A14: 22 | B14: 1714 | C14: Ghazi Omar Salim Al Hadi Ba Omar | D14: 458.9 | E14: 0.4 | F14: =D14*E14 -> 183.56 | G14: =179.45+4.11 -> 183.56 | H14: =F14-G14 -> 0 | I14: 6285703 | J14: 0406003231910018 | K14: Bank Muscat | L14: BMUSOMRX | N14: 27-08-2024-feeds | O14: 45573
A15: 23 | B15: 1715 | C15: AHMED AWADH MASOUD KIKAB AL SHIHRI | D15: 449.6 | E15: 0.4 | F15: =D15*E15 -> 179.84 | G15: =177.1+2.74 -> 179.84 | H15: =F15-G15 -> 0 | I15: 6511663 | J15: 0439014008250027 | K15: Bank Muscat | L15: BMUSOMRX | N15: 21-08-2024-feeds | O15: 45630
A16: 24 | B16: 1723 | C16: SALIM Azad Ali Bait Said | D16: 529 | E16: 0.4 | F16: =D16*E16 -> 211.6 | G16: =207.2+4.4 -> 211.6 | H16: =F16-G16 -> 0 | I16: 6631224 | J16: 0406003245850018 | K16: Bank Muscat | L16: BMUSOMRX | M16: 92666839 | N16: 13-08-2024-feeds | O16: 45602
A17: 25 | B17: 1724 | C17: SAID SALIM MOHAMMED GHAWAS BAIT KATHIR | D17: 460 | E17: 0.4 | F17: =D17*E17 -> 184 | G17: =181.45+2.55 -> 184 | H17: =F17-G17 -> 0 | I17: 10795143 | J17: 1083705599017 | K17: NBO | L17: NBOMOMRX | M17: 99494166 | N17: 12-08-2024-feeds | O17: 45601
A18: 29 | B18: 1755 | C18: ABDULLAH ABDUL SALLAM ABDULLAH AL RAWAS | D18: 908.4 | E18: 0.4 | F18: =D18*E18 -> 363.36 | G18: =362.5+0.86 -> 363.36 | H18: =F18-G18 -> 0 | I18: 10592143 | J18: 3109139871500 | K18: Oman Arab Bank | L18: OMABOMRU | N18: 16-09-2024 | O18: 45614
A19: 30 | B19: 1758 | C19: AHMED SUHAIL HARIZ ALDAKRI ALKATHIRI | D19: 842.8 | E19: 0.4 | F19: =D19*E19 -> 337.12 | G19: =169.75+164.9+2.47 -> 337.12 | H19: =F19-G19 -> 0 | I19: 2443662 | J19: 0396003234530018 | K19: Bank Muscat | L19: BMUSOMRX | M19: 99608818 | N19: 9/5/2024, 16-09
A20: 35 | B20: 1787 | C20: SALIM MAHAD FAEL BAIT SAID | D20: 460 | E20: 0.4 | F20: =D20*E20 -> 184 | G20: =181.55+2.45 -> 184 | H20: =F20-G20 -> 0 | I20: 22980157 | J20: 0401051479010017 | K20: Bank Muscat | L20: BMUSOMRX | M20: 91490491 | N20: 18-08-2024-feeds
A21: 36 | B21: 1791 | C21: KHALID SALIM AHMED JUMAA AL KATHIRI | D21: 460 | E21: 0.4 | F21: =D21*E21 -> 184 | G21: =177.32+6.68 -> 184 | H21: =F21-G21 -> 0 | I21: 5335073 | J21: 0406003449250017 | K21: Bank Muscat | L21: BMUSOMRX | M21: 99806280 | N21: 18-08-2024-feeds
A22: 37 | B22: 1794 | C22: Said Mohammed Ahmed Bait Said | D22: 498.2 | E22: 0.4 | F22: =D22*E22 -> 199.28 | G22: =199+0.28 -> 199.28 | H22: =F22-G22 -> 0 | I22: 6122928 | J22: 0397003656600012 | K22: Bank Muscat | L22: BMUSOMRX | N22: 19-08-2024-feeds | O22: 45602
A23: 38 | B23: 1798 | C23: BAKHIT SALIM ALI AZAD AL KATHIRI | D23: 474.8 | E23: 0.4 | F23: =D23*E23 -> 189.92 | G23: =189.15+0.77 -> 189.92 | H23: =F23-G23 -> 0 | I23: 5314229 | J23: 01010855197001 | K23: Bank Dhofar | L23: BDOFOMRU | N23: 16-09-2024 | O23: 45623
A24: 39 | B24: 1808 | C24: SALIM ALI NASIB KIKAB AL SHAHRI | D24: 421 | E24: 0.4 | F24: =D24*E24 -> 168.4 | G24: =168.15+0.25 -> 168.4 | H24: =F24-G24 -> 0 | I24: 611136 | J24: 1083545856017 | K24: NBO | L24: NBOMOMRX | N24: 11-08-2024-feeds | O24: 45651
A25: 43 | B25: 1826 | C25: SALIM ALI AHMED SHDAR ALKATHIRI | D25: 454.5 | E25: 0.4 | F25: =D25*E25 -> 181.8 | G25: =F25 -> 181.8 | H25: =F25-G25 -> 0 | I25: 381215 | J25: 0406003301170017 | K25: BANK MUSCAT | L25: BMUSOMRX | M25: 95110746 | O25: 2.5 BT
A26: 45 | B26: 3763 | C26: GHANEM AHMED SALIM BAIT SAID | D26: 447.6 | E26: 0.4 | F26: =D26*E26 -> 179.04 | G26: =178.26+0.78 -> 179.04 | H26: =F26-G26 -> 0 | I26: 19189247 | J26: 0396003245930018 | K26: Bank Muscat | L26: BMUSOMRX | M26: 99846685 | N26: 13-08-2024-feeds
D27: =SUM(D3:D26) -> 15841.4 | F27: =SUM(F3:F26) -> 6336.56 | G27: =SUM(G3:G26) -> 6336.56 | H27: =SUM(H3:H26) -> 0
H31: =H27-118.06 -> -118.06
G32: =G27/F27 -> 1

Sheet center-06-24
A1: Milk Chilling Centre(Ghado) - Monthly Camel Milk Procurement Report - 01-06-2024 TO 30-06-2024
A2: SR. NO. | B2: Farmer Code | C2: Farmer Name | D2: Total Quantity Supplied(Lits) | E2: Camel Milk Price/Lit(OMR) | F2: Total Value Milk (OMR) | I2: ID No: | J2: Account No | K2: Bank Name | L2: BANK SWIFT CODE | M2: Phone No: | N2: Remarks | P2: Farmer Code | R2: Farmer Name | T2: ID No: | V2: Account No | X2: BANK SWIFT CODE
A3: 1 | B3: 1001 | C3: Abdul Hakim Musallam Salim Al Katini Al Rawas | D3: 268.9 | E3: 0.4 | F3: =D3*E3 -> 107.56 | G3: =F3 -> 107.56 | H3: =F3-G3 -> 0 | I3: 2130934 | J3: 0397020829680019 | K3: Bank Muscat | L3: BMUSOMRX | M3: 92911133 | N3: 45544 | O3: 1.06-Bt-19-12-24 | P3: 1001 | Q3: =P3=B3 -> TRUE | R3: Abdul Hakim Musallam Salim Al Katini Al Rawas | S3: =R3=C3 -> TRUE | T3: 2130934 | U3: =T3=I3 -> TRUE | V3: 0397020829680019 | W3: =V3=J3 -> TRUE | X3: BMUSOMRX | Y3: =X3=L3 -> TRUE
A4: 14 | B4: 1122 | C4: Hamed Hilal Said Al Kathiri | D4: 263.8 | E4: 0.4 | F4: =D4*E4 -> 105.52 | G4: =105.1+0.42 -> 105.52 | H4: =F4-G4 -> 0 | I4: 5219876 | J4: 0406045268200015 | K4: Bank Muscat | L4: BMUSOMRX | M4: 99066779 | N4: 23-09-2024 | O4: 45621 | P4: 1122 | Q4: =P4=B4 -> TRUE | R4: Hamed Hilal Said Al Kathiri | S4: =R4=C4 -> TRUE | T4: 5219876 | U4: =T4=I4 -> TRUE | V4: 0406045268200015 | W4: =V4=J4 -> TRUE | X4: BMUSOMRX | Y4: =X4=L4 -> TRUE
A5: 15 | B5: 1135 | C5: Khalid Said Ali Al Kathiri | D5: 591.7 | E5: 0.4 | F5: =D5*E5 -> 236.68 | G5: =235.75+0.93 -> 236.68 | H5: =F5-G5 -> 0 | I5: 19202954 | J5: 01013808698001 | K5: Bank Dhofar | L5: BDOFOMRU | M5: 92771786 | N5: 23-09-2024 | O5: 45601 | P5: 1135 | Q5: =P5=B5 -> TRUE | R5: Khalid Said Ali Al Kathiri | S5: =R5=C5 -> TRUE | T5: 19202954 | U5: =T5=I5 -> TRUE | V5: 01013808698001 | W5: =V5=J5 -> TRUE | X5: BDOFOMRU | Y5: =X5=L5 -> TRUE
A6: 26 | B6: 1247 | C6: Said Salim Azad Bait Ali Badar | D6: 528 | E6: 0.4 | F6: =D6*E6 -> 211.2 | G6: =208.35+2.85 -> 211.2 | H6: =F6-G6 -> 0 | I6: 4748561 | J6: 01040280570002 | K6: Bank Dhofar | L6: BDOFOMRU | M6: 92345282 | N6: 23-09-2024 | O6: 45637 | P6: 1247 | Q6: =P6=B6 -> TRUE | R6: Said Salim Azad Bait Ali Badar | S6: =R6=C6 -> TRUE | T6: 4748561 | U6: =T6=I6 -> TRUE | V6: 01040280570002 | W6: =V6=J6 -> TRUE | X6: BDOFOMRU | Y6: =X6=L6 -> TRUE
A7: 28 | B7: 1258 | C7: Said Ali Musallam Al Noubi Al Kathiri | D7: 698.9 | E7: 0.4 | F7: =D7*E7 -> 279.56 | G7: =279.04+0.52 -> 279.56 | H7: =F7-G7 -> 0 | I7: 1924174 | J7: 01040280044001 | K7: Bank Dhofar | L7: BDOFOMRU | M7: 99297990 | N7: 23-09-2024 | O7: 45644 | P7: 1258 | Q7: =P7=B7 -> TRUE | R7: Said Ali Musallam Al Noubi Al Kathiri | S7: =R7=C7 -> TRUE | T7: 1924174 | U7: =T7=I7 -> TRUE | V7: 01040280044001 | W7: =V7=J7 -> TRUE | X7: BDOFOMRU | Y7: =X7=L7 -> TRUE
A8: 30 | B8: 1261 | C8: Said Ali Nasib Kikab Al shahri | D8: 347.9 | E8: 0.4 | F8: =D8*E8 -> 139.16 | G8: =138.09+1.07 -> 139.16 | H8: =F8-G8 -> 0 | I8: 14429332 | J8: 0439018203570018 | K8: Bank Muscat | L8: BMUSOMRX | M8: 92939445 | N8: 45588 | O8: 45607 | P8: 1261 | Q8: =P8=B8 -> TRUE | R8: Said Ali Nasib Kikab Al shahri | S8: =R8=C8 -> TRUE | T8: 14429332 | U8: =T8=I8 -> TRUE | V8: 0439018203570018 | W8: =V8=J8 -> TRUE | X8: BMUSOMRX | Y8: =X8=L8 -> TRUE
A9: 31 | B9: 1268 | C9: Said Musallam Ali Ghawas | D9: 440 | E9: 0.4 | F9: =D9*E9 -> 176 | G9: =174.58+1.42 -> 176 | H9: =F9-G9 -> 0 | I9: 722058 | J9: 0397003940070023 | K9: Bank Muscat | L9: BMUSOMRX | M9: 92848609 | N9: 45635 | O9: 45573 | P9: 1268 | Q9: =P9=B9 -> TRUE | R9: Said Musallam Ali Ghawas | S9: =R9=C9 -> TRUE | T9: 722058 | U9: =T9=I9 -> TRUE | V9: 0397003940070023 | W9: =V9=J9 -> TRUE | X9: BMUSOMRX | Y9: =X9=L9 -> TRUE
A10: 32 | B10: 1282 | C10: Salim Ali Musallam Al Noubi Al Kathiri | D10: 588.7 | E10: 0.4 | F10: =D10*E10 -> 235.48 | G10: =234.2+1.28 -> 235.48 | H10: =F10-G10 -> 0 | I10: 2997747 | J10: 3109601542500 | K10: Oman Arab Bank | L10: OMABOMRU | M10: 92660969 | N10: 16-09-24 | O10: BT | P10: 1282 | Q10: =P10=B10 -> TRUE | R10: Salim Ali Musallam Al Noubi Al Kathiri | S10: =R10=C10 -> TRUE | T10: 2997747 | U10: =T10=I10 -> TRUE | V10: 3109601542500 | W10: =V10=J10 -> TRUE | X10: OMABOMRU | Y10: =X10=L10 -> TRUE
A11: 33 | B11: 1284 | C11: Salim Ali Said Al Nubi Al Kathiri | D11: 572 | E11: 0.4 | F11: =D11*E11 -> 228.8 | G11: =227.95+0.85 -> 228.8 | H11: =F11-G11 -> 0 | I11: 1177598 | J11: 01040280595001 | K11: Bank Dhofar | L11: BDOFOMRU | M11: 92825228 | N11: 45635 | P11: 1284 | Q11: =P11=B11 -> TRUE | R11: Salim Ali Said Al Nubi Al Kathiri | S11: =R11=C11 -> TRUE | T11: 1177598 | U11: =T11=I11 -> TRUE | V11: 01040280595001 | W11: =V11=J11 -> TRUE | X11: BDOFOMRU | Y11: =X11=L11 -> TRUE
A12: 37 | B12: 1328 | C12: Suhail Saeed Suhail ghawas | D12: 390.9 | E12: 0.4 | F12: =D12*E12 -> 156.36 | G12: =152.75+3.61 -> 156.36 | H12: =F12-G12 -> 0 | I12: 782833 | J12: 01015382117001 | K12: Bank Dhofar | L12: BDOFOMRU | M12: 92475895 | N12: 45575 | O12: 45601 | P12: 1328 | Q12: =P12=B12 -> TRUE | R12: Suhail Saeed Suhail ghawas | S12: =R12=C12 -> TRUE | T12: 782833 | U12: =T12=I12 -> TRUE | V12: 01015382117001 | W12: =V12=J12 -> TRUE | X12: BDOFOMRU | Y12: =X12=L12 -> TRUE
A13: 38 | B13: 1330 | C13: Said Mahad Ali Al Kathiri | D13: 601.6 | E13: 0.4 | F13: =D13*E13 -> 240.64 | G13: =237.65+2.99 -> 240.64 | H13: =F13-G13 -> 0 | I13: 12194826 | J13: 00510129167001 | K13: Bank Nizwa | L13: BNZWOMRX | M13: 91299100 | N13: 45567 | O13: 45686 | P13: 1330 | Q13: =P13=B13 -> TRUE | R13: Said Mahad Ali Al Kathiri | S13: =R13=C13 -> TRUE | T13: 12194826 | U13: =T13=I13 -> TRUE | V13: 00510129167001 | W13: =V13=J13 -> TRUE | X13: BNZWOMRX | Y13: =X13=L13 -> TRUE
A14: 48 | B14: 1396 | C14: Mustahil Ali Azad Al Kathiri | D14: 386.6 | E14: 0.4 | F14: =D14*E14 -> 154.64 | G14: =152.54+2.1 -> 154.64 | H14: =F14-G14 -> 0 | I14: 905845 | J14: 0397003647340016 | K14: Bank Muscat | L14: BMUSOMRX | M14: 99696204 | N14: 45567 | O14: 45628 | P14: 1396 | Q14: =P14=B14 -> TRUE | R14: Mustahil Ali Azad Al Kathiri | S14: =R14=C14 -> TRUE | T14: 905845 | U14: =T14=I14 -> TRUE | V14: 0397003647340016 | W14: =V14=J14 -> TRUE | X14: BMUSOMRX | Y14: =X14=L14 -> TRUE
A15: 49 | B15: 1397 | C15: Ahmed Musallam Amer Al Kathiri | D15: 327.2 | E15: 0.4 | F15: =D15*E15 -> 130.88 | G15: =128.65+2.23 -> 130.88 | H15: =F15-G15 -> 0 | I15: 1292885 | J15: 254001118001 | K15: HSBC | L15: BBMEOMRX | M15: 92307552 | N15: 16-09-2024 | O15: 45656 | P15: 1397 | Q15: =P15=B15 -> TRUE | R15: Ahmed Musallam Amer Al Kathiri | S15: =R15=C15 -> TRUE | T15: 1292885 | U15: =T15=I15 -> TRUE | V15: 254001118001 | W15: =V15=J15 -> TRUE | X15: BBMEOMRX | Y15: =X15=L15 -> TRUE
A16: 66 | B16: 1421 | C16: Malik Musallam Salim Masoud Al Rawas | D16: 638 | E16: 0.4 | F16: =D16*E16 -> 255.2 | G16: =252.8+2.4 -> 255.2 | H16: =F16-G16 -> 0 | I16: 15314262 | J16: 0397019441080011 | K16: Bank Muscat | L16: BMUSOMRX | M16: 90333361 | N16: 16-09-2024 | P16: 1421 | Q16: =P16=B16 -> TRUE | R16: Malik Musallam Salim Masoud Al Rawas | S16: =R16=C16 -> TRUE | T16: 15314262 | U16: =T16=I16 -> TRUE | V16: 0397019441080011 | W16: =V16=J16 -> TRUE | X16: BMUSOMRX | Y16: =X16=L16 -> TRUE
A17: 67 | B17: 1423 | C17: Ahmed Said Ali Azad Al Kathiri | D17: 593.2 | E17: 0.4 | F17: =D17*E17 -> 237.28 | G17: =232.8+4.48 -> 237.28 | H17: =F17-G17 -> 0 | I17: 5044397 | J17: 0397003645500016 | K17: Bank Muscat | L17: BMUSOMRX | M17: 99580550 | N17: 30-09-2024 | O17: 45677 | P17: 1423 | Q17: =P17=B17 -> TRUE | R17: Ahmed Said Ali Azad Al Kathiri | S17: =R17=C17 -> TRUE | T17: 5044397 | U17: =T17=I17 -> TRUE | V17: 0397003645500016 | W17: =V17=J17 -> TRUE | X17: BMUSOMRX | Y17: =X17=L17 -> TRUE
A18: 70 | B18: 1427 | C18: Salim Said Mohammed Musallam Al Nubi Al kathiri | D18: 305.1 | E18: 0.4 | F18: =D18*E18 -> 122.04 | G18: =118.99+3.05 -> 122.04 | H18: =F18-G18 -> 0 | I18: 24171637 | J18: 0439025022760016 | K18: Bank Muscat | L18: BMUSOMRX | M18: 97030409 | N18: 45635 | O18: 45665 | P18: 1427 | Q18: =P18=B18 -> TRUE | R18: Salim Said Mohammed Musallam Al Nubi Al kathiri | S18: =R18=C18 -> TRUE | T18: 24171637 | U18: =T18=I18 -> TRUE | V18: 0439025022760016 | W18: =V18=J18 -> TRUE | X18: BMUSOMRX | Y18: =X18=L18 -> TRUE
A19: 72 | B19: 1430 | C19: Ahmed Said Mohammed Houmdi Al Siari | D19: 308 | E19: 0.4 | F19: =D19*E19 -> 123.2 | G19: =122.04+1.16 -> 123.2 | H19: =F19-G19 -> 0 | I19: 564698 | J19: 0406003186630017 | K19: Bank Muscat | L19: BMUSOMRX | M19: 99189793 | N19: 23-09-2024 | O19: 45600 | P19: 1430 | Q19: =P19=B19 -> TRUE | R19: Ahmed Said Mohammed Houmdi Al Siari | S19: =R19=C19 -> TRUE | T19: 564698 | U19: =T19=I19 -> TRUE | V19: 0406003186630017 | W19: =V19=J19 -> TRUE | X19: BMUSOMRX | Y19: =X19=L19 -> TRUE
A20: 75 | B20: 1434 | C20: Muhssin Said Mohammed Ghawas | D20: 336.1 | E20: 0.4 | F20: =D20*E20 -> 134.44 | G20: =131.06+3.38 -> 134.44 | H20: =F20-G20 -> 0 | I20: 19197503 | J20: 0403015046590039 | K20: Bank Muscat | L20: BMUSOMRX | M20: 92466605 | N20: 18-09-2024 | O20: 45614 | P20: 1434 | Q20: =P20=B20 -> TRUE | R20: Muhssin Said Mohammed Ghawas | S20: =R20=C20 -> TRUE | T20: 19197503 | U20: =T20=I20 -> TRUE | V20: 0403015046590039 | W20: =V20=J20 -> TRUE | X20: BMUSOMRX | Y20: =X20=L20 -> TRUE
A21: 76 | B21: 1435 | C21: Salim Said aoubad Ghawas | D21: 968 | E21: 0.4 | F21: =D21*E21 -> 387.2 | G21: =383.15+4.05 -> 387.2 | H21: =F21-G21 -> 0 | I21: 1305522 | J21: 0397003064100017 | K21: Bank Muscat | L21: BMUSOMRX | M21: 93246263 | N21: 25-09-2024 | O21: 05/11/241 | P21: 1435 | Q21: =P21=B21 -> TRUE | R21: Salim Said aoubad Ghawas | S21: =R21=C21 -> TRUE | T21: 1305522 | U21: =T21=I21 -> TRUE | V21: 0397003064100017 | W21: =V21=J21 -> TRUE | X21: BMUSOMRX | Y21: =X21=L21 -> TRUE
A22: 77 | B22: 1437 | C22: Ahmed Ali Ahmed Shadar Al Kathiri | D22: 638 | E22: 0.4 | F22: =D22*E22 -> 255.2 | G22: =254.5+0.7 -> 255.2 | H22: =F22-G22 -> 0 | I22: 9685144 | J22: 250056066001 | K22: HSBC | L22: BBMEOMRX | M22: 96907302 | N22: 45544 | O22: 45614 | P22: 1437 | Q22: =P22=B22 -> TRUE | R22: Ahmed Ali Ahmed Shadar Al Kathiri | S22: =R22=C22 -> TRUE | T22: 9685144 | U22: =T22=I22 -> TRUE | V22: 250056066001 | W22: =V22=J22 -> TRUE | X22: BBMEOMRX | Y22: =X22=L22 -> TRUE
A23: 78 | B23: 1438 | C23: Salim Aubad Al Maslamin Al Mashali | D23: 968 | E23: 0.4 | F23: =D23*E23 -> 387.2 | G23: =383.15+4.05 -> 387.2 | H23: =F23-G23 -> 0 | I23: 656621 | J23: 1023386437017 | K23: NBO | L23: NBOMOMRX | M23: 92509804 | N23: 45581 | O23: 45637 | P23: 1438 | Q23: =P23=B23 -> TRUE | R23: Salim Aubad Al Maslamin Al Mashali | S23: =R23=C23 -> TRUE | T23: 656621 | U23: =T23=I23 -> TRUE | V23: 1023386437017 | W23: =V23=J23 -> TRUE | X23: NBOMOMRX | Y23: =X23=L23 -> TRUE
A24: 82 | B24: 1448 | C24: Salim Said Masoud Said Al Kathiri | D24: 270.7 | E24: 0.4 | F24: =D24*E24 -> 108.28 | G24: =107.86+0.42 -> 108.28 | H24: =F24-G24 -> 0 | I24: 26433121 | J24: 0397060499480017 | K24: Bank Muscat | L24: BMUSOMRX | M24: 93229244 | N24: 45635 | O24: 45656 | P24: 1448 | Q24: =P24=B24 -> TRUE | R24: Salim Said Masoud Said Al Kathiri | S24: =R24=C24 -> TRUE | T24: 26433121 | U24: =T24=I24 -> TRUE | V24: 0397060499480017 | W24: =V24=J24 -> TRUE | X24: BMUSOMRX | Y24: =X24=L24 -> TRUE
A25: 90 | B25: 1468 | C25: Ahmed Salim Ahmed Al Kathiri | D25: 655.7 | E25: 0.4 | F25: =D25*E25 -> 262.28 | G25: =258.14+4.14 -> 262.28 | H25: =F25-G25 -> 0 | I25: 6996485 | J25: 0439016595760027 | K25: Bank Muscat | L25: BMUSOMRX | M25: 92947741 | N25: 30-09-2024 | O25: 45642 | P25: 1468 | Q25: =P25=B25 -> TRUE | R25: Ahmed Salim Ahmed Al Kathiri | S25: =R25=C25 -> TRUE | T25: 6996485 | U25: =T25=I25 -> TRUE | V25: 0439016595760027 | W25: =V25=J25 -> TRUE | X25: BMUSOMRX | Y25: =X25=L25 -> TRUE
A26: 93 | B26: 1475 | C26: Musallam Said Ahmed Al kathiri | D26: 330.1 | E26: 0.4 | F26: =D26*E26 -> 132.04 | G26: =130.82+1.22 -> 132.04 | H26: =F26-G26 -> 0 | I26: 4584011 | J26: 0439061793370011 | K26: Bank Muscat | L26: BMUSOMRX | M26: 98822862 | N26: 30-09-2024 | O26: 45684 | P26: 1475 | Q26: =P26=B26 -> TRUE | R26: Musallam Said Ahmed Al kathiri | S26: =R26=C26 -> TRUE | T26: 4584011 | U26: =T26=I26 -> TRUE | V26: 0439061793370011 | W26: =V26=J26 -> TRUE | X26: BMUSOMRX | Y26: =X26=L26 -> TRUE
A27: 103 | B27: 1706 | C27: AIL MUSALLAM AMER AL KATHIRI | D27: 302.6 | E27: 0.4 | F27: =D27*E27 -> 121.04 | G27: =118.25+2.79 -> 121.04 | H27: =F27-G27 -> 0 | I27: 2520947 | J27: 250010035731 | K27: Bank Sohar | L27: BSHROMRU | M27: 92246641 | N27: 16-09-2024 | O27: 45573 | P27: 1706 | Q27: =P27=B27 -> TRUE | R27: AIL MUSALLAM AMER AL KATHIRI | S27: =R27=C27 -> TRUE | T27: 2520947 | U27: =T27=I27 -> TRUE | V27: 250010035731 | W27: =V27=J27 -> TRUE | X27: BSHROMRU | Y27: =X27=L27 -> TRUE
A28: 108 | B28: 1713 | C28: MOHAMMED SALIM ALI AL NOBI AL KATHIRI | D28: 352 | E28: 0.4 | F28: =D28*E28 -> 140.8 | G28: =138.7+2.1 -> 140.8 | H28: =F28-G28 -> 0 | I28: 19890467 | J28: 01010856539002 | K28: Bank Dhofar | L28: BDOFOMRU | N28: 45635 | P28: 1713 | Q28: =P28=B28 -> TRUE | R28: MOHAMMED SALIM ALI AL NOBI AL KATHIRI | S28: =R28=C28 -> TRUE | T28: 19890467 | U28: =T28=I28 -> TRUE | V28: 01010856539002 | W28: =V28=J28 -> TRUE | X28: BDOFOMRU | Y28: =X28=L28 -> TRUE
A29: 113 | B29: 1718 | C29: ADNAN SALIM ALI ALNOOB AL KATHIRI | D29: 330 | E29: 0.4 | F29: =D29*E29 -> 132 | G29: =F29 -> 132 | H29: =F29-G29 -> 0 | I29: 18656137 | J29: 250010162782 | K29: Bank Sohar | L29: BSHROMRU | N29: 16-09-2024 | O29: 2.5 bt | P29: 1718 | Q29: =P29=B29 -> TRUE | R29: ADNAN SALIM ALI ALNOOB AL KATHIRI | S29: =R29=C29 -> TRUE | T29: 18656137 | U29: =T29=I29 -> TRUE | V29: 250010162782 | W29: =V29=J29 -> TRUE | X29: BSHROMRU | Y29: =X29=L29 -> TRUE
A30: 122 | B30: 1730 | C30: Salim Mohsin Salim Saluma Baawain | D30: 385.5 | E30: 0.4 | F30: =D30*E30 -> 154.2 | G30: =152.97+1.23 -> 154.2 | H30: =F30-G30 -> 0 | I30: 18458405 | J30: 0396059029400018 | K30: Bank Muscat | L30: BMUSOMRX | M30: 98566660 | N30: 45635 | P30: 1730 | Q30: =P30=B30 -> TRUE | R30: Salim Mohsin Salim Saluma Baawain | S30: =R30=C30 -> TRUE | T30: 18458405 | U30: =T30=I30 -> TRUE | V30: 0396059029400018 | W30: =V30=J30 -> TRUE | X30: BMUSOMRX | Y30: =X30=L30 -> TRUE
A31: 126 | B31: 1736 | C31: HILAL SAID AZAD AL KATHIRI | D31: 282.4 | E31: 0.4 | F31: =D31*E31 -> 112.96 | G31: =112.13+0.83 -> 112.96 | H31: =F31-G31 -> 0 | I31: 960639 | J31: 0406003189710011 | K31: Bank Muscat | L31: BMUSOMRX | N31: 23-09-2024 | O31: 45621 | P31: 1736 | Q31: =P31=B31 -> TRUE | R31: HILAL SAID AZAD AL KATHIRI | S31: =R31=C31 -> TRUE | T31: 960639 | U31: =T31=I31 -> TRUE | V31: 0406003189710011 | W31: =V31=J31 -> TRUE | X31: BMUSOMRX | Y31: =X31=L31 -> TRUE
A32: 128 | B32: 1738 | C32: SALIM SUHAIL MAHAD ALI BAIT SAID | D32: 329.7 | E32: 0.4 | F32: =D32*E32 -> 131.88 | G32: =115.5+16.38 -> 131.88 | H32: =F32-G32 -> 0 | I32: 23187863 | J32: 0406042709700017 | K32: Bank Muscat | L32: BMUSOMRX | M32: 99464736 | N32: 45567 | O32: dcf-27-01-25 | P32: 1738 | Q32: =P32=B32 -> TRUE | R32: SALIM SUHAIL MAHAD ALI BAIT SAID | S32: =R32=C32 -> TRUE | T32: 23187863 | U32: =T32=I32 -> TRUE | V32: 0406042709700017 | W32: =V32=J32 -> TRUE | X32: BMUSOMRX | Y32: =X32=L32 -> TRUE
A33: 135 | B33: 1748 | C33: BAKHIT HAREEZ AHMED AL KATHAIRI | D33: 307.9 | E33: 0.4 | F33: =D33*E33 -> 123.16 | G33: =119.85+3.31 -> 123.16 | H33: =F33-G33 -> 0 | I33: 1354182 | J33: 0396003221340015 | K33: Bank Muscat | L33: BMUSOMRX | M33: 98953022 | N33: 45544 | O33: 45600 | P33: 1748 | Q33: =P33=B33 -> TRUE | R33: BAKHIT HAREEZ AHMED AL KATHAIRI | S33: =R33=C33 -> TRUE | T33: 1354182 | U33: =T33=I33 -> TRUE | V33: 0396003221340015 | W33: =V33=J33 -> TRUE | X33: BMUSOMRX | Y33: =X33=L33 -> TRUE
A34: 138 | B34: 1752 | C34: MOHAMMED SAID MOHAMMED GHAWAS | D34: 346.4 | E34: 0.4 | F34: =D34*E34 -> 138.56 | G34: =136.86+1.7 -> 138.56 | H34: =F34-G34 -> 0 | I34: 2808921 | J34: 0403015046590039 | K34: Bank Muscat | L34: BMUSOMRX | M34: 92740803 | N34: 18-09-2024 | O34: 45614 | P34: 1752 | Q34: =P34=B34 -> TRUE | R34: MOHAMMED SAID MOHAMMED GHAWAS | S34: =R34=C34 -> TRUE | T34: 2808921 | U34: =T34=I34 -> TRUE | V34: 0403015046590039 | W34: =V34=J34 -> TRUE | X34: BMUSOMRX | Y34: =X34=L34 -> TRUE
A35: 149 | B35: 1768 | C35: SALIM MUSTAHIL ALI AL KATHIRI | D35: 324.7 | E35: 0.4 | F35: =D35*E35 -> 129.88 | G35: =126.1+3.78 -> 129.88 | H35: =F35-G35 -> 0 | I35: 13899464 | J35: 0397003573860012 | K35: Bank Muscat | L35: BMUSOMRX | M35: 99166449 | N35: 30-09-2024 | P35: 1768 | Q35: =P35=B35 -> TRUE | R35: SALIM MUSTAHIL ALI AL KATHIRI | S35: =R35=C35 -> TRUE | T35: 13899464 | U35: =T35=I35 -> TRUE | V35: 0397003573860012 | W35: =V35=J35 -> TRUE | X35: BMUSOMRX | Y35: =X35=L35 -> TRUE
A36: 152 | B36: 1771 | C36: Abdullah Said Ali Azad Al Kathiri | D36: 330 | E36: 0.4 | F36: =D36*E36 -> 132 | G36: =130.95+1.05 -> 132 | H36: =F36-G36 -> 0 | I36: 5044401 | J36: 0397003645500016 | K36: Bank Muscat | L36: BMUSOMRX | M36: 93556616 | N36: 30-09-2024 | O36: 45635 | P36: 1771 | Q36: =P36=B36 -> TRUE | R36: Abdullah Said Ali Azad Al Kathiri | S36: =R36=C36 -> TRUE | T36: 5044401 | U36: =T36=I36 -> TRUE | V36: 0397003645500016 | W36: =V36=J36 -> TRUE | X36: BMUSOMRX | Y36: =X36=L36 -> TRUE
A37: 155 | B37: 1774 | C37: ADNAN MOHAMMED MOHISEEN HOUMDI AL SIARI | D37: 329.7 | E37: 0.4 | F37: =D37*E37 -> 131.88 | G37: =131.25+0.63 -> 131.88 | H37: =F37-G37 -> 0 | I37: 20865047 | J37: 0406051045750013 | K37: Bank Muscat | L37: BMUSOMRX | M37: 98825083 | N37: 45567 | O37: 45663 | P37: 1774 | Q37: =P37=B37 -> TRUE | R37: ADNAN MOHAMMED MOHISEEN HOUMDI AL SIARI | S37: =R37=C37 -> TRUE | T37: 20865047 | U37: =T37=I37 -> TRUE | V37: 0406051045750013 | W37: =V37=J37 -> TRUE | X37: BMUSOMRX | Y37: =X37=L37 -> TRUE
A38: 163 | B38: 1783 | C38: MUSALLAM HAREEZ AHMED ALDAKRI ALKATHIRI | D38: 272.5 | E38: 0.4 | F38: =D38*E38 -> 109 | G38: =106.38+2.62 -> 109 | H38: =F38-G38 -> 0 | I38: 1500187 | J38: 0396003224620019 | K38: Bank Muscat | L38: BMUSOMRX | M38: 91159122 | N38: 45544 | O38: 45600 | P38: 1783 | Q38: =P38=B38 -> TRUE | R38: MUSALLAM HAREEZ AHMED ALDAKRI ALKATHIRI | S38: =R38=C38 -> TRUE | T38: 1500187 | U38: =T38=I38 -> TRUE | V38: 0396003224620019 | W38: =V38=J38 -> TRUE | X38: BMUSOMRX | Y38: =X38=L38 -> TRUE
A39: 165 | B39: 1785 | C39: SUHAIL ALI ABDULLAH GHAWAS | D39: 326.1 | E39: 0.4 | F39: =D39*E39 -> 130.44 | G39: =126.4+4.04 -> 130.44 | H39: =F39-G39 -> 0 | I39: 7374743 | J39: 0406012723080017 | K39: Bank Muscat | L39: BMUSOMRX | M39: 93875087 | N39: 23-09-2024 | P39: 1785 | Q39: =P39=B39 -> TRUE | R39: SUHAIL ALI ABDULLAH GHAWAS | S39: =R39=C39 -> TRUE | T39: 7374743 | U39: =T39=I39 -> TRUE | V39: 0406012723080017 | W39: =V39=J39 -> TRUE | X39: BMUSOMRX | Y39: =X39=L39 -> TRUE
A40: 166 | B40: 1786 | C40: SUHAIL MOHAMMED ALI AL NUBI AL KATHIRI | D40: 314 | E40: 0.4 | F40: =D40*E40 -> 125.6 | G40: =121.25+4.35 -> 125.6 | H40: =F40-G40 -> 0 | I40: 5614637 | J40: 0406012235220015 | K40: Bank Muscat | L40: BMUSOMRX | M40: 92924645 | N40: 45567 | O40: 45686 | P40: 1786 | Q40: =P40=B40 -> TRUE | R40: SUHAIL MOHAMMED ALI AL NUBI AL KATHIRI | S40: =R40=C40 -> TRUE | T40: 5614637 | U40: =T40=I40 -> TRUE | V40: 0406012235220015 | W40: =V40=J40 -> TRUE | X40: BMUSOMRX | Y40: =X40=L40 -> TRUE
...

Sheet center-July
A1: Milk Chilling Centre(Ghado) - Monthly Camel Milk Procurement Report - 01-07-2024 TO 31-07-2024
A2: SR. NO. | B2: Farmer Code | C2: Farmer Name | D2: Total Quantity Supplied(Lits) | E2: Camel Milk Price/Lit(OMR) | F2: Total Value Milk (OMR) | G2: Paid | H2: Balance | I2: ID No: | J2: Account No | K2: Bank Name | L2: BANK SWIFT CODE | M2: Phone No: | N2: Remarks
A3: 1 | B3: 1001 | C3: Abdul Hakim Musallam Salim Al Katini Al Rawas | D3: 340.5 | E3: 0.4 | F3: =D3*E3 -> 136.2 | G3: =F3 -> 136.2 | H3: =F3-G3 -> 0 | I3: 2130934 | J3: 0397020829680019 | K3: Bank Muscat | L3: BMUSOMRX | M3: 92911133
A4: 2 | B4: 1007 | C4: Ahmed Abdullah Said Al Rawas | D4: 1844 | E4: 0.4 | F4: =D4*E4 -> 737.6 | G4: =736.13+1.47 -> 737.6 | H4: =F4-G4 -> 0 | I4: 1515504 | J4: 3109147237500 | K4: Oman Arab Bank | L4: OMABOMRU | M4: 91748840 | N4: 45595 | O4: 45614
A5: 3 | B5: 1028 | C5: Ahmed Saeed Maatouq Al kathiri | D5: 400.3 | E5: 0.4 | F5: =D5*E5 -> 160.12 | G5: =160.05+0.07 -> 160.12 | H5: =F5-G5 -> 0 | I5: 802875 | J5: 0397004247250014 | K5: Bank Muscat | L5: BMUSOMRX | M5: 99498677 | N5: 45593
A6: 4 | B6: 1033 | C6: Ahmed Said Ali Al Nobi Al Kathiri | D6: 810 | E6: 0.4 | F6: =D6*E6 -> 324 | G6: =319.28+4.72 -> 324 | H6: =F6-G6 -> 0 | I6: 10132435 | J6: 01011076521002 | K6: Bank Dhofar | L6: BDOFOMRU | M6: 92268168 | N6: CHANGE THE ACCOUNT | O6: 45567 | P6: 45601
A7: 5 | B7: 1040 | C7: Ahmed Said Mahad Jamaan Dhishil al Kathiri | D7: 331 | E7: 0.4 | F7: =D7*E7 -> 132.4 | G7: =F7 -> 132.4 | H7: =F7-G7 -> 0 | I7: 25082374 | J7: 0406041201480018 | K7: Bank Muscat | L7: BMUSOMRX | M7: 99816344
A8: 6 | B8: 1044 | C8: Ahmed Salim Ahmed Al Hadi Baomar | D8: 405 | E8: 0.4 | F8: =D8*E8 -> 162 | G8: =F8 -> 162 | H8: =F8-G8 -> 0 | I8: 81904 | J8: 0406003182770027 | K8: Bank Muscat | L8: BMUSOMRX | M8: 99494120
A9: 7 | B9: 1080 | C9: Ali Saeed Matoq Alkthiri | D9: 354.1 | E9: 0.4 | F9: =D9*E9 -> 141.64 | G9: =F9 -> 141.64 | H9: =F9-G9 -> 0 | I9: 78762 | J9: 0397004237620018 | K9: Bank Muscat | L9: BMUSOMRX | M9: 92440088
A10: 8 | B10: 1089 | C10: Ali Said Nasib | D10: 641 | E10: 0.4 | F10: =D10*E10 -> 256.4 | G10: =F10 -> 256.4 | H10: =F10-G10 -> 0 | I10: 892683 | J10: 1023281341086 | K10: NBO | L10: NBOMOMRX | M10: 99506162
A11: 9 | B11: 1096 | C11: Ali Salim Awadh Al Kathiri | D11: 607.9 | E11: 0.4 | F11: =D11*E11 -> 243.16 | G11: =242.43+0.73 -> 243.16 | H11: =F11-G11 -> 0 | I11: 1959918 | J11: 3109647718500 | K11: Oman Arab Bank | L11: OMABOMRU | M11: 92699781 | N11: 45593 | O11: 45609
A12: 10 | B12: 1106 | C12: Badar Said Masood Al Kathiri | D12: 1188 | E12: 0.4 | F12: =D12*E12 -> 475.2 | G12: =F12 -> 475.2 | H12: =F12-G12 -> 0 | I12: 5502751 | J12: 10060192223001 | K12: NBO | L12: NBOMOMRX | M12: 99270001
A13: 11 | B13: 1110 | C13: Bakhit Salim Azad Al Kathiri | D13: 621 | E13: 0.4 | F13: =D13*E13 -> 248.4 | G13: =F13 -> 248.4 | H13: =F13-G13 -> 0 | I13: 934298 | J13: 0406003101920011 | K13: Bank Muscat | L13: BMUSOMRX | M13: 92811415 | N13: 45607
A14: 12 | B14: 1111 | C14: Bakhit Salim Ali Shadar Al Kathiri | D14: 711 | E14: 0.4 | F14: =D14*E14 -> 284.4 | G14: =F14 -> 284.4 | H14: =F14-G14 -> 0 | I14: 15571992 | J14: 01011058653001 | K14: Bank Dhofar | L14: BDOFOMRU | M14: 92708951
A15: 13 | B15: 1119 | C15: Ghanim Abdul Aziz Masoud Abdul Aziz Alash Al Kathiri | D15: 510 | E15: 0.4 | F15: =D15*E15 -> 204 | G15: =F15 -> 204 | H15: =F15-G15 -> 0 | I15: 24000245 | J15: 0397020978260014 | K15: Bank Muscat | L15: BMUSOMRX | M15: 90911369
A16: 14 | B16: 1122 | C16: Hamed Hilal Said Al Kathiri | D16: 367.7 | E16: 0.4 | F16: =D16*E16 -> 147.08 | G16: =F16 -> 147.08 | H16: =F16-G16 -> 0 | I16: 5219876 | J16: 0406045268200015 | K16: Bank Muscat | L16: BMUSOMRX | M16: 99066779 | N16: 45621
A17: 15 | B17: 1135 | C17: Khalid Said Ali Al Kathiri | D17: 729 | E17: 0.4 | F17: =D17*E17 -> 291.6 | G17: =290.07+1.53 -> 291.6 | H17: =F17-G17 -> 0 | I17: 19202954 | J17: 01013808698001 | K17: Bank Dhofar | L17: BDOFOMRU | M17: 92771786 | N17: 45601 | O17: 45628
A18: 16 | B18: 1141 | C18: Malik Said Ahmed Habkook Hat Al Shahri | D18: 746.7 | E18: 0.4 | F18: =D18*E18 -> 298.68 | G18: =298.14+0.54 -> 298.68 | H18: =F18-G18 -> 0 | I18: 11753992 | J18: 0396051591490029 | K18: Bank Muscat | L18: BMUSOMRX | M18: 99205960 | N18: 45575 | O18: 45609
A19: 17 | B19: 1154 | C19: Mohammed Salim Abdullah Al kathiri | D19: 1058.1 | E19: 0.4 | F19: =D19*E19 -> 423.24 | G19: =F19 -> 423.24 | H19: =F19-G19 -> 0 | I19: 18654817 | J19: 0439053703720016 | K19: Bank Muscat | L19: BMUSOMRX | M19: 98887846
A20: 18 | B20: 1161 | C20: Mohammed Ali Musallam Al Nubi Al Kathiri | D20: 405 | E20: 0.4 | F20: =D20*E20 -> 162 | G20: =160.05+1.95 -> 162 | H20: =F20-G20 -> 0 | I20: 257926 | J20: 3109603718500 | K20: Oman Arab Bank | L20: OMABOMRU | M20: 99589267 | N20: 45601 | O20: 45718
A21: 19 | B21: 1168 | C21: Mohammed Salim Said Jumaa Al Kathiri | D21: 645 | E21: 0.4 | F21: =D21*E21 -> 258 | G21: =F21 -> 258 | H21: =F21-G21 -> 0 | I21: 15498714 | J21: 00510097414001 | K21: Bank Nizwa | L21: BNZWOMRX | M21: 99292524
A22: 20 | B22: 1177 | C22: Said Salim Said BaitSaid | D22: 430 | E22: 0.4 | F22: =D22*E22 -> 172 | G22: =F22 -> 172 | H22: =F22-G22 -> 0 | I22: 219353 | J22: 01010127872001 | K22: Bank Dhofar | L22: BDOFOMRU | M22: 99485534
A23: 21 | B23: 1178 | C23: Mohammed Said Mohammed Akdha Al Rawas | D23: 753.5 | E23: 0.4 | F23: =D23*E23 -> 301.4 | G23: =296.86+4.54 -> 301.4 | H23: =F23-G23 -> 0 | I23: 970872 | J23: 1006123229017 | K23: NBO | L23: NBOMOMRX | M23: 99485535 | N23: 45567 | O23: 45607
A24: 22 | B24: 1224 | C24: Naif Masoud Awadh Nasib Kikab Al Shihri | D24: 827.1 | E24: 0.4 | F24: =D24*E24 -> 330.84 | G24: =329.8+1.04 -> 330.84 | H24: =F24-G24 -> 0 | I24: 24911691 | J24: 0406060856030017 | K24: Bank Muscat | L24: BMUSOMRX | M24: 99192216 | N24: 45595 | O24: 45644
A25: 23 | B25: 1225 | C25: Naif Said Awadh Fadhl | D25: 586.9 | E25: 0.4 | F25: =D25*E25 -> 234.76 | G25: =F25 -> 234.76 | H25: =F25-G25 -> 0 | I25: 9642357 | J25: 1501079705330 | K25: Ahli bank | L25: AUBOOMRU | M25: 99777877
A26: 24 | B26: 1235 | C26: Saeed Abdul Aziz Abdullah Al kathiri | D26: 783 | E26: 0.4 | F26: =D26*E26 -> 313.2 | G26: =312.66+0.54 -> 313.2 | H26: =F26-G26 -> 0 | I26: 1992436 | J26: 0402003122620013 | K26: BANK MUSCAT | L26: BMUSOMRX | M26: 99484668 | N26: 45586
A27: 25 | B27: 1241 | C27: Said Mohammed Abdallah Al kathiri | D27: 652.2 | E27: 0.4 | F27: =D27*E27 -> 260.88 | G27: =258.07+2.81 -> 260.88 | H27: =F27-G27 -> 0 | I27: 5343254 | J27: 0406003410830019 | K27: Bank Muscat | L27: BMUSOMRX | M27: 98964664 | N27: 45567 | O27: 11/11/2024 - 13-11-2024
A28: 26 | B28: 1247 | C28: Said Salim Azad Bait Ali Badar | D28: 648 | E28: 0.4 | F28: =D28*E28 -> 259.2 | G28: =259.05+0.15 -> 259.2 | H28: =F28-G28 -> 0 | I28: 4748561 | J28: 01040280570002 | K28: Bank Dhofar | L28: BDOFOMRU | M28: 92345282 | N28: 45637 | O28: 45644
A29: 27 | B29: 1252 | C29: Said Ahmed Ali Bait Said | D29: 594 | E29: 0.4 | F29: =D29*E29 -> 237.6 | G29: =F29 -> 237.6 | H29: =F29-G29 -> 0 | I29: 2433959 | J29: 01010120819002 | K29: Bank Dhofar | L29: BDOFOMRU | M29: 93555999
A30: 28 | B30: 1258 | C30: Said Ali Musallam Al Noubi Al Kathiri | D30: 810 | E30: 0.4 | F30: =D30*E30 -> 324 | G30: =F30 -> 324 | H30: =F30-G30 -> 0 | I30: 1924174 | J30: 01040280044001 | K30: Bank Dhofar | L30: BDOFOMRU | M30: 99297990
A31: 29 | B31: 1260 | C31: Said Salim Ali Kibab Al Shahri | D31: 756 | E31: 0.4 | F31: =D31*E31 -> 302.4 | G31: =299.43+2.97 -> 302.4 | H31: =F31-G31 -> 0 | I31: 18363579 | J31: 01041057246001 | K31: Bank Dhofar | L31: BDOFOMRU | M31: 98217444 | N31: 45595 | O31: 45621
A32: 30 | B32: 1261 | C32: Said Ali Nasib Kikab Al shahri | D32: 423.5 | E32: 0.4 | F32: =D32*E32 -> 169.4 | G32: =168.68+0.72 -> 169.4 | H32: =F32-G32 -> 0 | I32: 14429332 | J32: 0439018203570018 | K32: Bank Muscat | L32: BMUSOMRX | M32: 92939445 | N32: 45607 | O32: 45623
A33: 31 | B33: 1268 | C33: Said Musallam Ali Ghawas | D33: 540 | E33: 0.4 | F33: =D33*E33 -> 216 | G33: =212.58+3.42 -> 216 | H33: =F33-G33 -> 0 | I33: 722058 | J33: 0397003940070023 | K33: Bank Muscat | L33: BMUSOMRX | M33: 92848609 | N33: 45573 | O33: 45600
A34: 32 | B34: 1282 | C34: Salim Ali Musallam Al Noubi Al Kathiri | D34: 702 | E34: 0.4 | F34: =D34*E34 -> 280.8 | G34: =F34 -> 280.8 | H34: =F34-G34 -> 0 | I34: 2997747 | J34: 3109601542500 | K34: Oman Arab Bank | L34: OMABOMRU | M34: 92660969 | N34: Bank transfer-04-11-2024
A35: 33 | B35: 1284 | C35: Salim Ali Said Al Nubi Al Kathiri | D35: 702 | E35: 0.4 | F35: =D35*E35 -> 280.8 | G35: =280.45+0.35 -> 280.8 | H35: =F35-G35 -> 0 | I35: 1177598 | J35: 01040280595001 | K35: Bank Dhofar | L35: BDOFOMRU | M35: 92825228 | N35: 45573 | O35: 45602
A36: 34 | B36: 1300 | C36: Salem Suhail Omer Bit Fhadel | D36: 862.2 | E36: 0.4 | F36: =D36*E36 -> 344.88 | G36: =F36 -> 344.88 | H36: =F36-G36 -> 0 | I36: 19534277 | J36: 0439016892350027 | K36: Bank Muscat | L36: BMUSOMRX | M36: 99710505
A37: 35 | B37: 1306 | C37: Salim Ali Nasib Al Kathiri | D37: 428.4 | E37: 0.4 | F37: =D37*E37 -> 171.36 | G37: =168.53+2.83 -> 171.36 | H37: =F37-G37 -> 0 | I37: 2006904 | J37: 0439051845390018 | K37: Bank Muscat | L37: BMUSOMRX | M37: 96137717 | N37: 45600
A38: 36 | B38: 1315 | C38: Salim Said Ali Ghawas | D38: 367.4 | E38: 0.4 | F38: =D38*E38 -> 146.96 | G38: =F38 -> 146.96 | H38: =F38-G38 -> 0 | I38: 19528845 | J38: 0439026234320047 | K38: Bank Muscat | L38: BMUSOMRX | M38: 92432606
A39: 37 | B39: 1328 | C39: Suhail Saeed Suhail ghawas | D39: 482.7 | E39: 0.4 | F39: =D39*E39 -> 193.08 | G39: =F39 -> 193.08 | H39: =F39-G39 -> 0 | I39: 782833 | J39: 01015382117001 | K39: Bank Dhofar | L39: BDOFOMRU | M39: 92475895 | N39: 45601
A40: 38 | B40: 1330 | C40: Said Mahad Ali Al Kathiri | D40: 738 | E40: 0.4 | F40: =D40*E40 -> 295.2 | G40: =F40 -> 295.2 | H40: =F40-G40 -> 0 | I40: 12194826 | J40: 00510129167001 | K40: Bank Nizwa | L40: BNZWOMRX | M40: 91299100
...

Sheet center-Aug
A1: Milk Chilling Centre(Ghado) - Monthly Camel Milk Procurement Report - 01-08-2024 TO 31-08-2024
A2: SR. NO. | B2: Farmer Code | D2: Total Quantity Supplied(Lits) | E2: Camel Milk Price/Lit(OMR) | F2: Total Value Milk (OMR) | I2: ID No: | J2: Remarks
A3: 1 | B3: 1001 | C3: Abdul Hakim Musallam Salim Al Katini Al Rawas | D3: 295.6 | E3: 0.4 | F3: =D3*E3 -> 118.24 | G3: =F3 -> 118.24 | H3: =F3-G3 -> 0 | I3: 2130934 | J3: BT-19-12-24
A4: 2 | B4: 1007 | C4: Ahmed Abdullah Said Al Rawas | D4: 1775 | E4: 0.4 | F4: =D4*E4 -> 710 | G4: =704.78+5.22 -> 710 | H4: =F4-G4 -> 0 | I4: 1515504 | J4: 45614 | K4: 45630
A5: 3 | B5: 1028 | C5: Ahmed Saeed Maatouq Al kathiri | D5: 347.5 | E5: 0.4 | F5: =D5*E5 -> 139 | G5: =F5 -> 139 | H5: =F5-G5 -> 0 | I5: 802875
A6: 4 | B6: 1033 | C6: Ahmed Said Ali Al Nobi Al Kathiri | D6: 745.8 | E6: 0.4 | F6: =D6*E6 -> 298.32 | G6: =295.98+2.34 -> 298.32 | H6: =F6-G6 -> 0 | I6: 10132435 | J6: 45601 | K6: 45621
A7: 5 | B7: 1040 | C7: Ahmed Said Mahad Jamaan Dhishil al Kathiri | D7: 325 | E7: 0.4 | F7: =D7*E7 -> 130 | G7: =F7 -> 130 | H7: =F7-G7 -> 0 | I7: 25082374 | J7: 45684
A8: 6 | B8: 1044 | C8: Ahmed Salim Ahmed Al Hadi Baomar | D8: 365 | E8: 0.4 | F8: =D8*E8 -> 146 | G8: =145.5 -> 145.5 | H8: =F8-G8 -> 0.5 | I8: 81904 | J8: 45810
A9: 7 | B9: 1080 | C9: Ali Saeed Matoq Alkthiri | D9: 315.4 | E9: 0.4 | F9: =D9*E9 -> 126.16 | G9: =F9 -> 126.16 | H9: =F9-G9 -> 0 | I9: 78762
A10: 8 | B10: 1089 | C10: Ali Said Nasib | D10: 572.1 | E10: 0.4 | F10: =D10*E10 -> 228.84 | G10: =F10 -> 228.84 | H10: =F10-G10 -> 0 | I10: 892683 | J10: 45644
A11: 9 | B11: 1096 | C11: Ali Salim Awadh Al Kathiri | D11: 483.1 | E11: 0.4 | F11: =D11*E11 -> 193.24 | G11: =192.97+0.27 -> 193.24 | H11: =F11-G11 -> 0 | I11: 1959918 | J11: 45609 | K11: 45623
A12: 10 | B12: 1106 | C12: Badar Said Masood Al Kathiri | D12: 1100 | E12: 0.4 | F12: =D12*E12 -> 440 | G12: =F12 -> 440 | H12: =F12-G12 -> 0 | I12: 5502751
A13: 11 | B13: 1110 | C13: Bakhit Salim Azad Al Kathiri | D13: 575 | E13: 0.4 | F13: =D13*E13 -> 230 | G13: =226.9+3.1 -> 230 | H13: =F13-G13 -> 0 | I13: 934298 | J13: 45607 | K13: 45628
A14: 12 | B14: 1111 | C14: Bakhit Salim Ali Shadar Al Kathiri | D14: 662 | E14: 0.4 | F14: =D14*E14 -> 264.8 | G14: =F14 -> 264.8 | H14: =F14-G14 -> 0 | I14: 15571992
A15: 13 | B15: 1119 | C15: Ghanim Abdul Aziz Masoud Abdul Aziz Alash Al Kathiri | D15: 305.1 | E15: 0.4 | F15: =D15*E15 -> 122.04 | G15: =F15 -> 122.04 | H15: =F15-G15 -> 0 | I15: 24000245
A16: 14 | B16: 1122 | C16: Hamed Hilal Said Al Kathiri | D16: 348.3 | E16: 0.4 | F16: =D16*E16 -> 139.32 | G16: =138.65+0.67 -> 139.32 | H16: =F16-G16 -> 0 | I16: 5219876 | J16: 45621 | K16: 45643
A17: 15 | B17: 1135 | C17: Khalid Said Ali Al Kathiri | D17: 674.2 | E17: 0.4 | F17: =D17*E17 -> 269.68 | G17: =F17 -> 269.68 | H17: =F17-G17 -> 0 | I17: 19202954 | J17: 45628
A18: 16 | B18: 1141 | C18: Malik Said Ahmed Habkook Hat Al Shahri | D18: 593.1 | E18: 0.4 | F18: =D18*E18 -> 237.24 | G18: =237.11+0.13 -> 237.24 | H18: =F18-G18 -> 0 | I18: 11753992 | J18: 45609 | K18: 45644
A19: 17 | B19: 1154 | C19: Mohammed Salim Abdullah Al kathiri | D19: 938.2 | E19: 0.4 | F19: =D19*E19 -> 375.28 | G19: =F19 -> 375.28 | H19: =F19-G19 -> 0 | I19: 18654817
A20: 18 | B20: 1161 | C20: Mohammed Ali Musallam Al Nubi Al Kathiri | D20: 374.5 | E20: 0.4 | F20: =D20*E20 -> 149.8 | G20: =149.8 -> 149.8 | H20: =F20-G20 -> 0 | I20: 257926 | J20: 45691
A21: 19 | B21: 1168 | C21: Mohammed Salim Said Jumaa Al Kathiri | D21: 581.5 | E21: 0.4 | F21: =D21*E21 -> 232.6 | G21: =F21 -> 232.6 | H21: =F21-G21 -> 0 | I21: 15498714 | J21: 45691
A22: 20 | B22: 1177 | C22: Said Salim Said BaitSaid | D22: 399 | E22: 0.4 | F22: =D22*E22 -> 159.6 | G22: =F22 -> 159.6 | H22: =F22-G22 -> 0 | I22: 219353
A23: 21 | B23: 1178 | C23: Mohammed Said Mohammed Akdha Al Rawas | D23: 629.4 | E23: 0.4 | F23: =D23*E23 -> 251.76 | G23: =247.66+4.1 -> 251.76 | H23: =F23-G23 -> 0 | I23: 970872 | J23: 45607 | K23: 45656
A24: 22 | B24: 1224 | C24: Naif Masoud Awadh Nasib Kikab Al Shihri | D24: 743 | E24: 0.4 | F24: =D24*E24 -> 297.2 | G24: =294.81+2.39 -> 297.2 | H24: =F24-G24 -> 0 | I24: 24911691 | J24: 45644 | K24: 098-01-25
A25: 23 | B25: 1225 | C25: Naif Said Awadh Fadhl | D25: 610.5 | E25: 0.4 | F25: =D25*E25 -> 244.2 | G25: =F25 -> 244.2 | H25: =F25-G25 -> 0 | I25: 9642357
A26: 24 | B26: 1235 | C26: Saeed Abdul Aziz Abdullah Al kathiri | D26: 714 | E26: 0.4 | F26: =D26*E26 -> 285.6 | G26: =F26 -> 285.6 | H26: =F26-G26 -> 0 | I26: 1992436 | J26: 45609
A27: 25 | B27: 1241 | C27: Said Mohammed Abdallah Al kathiri | D27: 621.8 | E27: 0.4 | F27: =D27*E27 -> 248.72 | G27: =245.09+3.63 -> 248.72 | H27: =F27-G27 -> 0 | I27: 5343254 | J27: 45607 | K27: 45628
A28: 26 | B28: 1247 | C28: Said Salim Azad Bait Ali Badar | D28: 600 | E28: 0.4 | F28: =D28*E28 -> 240 | G28: =237.5+2.5 -> 240 | H28: =F28-G28 -> 0 | I28: 4748561 | J28: 45644 | K28: 45650
A29: 27 | B29: 1252 | C29: Said Ahmed Ali Bait Said | D29: 550 | E29: 0.4 | F29: =D29*E29 -> 220 | G29: =F29 -> 220 | H29: =F29-G29 -> 0 | I29: 2433959
A30: 28 | B30: 1258 | C30: Said Ali Musallam Al Noubi Al Kathiri | D30: 792 | E30: 0.4 | F30: =D30*E30 -> 316.8 | G30: =F30 -> 316.8 | H30: =F30-G30 -> 0 | I30: 1924174 | J30: 45644
A31: 29 | B31: 1260 | C31: Said Salim Ali Kibab Al Shahri | D31: 672 | E31: 0.4 | F31: =D31*E31 -> 268.8 | G31: =268.63+0.17 -> 268.8 | H31: =F31-G31 -> 0 | I31: 18363579 | J31: 45621 | K31: 45628
A32: 30 | B32: 1261 | C32: Said Ali Nasib Kikab Al shahri | D32: 380.7 | E32: 0.4 | F32: =D32*E32 -> 152.28 | G32: =149.63+2.65 -> 152.28 | H32: =F32-G32 -> 0 | I32: 14429332 | J32: 45623 | K32: 45637
A33: 31 | B33: 1268 | C33: Said Musallam Ali Ghawas | D33: 500 | E33: 0.4 | F33: =D33*E33 -> 200 | G33: =F33 -> 200 | H33: =F33-G33 -> 0 | I33: 722058 | J33: 45601
A34: 32 | B34: 1282 | C34: Salim Ali Musallam Al Noubi Al Kathiri | D34: 675 | E34: 0.4 | F34: =D34*E34 -> 270 | G34: =F34 -> 270 | H34: =F34-G34 -> 0 | I34: 2997747 | J34: 45621
A35: 33 | B35: 1284 | C35: Salim Ali Said Al Nubi Al Kathiri | D35: 648.5 | E35: 0.4 | F35: =D35*E35 -> 259.4 | G35: =256.7+2.7 -> 259.4 | H35: =F35-G35 -> 0 | I35: 1177598 | J35: 45602 | K35: 45635
A36: 34 | B36: 1300 | C36: Salem Suhail Omer Bit Fhadel | D36: 800 | E36: 0.4 | F36: =D36*E36 -> 320 | G36: =F36 -> 320 | H36: =F36-G36 -> 0 | I36: 19534277
A37: 35 | B37: 1306 | C37: Salim Ali Nasib Al Kathiri | D37: 393.8 | E37: 0.4 | F37: =D37*E37 -> 157.52 | G37: =157.22+0.3 -> 157.52 | H37: =F37-G37 -> 0 | I37: 2006904 | J37: 45600 | K37: 45630
A38: 36 | B38: 1315 | C38: Salim Said Ali Ghawas | D38: 336.2 | E38: 0.4 | F38: =D38*E38 -> 134.48 | G38: =F38 -> 134.48 | H38: =F38-G38 -> 0 | I38: 19528845
A39: 37 | B39: 1328 | C39: Suhail Saeed Suhail ghawas | D39: 438.2 | E39: 0.4 | F39: =D39*E39 -> 175.28 | G39: =172.56+2.72 -> 175.28 | H39: =F39-G39 -> 0 | I39: 782833 | J39: 45601 | K39: 45628
A40: 38 | B40: 1330 | C40: Said Mahad Ali Al Kathiri | D40: 646.2 | E40: 0.4 | F40: =D40*E40 -> 258.48 | G40: =F40 -> 258.48 | H40: =F40-G40 -> 0 | I40: 12194826 | J40: BT-29-01-25
...

Sheet center-Sept
A1: Milk Chilling Centre(Ghado) - Monthly Camel Milk Procurement Report - 01-09-2024 TO 30-09-2024
A2: SR. NO. | B2: Farmer Code | C2: Farmer Name | D2: Total Quantity Supplied(Lits) | E2: Camel Milk Price/Lit(OMR) | F2: Total Value Milk (OMR) | G2: Paid | H2: Balance | I2: ID No: | J2: Remarks
A3: 1 | B3: 1001 | C3: Abdul Hakim Musallam Salim Al Katini Al Rawas | D3: 263.5 | E3: 0.4 | F3: =D3*E3 -> 105.4 | G3: =F3 -> 105.4 | H3: =F3-G3 -> 0 | I3: 2130934 | J3: 45672
A4: 2 | B4: 1007 | C4: Ahmed Abdullah Said Al Rawas | D4: 1547.5 | E4: 0.4 | F4: =D4*E4 -> 619 | G4: =613.53+5.47 -> 619 | H4: =F4-G4 -> 0 | I4: 1515504 | J4: 45630 | K4: 45650
A5: 3 | B5: 1028 | C5: Ahmed Saeed Maatouq Al kathiri | D5: 284 | E5: 0.4 | F5: =D5*E5 -> 113.6 | H5: =F5-G5 -> 113.6 | I5: 802875
A6: 4 | B6: 1033 | C6: Ahmed Said Ali Al Nobi Al Kathiri | D6: 660 | E6: 0.4 | F6: =D6*E6 -> 264 | G6: =F6 -> 264 | H6: =F6-G6 -> 0 | I6: 10132435 | J6: 45622 | K6: .41 deduct from oct
A7: 5 | B7: 1040 | C7: Ahmed Said Mahad Jamaan Dhishil al Kathiri | D7: 283.5 | E7: 0.4 | F7: =D7*E7 -> 113.4 | G7: =0.95 -> 0.95 | H7: =F7-G7 -> 112.45 | I7: 25082374 | J7: 45684
A8: 6 | B8: 1044 | C8: Ahmed Salim Ahmed Al Hadi Baomar | D8: 328.8 | E8: 0.4 | F8: =D8*E8 -> 131.52 | H8: =F8-G8 -> 131.52 | I8: 81904
A9: 7 | B9: 1080 | C9: Ali Saeed Matoq Alkthiri | D9: 301.5 | E9: 0.4 | F9: =D9*E9 -> 120.6 | G9: =F9 -> 120.6 | H9: =F9-G9 -> 0 | I9: 78762 | J9: 45963
A10: 8 | B10: 1089 | C10: Ali Said Nasib | D10: 491.5 | E10: 0.4 | F10: =D10*E10 -> 196.6 | G10: =193.11+3.49 -> 196.6 | H10: =F10-G10 -> 0 | I10: 892683 | J10: 45644 | K10: 45686
A11: 9 | B11: 1096 | C11: Ali Salim Awadh Al Kathiri | D11: 393.4 | E11: 0.4 | F11: =D11*E11 -> 157.36 | G11: =154.63+2.73 -> 157.36 | H11: =F11-G11 -> 0 | I11: 1959918 | J11: 45623 | K11: 45658
A12: 10 | B12: 1106 | C12: Badar Said Masood Al Kathiri | D12: 968 | E12: 0.4 | F12: =D12*E12 -> 387.2 | H12: =F12-G12 -> 387.2 | I12: 5502751
A13: 11 | B13: 1110 | C13: Bakhit Salim Azad Al Kathiri | D13: 498 | E13: 0.4 | F13: =D13*E13 -> 199.2 | G13: =195.75+3.45 -> 199.2 | H13: =F13-G13 -> 0 | I13: 934298 | J13: 45628 | K13: 45658
A14: 12 | B14: 1111 | C14: Bakhit Salim Ali Shadar Al Kathiri | D14: 574.7 | E14: 0.4 | F14: =D14*E14 -> 229.88 | H14: =F14-G14 -> 229.88 | I14: 15571992
A15: 13 | B15: 1119 | C15: Ghanim Abdul Aziz Masoud Abdul Aziz Alash Al Kathiri | D15: 246.5 | E15: 0.4 | F15: =D15*E15 -> 98.6 | H15: =F15-G15 -> 98.6 | I15: 24000245
A16: 14 | B16: 1122 | C16: Hamed Hilal Said Al Kathiri | D16: 306.5 | E16: 0.4 | F16: =D16*E16 -> 122.6 | G16: =120.58+2.02 -> 122.6 | H16: =F16-G16 -> 0 | I16: 5219876 | J16: 45643 | K16: 45658
A17: 15 | B17: 1135 | C17: Khalid Said Ali Al Kathiri | D17: 591.6 | E17: 0.4 | F17: =D17*E17 -> 236.64 | G17: =0.39+232.8+3.45 -> 236.64 | H17: =F17-G17 -> 0 | I17: 19202954 | J17: 45628 | K17: 45643 | L17: 45665
A18: 16 | B18: 1141 | C18: Malik Said Ahmed Habkook Hat Al Shahri | D18: 523.8 | E18: 0.4 | F18: =D18*E18 -> 209.52 | G18: =208.42+1.1 -> 209.52 | H18: =F18-G18 -> 0 | I18: 11753992 | J18: 45644 | K18: 45658
A19: 17 | B19: 1154 | C19: Mohammed Salim Abdullah Al kathiri | D19: 800 | E19: 0.4 | F19: =D19*E19 -> 320 | H19: =F19-G19 -> 320 | I19: 18654817
A20: 18 | B20: 1161 | C20: Mohammed Ali Musallam Al Nubi Al Kathiri | D20: 330 | E20: 0.4 | F20: =D20*E20 -> 132 | G20: =129.55+2.45 -> 132 | H20: =F20-G20 -> 0 | I20: 257926 | J20: 45691 | K20: 45810
A21: 19 | B21: 1168 | C21: Mohammed Salim Said Jumaa Al Kathiri | D21: 525.2 | E21: 0.4 | F21: =D21*E21 -> 210.08 | G21: =F21 -> 210.08 | H21: =F21-G21 -> 0 | I21: 15498714 | J21: 45691
A22: 20 | B22: 1177 | C22: Said Salim Said BaitSaid | D22: 336 | E22: 0.4 | F22: =D22*E22 -> 134.4 | H22: =F22-G22 -> 134.4 | I22: 219353
A23: 21 | B23: 1178 | C23: Mohammed Said Mohammed Akdha Al Rawas | D23: 585.6 | E23: 0.4 | F23: =D23*E23 -> 234.24 | G23: =233.55+0.69 -> 234.24 | H23: =F23-G23 -> 0 | I23: 970872 | J23: 45656 | K23: 45664
A24: 22 | B24: 1224 | C24: Naif Masoud Awadh Nasib Kikab Al Shihri | D24: 678.5 | E24: 0.4 | F24: =D24*E24 -> 271.4 | G24: =269.21+2.19 -> 271.4 | H24: =F24-G24 -> 0 | I24: 24911691 | J24: 45665 | K24: 45686
A25: 23 | B25: 1225 | C25: Naif Said Awadh Fadhl | D25: 563.2 | E25: 0.4 | F25: =D25*E25 -> 225.28 | H25: =F25-G25 -> 225.28 | I25: 9642357
A26: 24 | B26: 1235 | C26: Saeed Abdul Aziz Abdullah Al kathiri | D26: 607.3 | E26: 0.4 | F26: =D26*E26 -> 242.92 | G26: =242.55 -> 242.55 | H26: =F26-G26 -> 0.37 | I26: 1992436 | J26: 45658
A27: 25 | B27: 1241 | C27: Said Mohammed Abdallah Al kathiri | D27: 548.6 | E27: 0.4 | F27: =D27*E27 -> 219.44 | G27: =218.87+0.57 -> 219.44 | H27: =F27-G27 -> 0 | I27: 5343254 | J27: 45628 | K27: 45645
A28: 26 | B28: 1247 | C28: Said Salim Azad Bait Ali Badar | D28: 528 | E28: 0.4 | F28: =D28*E28 -> 211.2 | G28: =210.9+0.3 -> 211.2 | H28: =F28-G28 -> 0 | I28: 4748561 | J28: 45650 | K28: 45665
A29: 27 | B29: 1252 | C29: Said Ahmed Ali Bait Said | D29: 478.5 | E29: 0.4 | F29: =D29*E29 -> 191.4 | H29: =F29-G29 -> 191.4 | I29: 2433959
A30: 28 | B30: 1258 | C30: Said Ali Musallam Al Noubi Al Kathiri | D30: 683.3 | E30: 0.4 | F30: =D30*E30 -> 273.32 | G30: =269.53+3.79 -> 273.32 | H30: =F30-G30 -> 0 | I30: 1924174 | J30: 45644 | K30: 45658
A31: 29 | B31: 1260 | C31: Said Salim Ali Kibab Al Shahri | D31: 616 | E31: 0.4 | F31: =D31*E31 -> 246.4 | G31: =F31 -> 246.4 | H31: =F31-G31 -> 0 | I31: 18363579 | J31: 45628 | L31: .030 deduct from oct 2024
A32: 30 | B32: 1261 | C32: Said Ali Nasib Kikab Al shahri | D32: 333.9 | E32: 0.4 | F32: =D32*E32 -> 133.56 | G32: =133.15+0.41 -> 133.56 | H32: =F32-G32 -> 0 | I32: 14429332 | J32: 45637 | K32: 45658
A33: 31 | B33: 1268 | C33: Said Musallam Ali Ghawas | D33: 440 | E33: 0.4 | F33: =D33*E33 -> 176 | G33: =F33 -> 176 | H33: =G33-F33 -> 0 | I33: 722058 | J33: 109-05-11-24
A34: 32 | B34: 1282 | C34: Salim Ali Musallam Al Noubi Al Kathiri | D34: 594 | E34: 0.4 | F34: =D34*E34 -> 237.6 | G34: =234.4+3.2 -> 237.6 | H34: =F34-G34 -> 0 | I34: 2997747 | J34: 45621 | K34: 45656
A35: 33 | B35: 1284 | C35: Salim Ali Said Al Nubi Al Kathiri | D35: 571.2 | E35: 0.4 | F35: =D35*E35 -> 228.48 | G35: =225.25+3.23 -> 228.48 | H35: =F35-G35 -> 0 | I35: 1177598 | J35: 45635 | K35: 45663
A36: 34 | B36: 1300 | C36: Salem Suhail Omer Bit Fhadel | D36: 666.1 | E36: 0.4 | F36: =D36*E36 -> 266.44 | H36: =F36-G36 -> 266.44 | I36: 19534277
A37: 35 | B37: 1306 | C37: Salim Ali Nasib Al Kathiri | D37: 344.7 | E37: 0.4 | F37: =D37*E37 -> 137.88 | G37: =135.5+2.38 -> 137.88 | H37: =F37-G37 -> 0 | I37: 2006904 | J37: 45630 | K37: 45663
A38: 36 | B38: 1315 | C38: Salim Said Ali Ghawas | D38: 285.5 | E38: 0.4 | F38: =D38*E38 -> 114.2 | H38: =F38-G38 -> 114.2 | I38: 19528845
A39: 37 | B39: 1328 | C39: Suhail Saeed Suhail ghawas | D39: 396.7 | E39: 0.4 | F39: =D39*E39 -> 158.68 | G39: =157.33+1.35 -> 158.68 | H39: =F39-G39 -> 0 | I39: 782833 | J39: 45628 | K39: 45658
A40: 38 | B40: 1330 | C40: Said Mahad Ali Al Kathiri | D40: 550.8 | E40: 0.4 | F40: =D40*E40 -> 220.32 | G40: =F40 -> 220.32 | H40: =F40-G40 -> 0 | I40: 12194826 | J40: 45810
...

Sheet Center-oct
A1: Milk Chilling Centre(Ghado) - Monthly Camel Milk Procurement Report - 01-10-2024 TO 31-10-2024
A2: SR. NO. | B2: Farmer Code | C2: Farmer Name | D2: Total Quantity Supplied(Lits) | E2: Camel Milk Price/Lit(OMR) | F2: Total Value (OMR) | G2: Paid | H2: Balance | I2: ID No: | J2: Remarks | K2: Remarks
A3: 1 | B3: 1001 | C3: Abdul Hakim Musallam Salim Al Katini Al Rawas | D3: 293.7 | E3: 0.4 | F3: =D3*E3 -> 117.48 | G3: =112.85+4.63 -> 117.48 | H3: =F3-G3 -> 0 | I3: 2130934 | J3: 45672 | K3: 45963
A4: 2 | B4: 1007 | C4: Ahmed Abdullah Said Al Rawas | D4: 1627.9 | E4: 0.4 | F4: =D4*E4 -> 651.16 | G4: =650.78+0.38 -> 651.16 | H4: =F4-G4 -> 0 | I4: 1515504 | J4: 45650 | K4: 45665
A5: 3 | B5: 1028 | C5: Ahmed Saeed Maatouq Al kathiri | D5: 290.8 | E5: 0.4 | F5: =D5*E5 -> 116.32 | H5: =F5-G5 -> 116.32 | I5: 802875
A6: 4 | B6: 1033 | C6: Ahmed Said Ali Al Nobi Al Kathiri | D6: 690 | E6: 0.4 | F6: =D6*E6 -> 276 | G6: =271.6+4.4 -> 276 | H6: =F6-G6 -> 0 | I6: 10132435 | J6: 45644 | K6: 45670
A7: 5 | B7: 1040 | C7: Ahmed Said Mahad Jamaan Dhishil al Kathiri | D7: 297 | E7: 0.4 | F7: =D7*E7 -> 118.8 | H7: =F7-G7 -> 118.8 | I7: 25082374
A8: 6 | B8: 1044 | C8: Ahmed Salim Ahmed Al Hadi Baomar | D8: 345 | E8: 0.4 | F8: =D8*E8 -> 138 | H8: =F8-G8 -> 138 | I8: 81904
A9: 7 | B9: 1080 | C9: Ali Saeed Matoq Alkthiri | D9: 315.3 | E9: 0.4 | F9: =D9*E9 -> 126.12 | G9: =121.9 -> 121.9 | H9: =F9-G9 -> 4.22 | I9: 78762 | J9: 45963
A10: 8 | B10: 1089 | C10: Ali Said Nasib | D10: 544 | E10: 0.4 | F10: =D10*E10 -> 217.6 | G10: =F10 -> 217.6 | H10: =F10-G10 -> 0 | I10: 892683 | J10: 45686
A11: 9 | B11: 1096 | C11: Ali Salim Awadh Al Kathiri | D11: 451.5 | E11: 0.4 | F11: =D11*E11 -> 180.6 | G11: =176.72+3.88 -> 180.6 | H11: =F11-G11 -> 0 | I11: 1959918 | J11: 45658 | K11: 45686
A12: 10 | B12: 1106 | C12: Badar Said Masood Al Kathiri | D12: 1012 | E12: 0.4 | F12: =D12*E12 -> 404.8 | H12: =F12-G12 -> 404.8 | I12: 5502751
A13: 11 | B13: 1110 | C13: Bakhit Salim Azad Al Kathiri | D13: 529 | E13: 0.4 | F13: =D13*E13 -> 211.6 | G13: =209.95+1.65 -> 211.6 | H13: =F13-G13 -> 0 | I13: 934298 | J13: 45658 | K13: 45679
A14: 12 | B14: 1111 | C14: Bakhit Salim Ali Shadar Al Kathiri | D14: 596.3 | E14: 0.4 | F14: =D14*E14 -> 238.52 | H14: =F14-G14 -> 238.52 | I14: 15571992
A15: 13 | B15: 1119 | C15: Ghanim Abdul Aziz Masoud Abdul Aziz Alash Al Kathiri | D15: 339.9 | E15: 0.4 | F15: =D15*E15 -> 135.96 | H15: =F15-G15 -> 135.96 | I15: 24000245
A16: 14 | B16: 1122 | C16: Hamed Hilal Said Al Kathiri | D16: 319.6 | E16: 0.4 | F16: =D16*E16 -> 127.84 | G16: =124.08+3.76 -> 127.84 | H16: =F16-G16 -> 0 | I16: 5219876 | J16: 45658 | K16: 45684
A17: 15 | B17: 1135 | C17: Khalid Said Ali Al Kathiri | D17: 595.7 | E17: 0.4 | F17: =D17*E17 -> 238.28 | G17: =234.2+0.48 -> 234.68 | H17: =F17-G17 -> 3.6 | I17: 19202954 | J17: 45665 | K17: 45684
A18: 16 | B18: 1141 | C18: Malik Said Ahmed Habkook Hat Al Shahri | D18: 437.8 | E18: 0.4 | F18: =D18*E18 -> 175.12 | G18: =173.2+1.92 -> 175.12 | H18: =F18-G18 -> 0 | I18: 11753992 | J18: 45658 | K18: 45679
A19: 17 | B19: 1154 | C19: Mohammed Salim Abdullah Al kathiri | D19: 917.8 | E19: 0.4 | F19: =D19*E19 -> 367.12 | H19: =F19-G19 -> 367.12 | I19: 18654817
A20: 18 | B20: 1161 | C20: Mohammed Ali Musallam Al Nubi Al Kathiri | D20: 339.3 | E20: 0.4 | F20: =D20*E20 -> 135.72 | G20: =F20 -> 135.72 | H20: =F20-G20 -> 0 | I20: 257926 | J20: 45810
A21: 19 | B21: 1168 | C21: Mohammed Salim Said Jumaa Al Kathiri | D21: 533.7 | E21: 0.4 | F21: =D21*E21 -> 213.48 | G21: =212.1 -> 212.1 | H21: =F21-G21 -> 1.38 | I21: 15498714 | J21: 45691
A22: 20 | B22: 1177 | C22: Said Salim Said BaitSaid | D22: 338.3 | E22: 0.4 | F22: =D22*E22 -> 135.32 | H22: =F22-G22 -> 135.32 | I22: 219353
A23: 21 | B23: 1178 | C23: Mohammed Said Mohammed Akdha Al Rawas | D23: 580.4 | E23: 0.4 | F23: =D23*E23 -> 232.16 | G23: =232.11+0.05 -> 232.16 | H23: =F23-G23 -> 0 | I23: 970872 | J23: 45664 | K23: 45685
A24: 22 | B24: 1224 | C24: Naif Masoud Awadh Nasib Kikab Al Shihri | D24: 713 | E24: 0.4 | F24: =D24*E24 -> 285.2 | G24: =283.96 -> 283.96 | H24: =F24-G24 -> 1.24 | I24: 24911691 | J24: 45686
A25: 23 | B25: 1225 | C25: Naif Said Awadh Fadhl | D25: 592.8 | E25: 0.4 | F25: =D25*E25 -> 237.12 | H25: =F25-G25 -> 237.12 | I25: 9642357
A26: 24 | B26: 1235 | C26: Saeed Abdul Aziz Abdullah Al kathiri | D26: 662 | E26: 0.4 | F26: =D26*E26 -> 264.8 | H26: =F26-G26 -> 264.8 | I26: 1992436
A27: 25 | B27: 1241 | C27: Said Mohammed Abdallah Al kathiri | D27: 579.6 | E27: 0.4 | F27: =D27*E27 -> 231.84 | G27: =230.78+1.06 -> 231.84 | H27: =F27-G27 -> 0 | I27: 5343254 | J27: 45645 | K27: 45684
A28: 26 | B28: 1247 | C28: Said Salim Azad Bait Ali Badar | D28: 552 | E28: 0.4 | F28: =D28*E28 -> 220.8 | G28: =217.95+2.85 -> 220.8 | H28: =F28-G28 -> 0 | I28: 4748561 | J28: 45665 | K28: 45679
A29: 27 | B29: 1252 | C29: Said Ahmed Ali Bait Said | D29: 505.2 | E29: 0.4 | F29: =D29*E29 -> 202.08 | H29: =F29-G29 -> 202.08 | I29: 2433959
A30: 28 | B30: 1258 | C30: Said Ali Musallam Al Noubi Al Kathiri | D30: 733 | E30: 0.4 | F30: =D30*E30 -> 293.2 | G30: =292.06+1.14 -> 293.2 | H30: =F30-G30 -> 0 | I30: 1924174 | J30: 45658 | K30: 45677
A31: 29 | B31: 1260 | C31: Said Salim Ali Kibab Al Shahri | D31: 642 | E31: 0.4 | F31: =D31*E31 -> 256.8 | G31: =255.4+1.4 -> 256.8 | H31: =F31-G31 -> 0 | I31: 18363579 | J31: 45663 | K31: 45684
A32: 30 | B32: 1261 | C32: Said Ali Nasib Kikab Al shahri | D32: 331.9 | E32: 0.4 | F32: =D32*E32 -> 132.76 | G32: =130.54+2.22 -> 132.76 | H32: =F32-G32 -> 0 | I32: 14429332 | J32: 45658 | K32: 45679
A33: 31 | B33: 1268 | C33: Said Musallam Ali Ghawas | D33: 460 | E33: 0.4 | F33: =D33*E33 -> 184 | G33: =179.45+4.55 -> 184 | H33: =F33-G33 -> 0 | I33: 722058 | J33: 45670 | K33: 45684
A34: 32 | B34: 1282 | C34: Salim Ali Musallam Al Noubi Al Kathiri | D34: 621 | E34: 0.4 | F34: =D34*E34 -> 248.4 | G34: =247.35+1.05 -> 248.4 | H34: =F34-G34 -> 0 | I34: 2997747 | J34: 45656 | K34: 45684
A35: 33 | B35: 1284 | C35: Salim Ali Said Al Nubi Al Kathiri | D35: 598 | E35: 0.4 | F35: =D35*E35 -> 239.2 | G35: =234.42+4.78 -> 239.2 | H35: =F35-G35 -> 0 | I35: 1177598 | J35: 45663 | K35: 45679
A36: 34 | B36: 1300 | C36: Salem Suhail Omer Bit Fhadel | D36: 733.7 | E36: 0.4 | F36: =D36*E36 -> 293.48 | H36: =F36-G36 -> 293.48 | I36: 19534277
A37: 35 | B37: 1306 | C37: Salim Ali Nasib Al Kathiri | D37: 363.7 | E37: 0.4 | F37: =D37*E37 -> 145.48 | G37: =143.12+2.36 -> 145.48 | H37: =F37-G37 -> 0 | I37: 2006904 | J37: 45663 | K37: 45684
A38: 36 | B38: 1315 | C38: Salim Said Ali Ghawas | D38: 263 | E38: 0.4 | F38: =D38*E38 -> 105.2 | H38: =F38-G38 -> 105.2 | I38: 19528845
A39: 37 | B39: 1328 | C39: Suhail Saeed Suhail ghawas | D39: 400.2 | E39: 0.4 | F39: =D39*E39 -> 160.08 | G39: =158.7+1.38 -> 160.08 | H39: =F39-G39 -> 0 | I39: 782833 | J39: 45658 | K39: 45686
A40: 38 | B40: 1330 | C40: Said Mahad Ali Al Kathiri | D40: 631.5 | E40: 0.4 | F40: =D40*E40 -> 252.6 | G40: =36.73+213.4 -> 250.13 | H40: =F40-G40 -> 2.47 | I40: 12194826 | J40: 45810 | K40: 13-2-25
...

Sheet Center-Nov
A1: Milk Chilling Centre(Ghado) - Monthly Camel Milk Procurement Report - 01-11-2024 TO 30-11-2024
A2: SR. NO. | B2: Farmer Code | C2: Farmer Name | D2: Total Quantity Supplied(Lits) | E2: Camel Milk Price/Lit(OMR) | F2: Total Value (OMR) | G2: Paid | H2: Balance | I2: ID No: | J2: Account No | K2: Bank Name | L2: BANK SWIFT CODE | M2: Phone No: | N2: Remarks
A3: 1 | B3: 1001 | C3: Abdul Hakim Musallam Salim Al Katini Al Rawas | D3: 247 | E3: 0.4 | F3: =D3*E3 -> 98.8 | G3: =97.22 -> 97.22 | H3: =F3-G3 -> 1.58 | I3: 2130934 | J3: 0397020829680019 | K3: Bank Muscat | L3: BMUSOMRX | M3: 92911133 | N3: 45963
A4: 2 | B4: 1007 | C4: Ahmed Abdullah Said Al Rawas | D4: 1349 | E4: 0.4 | F4: =D4*E4 -> 539.6 | G4: =537.12 -> 537.12 | H4: =F4-G4 -> 2.48 | I4: 1515504 | J4: 3109147237500 | K4: Oman Arab Bank | L4: OMABOMRU | M4: 91748840 | N4: 45665
A5: 3 | B5: 1028 | C5: Ahmed Saeed Maatouq Al kathiri | D5: 258.6 | E5: 0.4 | F5: =D5*E5 -> 103.44 | H5: =F5-G5 -> 103.44 | I5: 802875 | J5: 0397004247250014 | K5: Bank Muscat | L5: BMUSOMRX | M5: 99498677
A6: 4 | B6: 1033 | C6: Ahmed Said Ali Al Nobi Al Kathiri | D6: 560 | E6: 0.4 | F6: =D6*E6 -> 224 | G6: =220.3+3.7 -> 224 | H6: =F6-G6 -> 0 | I6: 10132435 | J6: 01011076521002 | K6: Bank Dhofar | L6: BDOFOMRU | M6: 92268168 | N6: 45670 | O6: 45701
A7: 5 | B7: 1040 | C7: Ahmed Said Mahad Jamaan Dhishil al Kathiri | D7: 247 | E7: 0.4 | F7: =D7*E7 -> 98.8 | H7: =F7-G7 -> 98.8 | I7: 25082374 | J7: 0406041201480018 | K7: Bank Muscat | L7: BMUSOMRX | M7: 99816344
A8: 6 | B8: 1044 | C8: Ahmed Salim Ahmed Al Hadi Baomar | D8: 285 | E8: 0.4 | F8: =D8*E8 -> 114 | H8: =F8-G8 -> 114 | I8: 81904 | J8: 0406003182770027 | K8: Bank Muscat | L8: BMUSOMRX | M8: 99494120
