Workbook

Sheet center-April
A1: Milk Chilling Centre(Ghado) - Monthly Cow Milk Procurement Report 01-04-2024 TO30-04.2024
A2: SR. NO. | B2: Farmer Code | C2: Farmer Name | D2: Total Quantity Supplied(Lits) | E2: Cow Milk Price/Lit(OMR) | F2: Total Value Milk (OMR) | G2: Paid | H2: Balance | I2: ID No: | J2: Account No | K2: Bank Name | L2: IFSC Code | M2: Phone No: | N2: Remark | P2: Farmer Code | R2: Farmer Name | T2: ID No: | V2: Account No | X2: IFSC Code
A4: 25 | B4: 1362 | C4: Ali Masoud Salem Baitsaid | D4: 2336 | E4: 0.25 | F4: =SUM(D4*E4) -> 584 | G4: =582+2 -> 584 | H4: =F4-G4 -> 0 | I4: 2429041 | J4: 0397003875270017 | K4: BANK MUSCAT | L4: BMUSOMRX | M4: 93663694 | N4: 12-08-2024-feeds | O4: 45691 | P4: 1362 | Q4: =P4=B4 -> TRUE | R4: Ali Masoud Salem Baitsaid | S4: =R4=C4 -> TRUE | T4: 2429041 | U4: =T4=I4 -> TRUE | V4: 0397003875270017 | W4: =V4=J4 -> TRUE | X4: BMUSOMRX | Y4: =X4=L4 -> TRUE
A5: 29 | B5: 1370 | C5: Mohammed Ali Nassib Kikab Al Shahri | D5: 1635.9 | E5: 0.25 | F5: =SUM(D5*E5) -> 408.975 | G5: =408.85+0.125 -> 408.975 | H5: =F5-G5 -> 0 | I5: 14431965 | J5: 0439003719840022 | K5: BANK MUSCAT | L5: BMUSOMRX | M5: 99693775 | N5: 13-08-24-feeds | P5: 1370 | Q5: =P5=B5 -> TRUE | R5: Mohammed Ali Nassib Kikab Al Shahri | S5: =R5=C5 -> TRUE | T5: 14431965 | U5: =T5=I5 -> TRUE | V5: 0439003719840022 | W5: =V5=J5 -> TRUE | X5: BMUSOMRX | Y5: =X5=L5 -> TRUE
D6: =SUM(D4:D5) -> 3971.9 | F6: =SUM(F4:F5) -> 992.975 | G6: =SUM(G4:G5) -> 992.975 | H6: =SUM(H4:H5) -> 0
V12: Said Al Bahanata
V13: DGM

Sheet 05-24
A1: Milk Chilling Centre(Ghado) - Monthly Cow Milk Procurement Report 01-05-2024 TO31-05.2024
A2: SR. NO. | B2: Farmer Code | C2: Farmer Name | D2: Total Quantity Supplied(Lits) | E2: Cow Milk Price/Lit(OMR) | F2: Total Value Milk (OMR) | G2: Paid | H2: Balance | I2: ID No: | J2: Remark
A4: 5 | B4: 1086 | C4: Muslim Ali Said Hat AlShehri | D4: 1033.8 | E4: 0.25 | F4: =SUM(D4*E4) -> 258.45 | G4: =257.825+0.625 -> 258.45 | H4: =F4-G4 -> 0 | I4: 2379573 | J4: 16-09-2024 | K4: 45607
A5: 18 | B5: 1343 | C5: Masoud Mahad Masoud Baitsaid | D5: 923.8 | E5: 0.25 | F5: =SUM(D5*E5) -> 230.95 | G5: =227.15+3.8 -> 230.95 | H5: =F5-G5 -> 0 | I5: 5160297 | J5: 45540 | K5: 45657
D6: =SUM(D4:D5) -> 1957.6 | F6: =SUM(F4:F5) -> 489.4 | G6: =SUM(G4:G5) -> 489.4 | H6: =SUM(H4:H5) -> 0
F8: ='[1]Feeds Issued'!G19 -> 4160.15
F9: ='[1]Final Payment -Bank'!F32 -> 13280.2
F10: =SUM(F8:F9) -> 17440.35
F11: =F10+'[1]Decimals '!H9 -> 17451.375

Sheet center-June
A1: Milk Chilling Centre(Ghado) - Monthly Cow Milk Procurement Report 01-06-2024 TO 30-06.2024
A2: SR. NO. | B2: Farmer Code | C2: Farmer Name | D2: Total Quantity Supplied(Lits) | E2: Cow Milk Price/Lit(OMR) | F2: Total Value Milk (OMR) | I2: ID No: | J2: Remark
A4: 1 | B4: 1071 | C4: ALI MUSTAHIL MUBARAK ASAT AL SHIHRI | D4: 561.8 | E4: 0.25 | F4: =SUM(D4*E4) -> 140.45 | G4: =137.525+2.925 -> 140.45 | H4: =F4-G4 -> 0 | I4: 390741 | J4: 18-09-2024 | K4: 45602
A5: 2 | B5: 1123 | C5: Hamid Mohammed Zidi Bait said | D5: 1105.5 | E5: 0.25 | F5: =SUM(D5*E5) -> 276.375 | G5: =F5 -> 276.375 | H5: =F5-G5 -> 0 | I5: 655141 | J5: 45391 | K5: 4.675 DCF
A6: 3 | B6: 1308 | C6: Ahmed Said Mohammed Alash AlKathiri | D6: 569.9 | E6: 0.25 | F6: =SUM(D6*E6) -> 142.475 | G6: =141.025+1.45 -> 142.475 | H6: =F6-G6 -> 0 | I6: 6225641 | J6: 45567
A7: 4 | B7: 1340 | C7: Ahmed Suhail Ahmed Alash AlKathiri | D7: 1093.4 | E7: 0.25 | F7: =SUM(D7*E7) -> 273.35 | G7: =271.575+1.775 -> 273.35 | H7: =F7-G7 -> 0 | I7: 7279274 | J7: 23-09-2024 | K7: 45607
A8: 5 | B8: 1349 | C8: Muslim Suhail Salem Baitsaid | D8: 1980.8 | E8: 0.25 | F8: =SUM(D8*E8) -> 495.2 | G8: =492.8+2.4 -> 495.2 | H8: =F8-G8 -> 0 | I8: 7128679 | J8: 16-09-2024
A9: 6 | B9: 1366 | C9: Ahmed Salem Ali Kikab AlShehri | D9: 2156 | E9: 0.25 | F9: =SUM(D9*E9) -> 539 | G9: =535.375+3.625 -> 539 | H9: =F9-G9 -> 0 | I9: 8318385 | J9: 16-09-2024 | K9: 45644
A10: 7 | B10: 1371 | C10: Said Muhaisin Nassib Kikab AlShehri | D10: 1623.9 | E10: 0.25 | F10: =SUM(D10*E10) -> 405.975 | G10: =404.625+1.35 -> 405.975 | H10: =F10-G10 -> 0 | I10: 990755 | J10: 30-09-2024 | K10: 45677
A11: 8 | B11: 1378 | C11: Salem Ali Said Kikab AlShehri | D11: 1877.4 | E11: 0.25 | F11: =SUM(D11*E11) -> 469.35 | G11: =466.225+3.125 -> 469.35 | H11: =F11-G11 -> 0 | I11: 5996404 | J11: 30-09-2024 | K11: 45658
A12: 9 | B12: 1381 | C12: Abdellah Masoud Said Al Shihri | D12: 1098.3 | E12: 0.25 | F12: =SUM(D12*E12) -> 274.575 | G12: =274.3+0.275 -> 274.575 | H12: =F12-G12 -> 0 | I12: 19847623 | J12: 45581 | K12: 45600
A13: 10 | B13: 1390 | C13: Said Ahmed Said kikab Al shahri | D13: 550.9 | E13: 0.25 | F13: =SUM(D13*E13) -> 137.725 | G13: =137.6+0.125 -> 137.725 | H13: =F13-G13 -> 0 | I13: 13826903 | J13: 23-09-2024 | K13: 45637
A14: 11 | B14: 1393 | C14: Said Ali Ahmed Amor Jid | D14: 559 | E14: 0.25 | F14: =SUM(D14*E14) -> 139.75 | G14: =136.2+3.55 -> 139.75 | H14: =F14-G14 -> 0 | I14: 1650389 | J14: 16-09-2024 | K14: 45601
D15: =SUM(D4:D14) -> 13176.9 | F15: =SUM(F4:F14) -> 3294.225 | G15: =SUM(G4:G14) -> 3294.225 | H15: =SUM(H4:H14) -> 0
F19: =F12-274.3 -> 0.275

Sheet center-July
A1: Milk Chilling Centre(Ghado) - Monthly Cow Milk Procurement Report 01-07-2024 TO 31-07.2024
A2: SR. NO. | B2: Farmer Code | C2: Farmer Name | D2: Total Quantity Supplied(Lits) | E2: Cow Milk Price/Lit(OMR) | F2: Total Value Milk (OMR) | G2: Paid | H2: Balance | I2: ID No: | J2: Remark
A4: 1 | B4: 1010 | C4: Ahmed Ajham Omar Aghrib AlShehri | D4: 1922.8 | E4: 0.25 | F4: =SUM(D4*E4) -> 480.7 | G4: =F4 -> 480.7 | H4: =F4-G4 -> 0 | I4: 315313
A5: 2 | B5: 1038 | C5: Salem Ahmed Said Majdah AlKathiri | D5: 2056.8 | E5: 0.25 | F5: =SUM(D5*E5) -> 514.2 | G5: =F5 -> 514.2 | H5: =F5-G5 -> 0 | I5: 5247837
A6: 3 | B6: 1065 | C6: Ali Muhaisin Mohammed Humdi Al Saiari | D6: 638.3 | E6: 0.25 | F6: =SUM(D6*E6) -> 159.575 | G6: =F6 -> 159.575 | H6: =F6-G6 -> 0 | I6: 1276058
A7: 4 | B7: 1071 | C7: ALI MUSTAHIL MUBARAK ASAT AL SHIHRI | D7: 665 | E7: 0.25 | F7: =SUM(D7*E7) -> 166.25 | G7: =F7 -> 166.25 | H7: =F7-G7 -> 0 | I7: 390741 | J7: 45602
A8: 5 | B8: 1086 | C8: Muslim Ali Said Hat AlShehri | D8: 1286 | E8: 0.25 | F8: =SUM(D8*E8) -> 321.5 | G8: =317.325+4.175 -> 321.5 | H8: =F8-G8 -> 0 | I8: 2379573 | J8: 45607 | K8: 45628
A9: 6 | B9: 1123 | C9: Hamid Mohammed Zidi Bait said | D9: 1340.2 | E9: 0.25 | F9: =SUM(D9*E9) -> 335.05 | G9: =F9 -> 335.05 | H9: =F9-G9 -> 0 | I9: 655141 | J9: DCF FEED
A10: 7 | B10: 1130 | C10: Hassan said jman alhalai | D10: 1286.2 | E10: 0.25 | F10: =SUM(D10*E10) -> 321.55 | G10: =F10 -> 321.55 | H10: =F10-G10 -> 0 | I10: 5485645
A11: 8 | B11: 1152 | C11: Mohammed Rajab Ali Al Mashikhi | D11: 1833.4 | E11: 0.25 | F11: =SUM(D11*E11) -> 458.35 | G11: =F11 -> 458.35 | H11: =F11-G11 -> 0 | I11: 5254327
A12: 9 | B12: 1200 | C12: Muslim Ahmed Muslim AlKathiri | D12: 319 | E12: 0.25 | F12: =SUM(D12*E12) -> 79.75 | G12: =F12 -> 79.75 | H12: =F12-G12 -> 0 | I12: 7287174
A13: 10 | B13: 1276 | C13: Masoud Salim Said Baitsaid | D13: 649.5 | E13: 0.25 | F13: =SUM(D13*E13) -> 162.375 | G13: =F13 -> 162.375 | H13: =F13-G13 -> 0 | I13: 334495
A14: 11 | B14: 1281 | C14: Salem Ali Masoud Baitsaid | D14: 1856.5 | E14: 0.25 | F14: =SUM(D14*E14) -> 464.125 | G14: =F14 -> 464.125 | H14: =F14-G14 -> 0 | I14: 6310986
A15: 12 | B15: 1308 | C15: Ahmed Said Mohammed Alash AlKathiri | D15: 654 | E15: 0.25 | F15: =SUM(D15*E15) -> 163.5 | G15: =F15 -> 163.5 | H15: =F15-G15 -> 0 | I15: 6225641
A16: 13 | B16: 1337 | C16: Amer Bakhit Sohil Baitsaid | D16: 469.3 | E16: 0.25 | F16: =SUM(D16*E16) -> 117.325 | G16: =114.875+2.45 -> 117.325 | H16: =F16-G16 -> 0 | I16: 6719626 | J16: 45580 | K16: 45601
A17: 14 | B17: 1339 | C17: Said Ahmed Ali Baitsaid | D17: 5181.8 | E17: 0.25 | F17: =SUM(D17*E17) -> 1295.45 | G17: =F17 -> 1295.45 | H17: =F17-G17 -> 0 | I17: 3090574
A18: 15 | B18: 1340 | C18: Ahmed Suhail Ahmed Alash AlKathiri | D18: 994.2 | E18: 0.25 | F18: =SUM(D18*E18) -> 248.55 | G18: =248.475+0.075 -> 248.55 | H18: =F18-G18 -> 0 | I18: 7279274 | J18: 45607 | K18: 45628
A19: 16 | B19: 1341 | C19: Mahad Suhail Mahad Baitsaid | D19: 1403.6 | E19: 0.25 | F19: =SUM(D19*E19) -> 350.9 | G19: =F19 -> 350.9 | H19: =F19-G19 -> 0 | I19: 15977579
A20: 17 | B20: 1342 | C20: Mohammed Ali Said Al Nubi Al Kathiri | D20: 176.3 | E20: 0.25 | F20: =SUM(D20*E20) -> 44.075 | G20: =40.875+3.2 -> 44.075 | H20: =F20-G20 -> 0 | I20: 13950469 | J20: 45567 | K20: 45628
A21: 18 | B21: 1343 | C21: Masoud Mahad Masoud Baitsaid | D21: 1138.3 | E21: 0.25 | F21: =SUM(D21*E21) -> 284.575 | G21: =F21 -> 284.575 | H21: =F21-G21 -> 0 | I21: 5160297
A22: 19 | B22: 1345 | C22: Salim Said Ali Bait said | D22: 6189 | E22: 0.25 | F22: =SUM(D22*E22) -> 1547.25 | G22: =F22 -> 1547.25 | H22: =F22-G22 -> 0 | I22: 10578952
A23: 20 | B23: 1349 | C23: Muslim Suhail Salem Baitsaid | D23: 1940.4 | E23: 0.25 | F23: =SUM(D23*E23) -> 485.1 | G23: =F23 -> 485.1 | H23: =F23-G23 -> 0 | I23: 7128679
A24: 21 | B24: 1350 | C24: Ahmed Salem Zayed Baitsaid | D24: 4342.7 | E24: 0.25 | F24: =SUM(D24*E24) -> 1085.675 | G24: =F24 -> 1085.675 | H24: =F24-G24 -> 0 | I24: 6752017
A25: 22 | B25: 1353 | C25: Salem Amer Said Baitsaid | D25: 5938.8 | E25: 0.25 | F25: =SUM(D25*E25) -> 1484.7 | G25: 1484.7 | H25: =F25-G25 -> 0 | I25: 5217694 | J25: Paid 16-10-2024
A26: 23 | B26: 1355 | C26: Ahmed Zaidi Mahroos Baitsaid | D26: 2262.3 | E26: 0.25 | F26: =SUM(D26*E26) -> 565.575 | G26: =F26 -> 565.575 | H26: =F26-G26 -> 0 | I26: 585058
A27: 24 | B27: 1356 | C27: Said Salem Said Asout AlShehri | D27: 1315.9 | E27: 0.25 | F27: =SUM(D27*E27) -> 328.975 | G27: =F27 -> 328.975 | H27: =F27-G27 -> 0 | I27: 7494112 | J27: BT 10-12-2024
A28: 25 | B28: 1362 | C28: Ali Masoud Salem Baitsaid | D28: 1956.6 | E28: 0.25 | F28: =SUM(D28*E28) -> 489.15 | G28: =F28 -> 489.15 | H28: =F28-G28 -> 0 | I28: 2429041
A29: 26 | B29: 1363 | C29: Suhail Ali Said AlKathiri | D29: 1913.4 | E29: 0.25 | F29: =SUM(D29*E29) -> 478.35 | G29: =F29 -> 478.35 | H29: =F29-G29 -> 0 | I29: 322352
A30: 27 | B30: 1364 | C30: Omar Bakhit Ahmed Al Hilali | D30: 586.1 | E30: 0.25 | F30: =SUM(D30*E30) -> 146.525 | G30: =145.6+0.925 -> 146.525 | H30: =F30-G30 -> 0 | I30: 7113811 | J30: 45567 | K30: 45607
A31: 28 | B31: 1366 | C31: Ahmed Salem Ali Kikab AlShehri | D31: 2488.8 | E31: 0.25 | F31: =SUM(D31*E31) -> 622.2 | G31: =F31 -> 622.2 | H31: =F31-G31 -> 0 | I31: 8318385
A32: 29 | B32: 1370 | C32: Mohammed Ali Nassib Kikab Al Shahri | D32: 1859.9 | E32: 0.25 | F32: =SUM(D32*E32) -> 464.975 | G32: =F32 -> 464.975 | H32: =F32-G32 -> 0 | I32: 14431965
A33: 30 | B33: 1371 | C33: Said Muhaisin Nassib Kikab AlShehri | D33: 1850.1 | E33: 0.25 | F33: =SUM(D33*E33) -> 462.525 | G33: =F33 -> 462.525 | H33: =F33-G33 -> 0 | I33: 990755
A34: 31 | B34: 1372 | C34: Ali Said Zaidi Baitsaid | D34: 1860 | E34: 0.25 | F34: =SUM(D34*E34) -> 465 | G34: =F34 -> 465 | H34: =F34-G34 -> 0 | I34: 628655
A35: 32 | B35: 1373 | C35: Salim Ahmed Tamman Baitsaid | D35: 644.4 | E35: 0.25 | F35: =SUM(D35*E35) -> 161.1 | G35: =F35 -> 161.1 | H35: =F35-G35 -> 0 | I35: 734281 | J35: 45301
A36: 33 | B36: 1375 | C36: Muslim Mohammed Hassan Alash AlKathiri | D36: 629.3 | E36: 0.25 | F36: =SUM(D36*E36) -> 157.325 | G36: =F36 -> 157.325 | H36: =F36-G36 -> 0 | I36: 6748627
A37: 34 | B37: 1377 | C37: Ali Masoud Awad Kikab AlShehri | D37: 672.1 | E37: 0.25 | F37: =SUM(D37*E37) -> 168.025 | G37: =F37 -> 168.025 | H37: =F37-G37 -> 0 | I37: 5160404
A38: 35 | B38: 1378 | C38: Salem Ali Said Kikab AlShehri | D38: 2268.5 | E38: 0.25 | F38: =SUM(D38*E38) -> 567.125 | G38: =F38 -> 567.125 | H38: =F38-G38 -> 0 | I38: 5996404
A39: 36 | B39: 1381 | C39: Abdellah Masoud Said Al Shihri | D39: 1157.5 | E39: 0.25 | F39: =SUM(D39*E39) -> 289.375 | G39: =287.525+1.85 -> 289.375 | H39: =F39-G39 -> 0 | I39: 19847623 | J39: 45600 | K39: 45621
A40: 37 | B40: 1390 | C40: Said Ahmed Said kikab Al shahri | D40: 600.1 | E40: 0.25 | F40: =SUM(D40*E40) -> 150.025 | G40: =F40 -> 150.025 | H40: =F40-G40 -> 0 | I40: 13826903 | J40: 45637
A41: 38 | B41: 1392 | C41: Ahmed Abdullah Ali Al Kathiri | D41: 1549.9 | E41: 0.25 | F41: =SUM(D41*E41) -> 387.475 | G41: =F41 -> 387.475 | H41: =F41-G41 -> 0 | I41: 1353348
...

Sheet center-Aug
A1: Milk Chilling Centre(Ghado) - Monthly Cow Milk Procurement Report 01-08-2024 TO 31-08.2024
A2: SR. NO. | B2: Farmer Code | C2: Farmer Name | D2: Total Quantity Supplied(Lits) | E2: Cow Milk Price/Lit(OMR) | F2: Total Value Milk (OMR) | G2: Paid | H2: Balance | I2: ID No: | J2: Remark
A4: 1 | B4: 1010 | C4: Ahmed Ajham Omar Aghrib AlShehri | D4: 2046.9 | E4: 0.25 | F4: =SUM(D4*E4) -> 511.725 | G4: =F4 -> 511.725 | H4: =F4-G4 -> 0 | I4: 315313 | J4: Transfer9-1-25
A5: 2 | B5: 1038 | C5: Salem Ahmed Said Majdah AlKathiri | D5: 2016.8 | E5: 0.25 | F5: =SUM(D5*E5) -> 504.2 | G5: =F5 -> 504.2 | H5: =F5-G5 -> 0 | I5: 5247837
A6: 3 | B6: 1065 | C6: Ali Muhaisin Mohammed Humdi Al Saiari | D6: 642.3 | E6: 0.25 | F6: =SUM(D6*E6) -> 160.575 | G6: =F6 -> 160.575 | H6: =F6-G6 -> 0 | I6: 1276058
A7: 4 | B7: 1071 | C7: ALI MUSTAHIL MUBARAK ASAT AL SHIHRI | D7: 645.6 | E7: 0.25 | F7: =SUM(D7*E7) -> 161.4 | G7: =158.075+3.325 -> 161.4 | H7: =F7-G7 -> 0 | I7: 390741 | J7: 45602 | K7: 45621
A8: 5 | B8: 1086 | C8: Muslim Ali Said Hat AlShehri | D8: 1304.7 | E8: 0.25 | F8: =SUM(D8*E8) -> 326.175 | G8: =324.575+1.6 -> 326.175 | H8: =F8-G8 -> 0 | I8: 2379573 | J8: 45628 | K8: 45650
A9: 6 | B9: 1123 | C9: Hamid Mohammed Zidi Bait said | D9: 1320.6 | E9: 0.25 | F9: =SUM(D9*E9) -> 330.15 | G9: =F9 -> 330.15 | H9: =F9-G9 -> 0 | I9: 655141 | J9: DCF FEED
A10: 7 | B10: 1130 | C10: Hassan said jman alhalai | D10: 1149.2 | E10: 0.25 | F10: =SUM(D10*E10) -> 287.3 | G10: =F10 -> 287.3 | H10: =F10-G10 -> 0 | I10: 5485645 | J10: 45810
A11: 8 | B11: 1152 | C11: Mohammed Rajab Ali Al Mashikhi | D11: 1834.5 | E11: 0.25 | F11: =SUM(D11*E11) -> 458.625 | G11: =F11 -> 458.625 | H11: =F11-G11 -> 0 | I11: 5254327
A12: 9 | B12: 1200 | C12: Muslim Ahmed Muslim AlKathiri | D12: 209.3 | E12: 0.25 | F12: =SUM(D12*E12) -> 52.325 | G12: =50.05+2.275 -> 52.325 | H12: =F12-G12 -> 0 | I12: 7287174 | J12: 45644 | K12: 45656
A13: 10 | B13: 1276 | C13: Masoud Salim Said Baitsaid | D13: 640.7 | E13: 0.25 | F13: =SUM(D13*E13) -> 160.175 | G13: =F13 -> 160.175 | H13: =F13-G13 -> 0 | I13: 334495
A14: 11 | B14: 1281 | C14: Salem Ali Masoud Baitsaid | D14: 1854.8 | E14: 0.25 | F14: =SUM(D14*E14) -> 463.7 | G14: =F14 -> 463.7 | H14: =F14-G14 -> 0 | I14: 6310986
A15: 12 | B15: 1308 | C15: Ahmed Said Mohammed Alash AlKathiri | D15: 650.3 | E15: 0.25 | F15: =SUM(D15*E15) -> 162.575 | G15: =F15 -> 162.575 | H15: =F15-G15 -> 0 | I15: 6225641
A16: 13 | B16: 1337 | C16: Amer Bakhit Sohil Baitsaid | D16: 610.1 | E16: 0.25 | F16: =SUM(D16*E16) -> 152.525 | G16: =149.3+3.225 -> 152.525 | H16: =F16-G16 -> 0 | I16: 6719626 | J16: 45628 | K16: 45644
A17: 14 | B17: 1339 | C17: Said Ahmed Ali Baitsaid | D17: 3036.4 | E17: 0.25 | F17: =SUM(D17*E17) -> 759.1 | G17: =F17 -> 759.1 | H17: =F17-G17 -> 0 | I17: 3090574
A18: 15 | B18: 1340 | C18: Ahmed Suhail Ahmed Alash AlKathiri | D18: 631.2 | E18: 0.25 | F18: =SUM(D18*E18) -> 157.8 | G18: =F18 -> 157.8 | H18: =F18-G18 -> 0 | I18: 7279274 | J18: 45628
A19: 16 | B19: 1341 | C19: Mahad Suhail Mahad Baitsaid | D19: 1410.8 | E19: 0.25 | F19: =SUM(D19*E19) -> 352.7 | G19: =F19 -> 352.7 | H19: =F19-G19 -> 0 | I19: 15977579
A20: 17 | B20: 1343 | C20: Masoud Mahad Masoud Baitsaid | D20: 1177.4 | E20: 0.25 | F20: =SUM(D20*E20) -> 294.35 | G20: =1.7+188.7+103.95 -> 294.35 | H20: =F20-G20 -> 0 | I20: 5160297 | J20: 45644 | K20: 45650 | M20: cancelled PR-358 | O20: 45665
A21: 18 | B21: 1345 | C21: Salim Said Ali Bait said | D21: 6164.7 | E21: 0.25 | F21: =SUM(D21*E21) -> 1541.175 | G21: =F21 -> 1541.175 | H21: =F21-G21 -> 0 | I21: 10578952
A22: 19 | B22: 1349 | C22: Muslim Suhail Salem Baitsaid | D22: 1922.4 | E22: 0.25 | F22: =SUM(D22*E22) -> 480.6 | G22: =F22 -> 480.6 | H22: =F22-G22 -> 0 | I22: 7128679
A23: 20 | B23: 1350 | C23: Ahmed Salem Zayed Baitsaid | D23: 4420.9 | E23: 0.25 | F23: =SUM(D23*E23) -> 1105.225 | G23: =F23 -> 1105.225 | H23: =F23-G23 -> 0 | I23: 6752017
A24: 21 | B24: 1353 | C24: Salem Amer Said Baitsaid | D24: 6112.9 | E24: 0.25 | F24: =SUM(D24*E24) -> 1528.225 | G24: 1528.225 | H24: =F24-G24 -> 0 | I24: 5217694 | J24: BT 10-12-2024
A25: 22 | B25: 1355 | C25: Ahmed Zaidi Mahroos Baitsaid | D25: 2359.8 | E25: 0.25 | F25: =SUM(D25*E25) -> 589.95 | G25: =F25 -> 589.95 | H25: =F25-G25 -> 0 | I25: 585058 | J25: Transfer 8-1-2025
A26: 23 | B26: 1356 | C26: Said Salem Said Asout AlShehri | D26: 1311.8 | E26: 0.25 | F26: =SUM(D26*E26) -> 327.95 | G26: =F26 -> 327.95 | H26: =F26-G26 -> 0 | I26: 7494112 | J26: BT 10-12-2024
A27: 24 | B27: 1362 | C27: Ali Masoud Salem Baitsaid | D27: 2248.8 | E27: 0.25 | F27: =SUM(D27*E27) -> 562.2 | G27: =560.6+1.6 -> 562.2 | H27: =F27-G27 -> 0 | I27: 2429041 | J27: 45691 | K27: 13-2-25
A28: 25 | B28: 1363 | C28: Suhail Ali Said AlKathiri | D28: 1359.7 | E28: 0.25 | F28: =SUM(D28*E28) -> 339.925 | G28: =F28 -> 339.925 | H28: =F28-G28 -> 0 | I28: 322352
A29: 26 | B29: 1364 | C29: Omar Bakhit Ahmed Al Hilali | D29: 608.1 | E29: 0.25 | F29: =SUM(D29*E29) -> 152.025 | G29: =149.225+2.8 -> 152.025 | H29: =F29-G29 -> 0 | I29: 7113811 | J29: 45607 | K29: 45637
A30: 27 | B30: 1366 | C30: Ahmed Salem Ali Kikab AlShehri | D30: 2468.4 | E30: 0.25 | F30: =SUM(D30*E30) -> 617.1 | G30: =209.875+141+264.25+1.975 -> 617.1 | H30: =F30-G30 -> 0 | I30: 8318385 | J30: 45644 | K30: 45656 | L30: 45658 | M30: 45663
A31: 28 | B31: 1370 | C31: Mohammed Ali Nassib Kikab Al Shahri | D31: 1860 | E31: 0.25 | F31: =SUM(D31*E31) -> 465 | G31: =F31 -> 465 | H31: =F31-G31 -> 0 | I31: 14431965
A32: 29 | B32: 1371 | C32: Said Muhaisin Nassib Kikab AlShehri | D32: 1859.8 | E32: 0.25 | F32: =SUM(D32*E32) -> 464.95 | G32: =225.15+239.45 -> 464.6 | H32: =F32-G32 -> 0.35 | I32: 990755 | J32: 45677 | K32: 45691
A33: 30 | B33: 1372 | C33: Ali Said Zaidi Baitsaid | D33: 1844 | E33: 0.25 | F33: =SUM(D33*E33) -> 461 | G33: =F33 -> 461 | H33: =F33-G33 -> 0 | I33: 628655
A34: 31 | B34: 1373 | C34: Salim Ahmed Tamman Baitsaid | D34: 647.9 | E34: 0.25 | F34: =SUM(D34*E34) -> 161.975 | G34: =F34 -> 161.975 | H34: =F34-G34 -> 0 | I34: 734281 | J34: 27-01-25-dcf
A35: 32 | B35: 1375 | C35: Muslim Mohammed Hassan Alash AlKathiri | D35: 497.7 | E35: 0.25 | F35: =SUM(D35*E35) -> 124.425 | G35: =F35 -> 124.425 | H35: =F35-G35 -> 0 | I35: 6748627
A36: 33 | B36: 1377 | C36: Ali Masoud Awad Kikab AlShehri | D36: 620 | E36: 0.25 | F36: =SUM(D36*E36) -> 155 | G36: =F36 -> 155 | H36: =F36-G36 -> 0 | I36: 5160404
A37: 34 | B37: 1378 | C37: Salem Ali Said Kikab AlShehri | D37: 2442.2 | E37: 0.25 | F37: =SUM(D37*E37) -> 610.55 | G37: =607.975+2.575 -> 610.55 | H37: =F37-G37 -> 0 | I37: 5996404 | J37: 45658 | K37: 45684
A38: 35 | B38: 1381 | C38: Abdellah Masoud Said Al Shihri | D38: 908.7 | E38: 0.25 | F38: =SUM(D38*E38) -> 227.175 | G38: =224.1+3.075 -> 227.175 | H38: =F38-G38 -> 0 | I38: 19847623 | J38: 45621 | K38: 45635
A39: 36 | B39: 1390 | C39: Said Ahmed Said kikab Al shahri | D39: 558.2 | E39: 0.25 | F39: =SUM(D39*E39) -> 139.55 | G39: =F39 -> 139.55 | H39: =F39-G39 -> 0 | I39: 13826903 | J39: 45637
A40: 37 | B40: 1392 | C40: Ahmed Abdullah Ali Al Kathiri | D40: 1553.1 | E40: 0.25 | F40: =SUM(D40*E40) -> 388.275 | G40: =F40 -> 388.275 | H40: =F40-G40 -> 0 | I40: 1353348
A41: 38 | B41: 1393 | C41: Said Ali Ahmed Amor Jid | D41: 630.3 | E41: 0.25 | F41: =SUM(D41*E41) -> 157.575 | G41: =155.375+2.2 -> 157.575 | H41: =F41-G41 -> 0 | I41: 1650389 | J41: 45628 | K41: 45663
...

Sheet Center-Sept
A1: Milk Chilling Centre(Ghado) - Monthly Cow Milk Procurement Report 01-09-2024 TO 30-09.2024
A2: SR. NO. | B2: Farmer Code | C2: Farmer Name | D2: Total Quantity Supplied(Lits) | E2: Cow Milk Price/Lit(OMR) | F2: Total Value Milk (OMR) | G2: Paid | H2: Balance | I2: ID No: | J2: Account No | K2: Bank Name | L2: IFSC Code | M2: Phone No: | N2: Remark
A4: 1 | B4: 1010 | C4: Ahmed Ajham Omar Aghrib AlShehri | D4: 2386.5 | E4: 0.25 | F4: =SUM(D4*E4) -> 596.625 | G4: =F4 -> 596.625 | H4: =F4-G4 -> 0 | I4: 315313 | J4: 1006237426001 | K4: NBO | L4: NBOMOMRX | M4: 92600441
A5: 2 | B5: 1038 | C5: Salem Ahmed Said Majdah AlKathiri | D5: 1976.8 | E5: 0.25 | F5: =SUM(D5*E5) -> 494.2 | G5: =F5 -> 494.2 | H5: =F5-G5 -> 0 | I5: 5247837 | J5: 0406003267180024 | K5: BANK MUSCAT | L5: BMUSOMRX | M5: 99441537 | N5: 45963 | O5: 13-2-25
A6: 3 | B6: 1065 | C6: Ali Muhaisin Mohammed Humdi Al Saiari | D6: 581.9 | E6: 0.25 | F6: =SUM(D6*E6) -> 145.475 | G6: =F6 -> 145.475 | H6: =F6-G6 -> 0 | I6: 1276058 | J6: 0397003789920017 | K6: BANK MUSCAT | L6: BMUSOMRX | M6: 99498549
A7: 4 | B7: 1071 | C7: ALI MUSTAHIL MUBARAK ASAT AL SHIHRI | D7: 605.6 | E7: 0.25 | F7: =SUM(D7*E7) -> 151.4 | G7: =F7 -> 151.4 | H7: =F7-G7 -> 0 | I7: 390741 | J7: 01010120857001 | K7: BANK DHOFAR | L7: BDOFOMRU | M7: 99589144 | N7: 45621 | O7: 45663
A8: 5 | B8: 1086 | C8: Muslim Ali Said Hat AlShehri | D8: 1260.5 | E8: 0.25 | F8: =SUM(D8*E8) -> 315.125 | G8: =F8 -> 315.125 | H8: =F8-G8 -> 0 | I8: 2379573 | J8: 01010281105001 | K8: BANK DHOFAR | L8: BDOFOMRU | M8: 92917899 | N8: 45650 | O8: 45665
A9: 6 | B9: 1123 | C9: Hamid Mohammed Zidi Bait said | D9: 1288.7 | E9: 0.25 | F9: =SUM(D9*E9) -> 322.175 | G9: =F9 -> 322.175 | H9: =F9-G9 -> 0 | I9: 655141 | J9: 250097615001 | K9: HSBC | L9: BBMEOMRX | M9: 99485623 | N9: DCF feed
A10: 7 | B10: 1130 | C10: Hassan said jman alhalai | D10: 1069.1 | E10: 0.25 | F10: =SUM(D10*E10) -> 267.275 | G10: =F10 -> 267.275 | H10: =F10-G10 -> 0 | I10: 5485645 | J10: 0401003274570034 | K10: BANK MUSCAT | L10: BMUSOMRX | M10: 90977488 | N10: 45810
A11: 8 | B11: 1152 | C11: Mohammed Rajab Ali Al Mashikhi | D11: 1794.2 | E11: 0.25 | F11: =SUM(D11*E11) -> 448.55 | G11: =F11 -> 448.55 | H11: =F11-G11 -> 0 | I11: 5254327 | J11: 01011435284001 | K11: BANK DHOFAR | L11: BDOFOMRU | M11: 99692328
A12: 9 | B12: 1200 | C12: Muslim Ahmed Muslim AlKathiri | D12: 560.7 | E12: 0.25 | F12: =SUM(D12*E12) -> 140.175 | G12: =F12 -> 140.175 | H12: =F12-G12 -> 0 | I12: 7287174 | J12: 01010853216001 | K12: BANK DHOFAR | L12: BDOFOMRU | M12: 99673747 | N12: 45656 | O12: 45663 | P12: 45665
A13: 10 | B13: 1276 | C13: Masoud Salim Said Baitsaid | D13: 597.3 | E13: 0.25 | F13: =SUM(D13*E13) -> 149.325 | G13: =F13 -> 149.325 | H13: =F13-G13 -> 0 | I13: 334495 | J13: 0397003857450019 | K13: BANK MUSCAT | L13: BMUSOMRX | M13: 99170505
A14: 11 | B14: 1281 | C14: Salem Ali Masoud Baitsaid | D14: 1793.6 | E14: 0.25 | F14: =SUM(D14*E14) -> 448.4 | G14: =F14 -> 448.4 | H14: =F14-G14 -> 0 | I14: 6310986 | J14: 0406003431390019 | K14: BANK MUSCAT | L14: BMUSOMRX | M14: 92922944
A15: 12 | B15: 1308 | C15: Ahmed Said Mohammed Alash AlKathiri | D15: 648.4 | E15: 0.25 | F15: =SUM(D15*E15) -> 162.1 | G15: =F15 -> 162.1 | H15: =F15-G15 -> 0 | I15: 6225641 | J15: 01010407288003 | K15: BANK DHOFAR | L15: BDOFOMRU | M15: 92055550
A16: 13 | B16: 1337 | C16: Amer Bakhit Sohil Baitsaid | D16: 488.7 | E16: 0.25 | F16: =SUM(D16*E16) -> 122.175 | G16: =F16 -> 122.175 | H16: =F16-G16 -> 0 | I16: 6719626 | J16: 0401026589890018 | K16: BANK MUSCAT | L16: BMUSOMRX | M16: 97726288 | N16: 45644 | O16: 45670
A17: 14 | B17: 1339 | C17: Said Ahmed Ali Baitsaid | D17: 2958.5 | E17: 0.25 | F17: =SUM(D17*E17) -> 739.625 | G17: =F17 -> 739.625 | H17: =F17-G17 -> 0 | I17: 3090574 | J17: 01011207102001 | K17: BANK DHOFAR | L17: BDOFOMRU | M17: 99292421 | N17: 45779
A18: 15 | B18: 1340 | C18: Ahmed Suhail Ahmed Alash AlKathiri | D18: 950.5 | E18: 0.25 | F18: =SUM(D18*E18) -> 237.625 | G18: =234.025+3.6 -> 237.625 | H18: =F18-G18 -> 0 | I18: 7279274 | J18: 0204003564210038 | K18: Bank Muscat | L18: BMUSOMRX | M18: 93808816 | N18: 45628 | O18: 45657
A19: 16 | B19: 1341 | C19: Mahad Suhail Mahad Baitsaid | D19: 1360.1 | E19: 0.25 | F19: =SUM(D19*E19) -> 340.025 | G19: =F19 -> 340.025 | H19: =F19-G19 -> 0 | I19: 15977579 | J19: 0439003370920023 | K19: Bank Muscat | L19: BMUSOMRX | M19: 92578822
A20: 17 | B20: 1342 | C20: Mohammed Ali Said Al Nubi Al Kathiri | D20: 546.4 | E20: 0.25 | F20: =SUM(D20*E20) -> 136.6 | G20: =132.6+4 -> 136.6 | H20: =F20-G20 -> 0 | I20: 13950469 | J20: 0406003373420026 | K20: Bank Muscat | L20: BMUSOMRX | M20: 92341118 | N20: 45628 | O20: 45658
A21: 18 | B21: 1343 | C21: Masoud Mahad Masoud Baitsaid | D21: 1196.3 | E21: 0.25 | F21: =SUM(D21*E21) -> 299.075 | G21: =F21 -> 299.075 | H21: =F21-G21 -> 0 | I21: 5160297 | J21: 01013045567001 | K21: BANK DHOFAR | L21: BDOFOMRU | M21: 93501199 | N21: 45650 | O21: 45679
A22: 19 | B22: 1345 | C22: Salim Said Ali Bait said | D22: 5975 | E22: 0.25 | F22: =SUM(D22*E22) -> 1493.75 | G22: =F22 -> 1493.75 | H22: =F22-G22 -> 0 | I22: 10578952 | J22: 3109378368700 | K22: OAB | L22: OMABOMRU | M22: 92194382
A23: 20 | B23: 1349 | C23: Muslim Suhail Salem Baitsaid | D23: 2236.2 | E23: 0.25 | F23: =SUM(D23*E23) -> 559.05 | G23: =F23 -> 559.05 | H23: =F23-G23 -> 0 | I23: 7128679 | J23: 0406003474800016 | K23: BANK MUSCAT | L23: BMUSOMRX | M23: 91408836
A24: 21 | B24: 1350 | C24: Ahmed Salem Zayed Baitsaid | D24: 4331 | E24: 0.25 | F24: =SUM(D24*E24) -> 1082.75 | G24: =F24 -> 1082.75 | H24: =F24-G24 -> 0 | I24: 6752017 | J24: 0396003246310013 | K24: BANK MUSCAT | L24: BMUSOMRX | M24: 92520708
A25: 22 | B25: 1353 | C25: Salem Amer Said Baitsaid | D25: 5974.8 | E25: 0.25 | F25: =SUM(D25*E25) -> 1493.7 | G25: =F25 -> 1493.7 | H25: =F25-G25 -> 0 | I25: 5217694 | J25: 1011109062001 | K25: BANK DHOFAR | L25: BDOFOMRU | M25: 92749180
A26: 23 | B26: 1355 | C26: Ahmed Zaidi Mahroos Baitsaid | D26: 2240.2 | E26: 0.25 | F26: =SUM(D26*E26) -> 560.05 | G26: =F26 -> 560.05 | H26: =F26-G26 -> 0 | I26: 585058 | J26: 01010940683001 | K26: BANK DHOFAR | L26: BDOFOMRU | M26: 99055262 | N26: Transfer 8-1-2025
A27: 24 | B27: 1356 | C27: Said Salem Said Asout AlShehri | D27: 1221.2 | E27: 0.25 | F27: =SUM(D27*E27) -> 305.3 | G27: =F27 -> 305.3 | H27: =F27-G27 -> 0 | I27: 7494112 | J27: 397050056020018 | K27: BANK MUSCAT | L27: BMUSOMRX | M27: 99488186
A28: 25 | B28: 1362 | C28: Ali Masoud Salem Baitsaid | D28: 2382.2 | E28: 0.25 | F28: =SUM(D28*E28) -> 595.55 | G28: =F28 -> 595.55 | H28: =F28-G28 -> 0 | I28: 2429041 | J28: 0397003875270017 | K28: BANK MUSCAT | L28: BMUSOMRX | M28: 93663694 | N28: 13-2-25
A29: 26 | B29: 1363 | C29: Suhail Ali Said AlKathiri | D29: 1866.1 | E29: 0.25 | F29: =SUM(D29*E29) -> 466.525 | G29: =F29 -> 466.525 | H29: =F29-G29 -> 0 | I29: 322352 | J29: 0406003153460019 | K29: BANK MUSCAT | L29: BMUSOMRX | M29: 98842645
A30: 27 | B30: 1364 | C30: Omar Bakhit Ahmed Al Hilali | D30: 596.7 | E30: 0.25 | F30: =SUM(D30*E30) -> 149.175 | G30: =F30 -> 149.175 | H30: =F30-G30 -> 0 | I30: 7113811 | J30: 01010123044001 | K30: BANK DHOFAR | L30: BDOFOMRU | M30: 92969982 | N30: 45637 | O30: 45672
A31: 28 | B31: 1366 | C31: Ahmed Salem Ali Kikab AlShehri | D31: 2362.4 | E31: 0.25 | F31: =SUM(D31*E31) -> 590.6 | G31: =F31 -> 590.6 | H31: =F31-G31 -> 0 | I31: 8318385 | J31: 0406015165020012 | K31: BANK MUSCAT | L31: BMUSOMRX | M31: 90660210 | N31: 45663 | O31: 45670 | P31: 45684
A32: 29 | B32: 1370 | C32: Mohammed Ali Nassib Kikab Al Shahri | D32: 1768 | E32: 0.25 | F32: =SUM(D32*E32) -> 442 | G32: =F32 -> 442 | H32: =F32-G32 -> 0 | I32: 14431965 | J32: 0439003719840022 | K32: BANK MUSCAT | L32: BMUSOMRX | M32: 99693775
A33: 30 | B33: 1371 | C33: Said Muhaisin Nassib Kikab AlShehri | D33: 1784.2 | E33: 0.25 | F33: =SUM(D33*E33) -> 446.05 | G33: =F33 -> 446.05 | H33: =F33-G33 -> 0 | I33: 990755 | J33: 1023260068017 | K33: NBO | L33: NBOMOMRX | M33: 92556210
A34: 31 | B34: 1372 | C34: Ali Said Zaidi Baitsaid | D34: 1791.4 | E34: 0.25 | F34: =SUM(D34*E34) -> 447.85 | G34: =F34 -> 447.85 | H34: =F34-G34 -> 0 | I34: 628655 | J34: 01040280343001 | K34: BANK DHOFAR | L34: BDOFOMRU | M34: 98976629
A35: 32 | B35: 1373 | C35: Salim Ahmed Tamman Baitsaid | D35: 636.3 | E35: 0.25 | F35: =SUM(D35*E35) -> 159.075 | G35: =F35 -> 159.075 | H35: =F35-G35 -> 0 | I35: 734281 | J35: 0397003883150015 | K35: BANK MUSCAT | L35: BMUSOMRX | M35: 99891516 | N35: 27-01-25-dcf
A36: 33 | B36: 1375 | C36: Muslim Mohammed Hassan Alash AlKathiri | D36: 638.6 | E36: 0.25 | F36: =SUM(D36*E36) -> 159.65 | G36: =F36 -> 159.65 | H36: =F36-G36 -> 0 | I36: 6748627 | J36: 0500067548104002 | K36: alizz Islamic Bank | L36: IZZBOMRU | M36: 93707700
A37: 34 | B37: 1377 | C37: Ali Masoud Awad Kikab AlShehri | D37: 591.4 | E37: 0.25 | F37: =SUM(D37*E37) -> 147.85 | G37: =F37 -> 147.85 | H37: =F37-G37 -> 0 | I37: 5160404 | J37: 01041074963001 | K37: BANK DHOFAR | L37: BDOFOMRU | M37: 91120322
A38: 35 | B38: 1378 | C38: Salem Ali Said Kikab AlShehri | D38: 2297.6 | E38: 0.25 | F38: =SUM(D38*E38) -> 574.4 | G38: =F38 -> 574.4 | H38: =F38-G38 -> 0 | I38: 5996404 | J38: 0439061391880013 | K38: Bank Muscat | L38: BMUSOMRX | M38: 98976878 | N38: 45684 | O38: 45963
A39: 36 | B39: 1381 | C39: Abdellah Masoud Said Al Shihri | D39: 601.2 | E39: 0.25 | F39: =SUM(D39*E39) -> 150.3 | G39: =F39 -> 150.3 | H39: =F39-G39 -> 0 | I39: 19847623 | J39: 10600349647017 | K39: NBO | L39: NBOMOMRX | M39: 92802427 | N39: 45635 | O39: 45663
A40: 37 | B40: 1390 | C40: Said Ahmed Said kikab Al shahri | D40: 581 | E40: 0.25 | F40: =SUM(D40*E40) -> 145.25 | G40: =F40 -> 145.25 | H40: =F40-G40 -> 0 | I40: 13826903 | J40: 0397021600910017 | K40: BANK MUSCAT | L40: BMUSOMRX | N40: 45637 | O40: 11-2-256
A41: 38 | B41: 1392 | C41: Ahmed Abdullah Ali Al Kathiri | D41: 1500 | E41: 0.25 | F41: =SUM(D41*E41) -> 375 | G41: =F41 -> 375 | H41: =F41-G41 -> 0 | I41: 1353348 | J41: 01010850137001 | K41: BANK DHOFAR | L41: BDOFOMRU
...

Sheet Center-oct
A1: Milk Chilling Centre(Ghado) - Monthly Cow Milk Procurement Report 01-10-2024 TO 31-10.2024
A2: SR. NO. | B2: Farmer Code | C2: Farmer Name | D2: Total Quantity Supplied(Lits) | E2: Cow Milk Price/Lit(OMR) | F2: Total Value Milk (OMR) | G2: Paid | H2: Balance | I2: ID No: | J2: Account No | K2: Bank Name | L2: IFSC Code | M2: Phone No: | N2: Remark
B4: 1010 | C4: Ahmed Ajham Omar Aghrib AlShehri | D4: 2291.3 | E4: 0.25 | F4: =SUM(D4*E4) -> 572.825 | G4: =F4 -> 572.825 | H4: =F4-G4 -> 0 | I4: 315313 | J4: 1006237426001 | K4: NBO | L4: NBOMOMRX | M4: 92600441
A5: 2 | B5: 1038 | C5: Salem Ahmed Said Majdah AlKathiri | D5: 2038 | E5: 0.25 | F5: =SUM(D5*E5) -> 509.5 | G5: =F5 -> 509.5 | H5: =F5-G5 -> 0 | I5: 5247837 | J5: 0406003267180024 | K5: BANK MUSCAT | L5: BMUSOMRX | M5: 99441537 | N5: 13-2-25
A6: 3 | B6: 1065 | C6: Ali Muhaisin Mohammed Humdi Al Saiari | D6: 636.2 | E6: 0.25 | F6: =SUM(D6*E6) -> 159.05 | G6: =F6 -> 159.05 | H6: =F6-G6 -> 0 | I6: 1276058 | J6: 0397003789920017 | K6: BANK MUSCAT | L6: BMUSOMRX | M6: 99498549
A7: 4 | B7: 1071 | C7: ALI MUSTAHIL MUBARAK ASAT AL SHIHRI | D7: 609.2 | E7: 0.25 | F7: =SUM(D7*E7) -> 152.3 | G7: =F7 -> 152.3 | H7: =F7-G7 -> 0 | I7: 390741 | J7: 01010120857001 | K7: BANK DHOFAR | L7: BDOFOMRU | M7: 99589144 | N7: 45663 | O7: 45679
A8: 5 | B8: 1086 | C8: Muslim Ali Said Hat AlShehri | D8: 1296.6 | E8: 0.25 | F8: =SUM(D8*E8) -> 324.15 | G8: =F8 -> 324.15 | H8: =F8-G8 -> 0 | I8: 2379573 | J8: 01010281105001 | K8: BANK DHOFAR | L8: BDOFOMRU | M8: 92917899 | N8: 45665 | O8: 45684
A9: 6 | B9: 1123 | C9: Hamid Mohammed Zidi Bait said | D9: 1314.4 | E9: 0.25 | F9: =SUM(D9*E9) -> 328.6 | G9: =F9 -> 328.6 | H9: =F9-G9 -> 0 | I9: 655141 | J9: 250097615001 | K9: HSBC | L9: BBMEOMRX | M9: 99485623 | N9: DCF feed
A10: 7 | B10: 1130 | C10: Hassan said jman alhalai | D10: 1069.1 | E10: 0.25 | F10: =SUM(D10*E10) -> 267.275 | G10: =F10 -> 267.275 | H10: =F10-G10 -> 0 | I10: 5485645 | J10: 0401003274570034 | K10: BANK MUSCAT | L10: BMUSOMRX | M10: 90977488
A11: 8 | B11: 1152 | C11: Mohammed Rajab Ali Al Mashikhi | D11: 1848.7 | E11: 0.25 | F11: =SUM(D11*E11) -> 462.175 | G11: =F11 -> 462.175 | H11: =F11-G11 -> 0 | I11: 5254327 | J11: 01011435284001 | K11: BANK DHOFAR | L11: BDOFOMRU | M11: 99692328
A12: 9 | B12: 1200 | C12: Muslim Ahmed Muslim AlKathiri | D12: 680.2 | E12: 0.25 | F12: =SUM(D12*E12) -> 170.05 | G12: =F12 -> 170.05 | H12: =F12-G12 -> 0 | I12: 7287174 | J12: 01010853216001 | K12: BANK DHOFAR | L12: BDOFOMRU | M12: 99673747 | N12: 45665 | O12: 45677
A13: 10 | B13: 1276 | C13: Masoud Salim Said Baitsaid | D13: 572 | E13: 0.25 | F13: =SUM(D13*E13) -> 143 | G13: =F13 -> 143 | H13: =F13-G13 -> 0 | I13: 334495 | J13: 0397003857450019 | K13: BANK MUSCAT | L13: BMUSOMRX | M13: 99170505
A14: 11 | B14: 1281 | C14: Salem Ali Masoud Baitsaid | D14: 1860 | E14: 0.25 | F14: =SUM(D14*E14) -> 465 | G14: =F14 -> 465 | H14: =F14-G14 -> 0 | I14: 6310986 | J14: 0406003431390019 | K14: BANK MUSCAT | L14: BMUSOMRX | M14: 92922944
A15: 12 | B15: 1308 | C15: Ahmed Said Mohammed Alash AlKathiri | D15: 660.5 | E15: 0.25 | F15: =SUM(D15*E15) -> 165.125 | G15: =F15 -> 165.125 | H15: =F15-G15 -> 0 | I15: 6225641 | J15: 01010407288003 | K15: BANK DHOFAR | L15: BDOFOMRU | M15: 92055550
A16: 13 | B16: 1337 | C16: Amer Bakhit Sohil Baitsaid | D16: 620 | E16: 0.25 | F16: =SUM(D16*E16) -> 155 | G16: =F16 -> 155 | H16: =F16-G16 -> 0 | I16: 6719626 | J16: 0401026589890018 | K16: BANK MUSCAT | L16: BMUSOMRX | M16: 97726288 | N16: 45670
A17: 14 | B17: 1339 | C17: Said Ahmed Ali Baitsaid | D17: 3604.6 | E17: 0.25 | F17: =SUM(D17*E17) -> 901.15 | G17: =F17 -> 901.15 | H17: =F17-G17 -> 0 | I17: 3090574 | J17: 01011207102001 | K17: BANK DHOFAR | L17: BDOFOMRU | M17: 99292421
A18: 15 | B18: 1340 | C18: Ahmed Suhail Ahmed Alash AlKathiri | D18: 1160.3 | E18: 0.25 | F18: =SUM(D18*E18) -> 290.075 | G18: =F18 -> 290.075 | H18: =F18-G18 -> 0 | I18: 7279274 | J18: 0204003564210038 | K18: Bank Muscat | L18: BMUSOMRX | M18: 93808816 | N18: 45657 | O18: 45684
A19: 16 | B19: 1341 | C19: Mahad Suhail Mahad Baitsaid | D19: 1408.2 | E19: 0.25 | F19: =SUM(D19*E19) -> 352.05 | G19: =F19 -> 352.05 | H19: =F19-G19 -> 0 | I19: 15977579 | J19: 0439003370920023 | K19: Bank Muscat | L19: BMUSOMRX | M19: 92578822
A20: 17 | B20: 1342 | C20: Mohammed Ali Said Al Nubi Al Kathiri | D20: 612.8 | E20: 0.25 | F20: =SUM(D20*E20) -> 153.2 | G20: =F20 -> 153.2 | H20: =F20-G20 -> 0 | I20: 13950469 | J20: 0406003373420026 | K20: Bank Muscat | L20: BMUSOMRX | M20: 92341118 | N20: 45658 | O20: 45686
A21: 18 | B21: 1343 | C21: Masoud Mahad Masoud Baitsaid | D21: 1213.4 | E21: 0.25 | F21: =SUM(D21*E21) -> 303.35 | G21: =F21 -> 303.35 | H21: =F21-G21 -> 0 | I21: 5160297 | J21: 01013045567001 | K21: BANK DHOFAR | L21: BDOFOMRU | M21: 93501199 | N21: 45679 | O21: 45691
A22: 19 | B22: 1345 | C22: Salim Said Ali Bait said | D22: 6031.4 | E22: 0.25 | F22: =SUM(D22*E22) -> 1507.85 | G22: =F22 -> 1507.85 | H22: =F22-G22 -> 0 | I22: 10578952 | J22: 3109378368700 | K22: OAB | L22: OMABOMRU | M22: 92194382
A23: 20 | B23: 1349 | C23: Muslim Suhail Salem Baitsaid | D23: 2374.2 | E23: 0.25 | F23: =SUM(D23*E23) -> 593.55 | G23: =F23 -> 593.55 | H23: =F23-G23 -> 0 | I23: 7128679 | J23: 0406003474800016 | K23: BANK MUSCAT | L23: BMUSOMRX | M23: 91408836
A24: 21 | B24: 1350 | C24: Ahmed Salem Zayed Baitsaid | D24: 4492.5 | E24: 0.25 | F24: =SUM(D24*E24) -> 1123.125 | G24: =F24 -> 1123.125 | H24: =F24-G24 -> 0 | I24: 6752017 | J24: 0396003246310013 | K24: BANK MUSCAT | L24: BMUSOMRX | M24: 92520708
A25: 22 | B25: 1353 | C25: Salem Amer Said Baitsaid | D25: 6179.8 | E25: 0.25 | F25: =SUM(D25*E25) -> 1544.95 | G25: =F25 -> 1544.95 | H25: =F25-G25 -> 0 | I25: 5217694 | J25: 01011109062001 | K25: BANK DHOFAR | L25: BDOFOMRU | M25: 92749180
A26: 23 | B26: 1355 | C26: Ahmed Zaidi Mahroos Baitsaid | D26: 2487.3 | E26: 0.25 | F26: =SUM(D26*E26) -> 621.825 | G26: =F26 -> 621.825 | H26: =F26-G26 -> 0 | I26: 585058 | J26: 01010940683001 | K26: BANK DHOFAR | L26: BDOFOMRU | M26: 99055262 | N26: 45963
A27: 24 | B27: 1356 | C27: Said Salem Said Asout AlShehri | D27: 843.9 | E27: 0.25 | F27: =SUM(D27*E27) -> 210.975 | G27: =F27 -> 210.975 | H27: =F27-G27 -> 0 | I27: 7494112 | J27: 0397050056020018 | K27: BANK MUSCAT | L27: BMUSOMRX | M27: 99488186
A28: 25 | B28: 1362 | C28: Ali Masoud Salem Baitsaid | D28: 2491.5 | E28: 0.25 | F28: =SUM(D28*E28) -> 622.875 | G28: =F28 -> 622.875 | H28: =F28-G28 -> 0 | I28: 2429041 | J28: 0397003875270017 | K28: BANK MUSCAT | L28: BMUSOMRX | M28: 93663694
A29: 26 | B29: 1363 | C29: Suhail Ali Said AlKathiri | D29: 2507.7 | E29: 0.25 | F29: =SUM(D29*E29) -> 626.925 | G29: =F29 -> 626.925 | H29: =F29-G29 -> 0 | I29: 322352 | J29: 0406003153460019 | K29: BANK MUSCAT | L29: BMUSOMRX | M29: 98842645
A30: 27 | B30: 1364 | C30: Omar Bakhit Ahmed Al Hilali | D30: 620 | E30: 0.25 | F30: =SUM(D30*E30) -> 155 | G30: =F30 -> 155 | H30: =F30-G30 -> 0 | I30: 7113811 | J30: 01010123044001 | K30: BANK DHOFAR | L30: BDOFOMRU | M30: 92969982 | N30: 45672
A31: 28 | B31: 1366 | C31: Ahmed Salem Ali Kikab AlShehri | D31: 2488.7 | E31: 0.25 | F31: =SUM(D31*E31) -> 622.175 | G31: =F31 -> 622.175 | H31: =F31-G31 -> 0 | I31: 8318385 | J31: 0406015165020012 | K31: BANK MUSCAT | L31: BMUSOMRX | M31: 90660210 | N31: 45684 | O31: 45963
A32: 29 | B32: 1370 | C32: Mohammed Ali Nassib Kikab Al Shahri | D32: 1822.7 | E32: 0.25 | F32: =SUM(D32*E32) -> 455.675 | G32: =F32 -> 455.675 | H32: =F32-G32 -> 0 | I32: 14431965 | J32: 0439003719840022 | K32: BANK MUSCAT | L32: BMUSOMRX | M32: 99693775
A33: 30 | B33: 1371 | C33: Said Muhaisin Nassib Kikab AlShehri | D33: 1857.4 | E33: 0.25 | F33: =SUM(D33*E33) -> 464.35 | G33: =F33 -> 464.35 | H33: =F33-G33 -> 0 | I33: 990755 | J33: 1023260068017 | K33: NBO | L33: NBOMOMRX | M33: 92556210
A34: 31 | B34: 1372 | C34: Ali Said Zaidi Baitsaid | D34: 1801.8 | E34: 0.25 | F34: =SUM(D34*E34) -> 450.45 | G34: =F34 -> 450.45 | H34: =F34-G34 -> 0 | I34: 628655 | J34: 01040280343001 | K34: BANK DHOFAR | L34: BDOFOMRU | M34: 98976629
A35: 32 | B35: 1373 | C35: Salim Ahmed Tamman Baitsaid | D35: 659.7 | E35: 0.25 | F35: =SUM(D35*E35) -> 164.925 | G35: =F35 -> 164.925 | H35: =F35-G35 -> 0 | I35: 734281 | J35: 0397003883150015 | K35: BANK MUSCAT | L35: BMUSOMRX | M35: 99891516 | N35: 27-01-25-dcf
A36: 33 | B36: 1375 | C36: Muslim Mohammed Hassan Alash AlKathiri | D36: 663.3 | E36: 0.25 | F36: =SUM(D36*E36) -> 165.825 | G36: =F36 -> 165.825 | H36: =F36-G36 -> 0 | I36: 6748627 | J36: 0500067548104002 | K36: alizz Islamic Bank | L36: IZZBOMRU | M36: 93707700
A37: 34 | B37: 1377 | C37: Ali Masoud Awad Kikab AlShehri | D37: 638.7 | E37: 0.25 | F37: =SUM(D37*E37) -> 159.675 | G37: =F37 -> 159.675 | H37: =F37-G37 -> 0 | I37: 5160404 | J37: 01041074963001 | K37: BANK DHOFAR | L37: BDOFOMRU | M37: 91120322
A38: 35 | B38: 1378 | C38: Salem Ali Said Kikab AlShehri | D38: 2393.6 | E38: 0.25 | F38: =SUM(D38*E38) -> 598.4 | G38: =F38 -> 598.4 | H38: =F38-G38 -> 0 | I38: 5996404 | J38: 0439061391880013 | K38: Bank Muscat | L38: BMUSOMRX | M38: 98976878 | N38: 45963
A39: 36 | B39: 1381 | C39: Abdellah Masoud Said Al Shihri | D39: 621.1 | E39: 0.25 | F39: =SUM(D39*E39) -> 155.275 | G39: =F39 -> 155.275 | H39: =F39-G39 -> 0 | I39: 19847623 | J39: 10600349647017 | K39: NBO | L39: NBOMOMRX | M39: 92802427 | N39: 45663 | O39: 45684
A40: 37 | B40: 1390 | C40: Said Ahmed Said kikab Al shahri | D40: 622.9 | E40: 0.25 | F40: =SUM(D40*E40) -> 155.725 | G40: =F40 -> 155.725 | H40: =F40-G40 -> 0 | I40: 13826903 | J40: 0397021600910017 | K40: BANK MUSCAT | L40: BMUSOMRX | N40: 45963
A41: 38 | B41: 1392 | C41: Ahmed Abdullah Ali Al Kathiri | D41: 1554.6 | E41: 0.25 | F41: =SUM(D41*E41) -> 388.65 | G41: =F41 -> 388.65 | H41: =F41-G41 -> 0 | I41: 1353348 | J41: 01010850137001 | K41: BANK DHOFAR | L41: BDOFOMRU
...

Sheet Center-Nov
A1: Milk Chilling Centre(Ghado) - Monthly Cow Milk Procurement Report 01-11-2024 TO 30-11-2024
A2: SR. NO. | B2: Farmer Code | C2: Farmer Name | D2: Total Quantity Supplied(Lits) | E2: Cow Milk Price/Lit(OMR) | F2: Total Value Milk (OMR) | G2: Total Value Milk (OMR) | H2: Total Value Milk (OMR) | I2: ID No: | J2: Account No | K2: Bank Name | L2: IFSC Code | M2: Phone No: | N2: Remark
A4: 1 | B4: 1010 | C4: Ahmed Ajham Omar Aghrib AlShehri | D4: 1898 | E4: 0.25 | F4: =SUM(D4*E4) -> 474.5 | G4: =F4 -> 474.5 | H4: =F4-G4 -> 0 | I4: 315313 | J4: 1006237426001 | K4: NBO | L4: NBOMOMRX | M4: 92600441
A5: 2 | B5: 1038 | C5: Salem Ahmed Said Majdah AlKathiri | D5: 1880.1 | E5: 0.25 | F5: =SUM(D5*E5) -> 470.025 | G5: =F5 -> 470.025 | H5: =F5-G5 -> 0 | I5: 5247837 | J5: 0406003267180024 | K5: BANK MUSCAT | L5: BMUSOMRX | M5: 99441537
A6: 3 | B6: 1065 | C6: Ali Muhaisin Mohammed Humdi Al Saiari | D6: 613.3 | E6: 0.25 | F6: =SUM(D6*E6) -> 153.325 | G6: =F6 -> 153.325 | H6: =F6-G6 -> 0 | I6: 1276058 | J6: 0397003789920017 | K6: BANK MUSCAT | L6: BMUSOMRX | M6: 99498549
A7: 4 | B7: 1071 | C7: ALI MUSTAHIL MUBARAK ASAT AL SHIHRI | D7: 534.4 | E7: 0.25 | F7: =SUM(D7*E7) -> 133.6 | G7: =F7 -> 133.6 | H7: =F7-G7 -> 0 | I7: 390741 | J7: 01010120857001 | K7: BANK DHOFAR | L7: BDOFOMRU | M7: 99589144 | N7: 45679
A8: 5 | B8: 1086 | C8: Muslim Ali Said Hat AlShehri | D8: 1159.9 | E8: 0.25 | F8: =SUM(D8*E8) -> 289.975 | G8: =F8 -> 289.975 | H8: =F8-G8 -> 0 | I8: 2379573 | J8: 01010281105001 | K8: BANK DHOFAR | L8: BDOFOMRU | M8: 92917899 | N8: 45684
A9: 6 | B9: 1123 | C9: Hamid Mohammed Zidi Bait said | D9: 1196.1 | E9: 0.25 | F9: =SUM(D9*E9) -> 299.025 | G9: =F9 -> 299.025 | H9: =F9-G9 -> 0 | I9: 655141 | J9: 250097615001 | K9: HSBC | L9: BBMEOMRX | M9: 99485623 | N9: dcf-28-01-25
A10: 7 | B10: 1130 | C10: Hassan said jman alhalai | D10: 1178.6 | E10: 0.25 | F10: =SUM(D10*E10) -> 294.65 | G10: =F10 -> 294.65 | H10: =F10-G10 -> 0 | I10: 5485645 | J10: 0401003274570034 | K10: BANK MUSCAT | L10: BMUSOMRX | M10: 90977488
A11: 8 | B11: 1152 | C11: Mohammed Rajab Ali Al Mashikhi | D11: 1734.9 | E11: 0.25 | F11: =SUM(D11*E11) -> 433.725 | G11: =F11 -> 433.725 | H11: =F11-G11 -> 0 | I11: 5254327 | J11: 01011435284001 | K11: BANK DHOFAR | L11: BDOFOMRU | M11: 99692328
A12: 9 | B12: 1200 | C12: Muslim Ahmed Muslim AlKathiri | D12: 259.3 | E12: 0.25 | F12: =SUM(D12*E12) -> 64.825 | G12: =F12 -> 64.825 | H12: =F12-G12 -> 0 | I12: 7287174 | J12: 01010853216001 | K12: BANK DHOFAR | L12: BDOFOMRU | M12: 99673747 | N12: 45677
A13: 10 | B13: 1276 | C13: Masoud Salim Said Baitsaid | D13: 524.4 | E13: 0.25 | F13: =SUM(D13*E13) -> 131.1 | G13: =F13 -> 131.1 | H13: =F13-G13 -> 0 | I13: 334495 | J13: 0397003857450019 | K13: BANK MUSCAT | L13: BMUSOMRX | M13: 99170505
A14: 11 | B14: 1281 | C14: Salem Ali Masoud Baitsaid | D14: 1739 | E14: 0.25 | F14: =SUM(D14*E14) -> 434.75 | G14: =F14 -> 434.75 | H14: =F14-G14 -> 0 | I14: 6310986 | J14: 0406003431390019 | K14: BANK MUSCAT | L14: BMUSOMRX | M14: 92922944
A15: 12 | B15: 1308 | C15: Ahmed Said Mohammed Alash AlKathiri | D15: 610.7 | E15: 0.25 | F15: =SUM(D15*E15) -> 152.675 | G15: =F15 -> 152.675 | H15: =F15-G15 -> 0 | I15: 6225641 | J15: 01010407288003 | K15: BANK DHOFAR | L15: BDOFOMRU | M15: 92055550
A16: 13 | B16: 1337 | C16: Amer Bakhit Sohil Baitsaid | D16: 568.8 | E16: 0.25 | F16: =SUM(D16*E16) -> 142.2 | G16: =F16 -> 142.2 | H16: =F16-G16 -> 0 | I16: 6719626 | J16: 0401026589890018 | K16: BANK MUSCAT | L16: BMUSOMRX | M16: 97726288
A17: 14 | B17: 1339 | C17: Said Ahmed Ali Baitsaid | D17: 5067.5 | E17: 0.25 | F17: =SUM(D17*E17) -> 1266.875 | G17: =F17 -> 1266.875 | H17: =F17-G17 -> 0 | I17: 3090574 | J17: 01011207102001 | K17: BANK DHOFAR | L17: BDOFOMRU | M17: 99292421
A18: 15 | B18: 1340 | C18: Ahmed Suhail Ahmed Alash AlKathiri | D18: 974.6 | E18: 0.25 | F18: =SUM(D18*E18) -> 243.65 | G18: =F18 -> 243.65 | H18: =F18-G18 -> 0 | I18: 7279274 | J18: 0204003564210038 | K18: Bank Muscat | L18: BMUSOMRX | M18: 93808816 | N18: 45684
A19: 16 | B19: 1341 | C19: Mahad Suhail Mahad Baitsaid | D19: 1302.2 | E19: 0.25 | F19: =SUM(D19*E19) -> 325.55 | G19: =F19 -> 325.55 | H19: =F19-G19 -> 0 | I19: 15977579 | J19: 0439003370920023 | K19: Bank Muscat | L19: BMUSOMRX | M19: 92578822
A20: 17 | B20: 1342 | C20: Mohammed Ali Said Al Nubi Al Kathiri | D20: 543.9 | E20: 0.25 | F20: =SUM(D20*E20) -> 135.975 | G20: =F20 -> 135.975 | H20: =F20-G20 -> 0 | I20: 13950469 | J20: 0406003373420026 | K20: Bank Muscat | L20: BMUSOMRX | M20: 92341118 | N20: 45686 | O20: 45691
A21: 18 | B21: 1343 | C21: Masoud Mahad Masoud Baitsaid | D21: 1111.7 | E21: 0.25 | F21: =SUM(D21*E21) -> 277.925 | G21: =F21 -> 277.925 | H21: =F21-G21 -> 0 | I21: 5160297 | J21: 01013045567001 | K21: BANK DHOFAR | L21: BDOFOMRU | M21: 93501199 | N21: 45691
A22: 19 | B22: 1345 | C22: Salim Said Ali Bait said | D22: 5508 | E22: 0.25 | F22: =SUM(D22*E22) -> 1377 | G22: =F22 -> 1377 | H22: =F22-G22 -> 0 | I22: 10578952 | J22: 3109378368700 | K22: OAB | L22: OMABOMRU | M22: 92194382
A23: 20 | B23: 1349 | C23: Muslim Suhail Salem Baitsaid | D23: 2035.8 | E23: 0.25 | F23: =SUM(D23*E23) -> 508.95 | G23: =F23 -> 508.95 | H23: =F23-G23 -> 0 | I23: 7128679 | J23: 0406003474800016 | K23: BANK MUSCAT | L23: BMUSOMRX | M23: 91408836
A24: 21 | B24: 1350 | C24: Ahmed Salem Zayed Baitsaid | D24: 4168.8 | E24: 0.25 | F24: =SUM(D24*E24) -> 1042.2 | G24: =F24 -> 1042.2 | H24: =F24-G24 -> 0 | I24: 6752017 | J24: 0396003246310013 | K24: BANK MUSCAT | L24: BMUSOMRX | M24: 92520708
A25: 22 | B25: 1353 | C25: Salem Amer Said Baitsaid | D25: 5799.5 | E25: 0.25 | F25: =SUM(D25*E25) -> 1449.875 | G25: =F25 -> 1449.875 | H25: =F25-G25 -> 0 | I25: 5217694 | J25: 01011109062001 | K25: BANK DHOFAR | L25: BDOFOMRU | M25: 92749180
A26: 23 | B26: 1355 | C26: Ahmed Zaidi Mahroos Baitsaid | D26: 2342.8 | E26: 0.25 | F26: =SUM(D26*E26) -> 585.7 | G26: =F26 -> 585.7 | H26: =F26-G26 -> 0 | I26: 585058 | J26: 01010940683001 | K26: BANK DHOFAR | L26: BDOFOMRU | M26: 99055262 | N26: 45963
A27: 24 | B27: 1356 | C27: Said Salem Said Asout AlShehri | D27: 636.4 | E27: 0.25 | F27: =SUM(D27*E27) -> 159.1 | G27: =F27 -> 159.1 | H27: =F27-G27 -> 0 | I27: 7494112 | J27: 0397050056020018 | K27: BANK MUSCAT | L27: BMUSOMRX | M27: 99488186
A28: 25 | B28: 1362 | C28: Ali Masoud Salem Baitsaid | D28: 2329.6 | E28: 0.25 | F28: =SUM(D28*E28) -> 582.4 | G28: =F28 -> 582.4 | H28: =F28-G28 -> 0 | I28: 2429041 | J28: 0397003875270017 | K28: BANK MUSCAT | L28: BMUSOMRX | M28: 93663694
A29: 26 | B29: 1363 | C29: Suhail Ali Said AlKathiri | D29: 2444.1 | E29: 0.25 | F29: =SUM(D29*E29) -> 611.025 | G29: =F29 -> 611.025 | H29: =F29-G29 -> 0 | I29: 322352 | J29: 0406003153460019 | K29: BANK MUSCAT | L29: BMUSOMRX | M29: 98842645
A30: 27 | B30: 1364 | C30: Omar Bakhit Ahmed Al Hilali | D30: 572.9 | E30: 0.25 | F30: =SUM(D30*E30) -> 143.225 | G30: =F30 -> 143.225 | H30: =F30-G30 -> 0 | I30: 7113811 | J30: 01010123044001 | K30: BANK DHOFAR | L30: BDOFOMRU | M30: 92969982
A31: 28 | B31: 1366 | C31: Ahmed Salem Ali Kikab AlShehri | D31: 2331 | E31: 0.25 | F31: =SUM(D31*E31) -> 582.75 | G31: =F31 -> 582.75 | H31: =F31-G31 -> 0 | I31: 8318385 | J31: 0406015165020012 | K31: BANK MUSCAT | L31: BMUSOMRX | M31: 90660210 | N31: 45963
A32: 29 | B32: 1370 | C32: Mohammed Ali Nassib Kikab Al Shahri | D32: 1546.6 | E32: 0.25 | F32: =SUM(D32*E32) -> 386.65 | G32: =F32 -> 386.65 | H32: =F32-G32 -> 0 | I32: 14431965 | J32: 0439003719840022 | K32: BANK MUSCAT | L32: BMUSOMRX | M32: 99693775
A33: 30 | B33: 1371 | C33: Said Muhaisin Nassib Kikab AlShehri | D33: 1698.6 | E33: 0.25 | F33: =SUM(D33*E33) -> 424.65 | G33: =F33 -> 424.65 | H33: =F33-G33 -> 0 | I33: 990755 | J33: 1023260068017 | K33: NBO | L33: NBOMOMRX | M33: 92556210
A34: 31 | B34: 1372 | C34: Ali Said Zaidi Baitsaid | D34: 1436.1 | E34: 0.25 | F34: =SUM(D34*E34) -> 359.025 | G34: =F34 -> 359.025 | H34: =F34-G34 -> 0 | I34: 628655 | J34: 01040280343001 | K34: BANK DHOFAR | L34: BDOFOMRU | M34: 98976629
A35: 32 | B35: 1373 | C35: Salim Ahmed Tamman Baitsaid | D35: 610.2 | E35: 0.25 | F35: =SUM(D35*E35) -> 152.55 | G35: =F35 -> 152.55 | H35: =F35-G35 -> 0 | I35: 734281 | J35: 0397003883150015 | K35: BANK MUSCAT | L35: BMUSOMRX | M35: 99891516 | N35: 27-01-25-dcf
A36: 33 | B36: 1375 | C36: Muslim Mohammed Hassan Alash AlKathiri | D36: 602.7 | E36: 0.25 | F36: =SUM(D36*E36) -> 150.675 | G36: =F36 -> 150.675 | H36: =F36-G36 -> 0 | I36: 6748627 | J36: 0500067548104002 | K36: alizz Islamic Bank | L36: IZZBOMRU | M36: 93707700
A37: 34 | B37: 1377 | C37: Ali Masoud Awad Kikab AlShehri | D37: 564.8 | E37: 0.25 | F37: =SUM(D37*E37) -> 141.2 | G37: =F37 -> 141.2 | H37: =F37-G37 -> 0 | I37: 5160404 | J37: 01041074963001 | K37: BANK DHOFAR | L37: BDOFOMRU | M37: 91120322
A38: 35 | B38: 1378 | C38: Salem Ali Said Kikab AlShehri | D38: 2092.9 | E38: 0.25 | F38: =SUM(D38*E38) -> 523.225 | G38: =F38 -> 523.225 | H38: =F38-G38 -> 0 | I38: 5996404 | J38: 0439061391880013 | K38: Bank Muscat | L38: BMUSOMRX | M38: 98976878
A39: 36 | B39: 1381 | C39: Abdellah Masoud Said Al Shihri | D39: 595.2 | E39: 0.25 | F39: =SUM(D39*E39) -> 148.8 | G39: =F39 -> 148.8 | H39: =F39-G39 -> 0 | I39: 19847623 | J39: 10600349647017 | K39: NBO | L39: NBOMOMRX | M39: 92802427 | N39: 45684
A40: 37 | B40: 1390 | C40: Said Ahmed Said kikab Al shahri | D40: 542.2 | E40: 0.25 | F40: =SUM(D40*E40) -> 135.55 | G40: =F40 -> 135.55 | H40: =F40-G40 -> 0 | I40: 13826903 | J40: 0397021600910017 | K40: BANK MUSCAT | L40: BMUSOMRX
A41: 38 | B41: 1392 | C41: Ahmed Abdullah Ali Al Kathiri | D41: 1450.5 | E41: 0.25 | F41: =SUM(D41*E41) -> 362.625 | G41: =F41 -> 362.625 | H41: =F41-G41 -> 0 | I41: 1353348 | J41: 01010850137001 | K41: BANK DHOFAR | L41: BDOFOMRU
...

Sheet center-dec
A1: Milk Chilling Centre(Ghado) - Monthly Cow Milk Procurement Report 01-12-2024 TO 31-12-2024
A2: SR. NO. | B2: Farmer Code | C2: Farmer Name | D2: Total Quantity Supplied(Lits) | E2: Cow Milk Price/Lit(OMR) | F2: Total Value Milk (OMR) | G2: Paid | H2: Balance | I2: ID No: | J2: Account No | K2: Bank Name | L2: IFSC Code | M2: Phone No: | N2: Remark
A4: 1 | B4: 1010 | C4: Ahmed Ajham Omar Aghrib AlShehri | D4: 2229.2 | E4: 0.25 | F4: =SUM(D4*E4) -> 557.3 | G4: =F4 -> 557.3 | H4: =F4-G4 -> 0 | I4: 315313 | J4: 1006237426001 | K4: NBO | L4: NBOMOMRX | M4: 92600441
A5: 2 | B5: 1038 | C5: Salem Ahmed Said Majdah AlKathiri | D5: 2034 | E5: 0.25 | F5: =SUM(D5*E5) -> 508.5 | G5: =F5 -> 508.5 | H5: =F5-G5 -> 0 | I5: 5247837 | J5: 0406003267180024 | K5: BANK MUSCAT | L5: BMUSOMRX | M5: 99441537
A6: 3 | B6: 1065 | C6: Ali Muhaisin Mohammed Humdi Al Saiari | D6: 637.9 | E6: 0.25 | F6: =SUM(D6*E6) -> 159.475 | G6: =F6 -> 159.475 | H6: =F6-G6 -> 0 | I6: 1276058 | J6: 0397003789920017 | K6: BANK MUSCAT | L6: BMUSOMRX | M6: 99498549
A7: 4 | B7: 1071 | C7: ALI MUSTAHIL MUBARAK ASAT AL SHIHRI | D7: 591.1 | E7: 0.25 | F7: =SUM(D7*E7) -> 147.775 | G7: =F7 -> 147.775 | H7: =F7-G7 -> 0 | I7: 390741 | J7: 01010120857001 | K7: BANK DHOFAR | L7: BDOFOMRU | M7: 99589144
A8: 5 | B8: 1086 | C8: Muslim Ali Said Hat AlShehri | D8: 1289.5 | E8: 0.25 | F8: =SUM(D8*E8) -> 322.375 | G8: =F8 -> 322.375 | H8: =F8-G8 -> 0 | I8: 2379573 | J8: 01010281105001 | K8: BANK DHOFAR | L8: BDOFOMRU | M8: 92917899
A9: 6 | B9: 1123 | C9: Hamid Mohammed Zidi Bait said | D9: 1132.8 | E9: 0.25 | F9: =SUM(D9*E9) -> 283.2 | G9: =F9 -> 283.2 | H9: =F9-G9 -> 0 | I9: 655141 | J9: 250097615001 | K9: HSBC | L9: BBMEOMRX | M9: 99485623 | N9: 18-2-25
A10: 7 | B10: 1130 | C10: Hassan said jman alhalai | D10: 1225.1 | E10: 0.25 | F10: =SUM(D10*E10) -> 306.275 | G10: =F10 -> 306.275 | H10: =F10-G10 -> 0 | I10: 5485645 | J10: 0401003274570034 | K10: BANK MUSCAT | L10: BMUSOMRX | M10: 90977488
A11: 8 | B11: 1152 | C11: Mohammed Rajab Ali Al Mashikhi | D11: 1860 | E11: 0.25 | F11: =SUM(D11*E11) -> 465 | G11: =F11 -> 465 | H11: =F11-G11 -> 0 | I11: 5254327 | J11: 01011435284001 | K11: BANK DHOFAR | L11: BDOFOMRU | M11: 99692328
A12: 9 | B12: 1200 | C12: Muslim Ahmed Muslim AlKathiri | D12: 243.2 | E12: 0.25 | F12: =SUM(D12*E12) -> 60.8 | G12: =F12 -> 60.8 | H12: =F12-G12 -> 0 | I12: 7287174 | J12: 01010853216001 | K12: BANK DHOFAR | L12: BDOFOMRU | M12: 99673747
A13: 10 | B13: 1276 | C13: Masoud Salim Said Baitsaid | D13: 497.5 | E13: 0.25 | F13: =SUM(D13*E13) -> 124.375 | G13: =F13 -> 124.375 | H13: =F13-G13 -> 0 | I13: 334495 | J13: 0397003857450019 | K13: BANK MUSCAT | L13: BMUSOMRX | M13: 99170505
A14: 11 | B14: 1281 | C14: Salem Ali Masoud Baitsaid | D14: 1860 | E14: 0.25 | F14: =SUM(D14*E14) -> 465 | G14: =F14 -> 465 | H14: =F14-G14 -> 0 | I14: 6310986 | J14: 0406003431390019 | K14: BANK MUSCAT | L14: BMUSOMRX | M14: 92922944
A15: 12 | B15: 1308 | C15: Ahmed Said Mohammed Alash AlKathiri | D15: 650.3 | E15: 0.25 | F15: =SUM(D15*E15) -> 162.575 | G15: =F15 -> 162.575 | H15: =F15-G15 -> 0 | I15: 6225641 | J15: 01010407288003 | K15: BANK DHOFAR | L15: BDOFOMRU | M15: 92055550
A16: 13 | B16: 1337 | C16: Amer Bakhit Sohil Baitsaid | D16: 632 | E16: 0.25 | F16: =SUM(D16*E16) -> 158 | G16: =F16 -> 158 | H16: =F16-G16 -> 0 | I16: 6719626 | J16: 0401026589890018 | K16: BANK MUSCAT | L16: BMUSOMRX | M16: 97726288
A17: 14 | B17: 1339 | C17: Said Ahmed Ali Baitsaid | D17: 5643.5 | E17: 0.25 | F17: =SUM(D17*E17) -> 1410.875 | G17: =F17 -> 1410.875 | H17: =F17-G17 -> 0 | I17: 3090574 | J17: 01011207102001 | K17: BANK DHOFAR | L17: BDOFOMRU | M17: 99292421
A18: 15 | B18: 1340 | C18: Ahmed Suhail Ahmed Alash AlKathiri | D18: 607.5 | E18: 0.25 | F18: =SUM(D18*E18) -> 151.875 | G18: =F18 -> 151.875 | H18: =F18-G18 -> 0 | I18: 7279274 | J18: 0204003564210038 | K18: Bank Muscat | L18: BMUSOMRX | M18: 93808816
A19: 16 | B19: 1341 | C19: Mahad Suhail Mahad Baitsaid | D19: 1388.8 | E19: 0.25 | F19: =SUM(D19*E19) -> 347.2 | G19: =F19 -> 347.2 | H19: =F19-G19 -> 0 | I19: 15977579 | J19: 0439003370920023 | K19: Bank Muscat | L19: BMUSOMRX | M19: 92578822
A20: 17 | B20: 1342 | C20: Mohammed Ali Said Al Nubi Al Kathiri | D20: 627.1 | E20: 0.25 | F20: =SUM(D20*E20) -> 156.775 | G20: =F20 -> 156.775 | H20: =F20-G20 -> 0 | I20: 13950469 | J20: 0406003373420026 | K20: Bank Muscat | L20: BMUSOMRX | M20: 92341118 | N20: 45692
A21: 18 | B21: 1343 | C21: Masoud Mahad Masoud Baitsaid | D21: 1223.9 | E21: 0.25 | F21: =SUM(D21*E21) -> 305.975 | G21: =F21 -> 305.975 | H21: =F21-G21 -> 0 | I21: 5160297 | J21: 01013045567001 | K21: BANK DHOFAR | L21: BDOFOMRU | M21: 93501199
A22: 19 | B22: 1345 | C22: Salim Said Ali Bait said | D22: 6192.9 | E22: 0.25 | F22: =SUM(D22*E22) -> 1548.225 | G22: =F22 -> 1548.225 | H22: =F22-G22 -> 0 | I22: 10578952 | J22: 3109378368700 | K22: OAB | L22: OMABOMRU | M22: 92194382
A23: 20 | B23: 1349 | C23: Muslim Suhail Salem Baitsaid | D23: 2338.2 | E23: 0.25 | F23: =SUM(D23*E23) -> 584.55 | G23: =F23 -> 584.55 | H23: =F23-G23 -> 0 | I23: 7128679 | J23: 0406003474800016 | K23: BANK MUSCAT | L23: BMUSOMRX | M23: 91408836
A24: 21 | B24: 1350 | C24: Ahmed Salem Zayed Baitsaid | D24: 4434.3 | E24: 0.25 | F24: =SUM(D24*E24) -> 1108.575 | G24: =F24 -> 1108.575 | H24: =F24-G24 -> 0 | I24: 6752017 | J24: 0396003246310013 | K24: BANK MUSCAT | L24: BMUSOMRX | M24: 92520708
A25: 22 | B25: 1353 | C25: Salem Amer Said Baitsaid | D25: 6180.3 | E25: 0.25 | F25: =SUM(D25*E25) -> 1545.075 | G25: =F25 -> 1545.075 | H25: =F25-G25 -> 0 | I25: 5217694 | J25: 01011109062001 | K25: BANK DHOFAR | L25: BDOFOMRU | M25: 92749180 | N25: 18-12-25 | O25: 402-dfi | P25: 1139.75 deduct form 01-25
A26: 23 | B26: 1355 | C26: Ahmed Zaidi Mahroos Baitsaid | D26: 2483.6 | E26: 0.25 | F26: =SUM(D26*E26) -> 620.9 | G26: =F26 -> 620.9 | H26: =F26-G26 -> 0 | I26: 585058 | J26: 01010940683001 | K26: BANK DHOFAR | L26: BDOFOMRU | M26: 99055262
A27: 24 | B27: 1356 | C27: Said Salem Said Asout AlShehri | D27: 759.9 | E27: 0.25 | F27: =SUM(D27*E27) -> 189.975 | G27: =F27 -> 189.975 | H27: =F27-G27 -> 0 | I27: 7494112 | J27: 0397050056020018 | K27: BANK MUSCAT | L27: BMUSOMRX | M27: 99488186
A28: 25 | B28: 1362 | C28: Ali Masoud Salem Baitsaid | D28: 2503.8 | E28: 0.25 | F28: =SUM(D28*E28) -> 625.95 | G28: =F28 -> 625.95 | H28: =F28-G28 -> 0 | I28: 2429041 | J28: 0397003875270017 | K28: BANK MUSCAT | L28: BMUSOMRX | M28: 93663694
A29: 26 | B29: 1363 | C29: Suhail Ali Said AlKathiri | D29: 2633.7 | E29: 0.25 | F29: =SUM(D29*E29) -> 658.425 | G29: =F29 -> 658.425 | H29: =F29-G29 -> 0 | I29: 322352 | J29: 0406003153460019 | K29: BANK MUSCAT | L29: BMUSOMRX | M29: 98842645
A30: 27 | B30: 1364 | C30: Omar Bakhit Ahmed Al Hilali | D30: 614.5 | E30: 0.25 | F30: =SUM(D30*E30) -> 153.625 | G30: =F30 -> 153.625 | H30: =F30-G30 -> 0 | I30: 7113811 | J30: 01010123044001 | K30: BANK DHOFAR | L30: BDOFOMRU | M30: 92969982
A31: 28 | B31: 1366 | C31: Ahmed Salem Ali Kikab AlShehri | D31: 2498.1 | E31: 0.25 | F31: =SUM(D31*E31) -> 624.525 | G31: =F31 -> 624.525 | H31: =F31-G31 -> 0 | I31: 8318385 | J31: 0406015165020012 | K31: BANK MUSCAT | L31: BMUSOMRX | M31: 90660210
A32: 29 | B32: 1370 | C32: Mohammed Ali Nassib Kikab Al Shahri | D32: 1345.4 | E32: 0.25 | F32: =SUM(D32*E32) -> 336.35 | G32: =F32 -> 336.35 | H32: =F32-G32 -> 0 | I32: 14431965 | J32: 0439003719840022 | K32: BANK MUSCAT | L32: BMUSOMRX | M32: 99693775
A33: 30 | B33: 1371 | C33: Said Muhaisin Nassib Kikab AlShehri | D33: 1851.7 | E33: 0.25 | F33: =SUM(D33*E33) -> 462.925 | G33: =F33 -> 462.925 | H33: =F33-G33 -> 0 | I33: 990755 | J33: 1023260068017 | K33: NBO | L33: NBOMOMRX | M33: 92556210
A34: 31 | B34: 1372 | C34: Ali Said Zaidi Baitsaid | D34: 1794.1 | E34: 0.25 | F34: =SUM(D34*E34) -> 448.525 | G34: =F34 -> 448.525 | H34: =F34-G34 -> 0 | I34: 628655 | J34: 01040280343001 | K34: BANK DHOFAR | L34: BDOFOMRU | M34: 98976629
A35: 32 | B35: 1373 | C35: Salim Ahmed Tamman Baitsaid | D35: 654.4 | E35: 0.25 | F35: =SUM(D35*E35) -> 163.6 | G35: =F35 -> 163.6 | H35: =F35-G35 -> 0 | I35: 734281 | J35: 0397003883150015 | K35: BANK MUSCAT | L35: BMUSOMRX | M35: 99891516 | N35: 25-2-25
A36: 33 | B36: 1375 | C36: Muslim Mohammed Hassan Alash AlKathiri | D36: 655 | E36: 0.25 | F36: =SUM(D36*E36) -> 163.75 | G36: =F36 -> 163.75 | H36: =F36-G36 -> 0 | I36: 6748627 | J36: 0500067548104002 | K36: alizz Islamic Bank | L36: IZZBOMRU | M36: 93707700
A37: 34 | B37: 1377 | C37: Ali Masoud Awad Kikab AlShehri | D37: 572.7 | E37: 0.25 | F37: =SUM(D37*E37) -> 143.175 | G37: =F37 -> 143.175 | H37: =F37-G37 -> 0 | I37: 5160404 | J37: 01041074963001 | K37: BANK DHOFAR | L37: BDOFOMRU | M37: 91120322
A38: 35 | B38: 1378 | C38: Salem Ali Said Kikab AlShehri | D38: 2039.8 | E38: 0.25 | F38: =SUM(D38*E38) -> 509.95 | G38: =F38 -> 509.95 | H38: =F38-G38 -> 0 | I38: 5996404 | J38: 0439061391880013 | K38: Bank Muscat | L38: BMUSOMRX | M38: 98976878
A39: 36 | B39: 1381 | C39: Abdellah Masoud Said Al Shihri | D39: 633.8 | E39: 0.25 | F39: =SUM(D39*E39) -> 158.45 | G39: =F39 -> 158.45 | H39: =F39-G39 -> 0 | I39: 19847623 | J39: 10600349647017 | K39: NBO | L39: NBOMOMRX | M39: 92802427 | N39: 20-2-25 | P39: .250 will deduct from jan 25
A40: 37 | B40: 1390 | C40: Said Ahmed Said kikab Al shahri | D40: 484.3 | E40: 0.25 | F40: =SUM(D40*E40) -> 121.075 | G40: =F40 -> 121.075 | H40: =F40-G40 -> 0 | I40: 13826903 | J40: 0397021600910017 | K40: BANK MUSCAT | L40: BMUSOMRX
A41: 38 | B41: 1392 | C41: Ahmed Abdullah Ali Al Kathiri | D41: 1549.2 | E41: 0.25 | F41: =SUM(D41*E41) -> 387.3 | G41: =F41 -> 387.3 | H41: =F41-G41 -> 0 | I41: 1353348 | J41: 01010850137001 | K41: BANK DHOFAR | L41: BDOFOMRU
...

Sheet Purcahse Request
A6: AL MOROOJ DAIRY CO SAOC
A7: CR NO:1249988
A8: P.O BOX: 1385,PC-211
A9: VAT:OM1100091687
A10: SALALAH, SULTANATE OF OMAN
A12: PURCHASE REQUEST
A14: Farmer Name | B14: =IFERROR(VLOOKUP(B15,#REF!, 2, FALSE), "") | D14: PR Ref:
A15: Farmer Code | B15: 1343 | D15: PR Date: | E15: =TODAY() -> 46033
A16: Farmer ID | B16: =IFERROR(VLOOKUP(B15,#REF!, 8, FALSE), "")
A18: أسم المنتج / Product | B18: الوزن بالكيلوا / Weight | C18: السعر / Price | D18: الكمية / Quantity | E18: إجمالي المبلغ / Total
A19: مراعي ظفار Marai Dhofar | B19: 50 | C19: 6.25 | D19: 0 | E19: =C19*D19 -> 0 | F19: =IFERROR(VLOOKUP(B15,#REF!,7,FALSE),"") | G19: 1 | H19: =IFERROR(VLOOKUP(B15,#REF!,3,FALSE),"") | K19: .
A20: مراعي ظفار Marai Dhofar | B20: 40 | C20: 4.85 | D20: 0 | E20: =C20*D20 -> 0 | F20: =IFERROR(VLOOKUP(B15,#REF!,7,FALSE),"") | G20: 2 | H20: =IFERROR(VLOOKUP(B15,#REF!,3,FALSE),"")
A21: العلف الكامل Whole Feed | B21: 40 | C21: 4.75 | D21: 0 | E21: =C21*D21 -> 0 | F21: =IFERROR(VLOOKUP(B15,#REF!,7,FALSE),"") | G21: 3 | H21: =IFERROR(VLOOKUP(B15,#REF!,3,FALSE),"")
