Workbook

Sheet center-April
A1: HAJEEF CAMEL MILK PROCUREMENT FROM 01-APR-2024 TO 30-APR-2024
A3: Sr. No. | B3: Farmer Code | C3: Farmer Name | D3: Total Milk Qty | E3: Avg. Rate (OMR/Ltr.) | F3: Amount (OMR) | G3: paid | H3: balance | I3: ID No. | J3: remark 2
A4: 1 | B4: 1474 | C4: Mohamed Salam Amer Al Yafee | D4: 1158.9 | E4: 0.4 | F4: =E4*D4 -> 463.56 | G4: =460.75+2.81 -> 463.56 | H4: =F4-G4 -> 0 | I4: 4603773 | J4: 19-08-2024-feeds
A5: 2 | B5: 3136 | C5: Ghazi Salim Ahmed Al Kathiri | D5: 930.6 | E5: 0.4 | F5: =E5*D5 -> 372.24 | G5: =370.15+2.09 -> 372.24 | H5: =F5-G5 -> 0 | I5: 183498 | J5: 13-08-2024-FEEDS
A6: 4 | B6: 3700 | C6: Said Ahmed Suhail Alkathiri | D6: 1352.4 | E6: 0.4 | F6: 498.96 | G6: 498.96 | H6: =F6-G6 -> 0 | I6: 19729836
A7: 6 | B7: 3765 | C7: Wafi Musallam Ahmed Almasahli | D7: 1216 | E7: 0.4 | F7: =E7*D7 -> 486.4 | G7: =485.75+0.65 -> 486.4 | H7: =F7-G7 -> 0 | I7: 19752023 | J7: 19-08-2024-feeds | K7: 45663
A8: 7 | B8: 3770 | C8: Ali Mohammed Suhail Ghawas | D8: 340.2 | E8: 0.4 | F8: =E8*D8 -> 136.08 | G8: 135.8 | H8: =F8-G8 -> 0.28 | I8: 7198036 | J8: 18-08-2024-feeds
A9: 9 | B9: 3871 | C9: Ahmed Mohammed Ahmed Jashuul | D9: 1231.3 | E9: 0.4 | F9: =E9*D9 -> 492.52 | G9: =488.9+3.62 -> 492.52 | H9: =F9-G9 -> 0 | I9: 6920684 | J9: 14-08-24-feed
A10: 10 | B10: 3877 | C10: Musallm hassan Abdullah Khdhran Al Kathiri | D10: 475.7 | E10: 0.4 | F10: =E10*D10 -> 190.28 | G10: =187.85+2.43 -> 190.28 | H10: =F10-G10 -> 0 | I10: 14897254 | J10: 18-08-2024-feeds | K10: 13-01-25-dcf
C11: TOTAL | D11: =SUM(D4:D10) -> 6705.1 | F11: =SUM(F4:F10) -> 2640.04 | G11: =SUM(G4:G10) -> 2639.76 | H11: =SUM(H4:H10) -> 0.28
G13: Apr | H13: =H11 -> 0.28
G14: May | H14: ='center-May'!H32 -> 0
A15: Hassan Ghaly | E15: Sakku Mathew | G15: June | H15: ='06'!H57 -> 4.15
G16: July | H16: ='center-July'!H312 -> 0
G17: Aug | H17: ='center-Aug'!H309 -> 14.05
G18: Sep | H18: ='Center-Sept'!H312 -> 14434.09
G19: Oct | H19: 58708.52
G20: Nov | H20: 49811.8

Sheet center-May
A1: HAJEEF CAMEL MILK PROCUREMENT FROM 01-May-2024 TO 31-May-2024
A3: Sr. No. | B3: Farmer Code | C3: Farmer Name | D3: Total Milk Qty | E3: Avg. Rate (OMR/Ltr.) | F3: Amount (OMR) | G3: paid | H3: balance | I3: ID No. | J3: remark 2
A4: 1 | B4: 1431 | C4: Bakhit Mohamed Salim Rawas | D4: 440 | E4: 0.4 | F4: =E4*D4 -> 176 | G4: =174.6+1.4 -> 176 | H4: =F4-G4 -> 0 | I4: 721445 | J4: 26-08-2024-feeds | K4: 45607
A5: 2 | B5: 1483 | C5: Saed Ali Ahmed Al Kathiri | D5: 1140 | E5: 0.4 | F5: =E5*D5 -> 456 | G5: =452.94+3.06 -> 456 | H5: =F5-G5 -> 0 | I5: 1567826 | J5: 20-08-2024-feeds | K5: 45602
A6: 3 | B6: 3009 | C6: Ahmed Salim Bakhit Qatan | D6: 465.6 | E6: 0.4 | F6: =E6*D6 -> 186.24 | G6: =183.02+3.22 -> 186.24 | H6: =F6-G6 -> 0 | I6: 1448391 | J6: 05-09-2024-feeds
A7: 4 | B7: 3077 | C7: Mohammed Ali Suhail Qatan | D7: 917.4 | E7: 0.4 | F7: =E7*D7 -> 366.96 | G7: =365.42+1.54 -> 366.96 | H7: =F7-G7 -> 0 | I7: 21978752 | J7: 14-08-2024-feeds | K7: 45635
A8: 5 | B8: 3136 | C8: Ghazi Salim Ahmed Al Kathiri | D8: 892 | E8: 0.4 | F8: =E8*D8 -> 356.8 | G8: =354.05+2.75 -> 356.8 | H8: =F8-G8 -> 0 | I8: 183498 | J8: 45547 | K8: 45615
A9: 6 | B9: 3215 | C9: Suhail Awadh Salim Hawas Al Aamri | D9: 1017.9 | E9: 0.4 | F9: =E9*D9 -> 407.16 | G9: =404.79+2.37 -> 407.16 | H9: =F9-G9 -> 0 | I9: 11684091 | J9: 18-08-2024-feeds | K9: 45607
A10: 7 | B10: 3273 | C10: Masoud Salim Faraj Al Kathiri | D10: 896 | E10: 0.4 | F10: =E10*D10 -> 358.4 | G10: =356+2.4 -> 358.4 | H10: =F10-G10 -> 0 | I10: 7047221 | J10: 18-08-2024-feeds | K10: 45609
A11: 8 | B11: 3287 | C11: Ahmed Bakhit Ahmed Qatan | D11: 800.2 | E11: 0.4 | F11: =E11*D11 -> 320.08 | G11: =319.19+0.89 -> 320.08 | H11: =F11-G11 -> 0 | I11: 6504554 | J11: 12-08-2024-feeds | K11: 45629
A12: 9 | B12: 3329 | C12: Said Ahmed Mustahil Alshahri | D12: 460 | E12: 0.4 | F12: =E12*D12 -> 184 | G12: =182.55+1.45 -> 184 | H12: =F12-G12 -> 0 | I12: 9086292 | J12: 19-08-2024-feeds | K12: 05-014-25
A13: 10 | B13: 3334 | C13: Mohammed Said Mohammed Baitsaid | D13: 687.5 | E13: 0.4 | F13: =E13*D13 -> 275 | G13: =273.5+1.5 -> 275 | H13: =F13-G13 -> 0 | I13: 1176211 | J13: 26-08-2024-feeds | K13: 45691
A14: 11 | B14: 3340 | C14: Mohsin Suhail Ghawas | D14: 456.6 | E14: 0.4 | F14: =E14*D14 -> 182.64 | G14: =179.45+3.19 -> 182.64 | H14: =F14-G14 -> 0 | I14: 906355 | J14: 04-09-24-feeds
A15: 12 | B15: 3709 | C15: Abdul Aziz Ali Said Ali Kashoob | D15: 823.6 | E15: 0.4 | F15: =E15*D15 -> 329.44 | G15: =329.09+0.35 -> 329.44 | H15: =F15-G15 -> 0 | I15: 23860076 | J15: 14-08-2024-feeds
A16: 13 | B16: 3717 | C16: Salim Ali Musallam ALMaashani | D16: 917.2 | E16: 0.4 | F16: =E16*D16 -> 366.88 | G16: =363.37+3.51 -> 366.88 | H16: =F16-G16 -> 0 | I16: 6349394 | J16: feeds -06-08-2024
A17: 14 | B17: 3719 | C17: Said Ahmed Ali Al Zawamri | D17: 433 | E17: 0.4 | F17: =E17*D17 -> 173.2 | G17: =169.75+3.45 -> 173.2 | H17: =F17-G17 -> 0 | I17: 6610475 | J17: 45544
A18: 15 | B18: 3723 | C18: Said Suhail Said Qatan | D18: 454.8 | E18: 0.4 | F18: =E18*D18 -> 181.92 | G18: =179.9+2.02 -> 181.92 | H18: =F18-G18 -> 0 | I18: 993752 | J18: 13-08-24-feeds
A19: 16 | B19: 3725 | C19: Ahmed Bakhit Ahmed Qatan | D19: 671.8 | E19: 0.4 | F19: =E19*D19 -> 268.72 | G19: =267.53+1.19 -> 268.72 | H19: =F19-G19 -> 0 | I19: 1648248 | J19: 16-09-2024 | K19: 45602
A20: 17 | B20: 3764 | C20: Ali Musallam Amer Amer Jid Almahri | D20: 1205.5 | E20: 0.4 | F20: =E20*D20 -> 482.2 | G20: =480.15+2.05 -> 482.2 | H20: =F20-G20 -> 0 | I20: 1996843 | J20: 16-09-2024 | K20: 16-01-25
A21: 18 | B21: 3787 | C21: Ahmed Musallam Suhail Almaashani | D21: 899.9 | E21: 0.4 | F21: =E21*D21 -> 359.96 | G21: =357.32+2.64 -> 359.96 | H21: =F21-G21 -> 0 | I21: 813786 | J21: feeds -06-08-2024 | K21: 45652
A22: 19 | B22: 3799 | C22: Hamid Awadh Salim Hawas AL Aamri | D22: 1111.7 | E22: 0.4 | F22: =E22*D22 -> 444.68 | G22: =444.55+0.13 -> 444.68 | H22: =F22-G22 -> 0 | I22: 12494672 | J22: 18-09-2024-feeds | K22: 45607
A23: 20 | B23: 3823 | C23: Said Amer Azad AL Kathiri | D23: 457 | E23: 0.4 | F23: =E23*D23 -> 182.8 | G23: =179.45+3.35 -> 182.8 | H23: =F23-G23 -> 0 | I23: 865789 | J23: 26-08-2024-feeds | K23: 45602
A24: 21 | B24: 3829 | C24: Ahmed Suhail Ahmed Qatan | D24: 422.7 | E24: 0.4 | F24: =E24*D24 -> 169.08 | G24: =164.9+4.18 -> 169.08 | H24: =F24-G24 -> 0 | I24: 897384 | J24: 28-08-2024-feeds | K24: 45670
A25: 22 | B25: 3834 | C25: Musallem Ahmed Suhail Jashuul | D25: 920 | E25: 0.4 | F25: =E25*D25 -> 368 | G25: =364.35+3.65 -> 368 | H25: =F25-G25 -> 0 | I25: 5544756 | J25: 19-08-2024 feeds | K25: 45607
A26: 23 | B26: 3836 | C26: Mohammed Said Ahmed Shamas | D26: 867 | E26: 0.4 | F26: =E26*D26 -> 346.8 | G26: =345.92+0.88 -> 346.8 | H26: =F26-G26 -> 0 | I26: 20264434 | J26: 19-08-2024-feeds | K26: 45602
A27: 24 | B27: 3850 | C27: Said Salim Ali Jaboob | D27: 1114.7 | E27: 0.4 | F27: =E27*D27 -> 445.88 | G27: =444.22+1.66 -> 445.88 | H27: =F27-G27 -> 0 | I27: 5742985 | J27: 19-08-2024-feed | K27: 45650
A28: 25 | B28: 3862 | C28: Ali Mohammed Ali al Aamri | D28: 876.5 | E28: 0.4 | F28: =E28*D28 -> 350.6 | G28: =349.2+1.4 -> 350.6 | H28: =F28-G28 -> 0 | I28: 5892019 | J28: 27-08-2024-feeds
A29: 26 | B29: 3876 | C29: Mohammed Salim Ali Al Jahf ali | D29: 682.1 | E29: 0.4 | F29: =E29*D29 -> 272.84 | G29: =270.24+2.6 -> 272.84 | H29: =F29-G29 -> 0 | I29: 4767948 | J29: 12-08-2024-feeds | K29: 45635
A30: 27 | B30: 3878 | C30: Ahmed Salim Mustahil Ali Sakroon | D30: 460 | E30: 0.4 | F30: =E30*D30 -> 184 | G30: =181.69+2.31 -> 184 | H30: =F30-G30 -> 0 | I30: 22687078 | J30: 18-08-2024-feeds
A31: 28 | B31: 3884 | C31: Issa Salim Mubarak Raboob Al Shahri | D31: 409.4 | E31: 0.4 | F31: =E31*D31 -> 163.76 | G31: =161.31+2.45 -> 163.76 | H31: =F31-G31 -> 0 | I31: 22716378 | J31: 15-08-2024-feed | K31: 45630
C32: TOTAL | D32: =SUM(D4:D31) -> 20900.1 | F32: =SUM(F4:F31) -> 8360.04 | G32: =SUM(G4:G31) -> 8360.04 | H32: =SUM(H4:H31) -> 0
G34: =SUBTOTAL(9,G9:G32) -> 10521.52
F35: =G32/F32% -> 100

Sheet Sheet1
A6: May | B6: 3243 | C6: Asad Ali Ahmed Suhail Aamir Jid | D6: 453.8 | E6: 0.4 | F6: =E6*D6 -> 181.52 | H6: =F6-G6 -> 181.52 | AD6: 3708 | AE6: Said Salim Nassir Al Aamri | AF6: 925.2 | AG6: 0.4 | AH6: =AG6*AF6 -> 370.08 | AI6: 194 | AJ6: =AH6-AI6 -> 176.08
A7: June | B7: 3243 | C7: Asad Ali Ahmed Suhail Aamir Jid | D7: 327.1 | E7: 0.4 | F7: =E7*D7 -> 130.84 | H7: =F7-G7 -> 130.84
H8: =SUM(H6:H7) -> 312.36

Sheet 06
A1: HAJEEF CAMEL MILK PROCUREMENT FROM 01-June-2024 TO 30-June-2024
A3: Sr. No. | B3: Farmer Code | C3: Farmer Name | D3: Total Milk Qty | E3: Avg. Rate (OMR/Ltr.) | F3: Amount (OMR) | G3: Paid | H3: Balance | I3: ID No. | J3: remark 2
A4: 1 | B4: 1443 | C4: Ahmed Musallam Ahmed Al Kathiri | D4: 1271.7 | E4: 0.4 | F4: =E4*D4 -> 508.68 | G4: =F4 -> 508.68 | H4: =F4-G4 -> 0 | I4: 6026992 | J4: 45567
A5: 2 | B5: 1452 | C5: Sulaim Said Mohammed Hawas Al Aamri | D5: 412.9 | E5: 0.4 | F5: =E5*D5 -> 165.16 | G5: =162.1+3.06 -> 165.16 | H5: =F5-G5 -> 0 | I5: 20917176 | J5: 45538 | K5: 45602
A6: 3 | B6: 1461 | C6: Suhail Said Ali Bait said | D6: 326.7 | E6: 0.4 | F6: =E6*D6 -> 130.68 | G6: =F6 -> 130.68 | H6: =F6-G6 -> 0 | I6: 6828806 | J6: 45580
A7: 4 | B7: 3022 | C7: Hussein Masoud Aubad Al Kathiri | D7: 1080.1 | E7: 0.4 | F7: =E7*D7 -> 432.04 | G7: =430.39+1.65 -> 432.04 | H7: =F7-G7 -> 0 | I7: 5360253 | J7: 09-01-2024-feeds | K7: 45609
A8: 5 | B8: 3025 | C8: Musallam Salim Mahad Qatan | D8: 588.6 | E8: 0.4 | F8: =E8*D8 -> 235.44 | G8: =F8 -> 235.44 | H8: =F8-G8 -> 0 | I8: 7542172 | J8: 18-09-2024
A9: 6 | B9: 3030 | C9: Salim Ahmed Salim Amer Jid | D9: 330 | E9: 0.4 | F9: =E9*D9 -> 132 | G9: =130.65+1.35 -> 132 | H9: =F9-G9 -> 0 | I9: 6021175 | J9: 45580 | K9: 45650
A10: 7 | B10: 3043 | C10: Said Aubad Ali Ghawas | D10: 285.6 | E10: 0.4 | F10: =E10*D10 -> 114.24 | G10: =113.9+0.34 -> 114.24 | H10: =F10-G10 -> 0 | I10: 396336 | J10: 23-09-2024 | K10: 45642
A11: 8 | B11: 3072 | C11: Mohammed Salim Said Al Barami | D11: 293 | E11: 0.4 | F11: =E11*D11 -> 117.2 | G11: =F11 -> 117.2 | H11: =F11-G11 -> 0 | I11: 993077 | J11: 16-09-2024 feeds | K11: 45665
A12: 9 | B12: 3199 | C12: Ali Musallam Ahmed Tabuk | D12: 308.6 | E12: 0.4 | F12: =E12*D12 -> 123.44 | G12: =122.96+0.48 -> 123.44 | H12: =F12-G12 -> 0 | I12: 5168327 | J12: 45547 | K12: 45630
A13: 10 | B13: 3200 | C13: Ahmed Said Ahmed Qutan | D13: 291.3 | E13: 0.4 | F13: =E13*D13 -> 116.52 | G13: =113.65+2.87 -> 116.52 | H13: =F13-G13 -> 0 | I13: 21947578 | J13: 30-09-2024 | K13: 45628
A14: 11 | B14: 3209 | C14: Said Suhail Ali Al Kathiri | D14: 328.5 | E14: 0.4 | F14: =E14*D14 -> 131.4 | G14: =130.08+1.32 -> 131.4 | H14: =F14-G14 -> 0 | I14: 5634328 | J14: 18-09-2024 | K14: 45607
A15: 12 | B15: 3215 | C15: Suhail Awadh Salim Hawas Al Aamri | D15: 726.2 | E15: 0.4 | F15: =E15*D15 -> 290.48 | G15: =286.15+4.33 -> 290.48 | H15: =F15-G15 -> 0 | I15: 11684091 | J15: 45580 | K15: 45607
A16: 13 | B16: 3221 | C16: Musallam Mohammed Salim Al Barami | D16: 294.1 | E16: 0.4 | F16: =E16*D16 -> 117.64 | G16: =117.18+0.46 -> 117.64 | H16: =F16-G16 -> 0 | I16: 13362673 | J16: 16-09-2024-feeds | K16: 45630
A17: 14 | B17: 3222 | C17: Mohammed Ahmed Bakhit Qatan | D17: 555.3 | E17: 0.4 | F17: =E17*D17 -> 222.12 | G17: =218.1+4.02 -> 222.12 | H17: =F17-G17 -> 0 | I17: 18091329 | J17: 45544 | K17: 45602
A18: 15 | B18: 3231 | C18: Tanaf Suhail Ali Hawas Al Aamri | D18: 610.3 | E18: 0.4 | F18: =E18*D18 -> 244.12 | G18: =56+72.75+111.55+3.82 -> 244.12 | H18: =F18-G18 -> 0 | I18: 6203903 | J18: 25-09-2024,13-10-24,21-10
A19: 16 | B19: 3239 | C19: Ali Salim Bakhit Qatan | D19: 584 | E19: 0.4 | F19: =E19*D19 -> 233.6 | G19: =229.88+3.72 -> 233.6 | H19: =F19-G19 -> 0 | I19: 14379226 | J19: 09-01-2024-feeds | K19: 45609
A20: 17 | B20: 3240 | C20: Ali Said Salim Al kathiri | D20: 601.9 | E20: 0.4 | F20: =E20*D20 -> 240.76 | G20: =239.49+1.27 -> 240.76 | H20: =F20-G20 -> 0 | I20: 5622856 | J20: 23-09-2024 | K20: 45642
A21: 18 | B21: 3243 | C21: Asad Ali Ahmed Suhail Aamir Jid | D21: 327.1 | E21: 0.4 | F21: =E21*D21 -> 130.84 | G21: =128.88+1.96 -> 130.84 | H21: =F21-G21 -> 0 | I21: 25887256 | J21: 18-09-2024 | K21: 45615
A22: 19 | B22: 3244 | C22: Mohammed Ali Bakhit Qatan | D22: 253.4 | E22: 0.4 | F22: =E22*D22 -> 101.36 | G22: =F22 -> 101.36 | H22: =F22-G22 -> 0 | I22: 19340943 | J22: 23-09-2024
A23: 20 | B23: 3252 | C23: Said Amer Salim Qatan | D23: 233.8 | E23: 0.4 | F23: =E23*D23 -> 93.52 | G23: =92.96+0.56 -> 93.52 | H23: =F23-G23 -> 0 | I23: 460074 | J23: 09-01-2024-feeds | K23: 45621
A24: 21 | B24: 3254 | C24: Said Mohammed Musallam Al Shihri | D24: 552 | E24: 0.4 | F24: =E24*D24 -> 220.8 | G24: =220.47+0.33 -> 220.8 | H24: =F24-G24 -> 0 | I24: 6668983 | J24: 45547 | K24: 45602
A25: 22 | B25: 3258 | C25: Ahmed Salim Amer Qatan | D25: 806.7 | E25: 0.4 | F25: =E25*D25 -> 322.68 | G25: =320.1+2.58 -> 322.68 | H25: =F25-G25 -> 0 | I25: 15335306 | J25: 45538
A26: 23 | B26: 3286 | C26: Ali Salim Amor Salim Qatan | D26: 392 | E26: 0.4 | F26: =E26*D26 -> 156.8 | G26: =153.47+3.33 -> 156.8 | H26: =F26-G26 -> 0 | I26: 23232841 | J26: 16-09-24 | K26: 45624
A27: 24 | B27: 3294 | C27: Ahmed Ali Said Qatan | D27: 582 | E27: 0.4 | F27: =E27*D27 -> 232.8 | G27: =F27 -> 232.8 | H27: =F27-G27 -> 0 | I27: 19263029 | J27: 23-09-24 | K27: 45658
A28: 25 | B28: 3295 | C28: Ahmed Salim Ahmed Tabook | D28: 303.3 | E28: 0.4 | F28: =E28*D28 -> 121.32 | G28: =F28 -> 121.32 | H28: =F28-G28 -> 0 | I28: 20378353 | J28: 45332
A29: 26 | B29: 3302 | C29: Mohamed Ahmed Salim Khalis Almasahli | D29: 553.4 | E29: 0.4 | F29: =E29*D29 -> 221.36 | G29: =218.25+3.11 -> 221.36 | H29: =F29-G29 -> 0 | I29: 71004483 | J29: 23-09-2024 | K29: 3.11 dcf
A30: 27 | B30: 3309 | C30: Ahmed Said Amer Qatan | D30: 243.1 | E30: 0.4 | F30: =E30*D30 -> 97.24 | G30: =92.58+4.66 -> 97.24 | H30: =F30-G30 -> 0 | I30: 21453611 | J30: 09-01-2024-feeds | K30: 45621
A31: 28 | B31: 3312 | C31: Ahmed Salim Said Amor Jid Al Mahri | D31: 612 | E31: 0.4 | F31: =E31*D31 -> 244.8 | G31: =242.99+1.81 -> 244.8 | H31: =F31-G31 -> 0 | I31: 881326 | J31: 45582 | K31: 45602
A32: 29 | B32: 3314 | C32: Said Aubad Jamaan Al Kathiri | D32: 582.4 | E32: 0.4 | F32: =E32*D32 -> 232.96 | G32: =230.9+2.06 -> 232.96 | H32: =F32-G32 -> 0 | I32: 766893 | J32: 23-09-2024 | K32: 45609
A33: 30 | B33: 3315 | C33: Musallam Said Amer Qatan | D33: 240.8 | E33: 0.4 | F33: =E33*D33 -> 96.32 | G33: =92.44+3.88 -> 96.32 | H33: =F33-G33 -> 0 | I33: 23957422 | J33: 09-01-2024-feeds | K33: 45621
A34: 31 | B34: 3316 | C34: Amer Said Amer Salim Qatan | D34: 234.1 | E34: 0.4 | F34: =E34*D34 -> 93.64 | G34: =91.93+1.71 -> 93.64 | H34: =F34-G34 -> 0 | I34: 26159748 | J34: 09-01-2024-feeds | K34: 45621
A35: 32 | B35: 3325 | C35: Ali Salim Said Qatan | D35: 142.6 | E35: 0.4 | F35: =E35*D35 -> 57.04 | G35: =54.8+2.24 -> 57.04 | H35: =F35-G35 -> 0 | I35: 21849398 | J35: 45544 | K35: 45637
A36: 33 | B36: 3328 | C36: Ahmed Said Mohammed Tabook | D36: 592.1 | E36: 0.4 | F36: =E36*D36 -> 236.84 | G36: =230.78+6.06 -> 236.84 | H36: =F36-G36 -> 0 | I36: 1934204 | J36: 45538 | K36: 45602
A37: 34 | B37: 3720 | C37: Mohammed Ahmed Masoud Dakari ALKathiri | D37: 402.7 | E37: 0.4 | F37: =E37*D37 -> 161.08 | G37: =158.93+2.15 -> 161.08 | H37: =F37-G37 -> 0 | I37: 2518469 | J37: 09-01-2024-feeds | K37: 2.150 dcf feed
A38: 35 | B38: 3733 | C38: Salim Said Amer Salim Qatan | D38: 159 | E38: 0.4 | F38: =E38*D38 -> 63.6 | G38: =62+1.6 -> 63.6 | H38: =F38-G38 -> 0 | I38: 23270163 | J38: 45544 | K38: 45607
A39: 36 | B39: 3742 | C39: Mohammed Said Suhail Qatan | D39: 22.3 | E39: 0.4 | F39: =E39*D39 -> 8.92 | G39: =F39 -> 8.92 | H39: =F39-G39 -> 0 | I39: 1930281 | J39: 28=-1-25
A40: 37 | B40: 3746 | C40: Nadir Said Ahmed Al kathiri | D40: 369.5 | E40: 0.4 | F40: =E40*D40 -> 147.8 | G40: =143.96+3.84 -> 147.8 | H40: =F40-G40 -> 0 | I40: 21973713 | J40: 45567 | K40: 45624
A41: 38 | B41: 3755 | C41: Said Amer Said Amar Jid Al mahri | D41: 608.3 | E41: 0.4 | F41: =E41*D41 -> 243.32 | G41: =242.5+0.82 -> 243.32 | H41: =F41-G41 -> 0 | I41: 15536654 | J41: 45582 | K41: 45624
...

Sheet center-July
A1: HAJEEF CAMEL MILK PROCUREMENT FROM 01-July-2024 TO 31-July-2024
A3: Sr. No. | B3: Farmer Code | C3: Farmer Name | D3: Total Milk Qty | E3: Avg. Rate (OMR/Ltr.) | F3: Amount (OMR) | G3: Paid | H3: Balance | I3: ID No. | J3: Bank Account | K3: Bank Name. | L3: SWIFT | M3: Phone No. | N3: remark 2 | Q3: Farmer Code | S3: Farmer Name | U3: ID No. | W3: Bank Account | Y3: SWIFT
A4: 1 | B4: 1108 | C4: Bakhit Ahmed Musallam Al kathiri | D4: 1162.1 | E4: 0.4 | F4: =E4*D4 -> 464.84 | G4: =F4 -> 464.84 | H4: =F4-G4 -> 0 | I4: 15218386 | J4: 0439012124150013 | K4: BANK MUSCAT | L4: BMUSOMRX | M4: 92776884 | Q4: 1108 | R4: =Q4=B4 -> TRUE | S4: Bakhit Ahmed Musallam Al kathiri | T4: =S4=C4 -> TRUE | U4: 15218386 | V4: =U4=I4 -> TRUE | W4: 0439012124150013 | X4: =W4=J4 -> TRUE | Y4: BMUSOMRX | Z4: =Y4=L4 -> TRUE
A5: 2 | B5: 1390 | C5: Bakhait Salim Ahmed Alash Al Kathiri | D5: 400 | E5: 0.4 | F5: =E5*D5 -> 160 | G5: =155.15+4.85 -> 160 | H5: =F5-G5 -> 0 | I5: 12181822 | J5: 0439014599800023 | K5: BANK MUSCAT | L5: BMUSOMRX | M5: 92442060 | N5: 45596 | O5: 45609 | Q5: 1390 | R5: =Q5=B5 -> TRUE | S5: Bakhait Salim Ahmed Alash Al Kathiri | T5: =S5=C5 -> TRUE | U5: 12181822 | V5: =U5=I5 -> TRUE | W5: 0439014599800023 | X5: =W5=J5 -> TRUE | Y5: BMUSOMRX | Z5: =Y5=L5 -> TRUE
A6: 3 | B6: 1399 | C6: Mohammed Suhail Ali Hawas Al Aamri | D6: 304.3 | E6: 0.4 | F6: =E6*D6 -> 121.72 | G6: =118.07+3.65 -> 121.72 | H6: =F6-G6 -> 0 | I6: 10065546 | J6: 3109720870700 | K6: OAB | L6: OMABOMRU | N6: 45596 | O6: 45615 | Q6: 1399 | R6: =Q6=B6 -> TRUE | S6: Mohammed Suhail Ali Hawas Al Aamri | T6: =S6=C6 -> TRUE | U6: 10065546 | V6: =U6=I6 -> TRUE | W6: 3109720870700 | X6: =W6=J6 -> TRUE | Y6: OMABOMRU | Z6: =Y6=L6 -> TRUE
A7: 4 | B7: 1422 | C7: Mahammed Musallam Ahmed Hwas | D7: 310.5 | E7: 0.4 | F7: =E7*D7 -> 124.2 | G7: =119+5.2 -> 124.2 | H7: =F7-G7 -> 0 | I7: 3280016 | J7: 0397003987550015 | K7: BANK MUSCAT | L7: BMUSOMRX | N7: 45567 | O7: 45602 | Q7: 1422 | R7: =Q7=B7 -> TRUE | S7: Mahammed Musallam Ahmed Hwas | T7: =S7=C7 -> TRUE | U7: 3280016 | V7: =U7=I7 -> TRUE | W7: 0397003987550015 | X7: =W7=J7 -> TRUE | Y7: BMUSOMRX | Z7: =Y7=L7 -> TRUE
A8: 5 | B8: 1424 | C8: Said Ahmed Sabah Ali Badar | D8: 457 | E8: 0.4 | F8: =E8*D8 -> 182.8 | G8: =128.35+54.45 -> 182.8 | H8: =F8-G8 -> 0 | I8: 748395 | J8: 01012574607001 | K8: BANK DHOFAR | L8: BDOFOMRU | M8: 93011211 | N8: 45567 | O8: 45609 | Q8: 1424 | R8: =Q8=B8 -> TRUE | S8: Said Ahmed Sabah Ali Badar | T8: =S8=C8 -> TRUE | U8: 748395 | V8: =U8=I8 -> TRUE | W8: 01012574607001 | X8: =W8=J8 -> TRUE | Y8: BDOFOMRU | Z8: =Y8=L8 -> TRUE
A9: 6 | B9: 1429 | C9: Said Mohammed Salem Akdha Al Rawas | D9: 540 | E9: 0.4 | F9: =E9*D9 -> 216 | G9: =F9 -> 216 | H9: =F9-G9 -> 0 | I9: 339725 | J9: 0397003785300017 | K9: BANK MUSCAT | L9: BMUSOMRX | Q9: 1429 | R9: =Q9=B9 -> TRUE | S9: Said Mohammed Salem Akdha Al Rawas | T9: =S9=C9 -> TRUE | U9: 339725 | V9: =U9=I9 -> TRUE | W9: 0397003785300017 | X9: =W9=J9 -> TRUE | Y9: BMUSOMRX | Z9: =Y9=L9 -> TRUE
A10: 7 | B10: 1431 | C10: Bakhit Mohamed Salim Rawas | D10: 400.9 | E10: 0.4 | F10: =E10*D10 -> 160.36 | G10: =158.65+1.71 -> 160.36 | H10: =F10-G10 -> 0 | I10: 721445 | J10: 01010850230001 | K10: BANK DHOFAR | L10: BDOFOMRU | M10: 99291700 | N10: 45607 | O10: 45628 | Q10: 1431 | R10: =Q10=B10 -> TRUE | S10: Bakhit Mohamed Salim Rawas | T10: =S10=C10 -> TRUE | U10: 721445 | V10: =U10=I10 -> TRUE | W10: 01010850230001 | X10: =W10=J10 -> TRUE | Y10: BDOFOMRU | Z10: =Y10=L10 -> TRUE
A11: 8 | B11: 1443 | C11: Ahmed Musallam Ahmed Al Kathiri | D11: 1528.9 | E11: 0.4 | F11: =E11*D11 -> 611.56 | G11: =F11 -> 611.56 | H11: =F11-G11 -> 0 | I11: 6026992 | J11: 0439017196260028 | K11: BANK MUSCAT | L11: BMUSOMRX | M11: 95863774 | Q11: 1443 | R11: =Q11=B11 -> TRUE | S11: Ahmed Musallam Ahmed Al Kathiri | T11: =S11=C11 -> TRUE | U11: 6026992 | V11: =U11=I11 -> TRUE | W11: 0439017196260028 | X11: =W11=J11 -> TRUE | Y11: BMUSOMRX | Z11: =Y11=L11 -> TRUE
A12: 9 | B12: 1452 | C12: Sulaim Said Mohammed Hawas Al Aamri | D12: 220.6 | E12: 0.4 | F12: =E12*D12 -> 88.24 | G12: =88.24 -> 88.24 | H12: =F12-G12 -> 0 | I12: 20917176 | J12: 0406012189810015 | K12: BANK MUSCAT | L12: BMUSOMRX | M12: 95863774 | N12: 45602 | Q12: 1452 | R12: =Q12=B12 -> TRUE | S12: Sulaim Said Mohammed Hawas Al Aamri | T12: =S12=C12 -> TRUE | U12: 20917176 | V12: =U12=I12 -> TRUE | W12: 0406012189810015 | X12: =W12=J12 -> TRUE | Y12: BMUSOMRX | Z12: =Y12=L12 -> TRUE
A13: 10 | B13: 1458 | C13: Salim Mustahil Jamaan Al Shakl Al kathiri | D13: 369.5 | E13: 0.4 | F13: =E13*D13 -> 147.8 | G13: =F13 -> 147.8 | H13: =F13-G13 -> 0 | I13: 77628 | J13: 01012583986001 | K13: BANK DHOFAR | L13: BDOFOMRU | M13: 99275608 | Q13: 1458 | R13: =Q13=B13 -> TRUE | S13: Salim Mustahil Jamaan Al Shakl Al kathiri | T13: =S13=C13 -> TRUE | U13: 77628 | V13: =U13=I13 -> TRUE | W13: 01012583986001 | X13: =W13=J13 -> TRUE | Y13: BDOFOMRU | Z13: =Y13=L13 -> TRUE
A14: 11 | B14: 1461 | C14: Suhail Said Ali Bait said | D14: 342.9 | E14: 0.4 | F14: =E14*D14 -> 137.16 | G14: =F14 -> 137.16 | H14: =F14-G14 -> 0 | I14: 6828806 | J14: 0396003267730012 | K14: BANK MUSCAT | L14: BMUSOMRX | M14: 92330321 | Q14: 1461 | R14: =Q14=B14 -> TRUE | S14: Suhail Said Ali Bait said | T14: =S14=C14 -> TRUE | U14: 6828806 | V14: =U14=I14 -> TRUE | W14: 0396003267730012 | X14: =W14=J14 -> TRUE | Y14: BMUSOMRX | Z14: =Y14=L14 -> TRUE
A15: 12 | B15: 1465 | C15: Mahad Salim Zaed Baitsaid | D15: 354.1 | E15: 0.4 | F15: =E15*D15 -> 141.64 | G15: =F15 -> 141.64 | H15: =F15-G15 -> 0 | I15: 757601 | J15: 1023113274001 | K15: NBO | L15: NBOMOMRX | M15: 99892131 | Q15: 1465 | R15: =Q15=B15 -> TRUE | S15: Mahad Salim Zaed Baitsaid | T15: =S15=C15 -> TRUE | U15: 757601 | V15: =U15=I15 -> TRUE | W15: 1023113274001 | X15: =W15=J15 -> TRUE | Y15: NBOMOMRX | Z15: =Y15=L15 -> TRUE
A16: 13 | B16: 1474 | C16: Mohamed Salam Amer Al Yafee | D16: 915.7 | E16: 0.4 | F16: =E16*D16 -> 366.28 | G16: =360.94+5.34 -> 366.28 | H16: =F16-G16 -> 0 | I16: 4603773 | J16: 01041185194001 | K16: BANK DHOFAR | L16: BDOFOMRU | M16: 98820843 | N16: 45637 | O16: 45658 | Q16: 1474 | R16: =Q16=B16 -> TRUE | S16: Mohamed Salam Amer Al Yafee | T16: =S16=C16 -> TRUE | U16: 4603773 | V16: =U16=I16 -> TRUE | W16: 01041185194001 | X16: =W16=J16 -> TRUE | Y16: BDOFOMRU | Z16: =Y16=L16 -> TRUE
A17: 14 | B17: 1479 | C17: Ahmed Amer Said Baitsaid | D17: 383.7 | E17: 0.4 | F17: =E17*D17 -> 153.48 | G17: =F17 -> 153.48 | H17: =F17-G17 -> 0 | I17: 5217726 | J17: 0396003219770029 | K17: BANK MUSCAT | L17: BMUSOMRX | M17: 92610234 | N17: 45602
A18: 15 | B18: 1483 | C18: Saed Ali Ahmed Al Kathiri | D18: 912 | E18: 0.4 | F18: =E18*D18 -> 364.8 | G18: =360.69+4.11 -> 364.8 | H18: =F18-G18 -> 0 | I18: 1567826 | J18: 1083724895017 | K18: NBO | L18: NBOMOMRX | M18: 98532884 | N18: 45602 | O18: 45607 | Q18: 1483 | R18: =Q18=B18 -> TRUE | S18: Saed Ali Ahmed Al Kathiri | T18: =S18=C18 -> TRUE | U18: 1567826 | V18: =U18=I18 -> TRUE | W18: 1083724895017 | X18: =W18=J18 -> TRUE | Y18: NBOMOMRX | Z18: =Y18=L18 -> TRUE
A19: 16 | B19: 1486 | C19: Mosoud Ali Salim Al Kathiri | D19: 428.9 | E19: 0.4 | F19: =E19*D19 -> 171.56 | G19: =F19 -> 171.56 | H19: =F19-G19 -> 0 | I19: 22792564 | J19: 0401064266530014 | K19: BANK MUSCAT | L19: BMUSOMRX
A20: 17 | B20: 1762 | C20: MUSALLAM HASAN ALI BAIT SAID | D20: 1345 | E20: 0.4 | F20: =E20*D20 -> 538 | G20: =F20 -> 538 | H20: =F20-G20 -> 0 | I20: 1409527 | J20: 0397003183710017 | K20: Bank Muscat | L20: BMUSOMRX | N20: dcf feed | Q20: 1762 | R20: =Q20=B20 -> TRUE | S20: MUSALLAM HASAN ALI BAIT SAID | T20: =S20=C20 -> TRUE | U20: 1409527 | V20: =U20=I20 -> TRUE | W20: 0397003183710017 | X20: =W20=J20 -> TRUE | Y20: BMUSOMRX | Z20: =Y20=L20 -> TRUE
A21: 18 | B21: 1792 | C21: Musallam Bakhit Salim Al Aamri | D21: 394.1 | E21: 0.4 | F21: =E21*D21 -> 157.64 | G21: =F21 -> 157.64 | H21: =F21-G21 -> 0 | I21: 9545556 | J21: 01011373210001 | K21: BANK DHOFAR | L21: BDOFOMRU | Q21: 1792 | R21: =Q21=B21 -> TRUE | S21: Musallam Bakhit Salim Al Aamri | T21: =S21=C21 -> TRUE | U21: 9545556 | V21: =U21=I21 -> TRUE | W21: 01011373210001 | X21: =W21=J21 -> TRUE | Y21: BDOFOMRU | Z21: =Y21=L21 -> TRUE
A22: 19 | B22: 3009 | C22: Ahmed Salim Bakhit Qatan | D22: 352 | E22: 0.4 | F22: =E22*D22 -> 140.8 | G22: =F22 -> 140.8 | H22: =F22-G22 -> 0 | I22: 1448391 | J22: 3109628132500 | K22: OAB | L22: OMABOMRU | M22: 99100144 | Q22: 3009 | R22: =Q22=B22 -> TRUE | S22: Ahmed Salim Bakhit Qatan | T22: =S22=C22 -> TRUE | U22: 1448391 | V22: =U22=I22 -> TRUE | W22: 3109628132500 | X22: =W22=J22 -> TRUE | Y22: OMABOMRU | Z22: =Y22=L22 -> TRUE
A23: 20 | B23: 3012 | C23: Salim Suhail Ali Al Kathiri | D23: 364 | E23: 0.4 | F23: =E23*D23 -> 145.6 | G23: =142.67+2.93 -> 145.6 | H23: =F23-G23 -> 0 | I23: 5634422 | J23: 0406059374210012 | K23: BANK MUSCAT | L23: BMUSOMRX | M23: 96922118 | N23: 45586 | O23: 45624 | Q23: 3012 | R23: =Q23=B23 -> TRUE | S23: Salim Suhail Ali Al Kathiri | T23: =S23=C23 -> TRUE | U23: 5634422 | V23: =U23=I23 -> TRUE | W23: 0406059374210012 | X23: =W23=J23 -> TRUE | Y23: BMUSOMRX | Z23: =Y23=L23 -> TRUE
A24: 21 | B24: 3014 | C24: Ahmed Mohammed Salim Al Barami | D24: 315.1 | E24: 0.4 | F24: =E24*D24 -> 126.04 | G24: =123.35+2.69 -> 126.04 | H24: =F24-G24 -> 0 | I24: 648421 | J24: 3129711924500 | K24: OAB | L24: OMABOMRU | M24: 98815665 | N24: 45567 | O24: 45602 | Q24: 3014 | R24: =Q24=B24 -> TRUE | S24: Ahmed Mohammed Salim Al Barami | T24: =S24=C24 -> TRUE | U24: 648421 | V24: =U24=I24 -> TRUE | W24: 3129711924500 | X24: =W24=J24 -> TRUE | Y24: OMABOMRU | Z24: =Y24=L24 -> TRUE
A25: 22 | B25: 3015 | C25: Ahmed Mohammed Faraj Al Kathiri | D25: 372.4 | E25: 0.4 | F25: =E25*D25 -> 148.96 | G25: =F25 -> 148.96 | H25: =F25-G25 -> 0 | I25: 5753033 | J25: 0439058732890011 | K25: BANK MUSCAT | L25: BMUSOMRX | M25: 92838405 | Q25: 3015 | R25: =Q25=B25 -> TRUE | S25: Ahmed Mohammed Faraj Al Kathiri | T25: =S25=C25 -> TRUE | U25: 5753033 | V25: =U25=I25 -> TRUE | W25: 0439058732890011 | X25: =W25=J25 -> TRUE | Y25: BMUSOMRX | Z25: =Y25=L25 -> TRUE
A26: 23 | B26: 3018 | C26: Bakhit Salim Bakhit Qatan | D26: 297.2 | E26: 0.4 | F26: =E26*D26 -> 118.88 | G26: =117.88+1 -> 118.88 | H26: =F26-G26 -> 0 | I26: 1528087 | J26: 0397004184300024 | K26: BANK MUSCAT | L26: BMUSOMRX | N26: 45588 | O26: 45602 | Q26: 3018 | R26: =Q26=B26 -> TRUE | S26: Bakhit Salim Bakhit Qatan | T26: =S26=C26 -> TRUE | U26: 1528087 | V26: =U26=I26 -> TRUE | W26: 0397004184300024 | X26: =W26=J26 -> TRUE | Y26: BMUSOMRX | Z26: =Y26=L26 -> TRUE
A27: 24 | B27: 3020 | C27: Bakhit Ali Salim Qatan | D27: 672.4 | E27: 0.4 | F27: =E27*D27 -> 268.96 | G27: =268.09+0.87 -> 268.96 | H27: =F27-G27 -> 0 | I27: 5418422 | J27: 0401002342630017 | K27: BANK MUSCAT | L27: BMUSOMRX | M27: 99495434 | N27: 45567 | O27: 45602 | Q27: 3020 | R27: =Q27=B27 -> TRUE | S27: Bakhit Ali Salim Qatan | T27: =S27=C27 -> TRUE | U27: 5418422 | V27: =U27=I27 -> TRUE | W27: 0401002342630017 | X27: =W27=J27 -> TRUE | Y27: BMUSOMRX | Z27: =Y27=L27 -> TRUE
A28: 25 | B28: 3022 | C28: Hussein Masoud Aubad Al Kathiri | D28: 1246.9 | E28: 0.4 | F28: =E28*D28 -> 498.76 | G28: =497.9+0.86 -> 498.76 | H28: =F28-G28 -> 0 | I28: 5360253 | J28: 1060656310017 | K28: NBO | L28: NBOMOMRX | M28: 99257989 | N28: 45609 | O28: 45637 | Q28: 3022 | R28: =Q28=B28 -> TRUE | S28: Hussein Masoud Aubad Al Kathiri | T28: =S28=C28 -> TRUE | U28: 5360253 | V28: =U28=I28 -> TRUE | W28: 1060656310017 | X28: =W28=J28 -> TRUE | Y28: NBOMOMRX | Z28: =Y28=L28 -> TRUE
A29: 26 | B29: 3025 | C29: Musallam Salim Mahad Qatan | D29: 711.8 | E29: 0.4 | F29: =E29*D29 -> 284.72 | G29: =F29 -> 284.72 | H29: =F29-G29 -> 0 | I29: 7542172 | J29: 0401002461080028 | K29: BANK MUSCAT | L29: BMUSOMRX | Q29: 3025 | R29: =Q29=B29 -> TRUE | S29: Musallam Salim Mahad Qatan | T29: =S29=C29 -> TRUE | U29: 7542172 | V29: =U29=I29 -> TRUE | W29: 0401002461080028 | X29: =W29=J29 -> TRUE | Y29: BMUSOMRX | Z29: =Y29=L29 -> TRUE
A30: 27 | B30: 3026 | C30: Amer Salem Ahmed Qatan | D30: 374.6 | E30: 0.4 | F30: =E30*D30 -> 149.84 | G30: =F30 -> 149.84 | H30: =F30-G30 -> 0 | I30: 7033819 | J30: 0401003532620025 | K30: BANK MUSCAT | L30: BMUSOMRX | M30: 92256918 | Q30: 3026 | R30: =Q30=B30 -> TRUE | S30: Amer Salem Ahmed Qatan | T30: =S30=C30 -> TRUE | U30: 7033819 | V30: =U30=I30 -> TRUE | W30: 0401003532620025 | X30: =W30=J30 -> TRUE | Y30: BMUSOMRX | Z30: =Y30=L30 -> TRUE
A31: 28 | B31: 3027 | C31: Salim Ahmed Mahad Aamir Jid | D31: 732.8 | E31: 0.4 | F31: =E31*D31 -> 293.12 | G31: =292.65+0.47 -> 293.12 | H31: =F31-G31 -> 0 | I31: 6420643 | J31: 01011362595002 | K31: BANK DHOFAR | L31: BDOFOMRU | M31: 92288434 | N31: 45576 | O31: 45685 | Q31: 3027 | R31: =Q31=B31 -> TRUE | S31: Salim Ahmed Mahad Aamir Jid | T31: =S31=C31 -> TRUE | U31: 6420643 | V31: =U31=I31 -> TRUE | W31: 01011362595002 | X31: =W31=J31 -> TRUE | Y31: BDOFOMRU | Z31: =Y31=L31 -> TRUE
A32: 29 | B32: 3030 | C32: Salim Ahmed Salim Amer Jid | D32: 405 | E32: 0.4 | F32: =E32*D32 -> 162 | G32: =F32 -> 162 | H32: =F32-G32 -> 0 | I32: 6021175 | J32: 0401050718800013 | K32: BANK MUSCAT | L32: BMUSOMRX | M32: 91716888 | Q32: 3030 | R32: =Q32=B32 -> TRUE | S32: Salim Ahmed Salim Amer Jid | T32: =S32=C32 -> TRUE | U32: 6021175 | V32: =U32=I32 -> TRUE | W32: 0401050718800013 | X32: =W32=J32 -> TRUE | Y32: BMUSOMRX | Z32: =Y32=L32 -> TRUE
A33: 30 | B33: 3038 | C33: Said Ahmed Mahad Qatan | D33: 783 | E33: 0.4 | F33: =E33*D33 -> 313.2 | G33: =308.25+4.95 -> 313.2 | H33: =F33-G33 -> 0 | I33: 7976 | J33: 3109016888700 | K33: OAB | L33: OMABOMRU | M33: 98920007 | N33: 45602 | O33: 45621 | Q33: 3038 | R33: =Q33=B33 -> TRUE | S33: Said Ahmed Mahad Qatan | T33: =S33=C33 -> TRUE | U33: 7976 | V33: =U33=I33 -> TRUE | W33: 3109016888700 | X33: =W33=J33 -> TRUE | Y33: OMABOMRU | Z33: =Y33=L33 -> TRUE
A34: 31 | B34: 3043 | C34: Said Aubad Ali Ghawas | D34: 338.5 | E34: 0.4 | F34: =E34*D34 -> 135.4 | G34: =F34 -> 135.4 | H34: =F34-G34 -> 0 | I34: 396336 | J34: 0397003933630013 | K34: BANK MUSCAT | L34: BMUSOMRX | M34: 99498844 | Q34: 3043 | R34: =Q34=B34 -> TRUE | S34: Said Aubad Ali Ghawas | T34: =S34=C34 -> TRUE | U34: 396336 | V34: =U34=I34 -> TRUE | W34: 0397003933630013 | X34: =W34=J34 -> TRUE | Y34: BMUSOMRX | Z34: =Y34=L34 -> TRUE
A35: 32 | B35: 3058 | C35: Ali Bakhit Ahmed Qatan | D35: 1298.6 | E35: 0.4 | F35: =E35*D35 -> 519.44 | G35: =F35 -> 519.44 | H35: =F35-G35 -> 0 | I35: 965148 | J35: 3129376165700 | K35: OAB | L35: OMABOMRU | M35: 90980121 | Q35: 3058 | R35: =Q35=B35 -> TRUE | S35: Ali Bakhit Ahmed Qatan | T35: =S35=C35 -> TRUE | U35: 965148 | V35: =U35=I35 -> TRUE | W35: 3129376165700 | X35: =W35=J35 -> TRUE | Y35: OMABOMRU | Z35: =Y35=L35 -> TRUE
A36: 33 | B36: 3070 | C36: Mohamed Ahmed Suhail Qatan | D36: 1168.7 | E36: 0.4 | F36: =E36*D36 -> 467.48 | G36: =F36 -> 467.48 | H36: =F36-G36 -> 0 | I36: 1918001 | J36: 0397004395550019 | K36: BANK MUSCAT | L36: BMUSOMRX | M36: 92863640 | N36: 45627 | Q36: 3070 | R36: =Q36=B36 -> TRUE | S36: Mohamed Ahmed Suhail Qatan | T36: =S36=C36 -> TRUE | U36: 1918001 | V36: =U36=I36 -> TRUE | W36: 0397004395550019 | X36: =W36=J36 -> TRUE | Y36: BMUSOMRX | Z36: =Y36=L36 -> TRUE
A37: 34 | B37: 3072 | C37: Mohammed Salim Said Al Barami | D37: 379 | E37: 0.4 | F37: =E37*D37 -> 151.6 | G37: =149.8+1.8 -> 151.6 | H37: =F37-G37 -> 0 | I37: 993077 | J37: 250094968001 | K37: HSBC | L37: BBMEOMRX | M37: 92252981 | N37: 45630 | O37: 45665 | Q37: 3072 | R37: =Q37=B37 -> TRUE | S37: Mohammed Salim Said Al Barami | T37: =S37=C37 -> TRUE | U37: 993077 | V37: =U37=I37 -> TRUE | W37: 250094968001 | X37: =W37=J37 -> TRUE | Y37: BBMEOMRX | Z37: =Y37=L37 -> TRUE
A38: 35 | B38: 3077 | C38: Mohammed Ali Suhail Qatan | D38: 759.2 | E38: 0.4 | F38: =E38*D38 -> 303.68 | G38: =F38 -> 303.68 | H38: =F38-G38 -> 0 | I38: 21978752 | J38: 0396041232890032 | K38: BANK MUSCAT | L38: BMUSOMRX | M38: 90833336 | N38: 45635 | Q38: 3077 | R38: =Q38=B38 -> TRUE | S38: Mohammed Ali Suhail Qatan | T38: =S38=C38 -> TRUE | U38: 21978752 | V38: =U38=I38 -> TRUE | W38: 0396041232890032 | X38: =W38=J38 -> TRUE | Y38: BMUSOMRX | Z38: =Y38=L38 -> TRUE
A39: 36 | B39: 3081 | C39: Musallam Bakhit Masoud Qatan | D39: 519 | E39: 0.4 | F39: =E39*D39 -> 207.6 | G39: =207.15+0.45 -> 207.6 | H39: =F39-G39 -> 0 | I39: 21219868 | J39: 010010201414 | K39: Bank Sohar | L39: BSHROMRU | M39: 93288777 | N39: 45580 | O39: 45635 | Q39: 3081 | R39: =Q39=B39 -> TRUE | S39: Musallam Bakhit Masoud Qatan | T39: =S39=C39 -> TRUE | U39: 21219868 | V39: =U39=I39 -> TRUE | W39: 010010201414 | X39: =W39=J39 -> TRUE | Y39: BSHROMRU | Z39: =Y39=L39 -> TRUE
A40: 37 | B40: 3089 | C40: Yhaya Musallam Said Qatan | D40: 380.7 | E40: 0.4 | F40: =E40*D40 -> 152.28 | G40: =F40 -> 152.28 | H40: =F40-G40 -> 0 | I40: 18790484 | J40: 0401016503450018 | K40: BANK MUSCAT | L40: BMUSOMRX | Q40: 3089 | R40: =Q40=B40 -> TRUE | S40: Yhaya Musallam Said Qatan | T40: =S40=C40 -> TRUE | U40: 18790484 | V40: =U40=I40 -> TRUE | W40: 0401016503450018 | X40: =W40=J40 -> TRUE | Y40: BMUSOMRX | Z40: =Y40=L40 -> TRUE
A41: 38 | B41: 3093 | C41: Bakhit Amer Salem Qatan | D41: 615.4 | E41: 0.4 | F41: =E41*D41 -> 246.16 | G41: =F41 -> 246.16 | H41: =F41-G41 -> 0 | I41: 6361035 | J41: 00510034969002 | K41: BANK NIZWA | L41: BNZWOMRX | M41: 99497919 | Q41: 3093 | R41: =Q41=B41 -> TRUE | S41: Bakhit Amer Salem Qatan | T41: =S41=C41 -> TRUE | U41: 6361035 | V41: =U41=I41 -> TRUE | W41: 00510034969002 | X41: =W41=J41 -> TRUE | Y41: BNZWOMRX | Z41: =Y41=L41 -> TRUE
...

Sheet center-Aug
A1: HAJEEF CAMEL MILK PROCUREMENT FROM 01-Aug-2024 TO 31-Aug-2024
A3: Sr. No. | B3: Farmer Code | C3: Farmer Name | D3: Total Milk Qty | E3: Avg. Rate (OMR/Ltr.) | F3: Amount (OMR) | G3: Paid | H3: Balance | I3: ID No. | J3: remark 2
A4: 1 | B4: 1108 | C4: Bakhit Ahmed Musallam Al kathiri | D4: 1077 | E4: 0.4 | F4: =E4*D4 -> 430.8 | G4: =F4 -> 430.8 | H4: =F4-G4 -> 0 | I4: 15218386
A5: 2 | B5: 1390 | C5: Bakhait Salim Ahmed Alash Al Kathiri | D5: 373.5 | E5: 0.4 | F5: =E5*D5 -> 149.4 | G5: =145.5+3.9 -> 149.4 | H5: =F5-G5 -> 0 | I5: 12181822 | J5: 45609 | K5: 45635
A6: 3 | B6: 1399 | C6: Mohammed Suhail Ali Hawas Al Aamri | D6: 245.8 | E6: 0.4 | F6: =E6*D6 -> 98.32 | G6: =98.2+0.12 -> 98.32 | H6: =F6-G6 -> 0 | I6: 10065546 | J6: 45615 | K6: .120-dcf
A7: 4 | B7: 1422 | C7: Mahammed Musallam Ahmed Hwas | D7: 286.7 | E7: 0.4 | F7: =E7*D7 -> 114.68 | G7: =111.2+3.48 -> 114.68 | H7: =F7-G7 -> 0 | I7: 3280016 | J7: 45602 | K7: 45628
A8: 5 | B8: 1424 | C8: Said Ahmed Sabah Ali Badar | D8: 403.6 | E8: 0.4 | F8: =E8*D8 -> 161.44 | G8: =158.95+2.49 -> 161.44 | H8: =F8-G8 -> 0 | I8: 748395 | J8: 45609 | K8: 45624
A9: 6 | B9: 1429 | C9: Said Mohammed Salem Akdha Al Rawas | D9: 500 | E9: 0.4 | F9: =E9*D9 -> 200 | G9: =F9 -> 200 | H9: =F9-G9 -> 0 | I9: 339725
A10: 7 | B10: 1431 | C10: Bakhit Mohamed Salim Rawas | D10: 347 | E10: 0.4 | F10: =E10*D10 -> 138.8 | G10: =134.09+4.71 -> 138.8 | H10: =F10-G10 -> 0 | I10: 721445 | J10: 45628 | K10: 45642
A11: 8 | B11: 1443 | C11: Ahmed Musallam Ahmed Al Kathiri | D11: 1354.3 | E11: 0.4 | F11: =E11*D11 -> 541.72 | G11: =F11 -> 541.72 | H11: =F11-G11 -> 0 | I11: 6026992
A12: 9 | B12: 1452 | C12: Sulaim Said Mohammed Hawas Al Aamri | D12: 319.4 | E12: 0.4 | F12: =E12*D12 -> 127.76 | G12: =126.95+0.81 -> 127.76 | H12: =F12-G12 -> 0 | I12: 20917176 | J12: 45602 | K12: 45628
A13: 10 | B13: 1458 | C13: Salim Mustahil Jamaan Al Shakl Al kathiri | D13: 348.6 | E13: 0.4 | F13: =E13*D13 -> 139.44 | G13: =F13 -> 139.44 | H13: =F13-G13 -> 0 | I13: 77628
A14: 11 | B14: 1461 | C14: Suhail Said Ali Bait said | D14: 358.1 | E14: 0.4 | F14: =E14*D14 -> 143.24 | G14: =F14 -> 143.24 | H14: =F14-G14 -> 0 | I14: 6828806
A15: 12 | B15: 1465 | C15: Mahad Salim Zaed Baitsaid | D15: 360.8 | E15: 0.4 | F15: =E15*D15 -> 144.32 | G15: =F15 -> 144.32 | H15: =F15-G15 -> 0 | I15: 757601 | J15: DCF FEED
A16: 13 | B16: 1474 | C16: Mohamed Salam Amer Al Yafee | D16: 850.2 | E16: 0.4 | F16: =E16*D16 -> 340.08 | G16: =334.16+5.92 -> 340.08 | H16: =F16-G16 -> 0 | I16: 4603773 | J16: 45658 | K16: 45691
A17: 14 | B17: 1479 | C17: Ahmed Amer Said Baitsaid | D17: 389.5 | E17: 0.4 | F17: =E17*D17 -> 155.8 | G17: =152.07+3.73 -> 155.8 | H17: =F17-G17 -> 0 | I17: 5217726 | J17: 45602 | K17: 45637
A18: 15 | B18: 1483 | C18: Saed Ali Ahmed Al Kathiri | D18: 896.9 | E18: 0.4 | F18: =E18*D18 -> 358.76 | G18: =354.79+3.97 -> 358.76 | H18: =F18-G18 -> 0 | I18: 1567826 | J18: 45607 | K18: 45635
A19: 16 | B19: 1486 | C19: Mosoud Ali Salim Al Kathiri | D19: 387.8 | E19: 0.4 | F19: =E19*D19 -> 155.12 | G19: =F19 -> 155.12 | H19: =F19-G19 -> 0 | I19: 22792564 | J19: 45685
A20: 17 | B20: 1762 | C20: MUSALLAM HASAN ALI BAIT SAID | D20: 1237 | E20: 0.4 | F20: =E20*D20 -> 494.8 | G20: =F20 -> 494.8 | H20: =F20-G20 -> 0 | I20: 1409527 | J20: 22-08-2024 already payment has been transferred and paid again , hence deducted from Aug
A21: 18 | B21: 1792 | C21: Musallam Bakhit Salim Al Aamri | D21: 357.4 | E21: 0.4 | F21: =E21*D21 -> 142.96 | G21: =F21 -> 142.96 | H21: =F21-G21 -> 0 | I21: 9545556 | J21: 45658
A22: 19 | B22: 3009 | C22: Ahmed Salim Bakhit Qatan | D22: 311.8 | E22: 0.4 | F22: =E22*D22 -> 124.72 | G22: =F22 -> 124.72 | H22: =F22-G22 -> 0 | I22: 1448391
A23: 20 | B23: 3012 | C23: Salim Suhail Ali Al Kathiri | D23: 350 | E23: 0.4 | F23: =E23*D23 -> 140 | G23: =134.57+5.43 -> 140 | H23: =F23-G23 -> 0 | I23: 5634422 | J23: 45624 | K23: 45637
A24: 21 | B24: 3014 | C24: Ahmed Mohammed Salim Al Barami | D24: 307.3 | E24: 0.4 | F24: =E24*D24 -> 122.92 | G24: =118.81+4.11 -> 122.92 | H24: =F24-G24 -> 0 | I24: 648421 | J24: 45602 | K24: 45624
A25: 22 | B25: 3015 | C25: Ahmed Mohammed Faraj Al Kathiri | D25: 353.4 | E25: 0.4 | F25: =E25*D25 -> 141.36 | G25: =F25 -> 141.36 | H25: =F25-G25 -> 0 | I25: 5753033 | J25: 45779
A26: 23 | B26: 3018 | C26: Bakhit Salim Bakhit Qatan | D26: 256.9 | E26: 0.4 | F26: =E26*D26 -> 102.76 | G26: =100.85+1.91 -> 102.76 | H26: =F26-G26 -> 0 | I26: 1528087 | J26: 45602 | K26: 45629
A27: 24 | B27: 3020 | C27: Bakhit Ali Salim Qatan | D27: 298.1 | E27: 0.4 | F27: =E27*D27 -> 119.24 | G27: =115.53+3.71 -> 119.24 | H27: =F27-G27 -> 0 | I27: 5418422 | J27: 45602 | K27: 45624
A28: 25 | B28: 3022 | C28: Hussein Masoud Aubad Al Kathiri | D28: 907.2 | E28: 0.4 | F28: =E28*D28 -> 362.88 | G28: =358.04+4.84 -> 362.88 | H28: =F28-G28 -> 0 | I28: 5360253 | J28: 45637 | K28: 45656
A29: 26 | B29: 3025 | C29: Musallam Salim Mahad Qatan | D29: 661.1 | E29: 0.4 | F29: =E29*D29 -> 264.44 | G29: =F29 -> 264.44 | H29: =F29-G29 -> 0 | I29: 7542172
A30: 27 | B30: 3026 | C30: Amer Salem Ahmed Qatan | D30: 336 | E30: 0.4 | F30: =E30*D30 -> 134.4 | G30: =F30 -> 134.4 | H30: =F30-G30 -> 0 | I30: 7033819
A31: 28 | B31: 3027 | C31: Salim Ahmed Mahad Aamir Jid | D31: 703.4 | E31: 0.4 | F31: =E31*D31 -> 281.36 | G31: =F31 -> 281.36 | H31: =F31-G31 -> 0 | I31: 6420643 | J31: 45685
A32: 29 | B32: 3030 | C32: Salim Ahmed Salim Amer Jid | D32: 375 | E32: 0.4 | F32: =E32*D32 -> 150 | G32: =F32 -> 150 | H32: =F32-G32 -> 0 | I32: 6021175 | J32: 45650
A33: 30 | B33: 3038 | C33: Said Ahmed Mahad Qatan | D33: 714.2 | E33: 0.4 | F33: =E33*D33 -> 285.68 | G33: =282.6+3.08 -> 285.68 | H33: =F33-G33 -> 0 | I33: 7976 | J33: 45621 | K33: 45637
A34: 31 | B34: 3043 | C34: Said Aubad Ali Ghawas | D34: 321.8 | E34: 0.4 | F34: =E34*D34 -> 128.72 | G34: =125.76+2.96 -> 128.72 | H34: =F34-G34 -> 0 | I34: 396336 | J34: 45642 | K34: 45656
A35: 32 | B35: 3058 | C35: Ali Bakhit Ahmed Qatan | D35: 1071.7 | E35: 0.4 | F35: =E35*D35 -> 428.68 | G35: =F35 -> 428.68 | H35: =F35-G35 -> 0 | I35: 965148
A36: 33 | B36: 3070 | C36: Mohamed Ahmed Suhail Qatan | D36: 1116.5 | E36: 0.4 | F36: =E36*D36 -> 446.6 | G36: =F36 -> 446.6 | H36: =F36-G36 -> 0 | I36: 1918001 | J36: 45627
A37: 34 | B37: 3072 | C37: Mohammed Salim Said Al Barami | D37: 350 | E37: 0.4 | F37: =E37*D37 -> 140 | G37: =138.3+1.7 -> 140 | H37: =F37-G37 -> 0 | I37: 993077 | J37: 45665 | K37: 45779
A38: 35 | B38: 3077 | C38: Mohammed Ali Suhail Qatan | D38: 640 | E38: 0.4 | F38: =E38*D38 -> 256 | G38: =F38 -> 256 | H38: =F38-G38 -> 0 | I38: 21978752 | J38: 45635
A39: 36 | B39: 3081 | C39: Musallam Bakhit Masoud Qatan | D39: 478.2 | E39: 0.4 | F39: =E39*D39 -> 191.28 | G39: =96.55+94.73 -> 191.28 | H39: =F39-G39 -> 0 | I39: 21219868 | J39: 45635 | K39: 94.730-DFI
A40: 37 | B40: 3089 | C40: Yhaya Musallam Said Qatan | D40: 336.4 | E40: 0.4 | F40: =E40*D40 -> 134.56 | G40: =F40 -> 134.56 | H40: =F40-G40 -> 0 | I40: 18790484 | J40: 45656
A41: 38 | B41: 3093 | C41: Bakhit Amer Salem Qatan | D41: 518.1 | E41: 0.4 | F41: =E41*D41 -> 207.24 | G41: =F41 -> 207.24 | H41: =F41-G41 -> 0 | I41: 6361035
...

Sheet Center-Sept
A1: HAJEEF CAMEL MILK PROCUREMENT FROM 01-Sept-2024 TO 30-Sept-2024
A3: Sr. No. | B3: Farmer Code | C3: Farmer Name | D3: Total Milk Qty | E3: Avg. Rate (OMR/Ltr.) | F3: Amount (OMR) | G3: Paid | H3: Balance | I3: ID No. | J3: remark 2
A4: 1 | B4: 1108 | C4: Bakhit Ahmed Musallam Al kathiri | D4: 912.4 | E4: 0.4 | F4: =E4*D4 -> 364.96 | H4: =F4-G4 -> 364.96 | I4: 15218386
A5: 2 | B5: 1390 | C5: Bakhait Salim Ahmed Alash Al Kathiri | D5: 328.2 | E5: 0.4 | F5: =E5*D5 -> 131.28 | G5: =129.85+1.43 -> 131.28 | H5: =F5-G5 -> 0 | I5: 12181822 | J5: 45635 | K5: 45658
A6: 3 | B6: 1399 | C6: Mohammed Suhail Ali Hawas Al Aamri | D6: 241.6 | E6: 0.4 | F6: =E6*D6 -> 96.64 | G6: =F6 -> 96.64 | H6: =F6-G6 -> 0 | I6: 10065546 | J6: dcf feed
A7: 4 | B7: 1422 | C7: Mahammed Musallam Ahmed Hwas | D7: 263.5 | E7: 0.4 | F7: =E7*D7 -> 105.4 | G7: =103.22+2.18 -> 105.4 | H7: =F7-G7 -> 0 | I7: 3280016 | J7: 45628 | K7: 45658
A8: 5 | B8: 1424 | C8: Said Ahmed Sabah Ali Badar | D8: 371.9 | E8: 0.4 | F8: =E8*D8 -> 148.76 | G8: =147.86+0.9 -> 148.76 | H8: =F8-G8 -> 0 | I8: 748395 | J8: 45624 | K8: 45644
A9: 6 | B9: 1429 | C9: Said Mohammed Salem Akdha Al Rawas | D9: 440 | E9: 0.4 | F9: =E9*D9 -> 176 | G9: =174.6+1.4 -> 176 | H9: =F9-G9 -> 0 | I9: 339725 | J9: 45932 | K9: 13-2-25
A10: 7 | B10: 1431 | C10: Bakhit Mohamed Salim Rawas | D10: 329.4 | E10: 0.4 | F10: =E10*D10 -> 131.76 | G10: =131.09+0.67 -> 131.76 | H10: =F10-G10 -> 0 | I10: 721445 | J10: 45642 | K10: 45658
A11: 8 | B11: 1443 | C11: Ahmed Musallam Ahmed Al Kathiri | D11: 1188.9 | E11: 0.4 | F11: =E11*D11 -> 475.56 | H11: =F11-G11 -> 475.56 | I11: 6026992
A12: 9 | B12: 1452 | C12: Sulaim Said Mohammed Hawas Al Aamri | D12: 309.4 | E12: 0.4 | F12: =E12*D12 -> 123.76 | G12: =120.44+3.32 -> 123.76 | H12: =F12-G12 -> 0 | I12: 20917176 | J12: 45628 | K12: 45658
A13: 10 | B13: 1458 | C13: Salim Mustahil Jamaan Al Shakl Al kathiri | D13: 308.8 | E13: 0.4 | F13: =E13*D13 -> 123.52 | H13: =F13-G13 -> 123.52 | I13: 77628
A14: 11 | B14: 1461 | C14: Suhail Said Ali Bait said | D14: 303.9 | E14: 0.4 | F14: =E14*D14 -> 121.56 | H14: =F14-G14 -> 121.56 | I14: 6828806
A15: 12 | B15: 1465 | C15: Mahad Salim Zaed Baitsaid | D15: 315.1 | E15: 0.4 | F15: =E15*D15 -> 126.04 | G15: =F15 -> 126.04 | H15: =F15-G15 -> 0 | I15: 757601 | J15: dcf feed
A16: 13 | B16: 1474 | C16: Mohamed Salam Amer Al Yafee | D16: 706.6 | E16: 0.4 | F16: =E16*D16 -> 282.64 | G16: =280.23 -> 280.23 | H16: =F16-G16 -> 2.41 | I16: 4603773 | J16: 45691
A17: 14 | B17: 1479 | C17: Ahmed Amer Said Baitsaid | D17: 335.4 | E17: 0.4 | F17: =E17*D17 -> 134.16 | G17: =F17 -> 134.16 | H17: =F17-G17 -> 0 | I17: 5217726 | J17: 45637
A18: 15 | B18: 1483 | C18: Saed Ali Ahmed Al Kathiri | D18: 733.6 | E18: 0.4 | F18: =E18*D18 -> 293.44 | G18: =290.98+2.46 -> 293.44 | H18: =F18-G18 -> 0 | I18: 1567826 | J18: 45635 | K18: 45658
A19: 16 | B19: 1486 | C19: Mosoud Ali Salim Al Kathiri | D19: 351.5 | E19: 0.4 | F19: =E19*D19 -> 140.6 | G19: =F19 -> 140.6 | H19: =F19-G19 -> 0 | I19: 22792564 | J19: 45685
A20: 17 | B20: 1762 | C20: MUSALLAM HASAN ALI BAIT SAID | D20: 1093 | E20: 0.4 | F20: =E20*D20 -> 437.2 | G20: =132.96+304.24 -> 437.2 | H20: =F20-G20 -> 0 | I20: 1409527 | J20: 45526 | K20: 22-08-2024 already payment has been transferred and paid again , hence deducted from Aug | L20: 304.24-dcf
A21: 18 | B21: 1792 | C21: Musallam Bakhit Salim Al Aamri | D21: 316.9 | E21: 0.4 | F21: =E21*D21 -> 126.76 | G21: =F21 -> 126.76 | H21: =F21-G21 -> 0 | I21: 9545556 | J21: 45658
A22: 19 | B22: 3009 | C22: Ahmed Salim Bakhit Qatan | D22: 286.6 | E22: 0.4 | F22: =E22*D22 -> 114.64 | H22: =F22-G22 -> 114.64 | I22: 1448391
A23: 20 | B23: 3012 | C23: Salim Suhail Ali Al Kathiri | D23: 308 | E23: 0.4 | F23: =E23*D23 -> 123.2 | G23: =119.57+3.63 -> 123.2 | H23: =F23-G23 -> 0 | I23: 5634422 | J23: 45637 | K23: 45658
A24: 21 | B24: 3014 | C24: Ahmed Mohammed Salim Al Barami | D24: 260.6 | E24: 0.4 | F24: =E24*D24 -> 104.24 | G24: =102.59+1.65 -> 104.24 | H24: =F24-G24 -> 0 | I24: 648421 | J24: 45624 | K24: 45658
A25: 22 | B25: 3015 | C25: Ahmed Mohammed Faraj Al Kathiri | D25: 296.3 | E25: 0.4 | F25: =E25*D25 -> 118.52 | G25: =F25 -> 118.52 | H25: =F25-G25 -> 0 | I25: 5753033 | J25: 45779
A26: 23 | B26: 3018 | C26: Bakhit Salim Bakhit Qatan | D26: 209.4 | E26: 0.4 | F26: =E26*D26 -> 83.76 | G26: =80.54+3.22 -> 83.76 | H26: =F26-G26 -> 0 | I26: 1528087 | J26: 45629 | K26: 45658
A27: 24 | B27: 3020 | C27: Bakhit Ali Salim Qatan | D27: 391.8 | E27: 0.4 | F27: =E27*D27 -> 156.72 | G27: =156.34+0.38 -> 156.72 | H27: =F27-G27 -> 0 | I27: 5418422 | J27: 45624 | K27: 45650
A28: 25 | B28: 3022 | C28: Hussein Masoud Aubad Al Kathiri | D28: 865.8 | E28: 0.4 | F28: =E28*D28 -> 346.32 | G28: =344.36+1.96 -> 346.32 | H28: =F28-G28 -> 0 | I28: 5360253 | J28: 45656 | K28: 45670
A29: 26 | B29: 3025 | C29: Musallam Salim Mahad Qatan | D29: 587.6 | E29: 0.4 | F29: =E29*D29 -> 235.04 | H29: =F29-G29 -> 235.04 | I29: 7542172
A30: 27 | B30: 3026 | C30: Amer Salem Ahmed Qatan | D30: 308 | E30: 0.4 | F30: =E30*D30 -> 123.2 | H30: =F30-G30 -> 123.2 | I30: 7033819
A31: 28 | B31: 3027 | C31: Salim Ahmed Mahad Aamir Jid | D31: 638 | E31: 0.4 | F31: =E31*D31 -> 255.2 | G31: =F31 -> 255.2 | H31: =F31-G31 -> 0 | I31: 6420643 | J31: 45685
A32: 29 | B32: 3030 | C32: Salim Ahmed Salim Amer Jid | D32: 327 | E32: 0.4 | F32: =E32*D32 -> 130.8 | G32: =129.95+0.85 -> 130.8 | H32: =F32-G32 -> 0 | I32: 6021175 | J32: 45650 | K32: 45663
A33: 30 | B33: 3038 | C33: Said Ahmed Mahad Qatan | D33: 638 | E33: 0.4 | F33: =E33*D33 -> 255.2 | G33: =252.75+2.45 -> 255.2 | H33: =F33-G33 -> 0 | I33: 7976 | J33: 45637 | K33: 45650
A34: 31 | B34: 3043 | C34: Said Aubad Ali Ghawas | D34: 279.5 | E34: 0.4 | F34: =E34*D34 -> 111.8 | G34: =108.59+3.21 -> 111.8 | H34: =F34-G34 -> 0 | I34: 396336 | J34: 30-12-241 | K34: 45679
A35: 32 | B35: 3058 | C35: Ali Bakhit Ahmed Qatan | D35: 910.9 | E35: 0.4 | F35: =E35*D35 -> 364.36 | H35: =F35-G35 -> 364.36 | I35: 965148
A36: 33 | B36: 3070 | C36: Mohamed Ahmed Suhail Qatan | D36: 985.7 | E36: 0.4 | F36: =E36*D36 -> 394.28 | G36: =194+198.85+1.43 -> 394.28 | H36: =F36-G36 -> 0 | I36: 1918001 | J36: 45641 | K36: 45648 | L36: 45655
A37: 34 | B37: 3072 | C37: Mohammed Salim Said Al Barami | D37: 308 | E37: 0.4 | F37: =E37*D37 -> 123.2 | G37: =119.55 -> 119.55 | H37: =F37-G37 -> 3.65 | I37: 993077 | J37: 45779
A38: 35 | B38: 3077 | C38: Mohammed Ali Suhail Qatan | D38: 481.9 | E38: 0.4 | F38: =E38*D38 -> 192.76 | G38: =190.53 -> 190.53 | H38: =F38-G38 -> 2.23 | I38: 21978752 | J38: 45635
A39: 36 | B39: 3081 | C39: Musallam Bakhit Masoud Qatan | D39: 436.4 | E39: 0.4 | F39: =E39*D39 -> 174.56 | G39: =F39 -> 174.56 | H39: =F39-G39 -> 0 | I39: 21219868 | J39: dcf feed
A40: 37 | B40: 3089 | C40: Yhaya Musallam Said Qatan | D40: 320.5 | E40: 0.4 | F40: =E40*D40 -> 128.2 | G40: =127.34+0.86 -> 128.2 | H40: =F40-G40 -> 0 | I40: 18790484 | J40: 30-121-24 | K40: 45677
A41: 38 | B41: 3093 | C41: Bakhit Amer Salem Qatan | D41: 511.4 | E41: 0.4 | F41: =E41*D41 -> 204.56 | H41: =F41-G41 -> 204.56 | I41: 6361035
...

Sheet Center-Oct
A1: HAJEEF CAMEL MILK PROCUREMENT FROM 01-Oct-2024 TO 31-Oct-2024
A3: Sr. No. | B3: Farmer Code | C3: Farmer Name | D3: Total Milk Qty | E3: Avg. Rate (OMR/Ltr.) | F3: Amount (OMR) | G3: Amount (OMR) | H3: Amount (OMR) | I3: ID No. | J3: Bank Account | K3: Bank Name. | L3: SWIFT | M3: Phone No. | N3: remark 2 | O3: remark 3
A4: 1 | B4: 1108 | C4: Bakhit Ahmed Musallam Al kathiri | D4: 936.5 | E4: 0.4 | F4: =E4*D4 -> 374.6 | H4: =F4-G4 -> 374.6 | I4: 15218386 | J4: 0439012124150013 | K4: BANK MUSCAT | L4: BMUSOMRX | M4: 92776884
A5: 2 | B5: 1390 | C5: Bakhait Salim Ahmed Alash Al Kathiri | D5: 344.4 | E5: 0.4 | F5: =E5*D5 -> 137.76 | G5: =137.67+0.09 -> 137.76 | H5: =F5-G5 -> 0 | I5: 12181822 | J5: 0439014599800023 | K5: BANK MUSCAT | L5: BMUSOMRX | M5: 92442060 | N5: 45662 | O5: 45691
A6: 3 | B6: 1399 | C6: Mohammed Suhail Ali Hawas Al Aamri | D6: 260.4 | E6: 0.4 | F6: =E6*D6 -> 104.16 | G6: =101.85+2.31 -> 104.16 | H6: =F6-G6 -> 0 | I6: 10065546 | J6: 3109720870700 | K6: OAB | L6: OMABOMRU | N6: 45658 | O6: 45691
A7: 4 | B7: 1422 | C7: Mahammed Musallam Ahmed Hwas | D7: 261.6 | E7: 0.4 | F7: =E7*D7 -> 104.64 | G7: =104.52+0.12 -> 104.64 | H7: =F7-G7 -> 0 | I7: 3280016 | J7: 0397003987550015 | K7: BANK MUSCAT | L7: BMUSOMRX | N7: 45658 | O7: 45691
A8: 5 | B8: 1424 | C8: Said Ahmed Sabah Ali Badar | D8: 388.2 | E8: 0.4 | F8: =E8*D8 -> 155.28 | G8: =154.3+0.98 -> 155.28 | H8: =F8-G8 -> 0 | I8: 748395 | J8: 01012574607001 | K8: BANK DHOFAR | L8: BDOFOMRU | M8: 93011211 | N8: 45644 | O8: 45677
A9: 6 | B9: 1429 | C9: Said Mohammed Salem Akdha Al Rawas | D9: 420 | E9: 0.4 | F9: =E9*D9 -> 168 | G9: =163.5 -> 163.5 | H9: =F9-G9 -> 4.5 | I9: 339725 | J9: 0397003785300017 | K9: BANK MUSCAT | L9: BMUSOMRX | N9: 13-2-25
A10: 7 | B10: 1431 | C10: Bakhit Mohamed Salim Rawas | D10: 186.9 | E10: 0.4 | F10: =E10*D10 -> 74.76 | G10: =72.08+2.68 -> 74.76 | H10: =F10-G10 -> 0 | I10: 721445 | J10: 01010850230001 | K10: BANK DHOFAR | L10: BDOFOMRU | M10: 99291700 | N10: 45658 | O10: 45679
A11: 8 | B11: 1443 | C11: Ahmed Musallam Ahmed Al Kathiri | D11: 1189.4 | E11: 0.4 | F11: =E11*D11 -> 475.76 | H11: =F11-G11 -> 475.76 | I11: 6026992 | J11: 0439017196260028 | K11: BANK MUSCAT | L11: BMUSOMRX | M11: 95863774
A12: 9 | B12: 1452 | C12: Sulaim Said Mohammed Hawas Al Aamri | D12: 389 | E12: 0.4 | F12: =E12*D12 -> 155.6 | G12: =151.89+3.71 -> 155.6 | H12: =F12-G12 -> 0 | I12: 20917176 | J12: 0406012189810015 | K12: BANK MUSCAT | L12: BMUSOMRX | M12: 95863774 | N12: 45658 | O12: 45779
A13: 10 | B13: 1458 | C13: Salim Mustahil Jamaan Al Shakl Al kathiri | D13: 319 | E13: 0.4 | F13: =E13*D13 -> 127.6 | H13: =F13-G13 -> 127.6 | I13: 77628 | J13: 01012583986001 | K13: BANK DHOFAR | L13: BDOFOMRU | M13: 99275608
A14: 11 | B14: 1461 | C14: Suhail Said Ali Bait said | D14: 333.5 | E14: 0.4 | F14: =E14*D14 -> 133.4 | H14: =F14-G14 -> 133.4 | I14: 6828806 | J14: 0396003267730012 | K14: BANK MUSCAT | L14: BMUSOMRX | M14: 92330321
A15: 12 | B15: 1465 | C15: Mahad Salim Zaed Baitsaid | D15: 331.7 | E15: 0.4 | F15: =E15*D15 -> 132.68 | G15: =F15 -> 132.68 | H15: =F15-G15 -> 0 | I15: 757601 | J15: 1023113274001 | K15: NBO | L15: NBOMOMRX | M15: 99892131 | N15: dcf feed
A16: 13 | B16: 1474 | C16: Mohamed Salam Amer Al Yafee | D16: 613.5 | E16: 0.4 | F16: =E16*D16 -> 245.4 | H16: =F16-G16 -> 245.4 | I16: 4603773 | J16: 01041185194001 | K16: BANK DHOFAR | L16: BDOFOMRU | M16: 98820843
A17: 14 | B17: 1479 | C17: Ahmed Amer Said Baitsaid | D17: 303.2 | E17: 0.4 | F17: =E17*D17 -> 121.28 | G17: =119.16 -> 119.16 | H17: =F17-G17 -> 2.12 | I17: 5217726 | J17: 0396003219770029 | K17: BANK MUSCAT | L17: BMUSOMRX | M17: 92610234 | N17: 45637
A18: 15 | B18: 1483 | C18: Saed Ali Ahmed Al Kathiri | D18: 820.3 | E18: 0.4 | F18: =E18*D18 -> 328.12 | G18: =327.34+0.78 -> 328.12 | H18: =F18-G18 -> 0 | I18: 1567826 | J18: 1083724895017 | K18: NBO | L18: NBOMOMRX | M18: 98532884 | N18: 45658 | O18: 45691
A19: 16 | B19: 1486 | C19: Mosoud Ali Salim Al Kathiri | D19: 354.5 | E19: 0.4 | F19: =E19*D19 -> 141.8 | G19: =F19 -> 141.8 | H19: =F19-G19 -> 0 | I19: 22792564 | J19: 0401064266530014 | K19: BANK MUSCAT | L19: BMUSOMRX | N19: 45685
A20: 17 | B20: 1762 | C20: MUSALLAM HASAN ALI BAIT SAID | D20: 1119.5 | E20: 0.4 | F20: =E20*D20 -> 447.8 | G20: =444.45+3.35 -> 447.8 | H20: =F20-G20 -> 0 | I20: 1409527 | J20: 0397003183710017 | K20: Bank Muscat | L20: BMUSOMRX | N20: 45650 | O20: 45677
A21: 18 | B21: 1792 | C21: Musallam Bakhit Salim Al Aamri | D21: 300.2 | E21: 0.4 | F21: =E21*D21 -> 120.08 | G21: =118.28 -> 118.28 | H21: =F21-G21 -> 1.8 | I21: 9545556 | J21: 01011373210001 | K21: BANK DHOFAR | L21: BDOFOMRU | N21: 45658
A22: 19 | B22: 3009 | C22: Ahmed Salim Bakhit Qatan | D22: 219.2 | E22: 0.4 | F22: =E22*D22 -> 87.68 | H22: =F22-G22 -> 87.68 | I22: 1448391 | J22: 3109628132500 | K22: OAB | L22: OMABOMRU | M22: 99100144
A23: 20 | B23: 3012 | C23: Salim Suhail Ali Al Kathiri | D23: 319 | E23: 0.4 | F23: =E23*D23 -> 127.6 | G23: =122.47+5.13 -> 127.6 | H23: =F23-G23 -> 0 | I23: 5634422 | J23: 0406059374210012 | K23: BANK MUSCAT | L23: BMUSOMRX | M23: 96922118 | N23: 45658 | O23: 45677
A24: 21 | B24: 3014 | C24: Ahmed Mohammed Salim Al Barami | D24: 221.3 | E24: 0.4 | F24: =E24*D24 -> 88.52 | G24: =85.65+2.87 -> 88.52 | H24: =F24-G24 -> 0 | I24: 648421 | J24: 3129711924500 | K24: OAB | L24: OMABOMRU | M24: 98815665 | N24: 45658 | O24: 45685
A25: 22 | B25: 3015 | C25: Ahmed Mohammed Faraj Al Kathiri | D25: 223.8 | E25: 0.4 | F25: =E25*D25 -> 89.52 | G25: =84.47 -> 84.47 | H25: =F25-G25 -> 5.05 | I25: 5753033 | J25: 0439058732890011 | K25: BANK MUSCAT | L25: BMUSOMRX | M25: 92838405 | N25: 45779
A26: 23 | B26: 3018 | C26: Bakhit Salim Bakhit Qatan | D26: 128.6 | E26: 0.4 | F26: =E26*D26 -> 51.44 | G26: =50.13+1.31 -> 51.44 | H26: =F26-G26 -> 0 | I26: 1528087 | J26: 0397004184300024 | K26: BANK MUSCAT | L26: BMUSOMRX | N26: 45658 | O26: 45679
A27: 24 | B27: 3020 | C27: Bakhit Ali Salim Qatan | D27: 405.2 | E27: 0.4 | F27: =E27*D27 -> 162.08 | G27: =159.67+2.41 -> 162.08 | H27: =F27-G27 -> 0 | I27: 5418422 | J27: 0401002342630017 | K27: BANK MUSCAT | L27: BMUSOMRX | M27: 99495434 | N27: 45650 | O27: 45677
A28: 25 | B28: 3022 | C28: Hussein Masoud Aubad Al Kathiri | D28: 647.6 | E28: 0.4 | F28: =E28*D28 -> 259.04 | G28: =255.09+3.95 -> 259.04 | H28: =F28-G28 -> 0 | I28: 5360253 | J28: 1060656310017 | K28: NBO | L28: NBOMOMRX | M28: 99257989 | N28: 45670 | O28: 45685
A29: 26 | B29: 3025 | C29: Musallam Salim Mahad Qatan | D29: 596.5 | E29: 0.4 | F29: =E29*D29 -> 238.6 | H29: =F29-G29 -> 238.6 | I29: 7542172 | J29: 0401002461080028 | K29: BANK MUSCAT | L29: BMUSOMRX
A30: 27 | B30: 3026 | C30: Amer Salem Ahmed Qatan | D30: 323 | E30: 0.4 | F30: =E30*D30 -> 129.2 | H30: =F30-G30 -> 129.2 | I30: 7033819 | J30: 0401003532620025 | K30: BANK MUSCAT | L30: BMUSOMRX | M30: 92256918
A31: 28 | B31: 3027 | C31: Salim Ahmed Mahad Aamir Jid | D31: 667 | E31: 0.4 | F31: =E31*D31 -> 266.8 | G31: =F31 -> 266.8 | H31: =F31-G31 -> 0 | I31: 6420643 | J31: 01011362595002 | K31: BANK DHOFAR | L31: BDOFOMRU | M31: 92288434 | N31: 45685
A32: 29 | B32: 3030 | C32: Salim Ahmed Salim Amer Jid | D32: 326 | E32: 0.4 | F32: =E32*D32 -> 130.4 | G32: =130.1+0.3 -> 130.4 | H32: =F32-G32 -> 0 | I32: 6021175 | J32: 0401050718800013 | K32: BANK MUSCAT | L32: BMUSOMRX | M32: 91716888 | N32: 45663 | O32: 45691
A33: 30 | B33: 3038 | C33: Said Ahmed Mahad Qatan | D33: 638 | E33: 0.4 | F33: =E33*D33 -> 255.2 | G33: =253.15+2.05 -> 255.2 | H33: =F33-G33 -> 0 | I33: 7976 | J33: 3109016888700 | K33: OAB | L33: OMABOMRU | M33: 98920007 | N33: 45650 | O33: 45670
A34: 31 | B34: 3043 | C34: Said Aubad Ali Ghawas | D34: 287.7 | E34: 0.4 | F34: =E34*D34 -> 115.08 | G34: =108.34+6.74 -> 115.08 | H34: =F34-G34 -> 0 | I34: 396336 | J34: 0397003933630013 | K34: BANK MUSCAT | L34: BMUSOMRX | M34: 99498844 | N34: 45679
A35: 32 | B35: 3058 | C35: Ali Bakhit Ahmed Qatan | D35: 1025.6 | E35: 0.4 | F35: =E35*D35 -> 410.24 | H35: =F35-G35 -> 410.24 | I35: 965148 | J35: 3129376165700 | K35: OAB | L35: OMABOMRU | M35: 90980121
A36: 33 | B36: 3070 | C36: Mohamed Ahmed Suhail Qatan | D36: 1024 | E36: 0.4 | F36: =E36*D36 -> 409.6 | G36: =405.97+3.63 -> 409.6 | H36: =F36-G36 -> 0 | I36: 1918001 | J36: 0397004395550019 | K36: BANK MUSCAT | L36: BMUSOMRX | M36: 92863640 | N36: 45655 | O36: 45670
A37: 34 | B37: 3072 | C37: Mohammed Salim Said Al Barami | D37: 322 | E37: 0.4 | F37: =E37*D37 -> 128.8 | H37: =F37-G37 -> 128.8 | I37: 993077 | J37: 250094968001 | K37: HSBC | L37: BBMEOMRX | M37: 92252981
A38: 35 | B38: 3077 | C38: Mohammed Ali Suhail Qatan | D38: 604.3 | E38: 0.4 | F38: =E38*D38 -> 241.72 | H38: =F38-G38 -> 241.72 | I38: 21978752 | J38: 0396041232890032 | K38: BANK MUSCAT | L38: BMUSOMRX | M38: 90833336
A39: 36 | B39: 3081 | C39: Musallam Bakhit Masoud Qatan | D39: 434.9 | E39: 0.4 | F39: =E39*D39 -> 173.96 | G39: =F39 -> 173.96 | H39: =F39-G39 -> 0 | I39: 21219868 | J39: 010010201414 | K39: Bank Sohar | L39: BSHROMRU | M39: 93288777
A40: 37 | B40: 3089 | C40: Yhaya Musallam Said Qatan | D40: 288.2 | E40: 0.4 | F40: =E40*D40 -> 115.28 | G40: =F40 -> 115.28 | H40: =F40-G40 -> 0 | I40: 18790484 | J40: 0401016503450018 | K40: BANK MUSCAT | L40: BMUSOMRX | N40: 45677
A41: 38 | B41: 3093 | C41: Bakhit Amer Salem Qatan | D41: 428.2 | E41: 0.4 | F41: =E41*D41 -> 171.28 | H41: =F41-G41 -> 171.28 | I41: 6361035 | J41: 00510034969002 | K41: BANK NIZWA | L41: BNZWOMRX | M41: 99497919
...

Sheet Center-Nov
A1: HAJEEF CAMEL MILK PROCUREMENT FROM 01-Nov-2024 TO 30-Nov-2024
A3: Sr. No. | B3: Farmer Code | C3: Farmer Name | D3: Total Milk Qty | E3: Avg. Rate (OMR/Ltr.) | F3: Amount (OMR) | G3: Paid | H3: BALANCE | I3: ID No. | J3: Bank Account | K3: Bank Name. | L3: SWIFT | M3: Phone No. | N3: remark 2
A4: 1 | B4: 1108 | C4: Bakhit Ahmed Musallam Al kathiri | D4: 812.9 | E4: 0.4 | F4: =E4*D4 -> 325.16 | H4: =F4-G4 -> 325.16 | I4: 15218386 | J4: 0439012124150013 | K4: BANK MUSCAT | L4: BMUSOMRX | M4: 92776884
A5: 2 | B5: 1390 | C5: Bakhait Salim Ahmed Alash Al Kathiri | D5: 250.7 | E5: 0.4 | F5: =E5*D5 -> 100.28 | G5: =96.21 -> 96.21 | H5: =F5-G5 -> 4.07 | I5: 12181822 | J5: 0439014599800023 | K5: BANK MUSCAT | L5: BMUSOMRX | M5: 92442060 | N5: 45691
A6: 3 | B6: 1399 | C6: Mohammed Suhail Ali Hawas Al Aamri | D6: 187.7 | E6: 0.4 | F6: =E6*D6 -> 75.08 | G6: =70.44 -> 70.44 | H6: =F6-G6 -> 4.64 | I6: 10065546 | J6: 3109720870700 | K6: OAB | L6: OMABOMRU | N6: 45691
A7: 4 | B7: 1422 | C7: Mahammed Musallam Ahmed Hwas | D7: 185.2 | E7: 0.4 | F7: =E7*D7 -> 74.08 | G7: =72.63 -> 72.63 | H7: =F7-G7 -> 1.45 | I7: 3280016 | J7: 0397003987550015 | K7: BANK MUSCAT | L7: BMUSOMRX | N7: 45691
A8: 5 | B8: 1424 | C8: Said Ahmed Sabah Ali Badar | D8: 299.9 | E8: 0.4 | F8: =E8*D8 -> 119.96 | G8: =115.42+4.54 -> 119.96 | H8: =F8-G8 -> 0 | I8: 748395 | J8: 01012574607001 | K8: BANK DHOFAR | L8: BDOFOMRU | M8: 93011211 | N8: 45677 | O8: 45902
A9: 6 | B9: 1429 | C9: Said Mohammed Salem Akdha Al Rawas | D9: 349 | E9: 0.4 | F9: =E9*D9 -> 139.6 | H9: =F9-G9 -> 139.6 | I9: 339725 | J9: 0397003785300017 | K9: BANK MUSCAT | L9: BMUSOMRX
A10: 7 | B10: 1431 | C10: Bakhit Mohamed Salim Rawas | D10: 265.9 | E10: 0.4 | F10: =E10*D10 -> 106.36 | G10: =104.02 -> 104.02 | H10: =F10-G10 -> 2.34 | I10: 721445 | J10: 01010850230001 | K10: BANK DHOFAR | L10: BDOFOMRU | M10: 99291700 | N10: 45680
A11: 8 | B11: 1443 | C11: Ahmed Musallam Ahmed Al Kathiri | D11: 944.6 | E11: 0.4 | F11: =E11*D11 -> 377.84 | H11: =F11-G11 -> 377.84 | I11: 6026992 | J11: 0439017196260028 | K11: BANK MUSCAT | L11: BMUSOMRX | M11: 95863774
A12: 9 | B12: 1452 | C12: Sulaim Said Mohammed Hawas Al Aamri | D12: 327.7 | E12: 0.4 | F12: =E12*D12 -> 131.08 | G12: =127.24 -> 127.24 | H12: =F12-G12 -> 3.84 | I12: 20917176 | J12: 0406012189810015 | K12: BANK MUSCAT | L12: BMUSOMRX | M12: 95863774 | N12: 45779
A13: 10 | B13: 1458 | C13: Salim Mustahil Jamaan Al Shakl Al kathiri | D13: 260.3 | E13: 0.4 | F13: =E13*D13 -> 104.12 | H13: =F13-G13 -> 104.12 | I13: 77628 | J13: 01012583986001 | K13: BANK DHOFAR | L13: BDOFOMRU | M13: 99275608
A14: 11 | B14: 1461 | C14: Suhail Said Ali Bait said | D14: 259.8 | E14: 0.4 | F14: =E14*D14 -> 103.92 | H14: =F14-G14 -> 103.92 | I14: 6828806 | J14: 0396003267730012 | K14: BANK MUSCAT | L14: BMUSOMRX | M14: 92330321
