Workbook

Sheet center-April
A1: HAJEEF COW MILK PROCUREMENT FROM 01-APR-2024 TO 30-APR-2024
A2: Sr No. | B2: Farmer Code | C2: Farmer Name | D2: Milk Qty. (Ltr.) | E2: Avg. Rate (OMR/Ltr.) | F2: Amount (OMR) | G2: paid | H2: balance | I2: ID No. | J2: Bank Account No. | K2: Bank Name | L2: IFSC Code | M2: Phone No. | N2: Remarks
A4: 31 | B4: 3153 | C4: ALI MAHAD SAID QATAN | D4: 1897.7 | E4: 0.250 | F4: =D4*E4 -> 474.425 | G4: =473.5+0.925 -> 474.425 | H4: =F4-G4 -> 0 | I4: 6989479 | J4: 0397003672070015 | K4: BANK MUSCAT | L4: BMUSOMRX | M4: 99699500 | N4: 12-08-2024-feeds | P4: 3153 | Q4: =P4=B4 -> TRUE | R4: ALI MAHAD SAID QATAN | S4: =R4=C4 -> TRUE | T4: 6989479 | U4: =T4=I4 -> TRUE | V4: 0397003672070015 | W4: =V4=J4 -> TRUE | X4: BMUSOMRX | Y4: =X4=L4 -> TRUE
A5: 76 | B5: 3511 | C5: Said Ali Said Qatan | D5: 1359.8 | E5: 0.250 | F5: =D5*E5 -> 339.95 | G5: =337.05+2.9 -> 339.95 | H5: =F5-G5 -> 0 | I5: 2640016 | J5: 0501036199001 | K5: Ahli Islamic | L5: AUBOOMRUALH | M5: 92953388 | N5: 05-08-2024-feeds | O5: 45630 | P5: 3511 | Q5: =P5=B5 -> TRUE | R5: Said Ali Said Qatan | S5: =R5=C5 -> TRUE | T5: 2640016 | U5: =T5=I5 -> TRUE | V5: 0501036199001 | W5: =V5=J5 -> TRUE | X5: AUBOOMRUALH | Y5: =X5=L5 -> TRUE
D6: =SUM(D4:D5) -> 3257.5 | F6: =SUM(F4:F5) -> 814.375 | G6: =SUM(G4:G5) -> 814.375 | H6: =SUM(H4:H5) -> 0
A9: Hassan Ghaly | C9: Suresh Bose
A10: Cost Accountant | C10: Sr.Operations Officer
V12: Said Al Bahanata
V13: DGM

Sheet center-May
A1: HAJEEF COW MILK PROCUREMENT FROM 01-May-2024 TO 31-May-2024
A2: Sr No. | B2: Farmer Code | C2: Farmer Name | D2: Milk Qty. (Ltr.) | E2: Avg. Rate (OMR/Ltr.) | F2: Amount (OMR) | G2: Amount (OMR) | H2: Amount (OMR) | I2: ID No. | J2: Bank Account No. | K2: Bank Name | L2: IFSC Code | M2: Phone No. | N2: Remarks
A4: 6 | B4: 3169 | C4: MOHAMMED ALI SAID AL ZAWAMRY | D4: 1284.1 | E4: 0.250 | F4: =D4*E4 -> 321.025 | G4: =320.1+0.925 -> 321.025 | H4: =F4-G4 -> 0 | I4: 3068756 | J4: 01012573317001 | K4: BANK DHOFAR | L4: BDOFOMRU | M4: 99691806 | N4: 45547 | O4: 45615 | P4: 3169 | Q4: =P4=B4 -> TRUE | R4: MOHAMMED ALI SAID AL ZAWAMRY | S4: =R4=C4 -> TRUE | T4: 3068756 | U4: =T4=I4 -> TRUE | V4: 01012573317001 | W4: =V4=J4 -> TRUE | X4: BDOFOMRU | Y4: =X4=L4 -> TRUE
A5: 7 | B5: 3192 | C5: GHAZI SALIM MASOUD TABOOK | D5: 1124.5 | E5: 0.250 | F5: =D5*E5 -> 281.125 | G5: =279.73+1.395 -> 281.125 | H5: =F5-G5 -> 0 | I5: 5271448 | J5: 0401002602010018 | K5: BANK MUSCAT | L5: BMUSOMRX | M5: 99489918 | N5: 01-08-2024-feeds | O5: 09-12-234 | P5: 3192 | Q5: =P5=B5 -> TRUE | R5: GHAZI SALIM MASOUD TABOOK | S5: =R5=C5 -> TRUE | T5: 5271448 | U5: =T5=I5 -> TRUE | V5: 0426012948850015 | W5: =V5=J5 -> FALSE | X5: BMUSOMRX | Y5: =X5=L5 -> TRUE
A6: 8 | B6: 3198 | C6: ADIL SAID AHMED AL ZAWAMRI | D6: 591.6 | E6: 0.250 | F6: =D6*E6 -> 147.9 | G6: =144.15+3.75 -> 147.9 | H6: =F6-G6 -> 0 | I6: 6360793 | J6: 00510047506001 | K6: Bank Nizwa | L6: BNZWOMRX | M6: 99336200 | N6: 11-08-2024-feeds | P6: 3198 | Q6: =P6=B6 -> TRUE | R6: ADIL SAID AHMED AL ZAWAMRI | S6: =R6=C6 -> TRUE | T6: 6360793 | U6: =T6=I6 -> TRUE | V6: 00510047506001 | W6: =V6=J6 -> TRUE | X6: BNZWOMRX | Y6: =X6=L6 -> TRUE
A7: 9 | B7: 3508 | C7: Said Ali Said Al Zawamri | D7: 610.9 | E7: 0.250 | F7: =D7*E7 -> 152.725 | G7: =150.35+2.375 -> 152.725 | H7: =F7-G7 -> 0 | I7: 2567166 | J7: 0439004225500028 | K7: BANK MUSCAT | L7: BMUSOMRX | M7: 92570156 | N7: 45547 | O7: 45615 | P7: 3508 | Q7: =P7=B7 -> TRUE | R7: Said Ali Said Al Zawamri | S7: =R7=C7 -> TRUE | T7: 2567166 | U7: =T7=I7 -> TRUE | V7: 0439004225500028 | W7: =V7=J7 -> TRUE | X7: BMUSOMRX | Y7: =X7=L7 -> TRUE
A8: 11 | B8: 3515 | C8: Ali Ajaham Ali Bait said | D8: 1267.5 | E8: 0.250 | F8: =D8*E8 -> 316.875 | G8: =315.625+1.25 -> 316.875 | H8: =F8-G8 -> 0 | I8: 6645198 | J8: 01011180247001 | K8: BANK DHOFAR | L8: BDOFOMRU | M8: 94411217 | N8: 14-08-24-feeds | O8: 45635 | P8: 3515 | Q8: =P8=B8 -> TRUE | R8: Ali Ajaham Ali Bait said | S8: =R8=C8 -> TRUE | T8: 6645198 | U8: =T8=I8 -> TRUE | V8: 01011180247001 | W8: =V8=J8 -> TRUE | X8: BDOFOMRU | Y8: =X8=L8 -> TRUE
A9: 12 | B9: 3518 | C9: Ali Ahmed Ali Bait Said | D9: 899.8 | E9: 0.250 | F9: =D9*E9 -> 224.95 | G9: =221.275+3.675 -> 224.95 | H9: =F9-G9 -> 0 | I9: 20386956 | J9: 0396064567750014 | K9: BANK MUSCAT | L9: BMUSOMRX | N9: 14-08-24-feeds | P9: 3518 | Q9: =P9=B9 -> TRUE | R9: Ali Ahmed Ali Bait Said | S9: =R9=C9 -> TRUE | T9: 20386956 | U9: =T9=I9 -> TRUE | V9: 0396064567750014 | W9: =V9=J9 -> TRUE | X9: BMUSOMRX | Y9: =X9=L9 -> TRUE
D10: =SUM(D4:D9) -> 5778.4 | F10: =SUM(F4:F9) -> 1444.6 | G10: =SUM(G4:G9) -> 1444.6 | H10: =SUM(H4:H9) -> 0
A13: Hassan Ghaly | C13: Suresh Bose | D13: Dr .Nasser Ali Baitsaid | F13: Aqeel Ali Ibrahim | K13: Shk. | W13: Said Al Bahanta
A14: Cost Accountant | C14: Sr.Operations Officer | D14: General Manager | F14: Vice Chairman | K14: Chairman | W14: DGM

Sheet center-June
A1: HAJEEF COW MILK PROCUREMENT FROM 01-June-2024 TO 30-June-2024
A2: Sr No. | B2: Farmer Code | C2: Farmer Name | D2: Milk Qty. (Ltr.) | E2: Avg. Rate (OMR/Ltr.) | F2: Amount (OMR) | G2: Paid | H2: Balance | I2: ID No. | J2: Remarks
A4: 6 | B4: 1344 | C4: SAID AMERAHMED BAITSAID | D4: 2447.8 | E4: 0.250 | F4: =D4*E4 -> 611.95 | G4: =608.65+3.3 -> 611.95 | H4: =F4-G4 -> 0 | I4: 4014519 | J4: 45567 | K4: 45680
A5: 15 | B5: 3057 | C5: ALI AHMED MOHAMMED AL KATHIRI | D5: 2434.4 | E5: 0.250 | F5: =D5*E5 -> 608.6 | G5: =607.025+1.575 -> 608.6 | H5: =F5-G5 -> 0 | I5: 626819 | J5: 18-09-2024 | K5: 45607
A6: 45 | B6: 3184 | C6: ALI MOHAMMED MUSALLAM AL BARAAMI | D6: 1682 | E6: 0.250 | F6: =D6*E6 -> 420.5 | G6: =419.575+0.925 -> 420.5 | H6: =F6-G6 -> 0 | I6: 6701602 | J6: 25-09-2024
A7: 74 | B7: 3515 | C7: Ali Ajaham Ali Bait said | D7: 1459.6 | E7: 0.250 | F7: =D7*E7 -> 364.9 | G7: =362.5+2.4 -> 364.9 | H7: =F7-G7 -> 0 | I7: 6645198 | J7: 16-09-2024 | K7: 09-12-241
D9: =SUM(D4:D8) -> 8023.8 | F9: =SUM(F4:F8) -> 2005.95 | G9: =SUM(G4:G8) -> 2005.95 | H9: =SUM(H4:H8) -> 0

Sheet center-Aug
A1: HAJEEF COW MILK PROCUREMENT FROM 01-Aug-2024 TO 31-Aug-2024
A2: Sr No. | B2: Farmer Code | C2: Farmer Name | D2: Milk Qty. (Ltr.) | E2: Avg. Rate (OMR/Ltr.) | F2: Amount (OMR) | G2: Paid | H2: Balance | I2: ID No. | J2: Remarks
A4: 1 | B4: 1007 | C4: AHMED ABDULLAH SAID AL RAWAS | D4: 6235.9 | E4: 0.250 | F4: =D4*E4 -> 1558.975 | G4: =F4 -> 1558.975 | H4: =F4-G4 -> 0 | I4: 1515504
A5: 2 | B5: 1041 | C5: AHMED SALIM ALI BAITSAID | D5: 3114.6 | E5: 0.250 | F5: =D5*E5 -> 778.65 | G5: =F5 -> 778.65 | H5: =F5-G5 -> 0 | I5: 6827729
A6: 3 | B6: 1125 | C6: MUSALLAM SAID ALI BAITSAID | D6: 6268.6 | E6: 0.250 | F6: =D6*E6 -> 1567.15 | G6: =1231.5+335.65 -> 1567.15 | H6: =F6-G6 -> 0 | I6: 6828774 | J6: 45607 | K6: 45630
A7: 4 | B7: 1222 | C7: Mahad Salim Abdulaziz Alkathiri | D7: 81 | E7: 0.250 | F7: =D7*E7 -> 20.25 | G7: =F7 -> 20.25 | H7: =F7-G7 -> 0 | I7: 31221
A8: 5 | B8: 1286 | C8: SALIM AMER AHMED AL YAFAEI | D8: 3072.9 | E8: 0.250 | F8: =D8*E8 -> 768.225 | G8: =F8 -> 768.225 | H8: =F8-G8 -> 0 | I8: 368056
A9: 6 | B9: 1344 | C9: SAID AMERAHMED BAITSAID | D9: 2377.9 | E9: 0.250 | F9: =D9*E9 -> 594.475 | G9: =F9 -> 594.475 | H9: =F9-G9 -> 0 | I9: 4014519 | J9: 45680
A10: 7 | B10: 1352 | C10: MOHAMMED MASOUD AJHAM ALSH AL KATHIRI | D10: 1265 | E10: 0.250 | F10: =D10*E10 -> 316.25 | G10: =F10 -> 316.25 | H10: =F10-G10 -> 0 | I10: 1627344
A11: 8 | B11: 1354 | C11: AHMED SAID HASSAN BAITSAID | D11: 2517.5 | E11: 0.250 | F11: =D11*E11 -> 629.375 | G11: =F11 -> 629.375 | H11: =F11-G11 -> 0 | I11: 925709
A12: 9 | B12: 1357 | C12: MUSALLAM SAID ALI BAIT SAID | D12: 5109.3 | E12: 0.250 | F12: =D12*E12 -> 1277.325 | G12: =F12 -> 1277.325 | H12: =F12-G12 -> 0 | I12: 1052276
A13: 10 | B13: 1359 | C13: MUSALLAM MUSTAHIL SAID BAIT SAID | D13: 3123.6 | E13: 0.250 | F13: =D13*E13 -> 780.9 | G13: =325.675+455.225 -> 780.9 | H13: =F13-G13 -> 0 | I13: 4812026 | J13: 45630 | K13: 2 times taken from jan feed
A14: 11 | B14: 1367 | C14: ALI MUSALLAM AHMED BAIT SAID | D14: 1000 | E14: 0.250 | F14: =D14*E14 -> 250 | G14: =F14 -> 250 | H14: =F14-G14 -> 0 | I14: 6663593
A15: 12 | B15: 1368 | C15: MOHAMMD SAID AHMED AL KATHIRI | D15: 4041.6 | E15: 0.250 | F15: =D15*E15 -> 1010.4 | G15: =1008.875+1.525 -> 1010.4 | H15: =F15-G15 -> 0 | I15: 561902 | J15: 45601 | K15: 26-11-214
A16: 13 | B16: 3002 | C16: KHALID MUBARAK ALI ATQOON AL SHAHRI | D16: 1666.8 | E16: 0.250 | F16: =D16*E16 -> 416.7 | G16: =416.55+0.15 -> 416.7 | H16: =F16-G16 -> 0 | I16: 21220177 | J16: 45607 | K16: 45629
A17: 14 | B17: 3035 | C17: TARIQ SALIM SUHAIL AL BARAMI | D17: 389.8 | E17: 0.250 | F17: =D17*E17 -> 97.45 | G17: =F17 -> 97.45 | H17: =F17-G17 -> 0 | I17: 6725058
A18: 15 | B18: 3057 | C18: ALI AHMED MOHAMMED AL KATHIRI | D18: 2746.6 | E18: 0.250 | F18: =D18*E18 -> 686.65 | G18: =685.575+1.075 -> 686.65 | H18: =F18-G18 -> 0 | I18: 626819 | J18: 45607 | K18: 45629
A19: 16 | B19: 3062 | C19: ALI MAHAD SILMOUN QATAN | D19: 2523.4 | E19: 0.250 | F19: =D19*E19 -> 630.85 | G19: =312.375+315.25+3.2252 -> 630.8502 | H19: =F19-G19 -> -0.0002 | I19: 300741 | J19: 45615 | K19: 45644 | L19: 45677
A20: 17 | B20: 3080 | C20: MUSALLAM BAKHIT AWADH L BARAAMI | D20: 1270.2 | E20: 0.250 | F20: =D20*E20 -> 317.55 | G20: =F20 -> 317.55 | H20: =F20-G20 -> 0 | I20: 14301608
A21: 18 | B21: 3086 | C21: MUSALLAM ALI MATOOQ TABOOK | D21: 892.4 | E21: 0.250 | F21: =D21*E21 -> 223.1 | G21: =222.7+0.4 -> 223.1 | H21: =F21-G21 -> 0 | I21: 300033 | J21: 45607 | K21: 38325
A22: 19 | B22: 3132 | C22: HASHIM SALIM ALI ATIF AL YAFAI | D22: 1301.6 | E22: 0.250 | F22: =D22*E22 -> 325.4 | G22: =211.825+113.575 -> 325.4 | H22: =F22-G22 -> 0 | I22: 14606296 | J22: 45637 | K22: 45663
A23: 20 | B23: 3134 | C23: HASSAN SUHAIL MAHAD QATAN | D23: 1332.2 | E23: 0.250 | F23: =D23*E23 -> 333.05 | G23: =F23 -> 333.05 | H23: =F23-G23 -> 0 | I23: 2154413 | J23: 45672
A24: 21 | B24: 3142 | C24: MOHAMMED AHMED SAAD MASHRAH AL SHAHRI | D24: 4325.4 | E24: 0.250 | F24: =D24*E24 -> 1081.35 | G24: =F24 -> 1081.35 | H24: =F24-G24 -> 0 | I24: 165497 | J24: 29-01-25
A25: 22 | B25: 3145 | C25: MOHAMMED BAKHIT MASOUD QATAN | D25: 3318.2 | E25: 0.250 | F25: =D25*E25 -> 829.55 | G25: =F25 -> 829.55 | H25: =F25-G25 -> 0 | I25: 1915745 | J25: DCF feed
A26: 23 | B26: 3147 | C26: KHALID SAID MAHAD KASHOUB | D26: 810 | E26: 0.250 | F26: =D26*E26 -> 202.5 | G26: =F26 -> 202.5 | H26: =F26-G26 -> 0 | I26: 1662414 | J26: DCF feed
A27: 24 | B27: 3148 | C27: MUSALLAM AHMED MAHTOUQ AL ZAWAMRI | D27: 1233 | E27: 0.250 | F27: =D27*E27 -> 308.25 | G27: =F27 -> 308.25 | H27: =F27-G27 -> 0 | I27: 19545736 | J27: DCF feed
A28: 25 | B28: 3149 | C28: ALI SAID ALI AL ZAWAMRI | D28: 1465.5 | E28: 0.250 | F28: =D28*E28 -> 366.375 | G28: =F28 -> 366.375 | H28: =F28-G28 -> 0 | I28: 4941095 | J28: 032-12-24
A29: 26 | B29: 3152 | C29: BAKHIT SALIM MAHAD QATAN | D29: 2129.7 | E29: 0.250 | F29: =D29*E29 -> 532.425 | G29: =356.6+174.6+1.225 -> 532.425 | H29: =F29-G29 -> 0 | I29: 941993 | J29: 10-10-2024,PR-063 | K29: 45600 | L29: 174 | M29: 45621
A30: 27 | B30: 3153 | C30: ALI MAHAD SAID QATAN | D30: 2394.9 | E30: 0.250 | F30: =D30*E30 -> 598.725 | G30: =176.925+417.1+4.7 -> 598.725 | H30: =F30-G30 -> 0 | I30: 6989479 | J30: 45637 | K30: 45658 | M30: 15-01-245
A31: 28 | B31: 3155 | C31: SAID BAKHIT MAHAD QATAN | D31: 631.4 | E31: 0.250 | F31: =D31*E31 -> 157.85 | G31: =F31 -> 157.85 | H31: =F31-G31 -> 0 | I31: 19188794
A32: 29 | B32: 3158 | C32: AHMED OBAIDAN AHMED AL KATHIRI | D32: 2447.4 | E32: 0.250 | F32: =D32*E32 -> 611.85 | G32: =F32 -> 611.85 | H32: =F32-G32 -> 0 | I32: 596869
A33: 30 | B33: 3159 | C33: AHMED BAKHIT SALEM AL BARAMI | D33: 720.3 | E33: 0.250 | F33: =D33*E33 -> 180.075 | G33: =F33 -> 180.075 | H33: =F33-G33 -> 0 | I33: 1297478 | J33: BT 22-01-2025
A34: 31 | B34: 3160 | C34: NAIF MUBARAK BAKHIT AL BARAAMI | D34: 1751.3 | E34: 0.250 | F34: =D34*E34 -> 437.825 | G34: =F34 -> 437.825 | H34: =F34-G34 -> 0 | I34: 2837163
A35: 32 | B35: 3162 | C35: MOHAMMED SAID FARAJ AL KATHIRI | D35: 4854.9 | E35: 0.250 | F35: =D35*E35 -> 1213.725 | G35: =F35 -> 1213.725 | H35: =F35-G35 -> 0 | I35: 7017227 | J35: BT 22-01-2025
A36: 33 | B36: 3164 | C36: ALI MUSALLLAM HASSAN BAITSAID | D36: 2451.8 | E36: 0.250 | F36: =D36*E36 -> 612.95 | G36: =611.1 -> 611.1 | H36: =F36-G36 -> 1.85 | I36: 7466062 | J36: 45673
A37: 34 | B37: 3165 | C37: KHALID MOHAMMED MASAAOD AGGHRIB AL SHAHRI | D37: 442.2 | E37: 0.250 | F37: =D37*E37 -> 110.55 | G37: =F37 -> 110.55 | H37: =F37-G37 -> 0 | I37: 19029628
A38: 35 | B38: 3169 | C38: MOHAMMED ALI SAID AL ZAWAMRY | D38: 1784.1 | E38: 0.250 | F38: =D38*E38 -> 446.025 | G38: =441.6 -> 441.6 | H38: =F38-G38 -> 4.425 | I38: 3068756 | J38: 45615
A39: 36 | B39: 3171 | C39: HATAM AWADH SAID QATAN | D39: 1076 | E39: 0.250 | F39: =D39*E39 -> 269 | G39: =268.425+0.575 -> 269 | H39: =F39-G39 -> 0 | I39: 7239057 | J39: 45601
A40: 37 | B40: 3172 | C40: Fatima Suleimon Salim ALBaramiyah | D40: 697.8 | E40: 0.250 | F40: =D40*E40 -> 174.45 | G40: =F40 -> 174.45 | H40: =F40-G40 -> 0 | I40: 5276984
A41: 38 | B41: 3173 | C41: MUSALLAM AHMED SAAD AL BARAAMI | D41: 1255 | E41: 0.250 | F41: =D41*E41 -> 313.75 | G41: =F41 -> 313.75 | H41: =F41-G41 -> 0 | I41: 6825655 | J41: DCF feed
...

Sheet Center-Sept
A1: HAJEEF COW MILK PROCUREMENT FROM 01-Sept-2024 TO 30-Sept-2024
A2: Sr No. | B2: Farmer Code | C2: Farmer Name | D2: Milk Qty. (Ltr.) | E2: Avg. Rate (OMR/Ltr.) | F2: Amount (OMR) | G2: Paid | H2: Balance | I2: Remarks
A4: 1 | B4: 1007 | C4: AHMED ABDULLAH SAID AL RAWAS | D4: 6082.2 | E4: 0.250 | F4: =D4*E4 -> 1520.55 | H4: =F4-G4 -> 1520.55 | M4: 1007 | N4: =M4=B4 -> TRUE | O4: AHMED ABDULLAH SAID AL RAWAS | P4: =O4=C4 -> TRUE | Q4: 1515504 | R4: =Q4=#REF! -> #REF! | S4: 0615500670380001 | T4: =S4=#REF! -> #REF! | U4: BMUSOMRXISL | V4: =U4=#REF! -> #REF!
A5: 2 | B5: 1041 | C5: AHMED SALIM ALI BAITSAID | D5: 2583.1 | E5: 0.250 | F5: =D5*E5 -> 645.775 | H5: =F5-G5 -> 645.775 | M5: 1041 | N5: =M5=B5 -> TRUE | O5: AHMED SALIM ALI BAITSAID | P5: =O5=C5 -> TRUE | Q5: 6827729 | R5: =Q5=#REF! -> #REF! | S5: 0406003463970017 | T5: =S5=#REF! -> #REF! | U5: BMUSOMRX | V5: =U5=#REF! -> #REF!
A6: 3 | B6: 1125 | C6: MUSALLAM SAID ALI BAITSAID | D6: 6122.4 | E6: 0.250 | F6: =D6*E6 -> 1530.6 | G6: =1526.35+4.25 -> 1530.6 | H6: =F6-G6 -> 0 | I6: 45630 | J6: 45658 | M6: 1125 | N6: =M6=B6 -> TRUE | O6: MUSALLAM SAID ALI BAITSAID | P6: =O6=C6 -> TRUE | Q6: 6828774 | R6: =Q6=#REF! -> #REF! | S6: 01011456108001 | T6: =S6=#REF! -> #REF! | U6: BDOFOMRU | V6: =U6=#REF! -> #REF!
A7: 4 | B7: 1222 | C7: Mahad Salim Abdulaziz Alkathiri | D7: 965.7 | E7: 0.250 | F7: =D7*E7 -> 241.425 | H7: =F7-G7 -> 241.425
A8: 5 | B8: 1286 | C8: SALIM AMER AHMED AL YAFAEI | D8: 2975.1 | E8: 0.250 | F8: =D8*E8 -> 743.775 | H8: =F8-G8 -> 743.775 | M8: 1286 | N8: =M8=B8 -> TRUE | O8: SALIM AMER AHMED AL YAFAEI | P8: =O8=C8 -> TRUE | Q8: 368056 | R8: =Q8=#REF! -> #REF! | S8: 0406003218280013 | T8: =S8=#REF! -> #REF! | U8: BMUSOMRX | V8: =U8=#REF! -> #REF!
A9: 6 | B9: 1344 | C9: SAID AMERAHMED BAITSAID | D9: 2380 | E9: 0.250 | F9: =D9*E9 -> 595 | G9: =590.275+4.725 -> 595 | H9: =F9-G9 -> 0 | I9: 45680 | J9: DCF-27-01-25 | M9: 1344 | N9: =M9=B9 -> TRUE | O9: SAID AMERAHMED BAITSAID | P9: =O9=C9 -> TRUE | Q9: 4014519 | R9: =Q9=#REF! -> #REF! | S9: 3109370559500 | T9: =S9=#REF! -> #REF! | U9: OMABOMRU | V9: =U9=#REF! -> #REF!
A10: 7 | B10: 1352 | C10: MOHAMMED MASOUD AJHAM ALSH AL KATHIRI | D10: 1605.1 | E10: 0.250 | F10: =D10*E10 -> 401.275 | H10: =F10-G10 -> 401.275 | M10: 1352 | N10: =M10=B10 -> TRUE | O10: MOHAMMED MASOUD AJHAM ALSH AL KATHIRI | P10: =O10=C10 -> TRUE | Q10: 1627344 | R10: =Q10=#REF! -> #REF! | S10: 0397046773470015 | T10: =S10=#REF! -> #REF! | U10: BMUSOMRX | V10: =U10=#REF! -> #REF!
A11: 8 | B11: 1354 | C11: AHMED SAID HASSAN BAITSAID | D11: 2445.3 | E11: 0.250 | F11: =D11*E11 -> 611.325 | H11: =F11-G11 -> 611.325 | M11: 1354 | N11: =M11=B11 -> TRUE | O11: AHMED SAID HASSAN BAITSAID | P11: =O11=C11 -> TRUE | Q11: 925709 | R11: =Q11=#REF! -> #REF! | S11: 0406018690130014 | T11: =S11=#REF! -> #REF! | U11: BMUSOMRX | V11: =U11=#REF! -> #REF!
A12: 9 | B12: 1357 | C12: MUSALLAM SAID ALI BAIT SAID | D12: 4796.9 | E12: 0.250 | F12: =D12*E12 -> 1199.225 | H12: =F12-G12 -> 1199.225 | M12: 1357 | N12: =M12=B12 -> TRUE | O12: MUSALLAM SAID ALI BAIT SAID | P12: =O12=C12 -> TRUE | Q12: 1052276 | R12: =Q12=#REF! -> #REF! | S12: 01040280323001 | T12: =S12=#REF! -> #REF! | U12: BDOFOMRU | V12: =U12=#REF! -> #REF!
A13: 10 | B13: 1359 | C13: MUSALLAM MUSTAHIL SAID BAIT SAID | D13: 2673.6 | E13: 0.250 | F13: =D13*E13 -> 668.4 | G13: =665.125+3.275 -> 668.4 | H13: =F13-G13 -> 0 | I13: 45630 | J13: 45655 | M13: 1359 | N13: =M13=B13 -> TRUE | O13: MUSALLAM MUSTAHIL SAID BAIT SAID | P13: =O13=C13 -> TRUE | Q13: 4812026 | R13: =Q13=#REF! -> #REF! | S13: 1083517184017 | T13: =S13=#REF! -> #REF! | U13: NBOMOMRX | V13: =U13=#REF! -> #REF!
A14: 11 | B14: 1367 | C14: ALI MUSALLAM AHMED BAIT SAID | D14: 943.9 | E14: 0.250 | F14: =D14*E14 -> 235.975 | G14: =F14 -> 235.975 | H14: =F14-G14 -> 0 | I14: 45902 | M14: 1367 | N14: =M14=B14 -> TRUE | O14: ALI MUSALLAM AHMED BAIT SAID | P14: =O14=C14 -> TRUE | Q14: 6663593 | R14: =Q14=#REF! -> #REF! | S14: 0406003006560016 | T14: =S14=#REF! -> #REF! | U14: BMUSOMRX | V14: =U14=#REF! -> #REF!
A15: 12 | B15: 1368 | C15: MOHAMMD SAID AHMED AL KATHIRI | D15: 3718.3 | E15: 0.250 | F15: =D15*E15 -> 929.575 | G15: =F15 -> 929.575 | H15: =F15-G15 -> 0 | I15: 45622 | M15: 1368 | N15: =M15=B15 -> TRUE | O15: MOHAMMD SAID AHMED AL KATHIRI | P15: =O15=C15 -> TRUE | Q15: 561902 | R15: =Q15=#REF! -> #REF! | S15: 01040854387001 | T15: =S15=#REF! -> #REF! | U15: BDOFOMRU | V15: =U15=#REF! -> #REF!
A16: 13 | B16: 3002 | C16: KHALID MUBARAK ALI ATQOON AL SHAHRI | D16: 1600.5 | E16: 0.250 | F16: =D16*E16 -> 400.125 | G16: =399.45+0.675 -> 400.125 | H16: =F16-G16 -> 0 | I16: 45629 | J16: 45658 | M16: 3002 | N16: =M16=B16 -> TRUE | O16: KHALID MUBARAK ALI ATQOON AL SHAHRI | P16: =O16=C16 -> TRUE | Q16: 21220177 | R16: =Q16=#REF! -> #REF! | S16: 0401016727580038 | T16: =S16=#REF! -> #REF! | U16: BMUSOMRX | V16: =U16=#REF! -> #REF!
A17: 14 | B17: 3035 | C17: TARIQ SALIM SUHAIL AL BARAMI | E17: 0.250 | F17: =D17*E17 -> 0 | H17: =F17-G17 -> 0 | M17: 3035 | N17: =M17=B17 -> TRUE | O17: TARIQ SALIM SUHAIL AL BARAMI | P17: =O17=C17 -> TRUE | Q17: 6725058 | R17: =Q17=#REF! -> #REF! | S17: 01011059048001 | T17: =S17=#REF! -> #REF! | U17: BDOFOMRU | V17: =U17=#REF! -> #REF!
A18: 15 | B18: 3057 | C18: ALI AHMED MOHAMMED AL KATHIRI | D18: 2488.3 | E18: 0.250 | F18: =D18*E18 -> 622.075 | G18: =619.725+2.35 -> 622.075 | H18: =F18-G18 -> 0 | I18: 45629 | J18: 29-1224 | M18: 3057 | N18: =M18=B18 -> TRUE | O18: ALI AHMED MOHAMMED AL KATHIRI | P18: =O18=C18 -> TRUE | Q18: 626819 | R18: =Q18=#REF! -> #REF! | S18: 0397003510460014 | T18: =S18=#REF! -> #REF! | U18: BMUSOMRX | V18: =U18=#REF! -> #REF!
A19: 16 | B19: 3062 | C19: ALI MAHAD SILMOUN QATAN | D19: 3216.3 | E19: 0.250 | F19: =D19*E19 -> 804.075 | G19: =239.28+242.5 -> 481.78 | H19: =F19-G19 -> 322.295 | I19: 45677 | J19: 13-2-25 | M19: 3062 | N19: =M19=B19 -> TRUE | O19: ALI MAHAD SILMOUN QATAN | P19: =O19=C19 -> TRUE | Q19: 300741 | R19: =Q19=#REF! -> #REF! | S19: 0397004203200017 | T19: =S19=#REF! -> #REF! | U19: BMUSOMRX | V19: =U19=#REF! -> #REF!
A20: 17 | B20: 3080 | C20: MUSALLAM BAKHIT AWADH L BARAAMI | D20: 1219.6 | E20: 0.250 | F20: =D20*E20 -> 304.9 | H20: =F20-G20 -> 304.9 | M20: 3080 | N20: =M20=B20 -> TRUE | O20: MUSALLAM BAKHIT AWADH L BARAAMI | P20: =O20=C20 -> TRUE | Q20: 14301608 | R20: =Q20=#REF! -> #REF! | S20: 0397003041020024 | T20: =S20=#REF! -> #REF! | U20: BMUSOMRX | V20: =U20=#REF! -> #REF!
A21: 18 | B21: 3086 | C21: MUSALLAM ALI MATOOQ TABOOK | D21: 1179.1 | E21: 0.250 | F21: =D21*E21 -> 294.775 | G21: =290.6 -> 290.6 | H21: =F21-G21 -> 4.175 | I21: 45630 | M21: 3086 | N21: =M21=B21 -> TRUE | O21: MUSALLAM ALI MATOOQ TABOOK | P21: =O21=C21 -> TRUE | Q21: 300033 | R21: =Q21=#REF! -> #REF! | S21: 0397003905720015 | T21: =S21=#REF! -> #REF! | U21: BMUSOMRX | V21: =U21=#REF! -> #REF!
A22: 19 | B22: 3132 | C22: HASHIM SALIM ALI ATIF AL YAFAI | D22: 1254.1 | E22: 0.250 | F22: =D22*E22 -> 313.525 | G22: =F22 -> 313.525 | H22: =F22-G22 -> 0 | I22: 45663 | M22: 3132 | N22: =M22=B22 -> TRUE | O22: HASHIM SALIM ALI ATIF AL YAFAI | P22: =O22=C22 -> TRUE | Q22: 14606296 | R22: =Q22=#REF! -> #REF! | S22: 0401024314310011 | T22: =S22=#REF! -> #REF! | U22: BMUSOMRX | V22: =U22=#REF! -> #REF!
A23: 20 | B23: 3134 | C23: HASSAN SUHAIL MAHAD QATAN | D23: 981.4 | E23: 0.250 | F23: =D23*E23 -> 245.35 | G23: =F23 -> 245.35 | H23: =F23-G23 -> 0 | I23: 45672 | M23: 3134 | N23: =M23=B23 -> TRUE | O23: HASSAN SUHAIL MAHAD QATAN | P23: =O23=C23 -> TRUE | Q23: 2154413 | R23: =Q23=#REF! -> #REF! | S23: 01010850952003 | T23: =S23=#REF! -> #REF! | U23: BDOFOMRU | V23: =U23=#REF! -> #REF!
A24: 21 | B24: 3142 | C24: MOHAMMED AHMED SAAD MASHRAH AL SHAHRI | D24: 4550.2 | E24: 0.250 | F24: =D24*E24 -> 1137.55 | G24: =F24 -> 1137.55 | H24: =F24-G24 -> 0 | I24: 29-01-25 | M24: 3142 | N24: =M24=B24 -> TRUE | O24: MOHAMMED AHMED SAAD MASHRAH AL SHAHRI | P24: =O24=C24 -> TRUE | Q24: 165497 | R24: =Q24=#REF! -> #REF! | S24: 3129019324700 | T24: =S24=#REF! -> #REF! | U24: OMABOMRU | V24: =U24=#REF! -> #REF!
A25: 22 | B25: 3145 | C25: MOHAMMED BAKHIT MASOUD QATAN | D25: 2985.2 | E25: 0.250 | F25: =D25*E25 -> 746.3 | G25: =F25 -> 746.3 | H25: =F25-G25 -> 0 | I25: DCF FEED
A26: 23 | B26: 3147 | C26: KHALID SAID MAHAD KASHOUB | D26: 1415.1 | E26: 0.250 | F26: =D26*E26 -> 353.775 | G26: =F26 -> 353.775 | H26: =F26-G26 -> 0 | I26: DCF FEED | M26: 3147 | N26: =M26=B26 -> TRUE | O26: KHALID SAID MAHAD KASHOUB | P26: =O26=C26 -> TRUE | Q26: 1662414 | R26: =Q26=#REF! -> #REF! | S26: 3129770819700 | T26: =S26=#REF! -> #REF! | U26: OMABOMRU | V26: =U26=#REF! -> #REF!
A27: 24 | B27: 3148 | C27: MUSALLAM AHMED MAHTOUQ AL ZAWAMRI | D27: 1113.4 | E27: 0.250 | F27: =D27*E27 -> 278.35 | G27: =F27 -> 278.35 | H27: =F27-G27 -> 0 | I27: 15-01-25 | M27: 3148 | N27: =M27=B27 -> TRUE | O27: MUSALLAM AHMED MAHTOUQ AL ZAWAMRI | P27: =O27=C27 -> TRUE | Q27: 19545736 | R27: =Q27=#REF! -> #REF! | S27: 01011208343002 | T27: =S27=#REF! -> #REF! | U27: BDOFOMRU | V27: =U27=#REF! -> #REF!
A28: 25 | B28: 3149 | C28: ALI SAID ALI AL ZAWAMRI | D28: 1444.2 | E28: 0.250 | F28: =D28*E28 -> 361.05 | G28: =360.4+0.65 -> 361.05 | H28: =F28-G28 -> 0 | I28: 45629 | J28: 45663 | M28: 3149 | N28: =M28=B28 -> TRUE | O28: ALI SAID ALI AL ZAWAMRI | P28: =O28=C28 -> TRUE | Q28: 4941095 | R28: =Q28=#REF! -> #REF! | S28: 1104036354300 | T28: =S28=#REF! -> #REF! | U28: AUBOOMRU | V28: =U28=#REF! -> #REF!
A29: 26 | B29: 3152 | C29: BAKHIT SALIM MAHAD QATAN | D29: 2172.5 | E29: 0.250 | F29: =D29*E29 -> 543.125 | G29: =541.575+1.55 -> 543.125 | H29: =F29-G29 -> 0 | I29: 45621 | J29: 45662 | M29: 3152 | N29: =M29=B29 -> TRUE | O29: BAKHIT SALIM MAHAD QATAN | P29: =O29=C29 -> TRUE | Q29: 941993 | R29: =Q29=#REF! -> #REF! | S29: 01042574515001 | T29: =S29=#REF! -> #REF! | U29: BDOFOMRU | V29: =U29=#REF! -> #REF!
A30: 27 | B30: 3153 | C30: ALI MAHAD SAID QATAN | D30: 2780.2 | E30: 0.250 | F30: =D30*E30 -> 695.05 | G30: =149.3+541.7+4.05 -> 695.05 | H30: =F30-G30 -> 0 | I30: 45672 | J30: 45691 | K30: 13-2-25 | M30: 3153 | N30: =M30=B30 -> TRUE | O30: ALI MAHAD SAID QATAN | P30: =O30=C30 -> TRUE | Q30: 6989479 | R30: =Q30=#REF! -> #REF! | S30: 0397003672070015 | T30: =S30=#REF! -> #REF! | U30: BMUSOMRX | V30: =U30=#REF! -> #REF!
A31: 28 | B31: 3155 | C31: SAID BAKHIT MAHAD QATAN | D31: 615.7 | E31: 0.250 | F31: =D31*E31 -> 153.925 | H31: =F31-G31 -> 153.925 | M31: 3155 | N31: =M31=B31 -> TRUE | O31: SAID BAKHIT MAHAD QATAN | P31: =O31=C31 -> TRUE | Q31: 19188794 | R31: =Q31=#REF! -> #REF! | S31: 0402003042750013 | T31: =S31=#REF! -> #REF! | U31: BMUSOMRX | V31: =U31=#REF! -> #REF!
A32: 29 | B32: 3158 | C32: AHMED OBAIDAN AHMED AL KATHIRI | D32: 2320.7 | E32: 0.250 | F32: =D32*E32 -> 580.175 | H32: =F32-G32 -> 580.175 | M32: 3158 | N32: =M32=B32 -> TRUE | O32: AHMED OBAIDAN AHMED AL KATHIRI | P32: =O32=C32 -> TRUE | Q32: 596869 | R32: =Q32=#REF! -> #REF! | S32: 0401049081340015 | T32: =S32=#REF! -> #REF! | U32: BMUSOMRX | V32: =U32=#REF! -> #REF!
A33: 30 | B33: 3159 | C33: AHMED BAKHIT SALEM AL BARAMI | D33: 540.7 | E33: 0.250 | F33: =D33*E33 -> 135.175 | G33: =F33 -> 135.175 | H33: =F33-G33 -> 0 | I33: BT 22-01-2025 | M33: 3159 | N33: =M33=B33 -> TRUE | O33: AHMED BAKHIT SALEM AL BARAMI | P33: =O33=C33 -> TRUE | Q33: 1297478 | R33: =Q33=#REF! -> #REF! | S33: 0397003703480012 | T33: =S33=#REF! -> #REF! | U33: BMUSOMRX | V33: =U33=#REF! -> #REF!
A34: 31 | B34: 3160 | C34: NAIF MUBARAK BAKHIT AL BARAAMI | D34: 1794.3 | E34: 0.250 | F34: =D34*E34 -> 448.575 | H34: =F34-G34 -> 448.575 | M34: 3160 | N34: =M34=B34 -> TRUE | O34: NAIF MUBARAK BAKHIT AL BARAAMI | P34: =O34=C34 -> TRUE | Q34: 2837163 | R34: =Q34=#REF! -> #REF! | S34: 00510031862001 | T34: =S34=#REF! -> #REF! | U34: BNZWOMRX | V34: =U34=#REF! -> #REF!
A35: 32 | B35: 3162 | C35: MOHAMMED SAID FARAJ AL KATHIRI | D35: 4955.4 | E35: 0.250 | F35: =D35*E35 -> 1238.85 | H35: =F35-G35 -> 1238.85 | M35: 3162 | N35: =M35=B35 -> TRUE | O35: MOHAMMED SAID FARAJ AL KATHIRI | P35: =O35=C35 -> TRUE | Q35: 7017227 | R35: =Q35=#REF! -> #REF! | S35: 01010940071001 | T35: =S35=#REF! -> #REF! | U35: BDOFOMRU | V35: =U35=#REF! -> #REF!
A36: 33 | B36: 3164 | C36: ALI MUSALLLAM HASSAN BAITSAID | D36: 2373.1 | E36: 0.250 | F36: =D36*E36 -> 593.275 | H36: =F36-G36 -> 593.275 | M36: 3164 | N36: =M36=B36 -> TRUE | O36: ALI MUSALLLAM HASSAN BAITSAID | P36: =O36=C36 -> TRUE | Q36: 7466062 | R36: =Q36=#REF! -> #REF! | S36: 01646038607001 | T36: =S36=#REF! -> #REF! | U36: BDOFOMRUMIB | V36: =U36=#REF! -> #REF!
A37: 34 | B37: 3165 | C37: KHALID MOHAMMED MASAAOD AGGHRIB AL SHAHRI | D37: 494.4 | E37: 0.250 | F37: =D37*E37 -> 123.6 | H37: =F37-G37 -> 123.6 | M37: 3165 | N37: =M37=B37 -> TRUE | O37: KHALID MOHAMMED MASAAOD AGGHRIB AL SHAHRI | P37: =O37=C37 -> TRUE | Q37: 19029628 | R37: =Q37=#REF! -> #REF! | S37: 01011251497002 | T37: =S37=#REF! -> #REF! | U37: BDOFOMRU | V37: =U37=#REF! -> #REF!
A38: 35 | B38: 3169 | C38: MOHAMMED ALI SAID AL ZAWAMRY | D38: 1728.9 | E38: 0.250 | F38: =D38*E38 -> 432.225 | H38: =F38-G38 -> 432.225 | M38: 3169 | N38: =M38=B38 -> TRUE | O38: MOHAMMED ALI SAID AL ZAWAMRY | P38: =O38=C38 -> TRUE | Q38: 3068756 | R38: =Q38=#REF! -> #REF! | S38: 01012573317001 | T38: =S38=#REF! -> #REF! | U38: BDOFOMRU | V38: =U38=#REF! -> #REF!
A39: 36 | B39: 3171 | C39: HATAM AWADH SAID QATAN | D39: 1028.2 | E39: 0.250 | F39: =D39*E39 -> 257.05 | G39: =256.475+0.575 -> 257.05 | H39: =F39-G39 -> 0 | I39: 45629 | J39: 45663 | M39: 3171 | N39: =M39=B39 -> TRUE | O39: HATAM AWADH SAID QATAN | P39: =O39=C39 -> TRUE | Q39: 7239057 | R39: =Q39=#REF! -> #REF! | S39: 3109607126500 | T39: =S39=#REF! -> #REF! | U39: OMABOMRU | V39: =U39=#REF! -> #REF!
A40: 37 | B40: 3172 | C40: Fatima Suleimon Salim ALBaramiyah | D40: 592.8 | E40: 0.250 | F40: =D40*E40 -> 148.2 | H40: =F40-G40 -> 148.2
A41: 38 | B41: 3173 | C41: MUSALLAM AHMED SAAD AL BARAAMI | D41: 1535.8 | E41: 0.250 | F41: =D41*E41 -> 383.95 | G41: =F41 -> 383.95 | H41: =F41-G41 -> 0 | M41: 3173 | N41: =M41=B41 -> TRUE | O41: MUSALLAM AHMED SAAD AL BARAAMI | P41: =O41=C41 -> TRUE | Q41: 6825655 | R41: =Q41=#REF! -> #REF! | S41: 0397004380200011 | T41: =S41=#REF! -> #REF! | U41: BMUSOMRX | V41: =U41=#REF! -> #REF!
...

Sheet Center-Oct
A1: HAJEEF COW MILK PROCUREMENT FROM 01-Oct-2024 TO 31-Oct-2024
A2: Sr No. | B2: Farmer Code | C2: Farmer Name | D2: Milk Qty. (Ltr.) | E2: Avg. Rate (OMR/Ltr.) | F2: Amount (OMR) | G2: Paid | H2: Balance | I2: ID No. | J2: Bank Account No. | K2: Bank Name | L2: IFSC Code | M2: Phone No. | N2: Remarks
A4: 1 | B4: 1007 | C4: AHMED ABDULLAH SAID AL RAWAS | D4: 6320.7 | E4: 0.250 | F4: =D4*E4 -> 1580.175 | H4: =F4-G4 -> 1580.175 | I4: 1515504 | J4: 0615500670380001 | K4: Bank Meethaq | L4: BMUSOMRXISL | M4: 91748840
A5: 2 | B5: 1041 | C5: AHMED SALIM ALI BAITSAID | D5: 2412.1 | E5: 0.250 | F5: =D5*E5 -> 603.025 | H5: =F5-G5 -> 603.025 | I5: 6827729 | J5: 0406003463970017 | K5: BANK MUSCAT | L5: BMUSOMRX | M5: 92272935
A6: 3 | B6: 1125 | C6: MUSALLAM SAID ALI BAITSAID | D6: 6201 | E6: 0.250 | F6: =D6*E6 -> 1550.25 | G6: =1547+3.25 -> 1550.25 | H6: =F6-G6 -> 0 | I6: 6828774 | J6: 01011456108001 | K6: BANK DHOFAR | L6: BDOFOMRU | M6: 91267555 | N6: 45691
A7: 4 | B7: 1222 | C7: Mahad Salim Abdulaziz Alkathiri | D7: 499.2 | E7: 0.250 | F7: =D7*E7 -> 124.8 | H7: =F7-G7 -> 124.8 | I7: 31221 | J7: 1006623107017 | K7: NBO | L7: NBOMOMRX
A8: 5 | B8: 1286 | C8: SALIM AMER AHMED AL YAFAEI | D8: 3046.3 | E8: 0.250 | F8: =D8*E8 -> 761.575 | H8: =F8-G8 -> 761.575 | I8: 368056 | J8: 0406003218280013 | K8: BANK MUSCAT | L8: BMUSOMRX | M8: 99494264
A9: 6 | B9: 1344 | C9: SAID AMERAHMED BAITSAID | D9: 2436.7 | E9: 0.250 | F9: =D9*E9 -> 609.175 | G9: =F9 -> 609.175 | H9: =F9-G9 -> 0 | I9: 4014519 | J9: 3109370559500 | K9: OAB | L9: OMABOMRU | N9: DCf-27-01-25
A10: 7 | B10: 1352 | C10: MOHAMMED MASOUD AJHAM ALSH AL KATHIRI | D10: 1906.2 | E10: 0.250 | F10: =D10*E10 -> 476.55 | H10: =F10-G10 -> 476.55 | I10: 1627344 | J10: 0397046773470015 | K10: BANK MUSCAT | L10: BMUSOMRX
A11: 8 | B11: 1354 | C11: AHMED SAID HASSAN BAITSAID | D11: 2397.8 | E11: 0.250 | F11: =D11*E11 -> 599.45 | H11: =F11-G11 -> 599.45 | I11: 925709 | J11: 0406018690130014 | K11: BANK MUSCAT | L11: BMUSOMRX | M11: 95187860
A12: 9 | B12: 1357 | C12: MUSALLAM SAID ALI BAIT SAID | D12: 4704.6 | E12: 0.250 | F12: =D12*E12 -> 1176.15 | H12: =F12-G12 -> 1176.15 | I12: 1052276 | J12: 01040280323001 | K12: BANK DHOFAR | L12: BDOFOMRU | M12: 95301260
A13: 10 | B13: 1359 | C13: MUSALLAM MUSTAHIL SAID BAIT SAID | D13: 2434.3 | E13: 0.250 | F13: =D13*E13 -> 608.575 | G13: =602+6.575 -> 608.575 | H13: =F13-G13 -> 0 | I13: 4812026 | J13: 1083517184017 | K13: NBO | L13: NBOMOMRX | M13: 96616558 | N13: 45655 | O13: 45680
A14: 11 | B14: 1367 | C14: ALI MUSALLAM AHMED BAIT SAID | D14: 935 | E14: 0.250 | F14: =D14*E14 -> 233.75 | G14: =F14 -> 233.75 | H14: =F14-G14 -> 0 | I14: 6663593 | J14: 0406003006560016 | K14: BANK MUSCAT | L14: BMUSOMRX | M14: 92817702 | N14: 45902
A15: 12 | B15: 1368 | C15: MOHAMMD SAID AHMED AL KATHIRI | D15: 4093.2 | E15: 0.250 | F15: =D15*E15 -> 1023.3 | G15: =0.1+1023.2 -> 1023.3 | H15: =F15-G15 -> 0 | I15: 561902 | J15: 01040854387001 | K15: BANK DHOFAR | L15: BDOFOMRU | M15: 99499622 | N15: 45622 | O15: .150 WILL DEDUCT FROM NOV 24
A16: 13 | B16: 3002 | C16: KHALID MUBARAK ALI ATQOON AL SHAHRI | D16: 1634.3 | E16: 0.250 | F16: =D16*E16 -> 408.575 | G16: =406.725+1.85 -> 408.575 | H16: =F16-G16 -> 0 | I16: 21220177 | J16: 0401016727580038 | K16: BANK MUSCAT | L16: BMUSOMRX | M16: 99280644 | N16: 45658 | O16: 45691
A17: 14 | B17: 3057 | C17: ALI AHMED MOHAMMED AL KATHIRI | D17: 2498.6 | E17: 0.250 | F17: =D17*E17 -> 624.65 | G17: =623.3+1.35 -> 624.65 | H17: =F17-G17 -> 0 | I17: 626819 | J17: 0397003510460014 | K17: BANK MUSCAT | L17: BMUSOMRX | M17: 99298522 | N17: 45655 | O17: 45666
A18: 15 | B18: 3062 | C18: ALI MAHAD SILMOUN QATAN | D18: 3129 | E18: 0.250 | F18: =D18*E18 -> 782.25 | H18: =F18-G18 -> 782.25 | I18: 300741 | J18: 0397004203200017 | K18: BANK MUSCAT | L18: BMUSOMRX | M18: 99008320
A19: 16 | B19: 3080 | C19: MUSALLAM BAKHIT AWADH L BARAAMI | D19: 1265.9 | E19: 0.250 | F19: =D19*E19 -> 316.475 | H19: =F19-G19 -> 316.475 | I19: 14301608 | J19: 0397003041020024 | K19: BANK MUSCAT | L19: BMUSOMRX | M19: 98122611
A20: 17 | B20: 3086 | C20: MUSALLAM ALI MATOOQ TABOOK | D20: 1201.9 | E20: 0.250 | F20: =D20*E20 -> 300.475 | H20: =F20-G20 -> 300.475 | I20: 300033 | J20: 0397003905720015 | K20: BANK MUSCAT | L20: BMUSOMRX
A21: 18 | B21: 3132 | C21: HASHIM SALIM ALI ATIF AL YAFAI | D21: 1296.7 | E21: 0.250 | F21: =D21*E21 -> 324.175 | G21: =323.1+1.075 -> 324.175 | H21: =F21-G21 -> 0 | I21: 14606296 | J21: 0401024314310011 | K21: BANK MUSCAT | L21: BMUSOMRX | M21: 91493522 | N21: 45663 | O21: 45779
A22: 19 | B22: 3134 | C22: HASSAN SUHAIL MAHAD QATAN | D22: 1125.5 | E22: 0.250 | F22: =D22*E22 -> 281.375 | G22: =280.05 -> 280.05 | H22: =F22-G22 -> 1.325 | I22: 2154413 | J22: 01010850952003 | K22: BANK DHOFAR | L22: BDOFOMRU | M22: 99493731 | N22: 45672
A23: 20 | B23: 3142 | C23: MOHAMMED AHMED SAAD MASHRAH AL SHAHRI | D23: 4795.9 | E23: 0.250 | F23: =D23*E23 -> 1198.975 | H23: =F23-G23 -> 1198.975 | I23: 165497 | J23: 3129019324700 | K23: OAB | L23: OMABOMRU | M23: 99499872
A24: 21 | B24: 3145 | C24: MOHAMMED BAKHIT MASOUD QATAN | D24: 2436.3 | E24: 0.250 | F24: =D24*E24 -> 609.075 | G24: =F24 -> 609.075 | H24: =F24-G24 -> 0 | I24: 1915745 | J24: 0404002595460014 | K24: BANK MUSCAT | L24: BMUSOMRX | M24: 99489050 | N24: dcf feed
A25: 22 | B25: 3147 | C25: KHALID SAID MAHAD KASHOUB | D25: 1951.8 | E25: 0.250 | F25: =D25*E25 -> 487.95 | G25: =F25 -> 487.95 | H25: =F25-G25 -> 0 | I25: 1662414 | J25: 3129770819700 | K25: OAB | L25: OMABOMRU | M25: 99282006 | N25: 45778
A26: 23 | B26: 3148 | C26: MUSALLAM AHMED MAHTOUQ AL ZAWAMRI | D26: 1240.9 | E26: 0.250 | F26: =D26*E26 -> 310.225 | G26: =F26 -> 310.225 | H26: =F26-G26 -> 0 | I26: 19545736 | J26: 01011208343002 | K26: BANK DHOFAR | L26: BDOFOMRU | N26: 15-01-25
A27: 24 | B27: 3149 | C27: ALI SAID ALI AL ZAWAMRI | D27: 1078.8 | E27: 0.250 | F27: =D27*E27 -> 269.7 | G27: =266.1+3.6 -> 269.7 | H27: =F27-G27 -> 0 | I27: 4941095 | J27: 1104036354300 | K27: Ahli Bank | L27: AUBOOMRU | M27: 93500864 | N27: 45663 | O27: 45691
A28: 25 | B28: 3152 | C28: BAKHIT SALIM MAHAD QATAN | D28: 2035 | E28: 0.250 | F28: =D28*E28 -> 508.75 | G28: =252.2+255.5 -> 507.7 | H28: =F28-G28 -> 1.05 | I28: 941993 | J28: 01042574515001 | K28: BANK DHOFAR | L28: BDOFOMRU | M28: 99086500 | N28: Feeds ONLD 25-12-2024 | O28: 45662
A29: 26 | B29: 3153 | C29: ALI MAHAD SAID QATAN | D29: 2980.6 | E29: 0.250 | F29: =D29*E29 -> 745.15 | G29: =188.45 -> 188.45 | H29: =F29-G29 -> 556.7 | I29: 6989479 | J29: 0397003672070015 | K29: BANK MUSCAT | L29: BMUSOMRX | M29: 99699500 | N29: 13-2-25
A30: 27 | B30: 3155 | C30: SAID BAKHIT MAHAD QATAN | D30: 630.5 | E30: 0.250 | F30: =D30*E30 -> 157.625 | H30: =F30-G30 -> 157.625 | I30: 19188794 | J30: 0402003042750013 | K30: BANK MUSCAT | L30: BMUSOMRX | M30: 93215515
A31: 28 | B31: 3158 | C31: AHMED OBAIDAN AHMED AL KATHIRI | D31: 2372.7 | E31: 0.250 | F31: =D31*E31 -> 593.175 | H31: =F31-G31 -> 593.175 | I31: 596869 | J31: 0401049081340015 | K31: BANK MUSCAT | L31: BMUSOMRX | M31: 99694218
A32: 29 | B32: 3159 | C32: AHMED BAKHIT SALEM AL BARAMI | D32: 617.6 | E32: 0.250 | F32: =D32*E32 -> 154.4 | H32: =F32-G32 -> 154.4 | I32: 1297478 | J32: 0397003703480012 | K32: BANK MUSCAT | L32: BMUSOMRX | M32: 99497177
A33: 30 | B33: 3160 | C33: NAIF MUBARAK BAKHIT AL BARAAMI | D33: 1838.6 | E33: 0.250 | F33: =D33*E33 -> 459.65 | H33: =F33-G33 -> 459.65 | I33: 2837163 | J33: 00510031862001 | K33: Bank Nizwa | L33: BNZWOMRX | M33: 99497455
A34: 31 | B34: 3162 | C34: MOHAMMED SAID FARAJ AL KATHIRI | D34: 5248.6 | E34: 0.250 | F34: =D34*E34 -> 1312.15 | H34: =F34-G34 -> 1312.15 | I34: 7017227 | J34: 01010940071001 | K34: BANK DHOFAR | L34: BDOFOMRU | M34: 99523400
A35: 32 | B35: 3164 | C35: ALI MUSALLLAM HASSAN BAITSAID | D35: 2434 | E35: 0.250 | F35: =D35*E35 -> 608.5 | H35: =F35-G35 -> 608.5 | I35: 7466062 | J35: 01646038607001 | K35: Maisarah | L35: BDOFOMRUMIB | M35: 91135005
A36: 33 | B36: 3165 | C36: KHALID MOHAMMED MASAAOD AGGHRIB AL SHAHRI | D36: 516.6 | E36: 0.250 | F36: =D36*E36 -> 129.15 | H36: =F36-G36 -> 129.15 | I36: 19029628 | J36: 01011251497002 | K36: BANK DHOFAR | L36: BDOFOMRU | M36: 96055446
A37: 34 | B37: 3169 | C37: MOHAMMED ALI SAID AL ZAWAMRY | D37: 634.5 | E37: 0.250 | F37: =D37*E37 -> 158.625 | H37: =F37-G37 -> 158.625 | I37: 3068756 | J37: 01012573317001 | K37: BANK DHOFAR | L37: BDOFOMRU | M37: 99691806
A38: 35 | B38: 3171 | C38: HATAM AWADH SAID QATAN | D38: 985.4 | E38: 0.250 | F38: =D38*E38 -> 246.35 | G38: =241.925+4.425 -> 246.35 | H38: =F38-G38 -> 0 | I38: 7239057 | J38: 3109607126500 | K38: OAB | L38: OMABOMRU | M38: 95880860 | N38: 45663 | O38: 45692
A39: 36 | B39: 3172 | C39: Fatima Suleimon Salim ALBaramiyah | D39: 630.6 | E39: 0.250 | F39: =D39*E39 -> 157.65 | H39: =F39-G39 -> 157.65 | I39: 5276984 | J39: 0439046831000027 | K39: BANK MUSCAT | L39: BMUSOMRX | M39: 99188860
A40: 37 | B40: 3173 | C40: MUSALLAM AHMED SAAD AL BARAAMI | D40: 1865.1 | E40: 0.250 | F40: =D40*E40 -> 466.275 | G40: =F40 -> 466.275 | H40: =F40-G40 -> 0 | I40: 6825655 | J40: 0397004380200011 | K40: BANK MUSCAT | L40: BMUSOMRX | M40: 98957747 | N40: dcf feed
A41: 38 | B41: 3174 | C41: AHMED MUSALLAM SAID QATAN | D41: 1397.7 | E41: 0.250 | F41: =D41*E41 -> 349.425 | G41: =2.25+347.175 -> 349.425 | H41: =F41-G41 -> 0 | I41: 7547492 | J41: 0401002379960017 | K41: BANK MUSCAT | L41: BMUSOMRX | M41: 91790502 | N41: dcf feed
...

Sheet Center-Nov
A1: HAJEEF COW MILK PROCUREMENT FROM 01-Nov-2024 TO 30-Nov-2024
A2: Sr No. | B2: Farmer Code | C2: Farmer Name | D2: Milk Qty. (Ltr.) | E2: Avg. Rate (OMR/Ltr.) | F2: Amount (OMR) | G2: Paid | H2: Balance | I2: ID No. | J2: Remarks
A4: 1 | B4: 1007 | C4: AHMED ABDULLAH SAID AL RAWAS | D4: 5918.3 | E4: 0.250 | F4: =D4*E4 -> 1479.575 | H4: =F4-G4 -> 1479.575 | I4: 1515504
A5: 2 | B5: 1041 | C5: AHMED SALIM ALI BAITSAID | D5: 2883.4 | E5: 0.250 | F5: =D5*E5 -> 720.85 | H5: =F5-G5 -> 720.85 | I5: 6827729
A6: 3 | B6: 1125 | C6: MUSALLAM SAID ALI BAITSAID | D6: 5823.6 | E6: 0.250 | F6: =D6*E6 -> 1455.9 | G6: =1455.6 -> 1455.6 | H6: =F6-G6 -> 0.3 | I6: 6828774 | J6: 45691
A7: 4 | B7: 1222 | C7: Mahad Salim Abdulaziz Alkathiri | D7: 106.4 | E7: 0.250 | F7: =D7*E7 -> 26.6 | H7: =F7-G7 -> 26.6 | I7: 31221
A8: 5 | B8: 1286 | C8: SALIM AMER AHMED AL YAFAEI | D8: 3086.9 | E8: 0.250 | F8: =D8*E8 -> 771.725 | H8: =F8-G8 -> 771.725 | I8: 368056
A9: 6 | B9: 1344 | C9: SAID AMERAHMED BAITSAID | D9: 3155 | E9: 0.250 | F9: =D9*E9 -> 788.75 | G9: =F9 -> 788.75 | H9: =F9-G9 -> 0 | I9: 4014519 | J9: 45718
A10: 7 | B10: 1352 | C10: MOHAMMED MASOUD AJHAM ALSH AL KATHIRI | D10: 1804.3 | E10: 0.250 | F10: =D10*E10 -> 451.075 | H10: =F10-G10 -> 451.075 | I10: 1627344
A11: 8 | B11: 1354 | C11: AHMED SAID HASSAN BAITSAID | D11: 2119.4 | E11: 0.250 | F11: =D11*E11 -> 529.85 | H11: =F11-G11 -> 529.85 | I11: 925709
A12: 9 | B12: 1357 | C12: MUSALLAM SAID ALI BAIT SAID | D12: 4575.3 | E12: 0.250 | F12: =D12*E12 -> 1143.825 | H12: =F12-G12 -> 1143.825 | I12: 1052276
A13: 10 | B13: 1359 | C13: MUSALLAM MUSTAHIL SAID BAIT SAID | D13: 3449 | E13: 0.250 | F13: =D13*E13 -> 862.25 | G13: =856.725 -> 856.725 | H13: =F13-G13 -> 5.525 | I13: 4812026 | J13: 45680
A14: 11 | B14: 1367 | C14: ALI MUSALLAM AHMED BAIT SAID | D14: 1121 | E14: 0.250 | F14: =D14*E14 -> 280.25 | G14: =F14 -> 280.25 | H14: =F14-G14 -> 0 | I14: 6663593 | J14: 45902
A15: 12 | B15: 1368 | C15: MOHAMMD SAID AHMED AL KATHIRI | D15: 3909.6 | E15: 0.250 | F15: =D15*E15 -> 977.4 | G15: =F15 -> 977.4 | H15: =F15-G15 -> 0 | I15: 561902 | J15: DCF Feed-16-01-25
A16: 13 | B16: 3002 | C16: KHALID MUBARAK ALI ATQOON AL SHAHRI | D16: 1384.4 | E16: 0.250 | F16: =D16*E16 -> 346.1 | G16: =342.8 -> 342.8 | H16: =F16-G16 -> 3.3 | I16: 21220177 | J16: 45691
A17: 14 | B17: 3035 | C17: TARIQ SALIM SUHAIL AL BARAMI | D17: 618.6 | E17: 0.250 | F17: =D17*E17 -> 154.65 | H17: =F17-G17 -> 154.65 | I17: 6725058
A18: 15 | B18: 3057 | C18: ALI AHMED MOHAMMED AL KATHIRI | D18: 2358 | E18: 0.250 | F18: =D18*E18 -> 589.5 | G18: =585.5+4 -> 589.5 | H18: =F18-G18 -> 0 | I18: 626819 | J18: 45666 | K18: 45673
A19: 16 | B19: 3062 | C19: ALI MAHAD SILMOUN QATAN | D19: 2673.5 | E19: 0.250 | F19: =D19*E19 -> 668.375 | H19: =F19-G19 -> 668.375 | I19: 300741
A20: 17 | B20: 3080 | C20: MUSALLAM BAKHIT AWADH L BARAAMI | D20: 1190.9 | E20: 0.250 | F20: =D20*E20 -> 297.725 | H20: =F20-G20 -> 297.725 | I20: 14301608
A21: 18 | B21: 3086 | C21: MUSALLAM ALI MATOOQ TABOOK | D21: 1288.1 | E21: 0.250 | F21: =D21*E21 -> 322.025 | H21: =F21-G21 -> 322.025 | I21: 300033
A22: 19 | B22: 3132 | C22: HASHIM SALIM ALI ATIF AL YAFAI | D22: 1200.3 | E22: 0.250 | F22: =D22*E22 -> 300.075 | G22: =299.03 -> 299.03 | H22: =F22-G22 -> 1.045 | I22: 14606296 | J22: 45779
A23: 20 | B23: 3134 | C23: HASSAN SUHAIL MAHAD QATAN | D23: 942.6 | E23: 0.250 | F23: =D23*E23 -> 235.65 | H23: =F23-G23 -> 235.65 | I23: 2154413
A24: 21 | B24: 3142 | C24: MOHAMMED AHMED SAAD MASHRAH AL SHAHRI | D24: 4434.8 | E24: 0.250 | F24: =D24*E24 -> 1108.7 | H24: =F24-G24 -> 1108.7 | I24: 165497
A25: 22 | B25: 3145 | C25: MOHAMMED BAKHIT MASOUD QATAN | D25: 1948.9 | E25: 0.250 | F25: =D25*E25 -> 487.225 | G25: =F25 -> 487.225 | H25: =F25-G25 -> 0 | I25: 1915745 | J25: DCF Feed-29-01-25
A26: 23 | B26: 3147 | C26: KHALID SAID MAHAD KASHOUB | D26: 1884.9 | E26: 0.250 | F26: =D26*E26 -> 471.225 | G26: =F26 -> 471.225 | H26: =F26-G26 -> 0 | I26: 1662414 | J26: 45932
A27: 24 | B27: 3148 | C27: MUSALLAM AHMED MAHTOUQ AL ZAWAMRI | D27: 1017.5 | E27: 0.250 | F27: =D27*E27 -> 254.375 | G27: =F27 -> 254.375 | H27: =F27-G27 -> 0 | I27: 19545736 | J27: DCF Feed-15-01-25
A28: 25 | B28: 3149 | C28: ALI SAID ALI AL ZAWAMRI | D28: 980.5 | E28: 0.250 | F28: =D28*E28 -> 245.125 | G28: =244.85 -> 244.85 | H28: =F28-G28 -> 0.275 | I28: 4941095 | J28: 45691
A29: 26 | B29: 3152 | C29: BAKHIT SALIM MAHAD QATAN | D29: 1581.8 | E29: 0.250 | F29: =D29*E29 -> 395.45 | H29: =F29-G29 -> 395.45 | I29: 941993
A30: 27 | B30: 3153 | C30: ALI MAHAD SAID QATAN | D30: 2701.9 | E30: 0.250 | F30: =D30*E30 -> 675.475 | H30: =F30-G30 -> 675.475 | I30: 6989479
A31: 28 | B31: 3155 | C31: SAID BAKHIT MAHAD QATAN | D31: 560.7 | E31: 0.250 | F31: =D31*E31 -> 140.175 | H31: =F31-G31 -> 140.175 | I31: 19188794
A32: 29 | B32: 3158 | C32: AHMED OBAIDAN AHMED AL KATHIRI | D32: 2292.9 | E32: 0.250 | F32: =D32*E32 -> 573.225 | H32: =F32-G32 -> 573.225 | I32: 596869
A33: 30 | B33: 3159 | C33: AHMED BAKHIT SALEM AL BARAMI | D33: 590.8 | E33: 0.250 | F33: =D33*E33 -> 147.7 | H33: =F33-G33 -> 147.7 | I33: 1297478
A34: 31 | B34: 3160 | C34: NAIF MUBARAK BAKHIT AL BARAAMI | D34: 1701.8 | E34: 0.250 | F34: =D34*E34 -> 425.45 | H34: =F34-G34 -> 425.45 | I34: 2837163
A35: 32 | B35: 3162 | C35: MOHAMMED SAID FARAJ AL KATHIRI | D35: 4589.5 | E35: 0.250 | F35: =D35*E35 -> 1147.375 | H35: =F35-G35 -> 1147.375 | I35: 7017227
A36: 33 | B36: 3164 | C36: ALI MUSALLLAM HASSAN BAITSAID | D36: 2258.9 | E36: 0.250 | F36: =D36*E36 -> 564.725 | H36: =F36-G36 -> 564.725 | I36: 7466062
A37: 34 | B37: 3165 | C37: KHALID MOHAMMED MASAAOD AGGHRIB AL SHAHRI | D37: 463.2 | E37: 0.250 | F37: =D37*E37 -> 115.8 | H37: =F37-G37 -> 115.8 | I37: 19029628
A38: 35 | B38: 3169 | C38: MOHAMMED ALI SAID AL ZAWAMRY | D38: 751.4 | E38: 0.250 | F38: =D38*E38 -> 187.85 | H38: =F38-G38 -> 187.85 | I38: 3068756
A39: 36 | B39: 3171 | C39: HATAM AWADH SAID QATAN | D39: 952.6 | E39: 0.250 | F39: =D39*E39 -> 238.15 | G39: =238.08 -> 238.08 | H39: =F39-G39 -> 0.07 | I39: 7239057 | J39: 45692
A40: 37 | B40: 3172 | C40: Fatima Suleimon Salim ALBaramiyah | D40: 591.7 | E40: 0.250 | F40: =D40*E40 -> 147.925 | H40: =F40-G40 -> 147.925 | I40: 5276984
A41: 38 | B41: 3173 | C41: MUSALLAM AHMED SAAD AL BARAAMI | D41: 1917.9 | E41: 0.250 | F41: =D41*E41 -> 479.475 | G41: =F41 -> 479.475 | H41: =F41-G41 -> 0 | I41: 6825655 | J41: 45693
...

Sheet Center-dec
A1: HAJEEF COW MILK PROCUREMENT FROM 01-Dec-2024 TO 31-Dec-2024
A2: Sr No. | B2: Farmer Code | C2: Farmer Name | D2: Milk Qty. (Ltr.) | E2: Avg. Rate (OMR/Ltr.) | F2: Amount (OMR) | G2: Paid | H2: Balance | I2: ID No. | J2: Remarks
A4: 1 | B4: 1007 | C4: AHMED ABDULLAH SAID AL RAWAS | D4: 6267.6 | E4: 0.250 | F4: =D4*E4 -> 1566.9 | H4: =F4-G4 -> 1566.9 | I4: 1515504
A5: 2 | B5: 1041 | C5: AHMED SALIM ALI BAITSAID | D5: 3741.7 | E5: 0.250 | F5: =D5*E5 -> 935.425 | H5: =F5-G5 -> 935.425 | I5: 6827729
A6: 3 | B6: 1125 | C6: MUSALLAM SAID ALI BAITSAID | D6: 6440.3 | E6: 0.250 | F6: =D6*E6 -> 1610.075 | H6: =F6-G6 -> 1610.075 | I6: 6828774
A7: 4 | B7: 1222 | C7: Mahad Salim Abdulaziz Alkathiri | D7: 483.1 | E7: 0.250 | F7: =D7*E7 -> 120.775 | H7: =F7-G7 -> 120.775 | I7: 31221
A8: 5 | B8: 1286 | C8: SALIM AMER AHMED AL YAFAEI | D8: 3071.5 | E8: 0.250 | F8: =D8*E8 -> 767.875 | H8: =F8-G8 -> 767.875 | I8: 368056
A9: 6 | B9: 1344 | C9: SAID AMERAHMED BAITSAID | D9: 2569.5 | E9: 0.250 | F9: =D9*E9 -> 642.375 | H9: =F9-G9 -> 642.375 | I9: 4014519
A10: 7 | B10: 1352 | C10: MOHAMMED MASOUD AJHAM ALSH AL KATHIRI | D10: 1843 | E10: 0.250 | F10: =D10*E10 -> 460.75 | H10: =F10-G10 -> 460.75 | I10: 1627344
A11: 8 | B11: 1354 | C11: AHMED SAID HASSAN BAITSAID | D11: 2487.1 | E11: 0.250 | F11: =D11*E11 -> 621.775 | H11: =F11-G11 -> 621.775 | I11: 925709
A12: 9 | B12: 1357 | C12: MUSALLAM SAID ALI BAIT SAID | D12: 5185.2 | E12: 0.250 | F12: =D12*E12 -> 1296.3 | H12: =F12-G12 -> 1296.3 | I12: 1052276
A13: 10 | B13: 1359 | C13: MUSALLAM MUSTAHIL SAID BAIT SAID | D13: 4102.2 | E13: 0.250 | F13: =D13*E13 -> 1025.55 | H13: =F13-G13 -> 1025.55 | I13: 4812026
A14: 11 | B14: 1367 | C14: ALI MUSALLAM AHMED BAIT SAID | D14: 1284.6 | E14: 0.250 | F14: =D14*E14 -> 321.15 | G14: =F14 -> 321.15 | H14: =F14-G14 -> 0 | I14: 6663593 | J14: 45902
A15: 12 | B15: 1368 | C15: MOHAMMD SAID AHMED AL KATHIRI | D15: 4172 | E15: 0.250 | F15: =D15*E15 -> 1043 | G15: =F15 -> 1043 | H15: =F15-G15 -> 0 | I15: 561902 | J15: 16-2-25
A16: 13 | B16: 3002 | C16: KHALID MUBARAK ALI ATQOON AL SHAHRI | D16: 1778.3 | E16: 0.250 | F16: =D16*E16 -> 444.575 | H16: =F16-G16 -> 444.575 | I16: 21220177
A17: 14 | B17: 3035 | C17: TARIQ SALIM SUHAIL AL BARAMI | D17: 677 | E17: 0.250 | F17: =D17*E17 -> 169.25 | H17: =F17-G17 -> 169.25 | I17: 6725058
A18: 15 | B18: 3057 | C18: ALI AHMED MOHAMMED AL KATHIRI | D18: 2694.3 | E18: 0.250 | F18: =D18*E18 -> 673.575 | G18: =670.15+3.425 -> 673.575 | H18: =F18-G18 -> 0 | I18: 626819 | J18: 45673 | K18: 45691
A19: 16 | B19: 3062 | C19: ALI MAHAD SILMOUN QATAN | D19: 2834.9 | E19: 0.250 | F19: =D19*E19 -> 708.725 | H19: =F19-G19 -> 708.725 | I19: 300741
A20: 17 | B20: 3080 | C20: MUSALLAM BAKHIT AWADH L BARAAMI | D20: 1277.8 | E20: 0.250 | F20: =D20*E20 -> 319.45 | H20: =F20-G20 -> 319.45 | I20: 14301608
A21: 18 | B21: 3086 | C21: MUSALLAM ALI MATOOQ TABOOK | D21: 1292.8 | E21: 0.250 | F21: =D21*E21 -> 323.2 | H21: =F21-G21 -> 323.2 | I21: 300033
A22: 19 | B22: 3132 | C22: HASHIM SALIM ALI ATIF AL YAFAI | D22: 1300.8 | E22: 0.250 | F22: =D22*E22 -> 325.2 | H22: =F22-G22 -> 325.2 | I22: 14606296
A23: 20 | B23: 3134 | C23: HASSAN SUHAIL MAHAD QATAN | D23: 941.1 | E23: 0.250 | F23: =D23*E23 -> 235.275 | H23: =F23-G23 -> 235.275 | I23: 2154413
A24: 21 | B24: 3142 | C24: MOHAMMED AHMED SAAD MASHRAH AL SHAHRI | D24: 4729.1 | E24: 0.250 | F24: =D24*E24 -> 1182.275 | H24: =F24-G24 -> 1182.275 | I24: 165497
A25: 22 | B25: 3145 | C25: MOHAMMED BAKHIT MASOUD QATAN | D25: 1752.5 | E25: 0.250 | F25: =D25*E25 -> 438.125 | G25: =F25 -> 438.125 | H25: =F25-G25 -> 0 | I25: 1915745 | J25: 23-2-2025
A26: 23 | B26: 3147 | C26: KHALID SAID MAHAD KASHOUB | D26: 2251.05 | E26: 0.250 | F26: =D26*E26 -> 562.7625 | H26: =F26-G26 -> 562.7625 | I26: 1662414
A27: 24 | B27: 3148 | C27: MUSALLAM AHMED MAHTOUQ AL ZAWAMRI | D27: 902.5 | E27: 0.250 | F27: =D27*E27 -> 225.625 | G27: =F27 -> 225.625 | H27: =F27-G27 -> 0 | I27: 19545736 | J27: DCF Feed-15-01-25
A28: 25 | B28: 3149 | C28: ALI SAID ALI AL ZAWAMRI | D28: 935.6 | E28: 0.250 | F28: =D28*E28 -> 233.9 | H28: =F28-G28 -> 233.9 | I28: 4941095
A29: 26 | B29: 3152 | C29: BAKHIT SALIM MAHAD QATAN | D29: 2348.8 | E29: 0.250 | F29: =D29*E29 -> 587.2 | G29: =584.65+2.55 -> 587.2 | H29: =F29-G29 -> 0 | I29: 941993 | J29: 27-01-25 | K29: 23-1-25
A30: 27 | B30: 3153 | C30: ALI MAHAD SAID QATAN | D30: 2880.7 | E30: 0.250 | F30: =D30*E30 -> 720.175 | H30: =F30-G30 -> 720.175 | I30: 6989479
A31: 28 | B31: 3155 | C31: SAID BAKHIT MAHAD QATAN | D31: 632.1 | E31: 0.250 | F31: =D31*E31 -> 158.025 | H31: =F31-G31 -> 158.025 | I31: 19188794
A32: 29 | B32: 3158 | C32: AHMED OBAIDAN AHMED AL KATHIRI | D32: 2466.6 | E32: 0.250 | F32: =D32*E32 -> 616.65 | H32: =F32-G32 -> 616.65 | I32: 596869
A33: 30 | B33: 3159 | C33: AHMED BAKHIT SALEM AL BARAMI | D33: 924.6 | E33: 0.250 | F33: =D33*E33 -> 231.15 | H33: =F33-G33 -> 231.15 | I33: 1297478
A34: 31 | B34: 3160 | C34: NAIF MUBARAK BAKHIT AL BARAAMI | D34: 1853.6 | E34: 0.250 | F34: =D34*E34 -> 463.4 | H34: =F34-G34 -> 463.4 | I34: 2837163
A35: 32 | B35: 3162 | C35: MOHAMMED SAID FARAJ AL KATHIRI | D35: 4567.5 | E35: 0.250 | F35: =D35*E35 -> 1141.875 | H35: =F35-G35 -> 1141.875 | I35: 7017227
A36: 33 | B36: 3164 | C36: ALI MUSALLLAM HASSAN BAITSAID | D36: 2398.8 | E36: 0.250 | F36: =D36*E36 -> 599.7 | H36: =F36-G36 -> 599.7 | I36: 7466062
A37: 34 | B37: 3165 | C37: KHALID MOHAMMED MASAAOD AGGHRIB AL SHAHRI | D37: 523 | E37: 0.250 | F37: =D37*E37 -> 130.75 | H37: =F37-G37 -> 130.75 | I37: 19029628
A38: 35 | B38: 3169 | C38: MOHAMMED ALI SAID AL ZAWAMRY | D38: 1042.5 | E38: 0.250 | F38: =D38*E38 -> 260.625 | H38: =F38-G38 -> 260.625 | I38: 3068756
A39: 36 | B39: 3171 | C39: HATAM AWADH SAID QATAN | D39: 1009 | E39: 0.250 | F39: =D39*E39 -> 252.25 | H39: =F39-G39 -> 252.25 | I39: 7239057
A40: 37 | B40: 3172 | C40: Fatima Suleimon Salim ALBaramiyah | D40: 1178.5 | E40: 0.250 | F40: =D40*E40 -> 294.625 | H40: =F40-G40 -> 294.625 | I40: 5276984
A41: 38 | B41: 3173 | C41: MUSALLAM AHMED SAAD AL BARAAMI | D41: 2336.7 | E41: 0.250 | F41: =D41*E41 -> 584.175 | H41: =F41-G41 -> 584.175 | I41: 6825655
...

Sheet July 25
A1: HAJEEF COW MILK PROCUREMENT FROM 01-Jul-2025 to 31-Jul-2025
A2: Sr No. | B2: Farmer Code | C2: Farmer Name | D2: Milk Qty. (Ltr.) | E2: Avg. Rate (OMR/Ltr.) | F2: Amount (OMR) | G2: paid | H2: balance | I2: ID No. | J2: Bank Account No. | K2: Bank Name | L2: IFSC Code | M2: Phone No. | N2: Remarks
A4: 1 | B4: 1007 | C4: AHMED ABDULLAH SAID AL RAWAS | D4: 6375 | E4: 0.250 | F4: =D4*E4 -> 1593.75 | G4: =F4 -> 1593.75 | H4: =F4-G4 -> 0 | I4: 1515504 | J4: 0615500670380001 | K4: Bank Meethaq | L4: BMUSOMRXISL | M4: 91748840
A5: 2 | B5: 1041 | C5: AHMED SALIM ALI BAITSAID | D5: 3382.3 | E5: 0.250 | F5: =D5*E5 -> 845.575 | G5: =F5 -> 845.575 | H5: =F5-G5 -> 0 | I5: 6827729 | J5: 0406003463970017 | K5: BANK MUSCAT | L5: BMUSOMRX | M5: 92272935
A6: 3 | B6: 1125 | C6: MUSALLAM SAID ALI BAITSAID | D6: 5794.4 | E6: 0.250 | F6: =D6*E6 -> 1448.6 | G6: =F6 -> 1448.6 | H6: =F6-G6 -> 0 | I6: 6828774 | J6: 01011456108001 | K6: BANK DHOFAR | L6: BDOFOMRU | M6: 91267555 | N6: 20-10-2025
A7: 4 | B7: 1222 | C7: Mahad Salim Abdulaziz Alkathiri | E7: 0.250 | F7: =D7*E7 -> 0 | H7: =F7-G7 -> 0 | I7: 31221 | J7: 1006623107017 | K7: NBO | L7: NBOMOMRX
A8: 5 | B8: 1286 | C8: SALIM AMER AHMED AL YAFAEI | D8: 3002.7 | E8: 0.250 | F8: =D8*E8 -> 750.675 | G8: =F8 -> 750.675 | H8: =F8-G8 -> 0 | I8: 368056 | J8: 0406003218280013 | K8: BANK MUSCAT | L8: BMUSOMRX | M8: 99494264
A9: 6 | B9: 1344 | C9: SAID AMERAHMED BAITSAID | D9: 3180.4 | E9: 0.250 | F9: =D9*E9 -> 795.1 | G9: =793.925+1.175 -> 795.1 | H9: =F9-G9 -> 0 | I9: 4014519 | J9: 3109370559500 | K9: OAB | L9: OMABOMRU | N9: 45879 | O9: 15-10-25
A10: 7 | B10: 1352 | C10: MOHAMMED MASOUD AJHAM ALSH AL KATHIRI | D10: 1179.3 | E10: 0.250 | F10: =D10*E10 -> 294.825 | G10: =291.55+3.275 -> 294.825 | H10: =F10-G10 -> 0 | I10: 1627344 | J10: 0397046773470015 | K10: BANK MUSCAT | L10: BMUSOMRX | N10: 22.9.2025 | O10: 15-10-25
A11: 8 | B11: 1354 | C11: AHMED SAID HASSAN BAITSAID | D11: 2377.5 | E11: 0.250 | F11: =D11*E11 -> 594.375 | G11: =F11 -> 594.375 | H11: =F11-G11 -> 0 | I11: 925709 | J11: 0406018690130014 | K11: BANK MUSCAT | L11: BMUSOMRX | M11: 95187860
A12: 9 | B12: 1357 | C12: MUSALLAM SAID ALI BAIT SAID | D12: 5065.8 | E12: 0.250 | F12: =D12*E12 -> 1266.45 | G12: =F12 -> 1266.45 | H12: =F12-G12 -> 0 | I12: 1052276 | J12: 01040280323001 | K12: BANK DHOFAR | L12: BDOFOMRU | M12: 95301260
A13: 10 | B13: 1359 | C13: MUSALLAM MUSTAHIL SAID BAIT SAID | D13: 3841 | E13: 0.250 | F13: =D13*E13 -> 960.25 | G13: =959.05+1.2 -> 960.25 | H13: =F13-G13 -> 0 | I13: 4812026 | J13: 1083517184017 | K13: NBO | L13: NBOMOMRX | M13: 96616558 | N13: 18-9-2025 | O13: 15-10-25
A14: 11 | B14: 1367 | C14: ALI MUSALLAM AHMED BAIT SAID | D14: 1290.4 | E14: 0.250 | F14: =D14*E14 -> 322.6 | G14: =F14 -> 322.6 | H14: =F14-G14 -> 0 | I14: 6663593 | J14: 0406003006560016 | K14: BANK MUSCAT | L14: BMUSOMRX | M14: 92817702 | N14: 14-10-2025
A15: 12 | B15: 1368 | C15: MOHAMMD SAID AHMED AL KATHIRI | D15: 2271.9 | E15: 0.250 | F15: =D15*E15 -> 567.975 | G15: =F15 -> 567.975 | H15: =F15-G15 -> 0 | I15: 561902 | J15: 01040854387001 | K15: BANK DHOFAR | L15: BDOFOMRU | M15: 99499622
A16: 13 | B16: 2098 | C16: Bakhit Musallam Ali Kashoob | D16: 785.1 | E16: 0.250 | F16: =D16*E16 -> 196.275 | G16: =F16 -> 196.275 | H16: =F16-G16 -> 0 | I16: 1065899 | J16: 132857700081018 | K16: BANK MUSCAT | L16: BMUSOMRX | N16: 15-10-25
A17: 14 | B17: 3002 | C17: KHALID MUBARAK ALI ATQOON AL SHAHRI | D17: 1094.5 | E17: 0.250 | F17: =D17*E17 -> 273.625 | G17: =0.2+271.8+1.625 -> 273.625 | H17: =F17-G17 -> 0 | I17: 21220177 | J17: 0401016727580038 | K17: BANK MUSCAT | L17: BMUSOMRX | M17: 99280644 | N17: 45666 | O17: 18-9-2025 | P17: 15-10-25
A18: 15 | B18: 3035 | C18: TARIQ SALIM SUHAIL AL BARAMI | E18: 0.250 | F18: =D18*E18 -> 0 | H18: =F18-G18 -> 0 | I18: 6725058 | J18: 01011059048001 | K18: BANK DHOFAR | L18: BDOFOMRU | M18: 99198121
A19: 16 | B19: 3057 | C19: ALI AHMED MOHAMMED AL KATHIRI | D19: 2905.8 | E19: 0.250 | F19: =D19*E19 -> 726.45 | G19: =F19 -> 726.45 | H19: =F19-G19 -> 0 | I19: 626819 | J19: 0397003510460014 | K19: BANK MUSCAT | L19: BMUSOMRX | M19: 99298522 | N19: BT 04-12-2025
A20: 17 | B20: 3062 | C20: ALI MAHAD SILMOUN QATAN | D20: 2176.1 | E20: 0.250 | F20: =D20*E20 -> 544.025 | G20: =F20 -> 544.025 | H20: =F20-G20 -> 0 | I20: 300741 | J20: 0397004203200017 | K20: BANK MUSCAT | L20: BMUSOMRX | M20: 99008320
A21: 18 | B21: 3080 | C21: MUSALLAM BAKHIT AWADH L BARAAMI | D21: 1290.7 | E21: 0.250 | F21: =D21*E21 -> 322.675 | G21: =F21 -> 322.675 | H21: =F21-G21 -> 0 | I21: 14301608 | J21: 0397003041020024 | K21: BANK MUSCAT | L21: BMUSOMRX | M21: 98122611 | N21: BT 04-12-2025
A22: 19 | B22: 3086 | C22: MUSALLAM ALI MATOOQ TABOOK | D22: 39.5 | E22: 0.250 | F22: =D22*E22 -> 9.875 | G22: =6.3+3.575 -> 9.875 | H22: =F22-G22 -> 0 | I22: 300033 | J22: 0397003905720015 | K22: BANK MUSCAT | L22: BMUSOMRX | N22: 24.9.2025 | O22: 27-10-2025
A23: 20 | B23: 3132 | C23: HASHIM SALIM ALI ATIF AL YAFAI | D23: 1266.8 | E23: 0.250 | F23: =D23*E23 -> 316.7 | G23: =F23 -> 316.7 | H23: =F23-G23 -> 0 | I23: 14606296 | J23: 01013095125001 | K23: BANK DHOFAR | L23: BDOFOMRU | M23: 91493522 | O23: Update Bank account on 23-9-2025
A24: 21 | B24: 3134 | C24: HASSAN SUHAIL MAHAD QATAN | D24: 1344.5 | E24: 0.250 | F24: =D24*E24 -> 336.125 | G24: =F24 -> 336.125 | H24: =F24-G24 -> 0 | I24: 2154413 | J24: 01010850952003 | K24: BANK DHOFAR | L24: BDOFOMRU | M24: 99493731 | N24: BT 24-9-2025
A25: 22 | B25: 3142 | C25: MOHAMMED AHMED SAAD MASHRAH AL SHAHRI | D25: 4692.5 | E25: 0.250 | F25: =D25*E25 -> 1173.125 | G25: =0.3+584.25+584.25+4.325 -> 1173.125 | H25: =F25-G25 -> 0 | I25: 165497 | J25: 3129019324700 | K25: OAB | L25: OMABOMRU | M25: 99499872 | N25: 45666 | O25: 15-10-25
A26: 23 | B26: 3145 | C26: MOHAMMED BAKHIT MASOUD QATAN | D26: 2718.3 | E26: 0.250 | F26: =D26*E26 -> 679.575 | G26: =677.525+2.05 -> 679.575 | H26: =F26-G26 -> 0 | I26: 1915745 | J26: 0404002595460014 | K26: BANK MUSCAT | L26: BMUSOMRX | M26: 99489050 | N26: 29.9.2025 | O26: 20-10-2025
A27: 24 | B27: 3147 | C27: KHALID SAID MAHAD KASHOUB | D27: 1124.8 | E27: 0.250 | F27: =D27*E27 -> 281.2 | G27: =0.6+280.25+0.35 -> 281.2 | H27: =F27-G27 -> 0 | I27: 1662414 | J27: 3129770819700 | K27: OAB | L27: OMABOMRU | M27: 99282006 | N27: 17-9-2025 | O27: 45818 | P27: 27-10-2025
A28: 25 | B28: 3148 | C28: MUSALLAM AHMED MAHTOUQ AL ZAWAMRI | D28: 1299.3 | E28: 0.250 | F28: =D28*E28 -> 324.825 | G28: =324.725+0.1 -> 324.825 | H28: =F28-G28 -> 0 | I28: 19545736 | J28: 01011208343002 | K28: BANK DHOFAR | L28: BDOFOMRU | N28: 45667 | O28: 22-10-2025
A29: 26 | B29: 3149 | C29: ALI SAID ALI AL ZAWAMRI | D29: 1576.7 | E29: 0.250 | F29: =D29*E29 -> 394.175 | G29: =391.625+2.55 -> 394.175 | H29: =F29-G29 -> 0 | I29: 4941095 | J29: 1104036354300 | K29: Ahli Bank | L29: AUBOOMRU | M29: 93500864 | N29: 20-10-2025
A30: 27 | B30: 3152 | C30: BAKHIT SALIM MAHAD QATAN | D30: 3099.8 | E30: 0.250 | F30: =D30*E30 -> 774.95 | G30: =772.2+2.75 -> 774.95 | H30: =F30-G30 -> 0 | I30: 941993 | J30: 01042574515001 | K30: BANK DHOFAR | L30: BDOFOMRU | M30: 99086500 | N30: 45878
A31: 28 | B31: 3153 | C31: ALI MAHAD SAID QATAN | D31: 2859.2 | E31: 0.250 | F31: =D31*E31 -> 714.8 | G31: =F31 -> 714.8 | H31: =F31-G31 -> 0 | I31: 6989479 | J31: 0397003672070015 | K31: BANK MUSCAT | L31: BMUSOMRX | M31: 99699500
A32: 29 | B32: 3155 | C32: SAID BAKHIT MAHAD QATAN | D32: 631.9 | E32: 0.250 | F32: =D32*E32 -> 157.975 | G32: =F32 -> 157.975 | H32: =F32-G32 -> 0 | I32: 19188794 | J32: 0402003042750013 | K32: BANK MUSCAT | L32: BMUSOMRX | M32: 93215515
A33: 30 | B33: 3158 | C33: AHMED OBAIDAN AHMED AL KATHIRI | D33: 2875.5 | E33: 0.250 | F33: =D33*E33 -> 718.875 | G33: =F33 -> 718.875 | H33: =F33-G33 -> 0 | I33: 596869 | J33: 0401049081340015 | K33: BANK MUSCAT | L33: BMUSOMRX | M33: 99694218
A34: 31 | B34: 3159 | C34: AHMED BAKHIT SALEM AL BARAMI | D34: 1022.6 | E34: 0.250 | F34: =D34*E34 -> 255.65 | G34: =F34 -> 255.65 | H34: =F34-G34 -> 0 | I34: 1297478 | J34: 0397003703480012 | K34: BANK MUSCAT | L34: BMUSOMRX | M34: 99497177
A35: 32 | B35: 3160 | C35: NAIF MUBARAK BAKHIT AL BARAAMI | D35: 1834.9 | E35: 0.250 | F35: =D35*E35 -> 458.725 | G35: =F35 -> 458.725 | H35: =F35-G35 -> 0 | I35: 2837163 | J35: 00510031862001 | K35: Bank Nizwa | L35: BNZWOMRX | M35: 99497455
A36: 33 | B36: 3162 | C36: MOHAMMED SAID FARAJ AL KATHIRI | D36: 5679.5 | E36: 0.250 | F36: =D36*E36 -> 1419.875 | G36: =F36 -> 1419.875 | H36: =F36-G36 -> 0 | I36: 7017227 | J36: 0439003443420024 | K36: Bank Muscat | L36: BMUSOMRX | M36: 99523400 | N36: BT 28-10-2025 | O36: Update Bank Account
A37: 34 | B37: 3164 | C37: ALI MUSALLLAM HASSAN BAITSAID | D37: 2366.3 | E37: 0.250 | F37: =D37*E37 -> 591.575 | G37: =589.55+2.025 -> 591.575 | H37: =F37-G37 -> 0 | I37: 7466062 | J37: 01646038607001 | K37: Maisarah | L37: BDOFOMRUMIB | M37: 91135005 | N37: 29.9.2025 | O37: 29-10-2025
A38: 35 | B38: 3165 | C38: KHALID MOHAMMED MASAAOD AGGHRIB AL SHAHRI | D38: 345.2 | E38: 0.250 | F38: =D38*E38 -> 86.3 | G38: =F38 -> 86.3 | H38: =F38-G38 -> 0 | I38: 19029628 | J38: 01011251497002 | K38: BANK DHOFAR | L38: BDOFOMRU | M38: 96055446
A39: 36 | B39: 3169 | C39: MOHAMMED ALI SAID AL ZAWAMRY | D39: 1835.3 | E39: 0.250 | F39: =D39*E39 -> 458.825 | G39: =3.15+455.675 -> 458.825 | H39: =F39-G39 -> 0 | I39: 3068756 | J39: 01012573317001 | K39: BANK DHOFAR | L39: BDOFOMRU | M39: 99691806 | N39: 29-10-2025 | O39: 45727
A40: 37 | B40: 3171 | C40: HATAM AWADH SAID QATAN | D40: 1077.6 | E40: 0.250 | F40: =D40*E40 -> 269.4 | G40: =266.425+2.975 -> 269.4 | H40: =F40-G40 -> 0 | I40: 7239057 | J40: 3109607126500 | K40: OAB | L40: OMABOMRU | M40: 95880860 | N40: 18-9-2025 | O40: 15-10-25
A41: 38 | B41: 3172 | C41: Fatima Suleimon Salim ALBaramiyah | D41: 1274.3 | E41: 0.250 | F41: =D41*E41 -> 318.575 | G41: =F41 -> 318.575 | H41: =F41-G41 -> 0 | I41: 5276984 | J41: 0439046831000027 | K41: BANK MUSCAT | L41: BMUSOMRX | M41: 99188860
...

Sheet Aug 25
A1: HAJEEF COW MILK PROCUREMENT FROM 01-Aug-2025 to 31-Aug-2025
A2: Farmer Code | B2: Farmer Name | C2: Milk Qty. (Ltr.) | D2: Avg. Rate (OMR/Ltr.) | E2: Amount (OMR) | F2: paid | G2: balance | H2: ID No. | I2: Bank Account No. | J2: Bank Name | K2: IFSC Code | L2: Phone No. | M2: Remarks
A4: 1007 | B4: AHMED ABDULLAH SAID AL RAWAS | C4: 6339.5 | D4: 0.250 | E4: =C4*D4 -> 1584.875 | G4: =E4-F4 -> 1584.875 | H4: 1515504 | I4: 0615500670380001 | J4: Bank Meethaq | K4: BMUSOMRXISL | L4: 91748840
A5: 1041 | B5: AHMED SALIM ALI BAITSAID | C5: 2628 | D5: 0.250 | E5: =C5*D5 -> 657 | G5: =E5-F5 -> 657 | H5: 6827729 | I5: 0406003463970017 | J5: BANK MUSCAT | K5: BMUSOMRX | L5: 92272935
