Workbook

Sheet Nov  Full Employee (2)
O1: PASI CALCULATION
A4: Jan Salary -2024( 16-12-2023 to 15-01-2024) | O4: Employee Contribution | R4: Employer Contribution | T4: Total Payable to PASI (A) + (B)
A5: SL | B5: National ID | C5: NAME | D5: POSITION | E5: Nationality | F5: Basic Salary2023 | G5: Increment 24 | H5: Basic Salary2024 | I5: Allowance 2024 | J5: Gross Salary 2024 | K5: SOC | L5: Ded/add | M5: Net Salary | N5: Remark | O5: PASI 7% Gross Salary | P5: Social Security 1% Gross Salary | Q5: Total (A) | R5: PASI 12.5% Gross Salary | S5: Total (B)
A6: 1 | B6: 1574851 | C6: Dr Nasser Ali Baitsaid | D6: CEO | E6: Omani | F6: 2402.6964 | G6: =F6*4% -> 96.107858 | H6: =F6+G6 -> 2498.8043 | I6: 999.735 | J6: =H6+I6 -> 3498.5393 | K6: =-240 -> -240 | M6: =J6+K6+L6 -> 3258.5393 | O6: =3000*0.07 -> 210 | P6: =3000*0.01 -> 30 | Q6: =O6+P6 -> 240 | R6: =3000*0.125 -> 375 | S6: =R6 -> 375 | T6: =Q6+S6 -> 615 | U6: =Q6+K6 -> 0 | V6: =G6-U6 -> 96.107858
A7: 2 | B7: 9814493 | C7: Said Yahya Al Bahanta | D7: Deputy General Manager | E7: Omani | F7: 1500 | G7: =F7*4% -> 60 | H7: =F7+G7 -> 1560 | I7: 1000 | J7: =H7+I7 -> 2560 | K7: =-J7*8% -> -204.8 | M7: =J7+K7+L7 -> 2355.2 | O7: =J7*0.07 -> 179.2 | P7: =J7*0.01 -> 25.6 | Q7: =O7+P7 -> 204.8 | R7: =J7*0.125 -> 320 | S7: =R7 -> 320 | T7: =Q7+S7 -> 524.8 | U7: =Q7+K7 -> 0 | V7: =G7-U7 -> 60
A8: 3 | B8: 11693452 | C8: Ameena Ali Suhail Al Mashani | D8: Document controller | E8: Omani | F8: 348.0267 | G8: =F8*4% -> 13.921068 | H8: =F8+G8 -> 361.94777 | I8: 144.81 | J8: =H8+I8 -> 506.75777 | K8: =-J8*8% -> -40.540621 | M8: =J8+K8+L8 -> 466.21715 | O8: =J8*0.07 -> 35.473044 | P8: =J8*0.01 -> 5.0675777 | Q8: =O8+P8 -> 40.540621 | R8: =J8*0.125 -> 63.344721 | S8: =R8 -> 63.344721 | T8: =Q8+S8 -> 103.88534 | U8: =Q8+K8 -> 0 | V8: =G8-U8 -> 13.921068
A9: 4 | B9: 8537109 | C9: Said Mohammed Said Al Maamari | D9: PRO | E9: Omani | F9: 348.0267 | G9: =F9*4% -> 13.921068 | H9: =F9+G9 -> 361.94777 | I9: 144.81 | J9: =H9+I9 -> 506.75777 | K9: =-J9*8% -> -40.540621 | L9: 0 | M9: =J9+K9+L9 -> 466.21715 | N9: Deduct 701.161 Petty cash / 12 Month | O9: =J9*0.07 -> 35.473044 | P9: =J9*0.01 -> 5.0675777 | Q9: =O9+P9 -> 40.540621 | R9: =J9*0.125 -> 63.344721 | S9: =R9 -> 63.344721 | T9: =Q9+S9 -> 103.88534 | U9: =Q9+K9 -> 0 | V9: =G9-U9 -> 13.921068
A10: 5 | B10: 75524503 | C10: Mahmoud Abdel Sayed Ismail | D10: Legal Advisor | E10: Expat | F10: 464.0356 | G10: =F10*4% -> 18.561424 | H10: =F10+G10 -> 482.59702 | I10: 193.08 | J10: =H10+I10 -> 675.67702 | K10: 0 | M10: =J10+K10+L10 -> 675.67702 | O10: 0 | P10: 0 | Q10: =O10+P10 -> 0 | R10: 0 | S10: =R10 -> 0 | T10: =Q10+S10 -> 0 | U10: =Q10+K10 -> 0 | V10: =G10-U10 -> 18.561424
A11: 6 | B11: 118683789 | C11: Soumya Sinu | D11: Purchase Coordinator | E11: Expat | F11: 366.263 | G11: =F11*4% -> 14.65052 | H11: =F11+G11 -> 380.91352 | I11: 152.835 | J11: =H11+I11 -> 533.74852 | K11: 0 | L11: 0 | M11: =J11+K11+L11 -> 533.74852 | O11: 0 | P11: 0 | Q11: =O11+P11 -> 0 | R11: 0 | S11: =R11 -> 0 | T11: =Q11+S11 -> 0 | U11: =Q11+K11 -> 0 | V11: =G11-U11 -> 14.65052
A12: 7 | B12: 99955793 | C12: Hassan Hamdi Ebrahim | D12: Cost accountant | E12: Expat | F12: 556.2 | G12: =F12*4% -> 22.248 | H12: =F12+G12 -> 578.448 | I12: 360 | J12: =H12+I12 -> 938.448 | K12: 0 | M12: =J12+K12+L12 -> 938.448 | O12: 0 | P12: 0 | Q12: =O12+P12 -> 0 | R12: 0 | S12: =R12 -> 0 | T12: =Q12+S12 -> 0 | U12: =Q12+K12 -> 0 | V12: =G12-U12 -> 22.248
A13: 8 | B13: 18668266 | C13: Musallam Said Bakhit Zidan Al Baraami | D13: Accounts Executive | E13: Omani | F13: 373.06806 | G13: =F13*4% -> 14.922722 | H13: =F13+G13 -> 387.99078 | I13: 241.468 | J13: =H13+I13 -> 629.45878 | K13: =-J13*8% -> -50.356703 | M13: =J13+K13+L13 -> 579.10208 | O13: =J13*0.07 -> 44.062115 | P13: =J13*0.01 -> 6.2945878 | Q13: =O13+P13 -> 50.356703 | R13: =J13*0.125 -> 78.682348 | S13: =R13 -> 78.682348 | T13: =Q13+S13 -> 129.03905 | U13: =Q13+K13 -> 0 | V13: =G13-U13 -> 14.922722
A14: 9 | B14: 13432024 | C14: Mohammed AbdullahSalim Al Sarj Al Marhun | D14: IT Executive | E14: Omani | F14: 373.06806 | G14: =F14*4% -> 14.922722 | H14: =F14+G14 -> 387.99078 | I14: 241.468 | J14: =H14+I14 -> 629.45878 | K14: =-J14*8% -> -50.356703 | M14: =J14+K14+L14 -> 579.10208 | O14: =J14*0.07 -> 44.062115 | P14: =J14*0.01 -> 6.2945878 | Q14: =O14+P14 -> 50.356703 | R14: =J14*0.125 -> 78.682348 | S14: =R14 -> 78.682348 | T14: =Q14+S14 -> 129.03905 | U14: =Q14+K14 -> 0 | V14: =G14-U14 -> 14.922722
A15: 10 | B15: 14105567 | C15: Said Mohammed Said Baqwair | D15: Exe. Secretary | E15: Omani | F15: 311.4 | G15: =F15*4% -> 12.456 | H15: =F15+G15 -> 323.856 | I15: 207.6 | J15: =H15+I15 -> 531.456 | K15: =-J15*8% -> -42.51648 | L15: 0 | M15: =J15+K15+L15 -> 488.93952 | O15: =J15*0.07 -> 37.20192 | P15: =J15*0.01 -> 5.31456 | Q15: =O15+P15 -> 42.51648 | R15: =J15*0.125 -> 66.432 | S15: =R15 -> 66.432 | T15: =Q15+S15 -> 108.94848 | U15: =Q15+K15 -> 0 | V15: =G15-U15 -> 12.456
A16: 11 | B16: 114993752 | C16: Suresh Bose mani | D16: Operations | E16: Expat | F16: 741.6 | G16: =F16*4% -> 29.664 | H16: =F16+G16 -> 771.264 | I16: 480 | J16: =H16+I16 -> 1251.264 | K16: 0 | M16: =J16+K16+L16 -> 1251.264 | O16: 0 | P16: 0 | Q16: =O16+P16 -> 0 | R16: 0 | S16: =R16 -> 0 | T16: =Q16+S16 -> 0 | U16: =Q16+K16 -> 0 | V16: =G16-U16 -> 29.664
A17: 12 | B17: 117241993 | C17: Sankar Sadasivam | D17: Quality Specialist | E17: Expat | F17: 440.3868 | G17: =F17*4% -> 17.615472 | H17: =F17+G17 -> 458.00227 | I17: 285.04 | J17: =H17+I17 -> 743.04227 | K17: 0 | M17: =J17+K17+L17 -> 743.04227 | O17: 0 | P17: 0 | Q17: =O17+P17 -> 0 | R17: 0 | S17: =R17 -> 0 | T17: =Q17+S17 -> 0 | U17: =Q17+K17 -> 0 | V17: =G17-U17 -> 17.615472
A18: 13 | B18: 6534754 | C18: Hassan Salim Mohammad Kashoob | D18: Center Supervisor | E18: Omani | F18: 427.656 | G18: =F18*4% -> 17.10624 | H18: =F18+G18 -> 444.76224 | I18: 276.8 | J18: =H18+I18 -> 721.56224 | K18: =-J18*8% -> -57.724979 | L18: 0 | M18: =J18+K18+L18 -> 663.83726 | N18: Deduct 314.285 Petty cash / 12 Month | O18: =J18*0.07 -> 50.509357 | P18: =J18*0.01 -> 7.2156224 | Q18: =O18+P18 -> 57.724979 | R18: =J18*0.125 -> 90.19528 | S18: =R18 -> 90.19528 | T18: =Q18+S18 -> 147.92026 | U18: =Q18+K18 -> 0 | V18: =G18-U18 -> 17.10624
A19: 14 | B19: 3364532 | C19: Mohammad Ahmed Said Al Marhoon | D19: Center Supervisor | E19: Omani | F19: 427.656 | G19: =F19*4% -> 17.10624 | H19: =F19+G19 -> 444.76224 | I19: 276.8 | J19: =H19+I19 -> 721.56224 | K19: =-J19*8% -> -57.724979 | L19: 0 | M19: =J19+K19+L19 -> 663.83726 | N19: Additional Allowance | O19: =J19*0.07 -> 50.509357 | P19: =J19*0.01 -> 7.2156224 | Q19: =O19+P19 -> 57.724979 | R19: =J19*0.125 -> 90.19528 | S19: =R19 -> 90.19528 | T19: =Q19+S19 -> 147.92026 | U19: =Q19+K19 -> 0 | V19: =G19-U19 -> 17.10624
A20: 15 | B20: 11733522 | C20: Musallam Nasser Salim qatan | D20: Supervisor Hajeef | E20: Omani | F20: 365.856 | G20: =F20*4% -> 14.63424 | H20: =F20+G20 -> 380.49024 | I20: 236.8 | J20: =H20+I20 -> 617.29024 | K20: =-J20*8% -> -49.383219 | M20: =J20+K20+L20 -> 567.90702 | O20: =J20*0.07 -> 43.210317 | P20: =J20*0.01 -> 6.1729024 | Q20: =O20+P20 -> 49.383219 | R20: =J20*0.125 -> 77.16128 | S20: =R20 -> 77.16128 | T20: =Q20+S20 -> 126.5445 | U20: =Q20+K20 -> 0 | V20: =G20-U20 -> 14.63424
A21: 16 | B21: 9599617 | C21: Qais Abdullah Al Ojaili | D21: Driver | E21: Omani | F21: 317.47278 | G21: =F21*4% -> 12.698911 | H21: =F21+G21 -> 330.17169 | I21: 205.484 | J21: =H21+I21 -> 535.65569 | K21: =-J21*8% -> -42.852455 | M21: =J21+K21+L21 -> 492.80324 | O21: =J21*0.07 -> 37.495898 | P21: =J21*0.01 -> 5.3565569 | Q21: =O21+P21 -> 42.852455 | R21: =J21*0.125 -> 66.956961 | S21: =R21 -> 66.956961 | T21: =Q21+S21 -> 109.80942 | U21: =Q21+K21 -> 0 | V21: =G21-U21 -> 12.698911
A22: 17 | B22: 14408161 | C22: Salim Ahmed Salim Bait Said | D22: Driver | E22: Omani | F22: 317.47278 | G22: =F22*4% -> 12.698911 | H22: =F22+G22 -> 330.17169 | I22: 205.484 | J22: =H22+I22 -> 535.65569 | K22: =-J22*8% -> -42.852455 | L22: 0 | M22: =J22+K22+L22 -> 492.80324 | O22: =J22*0.07 -> 37.495898 | P22: =J22*0.01 -> 5.3565569 | Q22: =O22+P22 -> 42.852455 | R22: =J22*0.125 -> 66.956961 | S22: =R22 -> 66.956961 | T22: =Q22+S22 -> 109.80942 | U22: =Q22+K22 -> 0 | V22: =G22-U22 -> 12.698911
A23: 18 | B23: 25472616 | C23: Amir Said Salim Ahmed Al khathri | D23: Driver | E23: Omani | F23: 317.47278 | G23: =F23*4% -> 12.698911 | H23: =F23+G23 -> 330.17169 | I23: 205.484 | J23: =H23+I23 -> 535.65569 | K23: =-J23*8% -> -42.852455 | M23: =J23+K23+L23 -> 492.80324 | O23: =J23*0.07 -> 37.495898 | P23: =J23*0.01 -> 5.3565569 | Q23: =O23+P23 -> 42.852455 | R23: =J23*0.125 -> 66.956961 | S23: =R23 -> 66.956961 | T23: =Q23+S23 -> 109.80942 | U23: =Q23+K23 -> 0 | V23: =G23-U23 -> 12.698911
A24: 19 | B24: 5829377 | C24: Salim Said Faraj Aghreeb Al Shahri | D24: Data Entry Executive | E24: Omani | F24: 373.06806 | G24: =F24*4% -> 14.922722 | H24: =F24+G24 -> 387.99078 | I24: 241.468 | J24: =H24+I24 -> 629.45878 | K24: =-J24*8% -> -50.356703 | M24: =J24+K24+L24 -> 579.10208 | O24: =J24*0.07 -> 44.062115 | P24: =J24*0.01 -> 6.2945878 | Q24: =O24+P24 -> 50.356703 | R24: =J24*0.125 -> 78.682348 | S24: =R24 -> 78.682348 | T24: =Q24+S24 -> 129.03905 | U24: =Q24+K24 -> 0 | V24: =G24-U24 -> 14.922722
A25: 20 | B25: 26785757 | C25: Mohammed Said Mohammed Tabook | D25: Data Entry Operator | E25: Omani | F25: 327.77484 | G25: =F25*4% -> 13.110994 | H25: =F25+G25 -> 340.88583 | I25: 212.152 | J25: =H25+I25 -> 553.03783 | K25: =-J25*8% -> -44.243027 | M25: =J25+K25+L25 -> 508.79481 | O25: =J25*0.07 -> 38.712648 | P25: =J25*0.01 -> 5.5303783 | Q25: =O25+P25 -> 44.243027 | R25: =J25*0.125 -> 69.129729 | S25: =R25 -> 69.129729 | T25: =Q25+S25 -> 113.37276 | U25: =Q25+K25 -> 0 | V25: =G25-U25 -> 13.110994
A26: 21 | B26: 22734098 | C26: Mustahil Salim Mustahil Ghafram Al Shahri | D26: Milk tester - Zeek | E26: Omani | F26: 297.258 | G26: =F26*4% -> 11.89032 | H26: =F26+G26 -> 309.14832 | I26: 192.4 | J26: =H26+I26 -> 501.54832 | K26: =-J26*8% -> -40.123866 | M26: =J26+K26+L26 -> 461.42445 | O26: =J26*0.07 -> 35.108382 | P26: =J26*0.01 -> 5.0154832 | Q26: =O26+P26 -> 40.123866 | R26: =J26*0.125 -> 62.69354 | S26: =R26 -> 62.69354 | T26: =Q26+S26 -> 102.81741 | U26: =Q26+K26 -> 0 | V26: =G26-U26 -> 11.89032
A27: 22 | B27: 23600713 | C27: Ahmed Bakhit Ali Thuaar | D27: Milk tester - Zeek | E27: Omani | F27: 297.258 | G27: =F27*4% -> 11.89032 | H27: =F27+G27 -> 309.14832 | I27: 192.4 | J27: =H27+I27 -> 501.54832 | K27: =-J27*8% -> -40.123866 | M27: =J27+K27+L27 -> 461.42445 | O27: =J27*0.07 -> 35.108382 | P27: =J27*0.01 -> 5.0154832 | Q27: =O27+P27 -> 40.123866 | R27: =J27*0.125 -> 62.69354 | S27: =R27 -> 62.69354 | T27: =Q27+S27 -> 102.81741 | U27: =Q27+K27 -> 0 | V27: =G27-U27 -> 11.89032
A28: 23 | B28: 4792636 | C28: Mohammed ahmed Salim Qatan | D28: Milk tester - Hajeef | E28: Omani | F28: 297.258 | G28: =F28*4% -> 11.89032 | H28: =F28+G28 -> 309.14832 | I28: 192.4 | J28: =H28+I28 -> 501.54832 | K28: =-J28*8% -> -40.123866 | L28: 0 | M28: =J28+K28+L28 -> 461.42445 | N28: Additional Allowance | O28: =J28*0.07 -> 35.108382 | P28: =J28*0.01 -> 5.0154832 | Q28: =O28+P28 -> 40.123866 | R28: =J28*0.125 -> 62.69354 | S28: =R28 -> 62.69354 | T28: =Q28+S28 -> 102.81741 | U28: =Q28+K28 -> 0 | V28: =G28-U28 -> 11.89032
A29: 24 | B29: 12194826 | C29: Said Mahad Ali Al Kathiri | D29: Milk tester - Ghado | E29: Omani | F29: 297.258 | G29: =F29*4% -> 11.89032 | H29: =F29+G29 -> 309.14832 | I29: 192.4 | J29: =H29+I29 -> 501.54832 | K29: =-J29*8% -> -40.123866 | M29: =J29+K29+L29 -> 461.42445 | O29: =J29*0.07 -> 35.108382 | P29: =J29*0.01 -> 5.0154832 | Q29: =O29+P29 -> 40.123866 | R29: =J29*0.125 -> 62.69354 | S29: =R29 -> 62.69354 | T29: =Q29+S29 -> 102.81741 | U29: =Q29+K29 -> 0 | V29: =G29-U29 -> 11.89032
A30: 25 | B30: 15107764 | C30: Ahmed Omar Ahmed Hatal Shihri | D30: Milk tester - Ghado | E30: Omani | F30: 297.258 | G30: =F30*4% -> 11.89032 | H30: =F30+G30 -> 309.14832 | I30: 192.4 | J30: =H30+I30 -> 501.54832 | K30: =-J30*8% -> -40.123866 | M30: =J30+K30+L30 -> 461.42445 | O30: =J30*0.07 -> 35.108382 | P30: =J30*0.01 -> 5.0154832 | Q30: =O30+P30 -> 40.123866 | R30: =J30*0.125 -> 62.69354 | S30: =R30 -> 62.69354 | T30: =Q30+S30 -> 102.81741 | U30: =Q30+K30 -> 0 | V30: =G30-U30 -> 11.89032
A31: 26 | B31: 14873156 | C31: Hassan Mohammed Hassan Atif Alyafai | D31: Milk tester - Hajeef | E31: Omani | F31: 297.258 | G31: =F31*4% -> 11.89032 | H31: =F31+G31 -> 309.14832 | I31: 192.4 | J31: =H31+I31 -> 501.54832 | K31: =-J31*8% -> -40.123866 | M31: =J31+K31+L31 -> 461.42445 | O31: =J31*0.07 -> 35.108382 | P31: =J31*0.01 -> 5.0154832 | Q31: =O31+P31 -> 40.123866 | R31: =J31*0.125 -> 62.69354 | S31: =R31 -> 62.69354 | T31: =Q31+S31 -> 102.81741 | U31: =Q31+K31 -> 0 | V31: =G31-U31 -> 11.89032
A32: 27 | B32: 4383259 | C32: Imad Abdul Hakeem Faraj Fadhil | D32: Mechanical | E32: Omani | F32: 320.742 | G32: =F32*4% -> 12.82968 | H32: =F32+G32 -> 333.57168 | I32: 207.6 | J32: =H32+I32 -> 541.17168 | K32: =-J32*8% -> -43.293734 | M32: =J32+K32+L32 -> 497.87795 | O32: =J32*0.07 -> 37.882018 | P32: =J32*0.01 -> 5.4117168 | Q32: =O32+P32 -> 43.293734 | R32: =J32*0.125 -> 67.64646 | S32: =R32 -> 67.64646 | T32: =Q32+S32 -> 110.94019 | U32: =Q32+K32 -> 0 | V32: =G32-U32 -> 12.82968
A33: 28 | B33: 18640539 | C33: Hassan Musallam Mohammed Tabook | D33: Electrical | E33: Omani | F33: 320.742 | G33: =F33*4% -> 12.82968 | H33: =F33+G33 -> 333.57168 | I33: 207.6 | J33: =H33+I33 -> 541.17168 | K33: =-J33*8% -> -43.293734 | M33: =J33+K33+L33 -> 497.87795 | O33: =J33*0.07 -> 37.882018 | P33: =J33*0.01 -> 5.4117168 | Q33: =O33+P33 -> 43.293734 | R33: =J33*0.125 -> 67.64646 | S33: =R33 -> 67.64646 | T33: =Q33+S33 -> 110.94019 | U33: =Q33+K33 -> 0 | V33: =G33-U33 -> 12.82968
A34: 29 | B34: 111114471 | C34: Saad yousuf Saad ibrahim | D34: Electrical | E34: Expat | F34: 278.1 | G34: =F34*4% -> 11.124 | H34: =F34+G34 -> 289.224 | I34: 180 | J34: =H34+I34 -> 469.224 | K34: 0 | M34: =J34+K34+L34 -> 469.224 | O34: 0 | P34: 0 | Q34: 0 | R34: 0 | S34: =R34 -> 0 | T34: 0 | U34: =Q34+K34 -> 0 | V34: =G34-U34 -> 11.124
A35: 30 | B35: 10132421 | C35: Khalid Said Ali Al Nubi Al Kathiri | D35: Security | E35: Omani | F35: 283.1058 | G35: =F35*4% -> 11.324232 | H35: =F35+G35 -> 294.43003 | I35: 183.24 | J35: =H35+I35 -> 477.67003 | K35: =-J35*8% -> -38.213603 | M35: =J35+K35+L35 -> 439.45643 | O35: =J35*0.07 -> 33.436902 | P35: =J35*0.01 -> 4.7767003 | Q35: =O35+P35 -> 38.213603 | R35: =J35*0.125 -> 59.708754 | S35: =R35 -> 59.708754 | T35: =Q35+S35 -> 97.922357 | U35: =Q35+K35 -> 0 | V35: =G35-U35 -> 11.324232
A36: 31 | B36: 6431446 | C36: Said Mohammed Ajaham Al Zawamri | D36: Security | E36: Omani | F36: 283.1058 | G36: =F36*4% -> 11.324232 | H36: =F36+G36 -> 294.43003 | I36: 183.24 | J36: =H36+I36 -> 477.67003 | K36: =-J36*8% -> -38.213603 | L36: 0 | M36: =J36+K36+L36 -> 439.45643 | O36: =J36*0.07 -> 33.436902 | P36: =J36*0.01 -> 4.7767003 | Q36: =O36+P36 -> 38.213603 | R36: =J36*0.125 -> 59.708754 | S36: =R36 -> 59.708754 | T36: =Q36+S36 -> 97.922357 | U36: =Q36+K36 -> 0 | V36: =G36-U36 -> 11.324232
A37: 32 | B37: 19315674 | C37: Osama Mohammed Said Al Kathiri | D37: Security | E37: Omani | F37: 283.1058 | G37: =F37*4% -> 11.324232 | H37: =F37+G37 -> 294.43003 | I37: 183.24 | J37: =H37+I37 -> 477.67003 | K37: =-J37*8% -> -38.213603 | M37: =J37+K37+L37 -> 439.45643 | O37: =J37*0.07 -> 33.436902 | P37: =J37*0.01 -> 4.7767003 | Q37: =O37+P37 -> 38.213603 | R37: =J37*0.125 -> 59.708754 | S37: =R37 -> 59.708754 | T37: =Q37+S37 -> 97.922357 | U37: =Q37+K37 -> 0 | V37: =G37-U37 -> 11.324232
A38: 33 | B38: 24834714 | C38: Ali Ben Mubarak Ben Awadh Mubarak Ausout Al Shahri | D38: Security | E38: Omani | F38: 283.1058 | G38: =F38*4% -> 11.324232 | H38: =F38+G38 -> 294.43003 | I38: 183.24 | J38: =H38+I38 -> 477.67003 | K38: =-J38*8% -> -38.213603 | M38: =J38+K38+L38 -> 439.45643 | O38: =J38*0.07 -> 33.436902 | P38: =J38*0.01 -> 4.7767003 | Q38: =O38+P38 -> 38.213603 | R38: =J38*0.125 -> 59.708754 | S38: =R38 -> 59.708754 | T38: =Q38+S38 -> 97.922357 | U38: =Q38+K38 -> 0 | V38: =G38-U38 -> 11.324232
A39: 34 | B39: 21973324 | C39: Suhail said Musallam Kashoob | D39: Security | E39: Omani | F39: 283.1058 | G39: =F39*4% -> 11.324232 | H39: =F39+G39 -> 294.43003 | I39: 183.24 | J39: =H39+I39 -> 477.67003 | K39: =-J39*8% -> -38.213603 | M39: =J39+K39+L39 -> 439.45643 | O39: =J39*0.07 -> 33.436902 | P39: =J39*0.01 -> 4.7767003 | Q39: =O39+P39 -> 38.213603 | R39: =J39*0.125 -> 59.708754 | S39: =R39 -> 59.708754 | T39: =Q39+S39 -> 97.922357 | U39: =Q39+K39 -> 0 | V39: =G39-U39 -> 11.324232
A40: 35 | B40: 19455653 | C40: Mohsin Suhail Ahmed Musallam Kashoob | D40: Security | E40: Omani | F40: 283.1058 | G40: =F40*4% -> 11.324232 | H40: =F40+G40 -> 294.43003 | I40: 183.24 | J40: =H40+I40 -> 477.67003 | K40: =-J40*8% -> -38.213603 | M40: =J40+K40+L40 -> 439.45643 | O40: =J40*0.07 -> 33.436902 | P40: =J40*0.01 -> 4.7767003 | Q40: =O40+P40 -> 38.213603 | R40: =J40*0.125 -> 59.708754 | S40: =R40 -> 59.708754 | T40: =Q40+S40 -> 97.922357 | U40: =Q40+K40 -> 0 | V40: =G40-U40 -> 11.324232
A41: 36 | B41: 19046538 | C41: Majid Said Ali Qatan | D41: Security | E41: Omani | F41: 278.1 | G41: =F41*4% -> 11.124 | H41: =F41+G41 -> 289.224 | I41: 180 | J41: =H41+I41 -> 469.224 | K41: =-J41*8% -> -37.53792 | M41: =J41+K41+L41 -> 431.68608 | O41: =J41*0.07 -> 32.84568 | P41: =J41*0.01 -> 4.69224 | Q41: =O41+P41 -> 37.53792 | R41: =J41*0.125 -> 58.653 | S41: =R41 -> 58.653 | T41: =Q41+S41 -> 96.19092 | U41: =Q41+K41 -> 0 | V41: =G41-U41 -> 11.124
A42: 37 | B42: 19743187 | C42: Suhail Mohammed Suhail Qatan | D42: Security | E42: Omani | F42: 278.1 | G42: =F42*4% -> 11.124 | H42: =F42+G42 -> 289.224 | I42: 180 | J42: =H42+I42 -> 469.224 | K42: =-J42*8% -> -37.53792 | M42: =J42+K42+L42 -> 431.68608 | O42: =J42*0.07 -> 32.84568 | P42: =J42*0.01 -> 4.69224 | Q42: =O42+P42 -> 37.53792 | R42: =J42*0.125 -> 58.653 | S42: =R42 -> 58.653 | T42: =Q42+S42 -> 96.19092 | U42: =Q42+K42 -> 0 | V42: =G42-U42 -> 11.124
...

Sheet hold
P1: PASI CALCULATION
A4: July Salary -2024( 16-06-2024 to 15-07-2024) | P4: Employee Contribution | S4: Employer Contribution | U4: Total Payable to PASI (A) + (B)
A5: SL | B5: National ID | C5: NAME | D5: POSITION | E5: Nationality | F5: Basic Salary2023 | G5: Increment 24 | H5: Basic Salary2024 | I5: Allowance 2024 | J5: Gross Salary 2024 | K5: SOC | L5: Deduction | M5: add | N5: Net Salary | O5: Remark | P5: PASI 7% Gross Salary | Q5: Social Security 1% Gross Salary | R5: Total (A) | S5: PASI 12.5% Gross Salary | T5: Total (B)
A7: Total | F7: =SUM('Salary 2025 - 11'!F21:F21) -> 380.49024 | G7: =SUM('Salary 2025 - 11'!G21:G21) -> 15.21961 | H7: =SUM('Salary 2025 - 11'!H21:H21) -> 395.70985 | I7: =SUM('Salary 2025 - 11'!I21:I21) -> 236.8 | J7: =SUM('Salary 2025 - 11'!J21:J21) -> 632.50985 | K7: =SUM('Salary 2025 - 11'!K21:K21) -> -50.600788 | L7: =SUM('Salary 2025 - 11'!M21:M21) -> 0 | M7: =SUM('Salary 2025 - 11'!N21:N21) -> 0 | N7: =SUM('Salary 2025 - 11'!O21:O21) -> 581.90906 | O7: =SUM('Salary 2025 - 11'!P21:P21) -> 0 | P7: =SUM('Salary 2025 - 11'!Q21:Q21) -> 44.275689 | Q7: =SUM('Salary 2025 - 11'!R21:R21) -> 6.3250985 | R7: =SUM('Salary 2025 - 11'!S21:S21) -> 50.600788 | S7: =SUM('Salary 2025 - 11'!T21:T21) -> 85.38883 | T7: =SUM('Salary 2025 - 11'!U21:U21) -> 85.38883 | U7: =SUM('Salary 2025 - 11'!#REF!) -> #REF!
A8: Grand Total | F8: =F7+#REF! -> #REF! | G8: =G7+#REF! -> #REF! | H8: =H7+#REF! -> #REF! | I8: =I7+#REF! -> #REF! | J8: =J7+#REF! -> #REF! | K8: =K7+#REF! -> #REF! | L8: =L7+#REF! -> #REF! | M8: =M7+#REF! -> #REF! | ... U8: =U7+#REF! -> #REF!
K10: =250/30 -> 8.3333333 | L10: =K10*15 -> 125
A14: Hassan Kashoob | I14: Hassan Ghaly | O14: Said Al Bahanta
A15: HR | I15: Cost accountant | O15: DGM
L23: =721.562*10% -> 72.1562
L24: 36

Sheet Salary 2025 - 11
Q1: PASI CALCULATION
Q4: Employee Contribution | T4: Employer Contribution
B5: National ID | C5: NAME | D5: POSITION | E5: Nationality | F5: Basic Salary2024 | G5: Increment 25 | H5: Basic Salary2025 | I5: Allowance 2025 | J5: Gross Salary 2025 | K5: SOC | L5: OJT Deduction | M5: Deduction | N5: add | O5: Net Salary | P5: Remark | Q5: PASI 7% Gross Salary | R5: Social Security 1% Gross Salary | S5: Total (A) | T5: PASI 13.5% Gross Salary | U5: Total (B)
B6: 2639937 | C6: Ahmed Mohamed Abu Bakar Al Dhahab | D6: Operations | E6: Omani | F6: 0 | G6: 0 | H6: 2250 | I6: 1500 | J6: =H6+I6 -> 3750 | K6: =-(225+18.75) -> -243.75 | O6: =J6+K6+N6+M6+L6 -> 3506.25 | Q6: =J6*0.07 -> 262.5 | R6: =J6*0.01 -> 37.5 | S6: =Q6+R6 -> 300 | T6: =J6*0.135 -> 506.25 | U6: =T6 -> 506.25 | V6: BNZWOMRX | W6: 00510063538001 | X6: =K6*-1 -> 243.75
B7: 9814493 | C7: Said Yahya Farah Al Bahanata | D7: Deputy General Manager | E7: Omani | F7: 1560 | G7: =(F7*4%) -> 62.4 | H7: =F7+G7 -> 1622.4 | I7: 1000 | J7: =H7+I7 -> 2622.4 | K7: =-J7*8% -> -209.792 | O7: =J7+K7+N7+M7+L7 -> 2412.608 | Q7: =J7*0.07 -> 183.568 | R7: =J7*0.01 -> 26.224 | S7: =Q7+R7 -> 209.792 | T7: =J7*0.135 -> 354.024 | U7: =T7 -> 354.024 | V7: BDOFOMRU | W7: 01040162518001 | X7: =K7*-1 -> 209.792
B8: 11693452 | C8: Ameena Ali Suhail Al Mashani | D8: Document controller | E8: Omani | F8: 336 | G8: =(F8*4%) -> 13.44 | H8: =F8+G8 -> 349.44 | I8: 224 | J8: =H8+I8 -> 573.44 | K8: =-J8*8% -> -45.8752 | O8: =J8+K8+N8+M8+L8 -> 527.5648 | Q8: =J8*0.07 -> 40.1408 | R8: =J8*0.01 -> 5.7344 | S8: =Q8+R8 -> 45.8752 | T8: =J8*0.135 -> 77.4144 | U8: =T8 -> 77.4144 | V8: BDOFOMRUMIB | W8: 01616026062001 | X8: =K8*-1 -> 45.8752
B9: 8537109 | C9: Said Mohammed Said Al Maamari | D9: PRO | E9: Omani | F9: 336 | G9: =(F9*4%) -> 13.44 | H9: =F9+G9 -> 349.44 | I9: 224 | J9: =H9+I9 -> 573.44 | K9: =-J9*8% -> -45.8752 | O9: =J9+K9+N9+M9+L9 -> 527.5648 | Q9: =J9*0.07 -> 40.1408 | R9: =J9*0.01 -> 5.7344 | S9: =Q9+R9 -> 45.8752 | T9: =J9*0.135 -> 77.4144 | U9: =T9 -> 77.4144 | V9: NBOMOMRX | W9: 1023524763001 | X9: =K9*-1 -> 45.8752
B10: 75524503 | C10: Mahmoud Abdel Sayed Ismail | D10: Legal Advisor | E10: Expat | F10: 482.59702 | G10: =(F10*4%) -> 19.303881 | H10: =F10+G10 -> 501.9009 | I10: 193.08 | J10: =H10+I10 -> 694.9809 | K10: 0 | M10: -75 | O10: =J10+K10+N10+M10+L10 -> 619.9809 | P10: 1,250/12 Month | Q10: 0 | R10: 0 | S10: =Q10+R10 -> 0 | T10: 0 | U10: =T10 -> 0 | V10: BSHROMRU | W10: 010010166409 | X10: =K10*-1 -> 0
B11: 118683789 | C11: Soumya Sinu | D11: Purchase Coordinator | E11: Expat | F11: 380.91352 | G11: =(F11*4%) -> 15.236541 | H11: =F11+G11 -> 396.15006 | I11: 152.835 | J11: =H11+I11 -> 548.98506 | K11: 0 | M11: 0 | N11: 0 | O11: =J11+K11+N11+M11+L11 -> 548.98506 | Q11: 0 | R11: 0 | S11: =Q11+R11 -> 0 | T11: 0 | U11: =T11 -> 0 | V11: OMABOMRU | W11: 3109733777700 | X11: =K11*-1 -> 0
B12: 99955793 | C12: Hassan Hamdi Ebrahim | D12: Cost accountant | E12: Expat | F12: 660.03808 | G12: =(F12*4%) -> 26.401523 | H12: 686.4396 | I12: 278.56 | J12: =H12+I12 -> 964.9996 | K12: 0 | O12: =J12+K12+N12+M12+L12 -> 964.9996 | Q12: 0 | R12: 0 | S12: 0 | T12: 0 | U12: 0 | V12: BDOFOMRUMIB | W12: 1646038371001 | X12: 0
B13: 18668266 | C13: Musallam Said Bakhit Zidan Al Baraami | D13: Accounts Executive | E13: Omani | F13: 387.99078 | G13: =(F13*4%) -> 15.519631 | H13: =F13+G13 -> 403.51041 | I13: 241.468 | J13: =H13+I13 -> 644.97841 | K13: =-J13*8% -> -51.598273 | O13: =J13+K13+N13+M13+L13 -> 593.38014 | Q13: =J13*0.07 -> 45.148489 | R13: =J13*0.01 -> 6.4497841 | S13: =Q13+R13 -> 51.598273 | T13: =J13*0.135 -> 87.072086 | U13: =T13 -> 87.072086 | V13: OMABOMRU | W13: 3109053271700 | X13: =K13*-1 -> 51.598273
B14: 13432024 | C14: Mohammed AbdullahSalim Al Sarj Al Marhun | D14: IT Executive | E14: Omani | F14: 387.99078 | G14: =(F14*4%) -> 15.519631 | H14: =F14+G14 -> 403.51041 | I14: 241.468 | J14: =H14+I14 -> 644.97841 | K14: =-J14*8% -> -51.598273 | O14: =J14+K14+N14+M14+L14 -> 593.38014 | Q14: =J14*0.07 -> 45.148489 | R14: =J14*0.01 -> 6.4497841 | S14: =Q14+R14 -> 51.598273 | T14: =J14*0.135 -> 87.072086 | U14: =T14 -> 87.072086 | V14: OMABOMRU | W14: 3129024775700 | X14: =K14*-1 -> 51.598273
B15: 14105567 | C15: Said Mohammed Said Baqwair | D15: Exe. Secretary | E15: Omani | F15: 323.856 | G15: =(F15*4%) -> 12.95424 | H15: =F15+G15 -> 336.81024 | I15: 207.6 | J15: =H15+I15 -> 544.41024 | K15: =-J15*8% -> -43.552819 | M15: 0 | N15: 0 | O15: =J15+K15+N15+M15+L15 -> 500.85742 | Q15: =J15*0.07 -> 38.108717 | R15: =J15*0.01 -> 5.4441024 | S15: =Q15+R15 -> 43.552819 | T15: =J15*0.135 -> 73.495382 | U15: =T15 -> 73.495382 | V15: BDOFOMRU | W15: 01011256095001 | X15: =K15*-1 -> 43.552819
B16: 118826764 | C16: Abdullah | D16: Office Boy | E16: Expat | F16: 90 | G16: =(F16*4%) -> 3.6 | H16: =F16+G16 -> 93.6 | I16: =150*40% -> 60 | J16: =H16+I16 -> 153.6 | K16: 0 | M16: 0 | N16: 0 | O16: =J16+K16+N16+M16+L16 -> 153.6 | Q16: 0 | R16: 0 | S16: 0 | T16: 0 | U16: =T16 -> 0 | V16: BNZWOMRX | W16: 00510128003001 | X16: =K16*-1 -> 0
B17: 138942588 | C17: Jassir Palakkaparambil | D17: Office Boy - Sales | E17: Expat | F17: 79.5 | G17: 0 | H17: =F17+G17 -> 79.5 | I17: =6.518+9.178+37.304 -> 53 | J17: =H17+I17 -> 132.5 | K17: 0 | O17: =J17+K17+N17+M17+L17 -> 132.5 | Q17: 0 | R17: 0 | S17: 0 | T17: 0 | U17: =T17 -> 0 | V17: BMUSOMRX | W17: 0397078787600018 | X17: =K17*-1 -> 0
B18: 117241993 | C18: Sankar Sadasivam | D18: Quality Specialist | E18: Expat | F18: 458.00227 | G18: =(F18*4%) -> 18.320091 | H18: =F18+G18 -> 476.32236 | I18: 285.04 | J18: =H18+I18 -> 761.36236 | K18: 0 | M18: 0 | O18: =J18+K18+N18+M18+L18 -> 761.36236 | Q18: 0 | R18: 0 | S18: =Q18+R18 -> 0 | T18: 0 | U18: =T18 -> 0 | V18: OMABOMRU | W18: 3109734563700 | X18: =K18*-1 -> 0
B19: 6534754 | C19: Hassan Salim Mohammad Kashoob | D19: Center Supervisor | E19: Omani | F19: 444.76224 | G19: =(F19*4%) -> 17.79049 | H19: =F19+G19 -> 462.55273 | I19: 276.8 | J19: =H19+I19 -> 739.35273 | K19: =-J19*8% -> -59.148218 | N19: =J19*10% -> 73.935273 | O19: =J19+K19+N19+M19+L19 -> 754.13978 | P19: 10% بدل انتداب | Q19: =J19*0.07 -> 51.754691 | R19: =J19*0.01 -> 7.3935273 | S19: =Q19+R19 -> 59.148218 | T19: =J19*0.135 -> 99.812618 | U19: =T19 -> 99.812618 | V19: NBOMOMRX | W19: 1006465813017 | X19: =K19*-1 -> 59.148218
B20: 3364532 | C20: Mohammad Ahmed Said Al Marhoon | D20: Center Supervisor | E20: Omani | F20: 444.76224 | G20: =(F20*4%) -> 17.79049 | H20: =F20+G20 -> 462.55273 | I20: 276.8 | J20: =H20+I20 -> 739.35273 | K20: =-J20*8% -> -59.148218 | M20: 0 | N20: =J20*10% -> 73.935273 | O20: =J20+K20+N20+M20+L20 -> 754.13978 | P20: 10% بدل انتداب | Q20: =J20*0.07 -> 51.754691 | R20: =J20*0.01 -> 7.3935273 | S20: =Q20+R20 -> 59.148218 | T20: =J20*0.135 -> 99.812618 | U20: =T20 -> 99.812618 | V20: OMABOMRU | W20: 3109103203700 | X20: =K20*-1 -> 59.148218
B21: 11733522 | C21: Musallam Nasser Salim qatan | D21: HSE | E21: Omani | F21: 380.49024 | G21: =(F21*4%) -> 15.21961 | H21: =F21+G21 -> 395.70985 | I21: 236.8 | J21: =H21+I21 -> 632.50985 | K21: =-J21*8% -> -50.600788 | O21: =J21+K21+N21+M21+L21 -> 581.90906 | Q21: =J21*0.07 -> 44.275689 | R21: =J21*0.01 -> 6.3250985 | S21: =Q21+R21 -> 50.600788 | T21: =J21*0.135 -> 85.38883 | U21: =T21 -> 85.38883 | V21: OMABOMRU | W21: 3109741755700 | X21: =K21*-1 -> 50.600788
B22: 9599617 | C22: Qais Abdullah Al Ojaili | D22: Driver | E22: Omani | F22: 330.17169 | G22: =(F22*4%) -> 13.206868 | H22: =F22+G22 -> 343.37856 | I22: 205.484 | J22: =H22+I22 -> 548.86256 | K22: =-J22*8% -> -43.909005 | M22: 0 | O22: =J22+K22+N22+M22+L22 -> 504.95355 | Q22: =J22*0.07 -> 38.420379 | R22: =J22*0.01 -> 5.4886256 | S22: =Q22+R22 -> 43.909005 | T22: =J22*0.135 -> 74.096445 | U22: =T22 -> 74.096445 | V22: BDOFOMRU | W22: 01010857117001 | X22: =K22*-1 -> 43.909005
B23: 14408161 | C23: Salim Ahmed Salim Bait Said | D23: Driver | E23: Omani | F23: 330.17169 | G23: =(F23*4%) -> 13.206868 | H23: =F23+G23 -> 343.37856 | I23: 205.484 | J23: =H23+I23 -> 548.86256 | K23: =-J23*8% -> -43.909005 | M23: 0 | N23: 0 | O23: =J23+K23+N23+M23+L23 -> 504.95355 | Q23: =J23*0.07 -> 38.420379 | R23: =J23*0.01 -> 5.4886256 | S23: =Q23+R23 -> 43.909005 | T23: =J23*0.135 -> 74.096445 | U23: =T23 -> 74.096445 | V23: OMABOMRU | W23: 3109734940700 | X23: =K23*-1 -> 43.909005
B24: 25472616 | C24: Amir Said Salim Ahmed Al khathri | D24: Driver | E24: Omani | F24: 330.17169 | G24: =(F24*4%) -> 13.206868 | H24: =F24+G24 -> 343.37856 | I24: 205.484 | J24: =H24+I24 -> 548.86256 | K24: =-J24*8% -> -43.909005 | M24: 0 | O24: =J24+K24+N24+M24+L24 -> 504.95355 | Q24: =J24*0.07 -> 38.420379 | R24: =J24*0.01 -> 5.4886256 | S24: =Q24+R24 -> 43.909005 | T24: =J24*0.135 -> 74.096445 | U24: =T24 -> 74.096445 | V24: OMABOMRU | W24: 3109021016700 | X24: =K24*-1 -> 43.909005
B25: 5829377 | C25: Salim Said Faraj Aghreeb Al Shahri | D25: Data Entry Executive | E25: Omani | F25: 387.99078 | G25: =(F25*4%) -> 15.519631 | H25: =F25+G25 -> 403.51041 | I25: 241.468 | J25: =H25+I25 -> 644.97841 | K25: =-J25*8% -> -51.598273 | O25: =J25+K25+N25+M25+L25 -> 593.38014 | Q25: =J25*0.07 -> 45.148489 | R25: =J25*0.01 -> 6.4497841 | S25: =Q25+R25 -> 51.598273 | T25: =J25*0.135 -> 87.072086 | U25: =T25 -> 87.072086 | V25: OMABOMRU | W25: 3158779066700 | X25: =K25*-1 -> 51.598273
B26: 26785757 | C26: Mohammed Said Mohammed Tabook | D26: Data Entry Operator | E26: Omani | F26: 340.88583 | G26: =(F26*4%) -> 13.635433 | H26: =F26+G26 -> 354.52127 | I26: 212.152 | J26: =H26+I26 -> 566.67327 | K26: =-J26*8% -> -45.333861 | O26: =J26+K26+N26+M26+L26 -> 521.33941 | Q26: =J26*0.07 -> 39.667129 | R26: =J26*0.01 -> 5.6667327 | S26: =Q26+R26 -> 45.333861 | T26: =J26*0.135 -> 76.500891 | U26: =T26 -> 76.500891 | V26: OMABOMRU | W26: 3109734108700 | X26: =K26*-1 -> 45.333861
B27: 22734098 | C27: Mustahil Salim Mustahil Ghafram Al Shahri | D27: Milk tester - Zeek | E27: Omani | F27: 309.14832 | G27: =(F27*4%) -> 12.365933 | H27: =F27+G27 -> 321.51425 | I27: 192.4 | J27: =H27+I27 -> 513.91425 | K27: =-J27*8% -> -41.11314 | M27: -75 | N27: =-J27/30*1 -> -17.130475 | O27: =J27+K27+N27+M27+L27 -> 380.67064 | P27: Deduct (600) Petty cash / 12 Month Transfer Full Salery | Q27: =J27*0.07 -> 35.973998 | R27: =J27*0.01 -> 5.1391425 | S27: =Q27+R27 -> 41.11314 | T27: =J27*0.135 -> 69.378424 | U27: =T27 -> 69.378424 | V27: OMABOMRU | W27: 3109730495700 | X27: =K27*-1 -> 41.11314
B28: 23600713 | C28: Ahmed Bakhit Ali Thuaar | D28: Milk tester - Zeek | E28: Omani | F28: 309.14832 | G28: =(F28*4%) -> 12.365933 | H28: =F28+G28 -> 321.51425 | I28: 192.4 | J28: =H28+I28 -> 513.91425 | K28: =-J28*8% -> -41.11314 | N28: =J28*10% -> 51.391425 | O28: =J28+K28+N28+M28+L28 -> 524.19254 | Q28: =J28*0.07 -> 35.973998 | R28: =J28*0.01 -> 5.1391425 | S28: =Q28+R28 -> 41.11314 | T28: =J28*0.135 -> 69.378424 | U28: =T28 -> 69.378424 | V28: OMABOMRU | W28: 3109732521700 | X28: =K28*-1 -> 41.11314
B29: 4792636 | C29: Mohammed ahmed Salim Qatan | D29: Supervisor Hajeef | E29: Omani | F29: 415.2 | G29: =(F29*4%) -> 16.608 | H29: =F29+G29 -> 431.808 | I29: =195+32.8+49 -> 276.8 | J29: =H29+I29 -> 708.608 | K29: =-J29*8% -> -56.68864 | O29: =J29+K29+N29+M29+L29 -> 651.91936 | Q29: =J29*0.07 -> 49.60256 | R29: =J29*0.01 -> 7.08608 | S29: =Q29+R29 -> 56.68864 | T29: =J29*0.135 -> 95.66208 | U29: =T29 -> 95.66208 | V29: OMABOMRU | W29: 3109521431700 | X29: =K29*-1 -> 56.68864
B30: 12194826 | C30: Said Mahad Ali Al Kathiri | D30: Milk tester - Ghado | E30: Omani | F30: 309.14832 | G30: =(F30*4%) -> 12.365933 | H30: =F30+G30 -> 321.51425 | I30: 192.4 | J30: =H30+I30 -> 513.91425 | K30: =-J30*8% -> -41.11314 | O30: =J30+K30+N30+M30+L30 -> 472.80111 | Q30: =J30*0.07 -> 35.973998 | R30: =J30*0.01 -> 5.1391425 | S30: =Q30+R30 -> 41.11314 | T30: =J30*0.135 -> 69.378424 | U30: =T30 -> 69.378424 | V30: BNZWOMRX | W30: 00510129167001 | X30: =K30*-1 -> 41.11314
B31: 15107764 | C31: Ahmed Omar Ahmed Hatal Shihri | D31: Milk tester - Ghado | E31: Omani | F31: 309.14832 | G31: =(F31*4%) -> 12.365933 | H31: =F31+G31 -> 321.51425 | I31: 192.4 | J31: =H31+I31 -> 513.91425 | K31: =-J31*8% -> -41.11314 | N31: =J31*10% -> 51.391425 | O31: =J31+K31+N31+M31+L31 -> 524.19254 | P31: 10% بدل انتداب | Q31: =J31*0.07 -> 35.973998 | R31: =J31*0.01 -> 5.1391425 | S31: =Q31+R31 -> 41.11314 | T31: =J31*0.135 -> 69.378424 | U31: =T31 -> 69.378424 | V31: OMABOMRU | W31: 3158749255700 | X31: =K31*-1 -> 41.11314
B32: 14873156 | C32: Hassan Mohammed Hassan Atif Alyafai | D32: Milk tester - Hajeef | E32: Omani | F32: 309.14832 | G32: =(F32*4%) -> 12.365933 | H32: =F32+G32 -> 321.51425 | I32: 192.4 | J32: =H32+I32 -> 513.91425 | K32: =-J32*8% -> -41.11314 | M32: =-900/12 -> -75 | O32: =J32+K32+N32+M32+L32 -> 397.80111 | P32: Advance 900 / 12 Month Start from Oct | Q32: =J32*0.07 -> 35.973998 | R32: =J32*0.01 -> 5.1391425 | S32: =Q32+R32 -> 41.11314 | T32: =J32*0.135 -> 69.378424 | U32: =T32 -> 69.378424 | V32: OMABOMRU | W32: 3109728935700 | X32: =K32*-1 -> 41.11314
B33: 4383259 | C33: Imad Abdul Hakeem Faraj Fadhil | D33: Mechanical | E33: Omani | F33: 333.57168 | G33: =(F33*4%) -> 13.342867 | H33: =F33+G33 -> 346.91455 | I33: 207.6 | J33: =H33+I33 -> 554.51455 | K33: =-J33*8% -> -44.361164 | O33: =J33+K33+N33+M33+L33 -> 510.15338 | Q33: =J33*0.07 -> 38.816018 | R33: =J33*0.01 -> 5.5451455 | S33: =Q33+R33 -> 44.361164 | T33: =J33*0.135 -> 74.859464 | U33: =T33 -> 74.859464 | V33: OMABOMRU | W33: 3109737191700 | X33: =K33*-1 -> 44.361164
B34: 18640539 | C34: Hassan Musallam Mohammed Tabook | D34: Electrical | E34: Omani | F34: 333.57168 | G34: =(F34*4%) -> 13.342867 | H34: =F34+G34 -> 346.91455 | I34: 207.6 | J34: =H34+I34 -> 554.51455 | K34: =-J34*8% -> -44.361164 | O34: =J34+K34+N34+M34+L34 -> 510.15338 | Q34: =J34*0.07 -> 38.816018 | R34: =J34*0.01 -> 5.5451455 | S34: =Q34+R34 -> 44.361164 | T34: =J34*0.135 -> 74.859464 | U34: =T34 -> 74.859464 | V34: OMABOMRU | W34: 3129733022500 | X34: =K34*-1 -> 44.361164
B35: 111114471 | C35: Saad yousuf Saad ibrahim | D35: Electrical | E35: Expat | F35: 289.224 | G35: =(F35*4%) -> 11.56896 | H35: =F35+G35 -> 300.79296 | I35: 180 | J35: =H35+I35 -> 480.79296 | K35: 0 | O35: =J35+K35+N35+M35+L35 -> 480.79296 | Q35: 0 | R35: 0 | S35: 0 | T35: 0 | U35: =T35 -> 0 | V35: OMABOMRU | W35: 3136571675700 | X35: =K35*-1 -> 0
B36: 10132421 | C36: Khalid Said Ali Al Nubi Al Kathiri | D36: Security | E36: Omani | F36: 294.43003 | G36: =(F36*4%) -> 11.777201 | H36: =F36+G36 -> 306.20723 | I36: 183.24 | J36: =H36+I36 -> 489.44723 | K36: =-J36*8% -> -39.155779 | O36: =J36+K36+N36+M36+L36 -> 450.29145 | Q36: =J36*0.07 -> 34.261306 | R36: =J36*0.01 -> 4.8944723 | S36: =Q36+R36 -> 39.155779 | T36: =J36*0.135 -> 66.075376 | U36: =T36 -> 66.075376 | V36: OMABOMRU | W36: 3109733974700 | X36: =K36*-1 -> 39.155779
B37: 6431446 | C37: Said Mohammed Ajaham Al Zawamri | D37: Security | E37: Omani | F37: 294.43003 | G37: =(F37*4%) -> 11.777201 | H37: =F37+G37 -> 306.20723 | I37: 183.24 | J37: =H37+I37 -> 489.44723 | K37: =-J37*8% -> -39.155779 | O37: =J37+K37+N37+M37+L37 -> 450.29145 | Q37: =J37*0.07 -> 34.261306 | R37: =J37*0.01 -> 4.8944723 | S37: =Q37+R37 -> 39.155779 | T37: =J37*0.135 -> 66.075376 | U37: =T37 -> 66.075376 | V37: OMABOMRU | W37: 3109787268700 | X37: =K37*-1 -> 39.155779
B38: 19315674 | C38: Osama Mohammed Said Al Kathiri | D38: Security | E38: Omani | F38: 294.43003 | G38: =(F38*4%) -> 11.777201 | H38: =F38+G38 -> 306.20723 | I38: 183.24 | J38: =H38+I38 -> 489.44723 | K38: =-J38*8% -> -39.155779 | O38: =J38+K38+N38+M38+L38 -> 450.29145 | Q38: =J38*0.07 -> 34.261306 | R38: =J38*0.01 -> 4.8944723 | S38: =Q38+R38 -> 39.155779 | T38: =J38*0.135 -> 66.075376 | U38: =T38 -> 66.075376 | V38: OMABOMRU | W38: 3109733202700 | X38: =K38*-1 -> 39.155779
B39: 24834714 | C39: Ali Ben Mubarak Ben Awadh Mubarak Ausout Al Shahri | D39: Security | E39: Omani | F39: 294.43003 | G39: =(F39*4%) -> 11.777201 | H39: =F39+G39 -> 306.20723 | I39: 183.24 | J39: =H39+I39 -> 489.44723 | K39: =-J39*8% -> -39.155779 | O39: =J39+K39+N39+M39+L39 -> 450.29145 | Q39: =J39*0.07 -> 34.261306 | R39: =J39*0.01 -> 4.8944723 | S39: =Q39+R39 -> 39.155779 | T39: =J39*0.135 -> 66.075376 | U39: =T39 -> 66.075376 | V39: IZZBOMRU | W39: 0500102447104001 | X39: =K39*-1 -> 39.155779
B40: 21973324 | C40: Suhail said Musallam Kashoob | D40: Security | E40: Omani | F40: 294.43003 | G40: =(F40*4%) -> 11.777201 | H40: =F40+G40 -> 306.20723 | I40: 183.24 | J40: =H40+I40 -> 489.44723 | K40: =-J40*8% -> -39.155779 | O40: =J40+K40+N40+M40+L40 -> 450.29145 | Q40: =J40*0.07 -> 34.261306 | R40: =J40*0.01 -> 4.8944723 | S40: =Q40+R40 -> 39.155779 | T40: =J40*0.135 -> 66.075376 | U40: =T40 -> 66.075376 | V40: OMABOMRU | W40: 3109733643700 | X40: =K40*-1 -> 39.155779
B41: 19455653 | C41: Mohsin Suhail Ahmed Musallam Kashoob | D41: Security | E41: Omani | F41: 294.43003 | G41: =(F41*4%) -> 11.777201 | H41: =F41+G41 -> 306.20723 | I41: 183.24 | J41: =H41+I41 -> 489.44723 | K41: =-J41*8% -> -39.155779 | O41: =J41+K41+N41+M41+L41 -> 450.29145 | Q41: =J41*0.07 -> 34.261306 | R41: =J41*0.01 -> 4.8944723 | S41: =Q41+R41 -> 39.155779 | T41: =J41*0.135 -> 66.075376 | U41: =T41 -> 66.075376 | V41: BNZWOMRX | W41: 00510129889001 | X41: =K41*-1 -> 39.155779
B42: 19046538 | C42: Majid Said Ali Qatan | D42: Security | E42: Omani | F42: 289.224 | G42: =(F42*4%) -> 11.56896 | H42: =F42+G42 -> 300.79296 | I42: 180 | J42: =H42+I42 -> 480.79296 | K42: =-J42*8% -> -38.463437 | O42: =J42+K42+N42+M42+L42 -> 442.32952 | Q42: =J42*0.07 -> 33.655507 | R42: =J42*0.01 -> 4.8079296 | S42: =Q42+R42 -> 38.463437 | T42: =J42*0.135 -> 64.90705 | U42: =T42 -> 64.90705 | V42: OMABOMRU | W42: 3109729247700 | X42: =K42*-1 -> 38.463437
...

Sheet Sheet2

Sheet Training staff
E2: Training staff
A3: SL | B3: NAME | C3: ID No | D3: POSITION | E3: Nationality | F3: Gross Fees | G3: Ded/add | H3: Net Fees | I3: Remark | J3: Bank A/C | K3: SWFT | L3: Bank | M3: Start Date | N3: End Month | O3: N. of Days | P3: Date End Contrect
A4: 1 | B4: Yasir Ahmed Hassan Kashob | C4: 7328813 | D4: IT | E4: Omani | F4: =(250/31)*O4 -> 250 | G4: 0 | H4: =F4-G4 -> 250 | J4: 0406017020660032 | K4: BMUSOMRX | L4: Bank Muscat | M4: =DATE(2024,12,16) -> 45642 | N4: =DATE(2025,1,15) -> 45672 | O4: =N4-M4+1 -> 31 | P4: =DATE(2025,1,24) -> 45681
A5: 2 | B5: Bakhit Ahmed Mahad Tabook | C5: 18643747 | D5: Project | E5: Omani | F5: =(250/31)*O5 -> 250 | G5: 0 | H5: =F5-G5 -> 250 | J5: 0397014842560014 | K5: BMUSOMRX | L5: Bank Muscat | M5: =DATE(2024,12,25) -> 45651 | N5: =DATE(2025,1,24) -> 45681 | O5: =N5-M5+1 -> 31 | P5: =DATE(2024,12,24) -> 45650
A6: 3 | B6: Ahmed Mohammed Mustahil Ahmed Al Maashani | C6: 18728716 | D6: Sales | E6: Omani | F6: =(250/31)*O6 -> 250 | G6: 0 | H6: =F6-G6 -> 250 | J6: 0398020980460024 | K6: BMUSOMRX | L6: Bank Muscat | M6: =DATE(2024,12,16) -> 45642 | N6: =DATE(2025,1,15) -> 45672 | O6: =N6-M6+1 -> 31 | P6: =DATE(2025,1,23) -> 45680
A7: 4 | B7: Khalid Salim Ahmed Al shanfari | C7: 6070659 | D7: Sales | E7: Omani | F7: =(250/31)*O7 -> 250 | G7: 0 | H7: =F7-G7 -> 250 | J7: 0397045703070013 | K7: BMUSOMRX | L7: Bank Muscat | M7: =DATE(2024,12,16) -> 45642 | N7: =DATE(2025,1,15) -> 45672 | O7: =N7-M7+1 -> 31 | P7: =DATE(2025,1,23) -> 45680
A8: 5 | B8: Salim Mohammed Salim Al hamar | C8: 14304376 | D8: Legal | E8: Omani | F8: =(250/31)*O8 -> 250 | H8: =F8-G8 -> 250 | J8: 01646113094001 | K8: BDOFOMRUMIB | L8: Bank Dhofar Islamic | M8: =DATE(2024,12,16) -> 45642 | N8: =DATE(2025,1,15) -> 45672 | O8: =N8-M8+1 -> 31 | P8: =DATE(2025,1,16) -> 45673
A9: 6 | B9: Aya Ahmed Said Al Masahli | C9: 18648607 | D9: HR | E9: Omani | F9: =(250/31)*O9 -> 250 | H9: =F9-G9 -> 250 | J9: 0406048680600019 | K9: BMUSOMRX | L9: Bank Muscat | M9: =DATE(2024,12,16) -> 45642 | N9: =DATE(2025,1,15) -> 45672 | O9: =N9-M9+1 -> 31 | P9: =DATE(2025,1,27) -> 45684
A10: 7 | B10: Musallam Bakhit Salim Kashob | C10: 21958653 | D10: Sales | E10: Omani | F10: =(250/31)*O10 -> 250 | H10: =F10-G10 -> 250 | J10: 70402005350401 | K10: BSHROMRUISL | L10: Bank Sohar Islamic | M10: =DATE(2024,12,16) -> 45642 | N10: =DATE(2025,1,15) -> 45672 | O10: =N10-M10+1 -> 31 | P10: =DATE(2025,2,8) -> 45696
A11: 8 | B11: Ali Musallam Ali Al Awaed | C11: 3987886 | D11: Sales | E11: Omani | F11: =(250/31)*O11 -> 250 | H11: =F11-G11 -> 250 | J11: 0401002519710019 | K11: BMUSOMRX | L11: Bank Muscat | M11: =DATE(2024,12,16) -> 45642 | N11: =DATE(2025,1,15) -> 45672 | O11: =N11-M11+1 -> 31 | P11: =DATE(2025,2,15) -> 45703
A12: Total | F12: =SUM(F4:F11) -> 2000 | G12: =SUM(G4:G9) -> 0 | H12: =SUM(H4:H11) -> 2000
K13: Admin | L13: =H4+H8 -> 500
K14: HR | L14: =H9 -> 250
K15: Opr | L15: =H5 -> 250
K16: Sales | L16: =H11+H10+H7+H6 -> 1000
A18: Hassan Kashoob | C18: Hassan Ghaly | H18: Said Al Bahanta
A19: HR | C19: Cost Account | H19: DGM

Sheet Office Boy
C12: Tanker No: | D12: Company
B13: 1 | C13: 9427 AK | D13: Al Morroj Dairy Co
B14: 2 | C14: 6097WA | D14: Al Morroj Dairy Co
B15: 3 | C15: 9141 HM
B16: 4 | C16: 8126DA
C22: Al Morooj Staffs
B23: 1 | C23: Qais Abdullah Al Ojaili
B24: 2 | C24: Salim Ahmed Salim Bait Said
B25: 3 | C25: Amir Said Salim Ahmed Al khathri
C26: Temporary Staffs
B27: 1 | C27: Basel Musallam Mahad Hubais
B28: 2 | C28: Mohammed Rabia Faraj Allah Bait Aziza
B29: 3 | C29: Ahmed Abdullah Khamis Al Balushi
C35: 22 | D35: 22734098 | E35: Mustahil Salim Mustahil Ghafram Al Shahri | F35: Milk tester - Zeek | G35: Omani | H35: =#REF!+#REF! -> #REF! | I35: =-H35*8% -> #REF! | J35: =H35+I35 -> #REF!
C41: SL | D41: NAME | E41: Passpor No | F41: POSITION | G41: Nationality | H41: Start Date | I41: End Month
C42: 1 | D42: Jassir | E42: B9530197 | F42: office boy Sales Department | G42: Expat | H42: =DATE(2025,1,12) -> 45669 | I42: =DATE(2025,3,13) -> 45729 | J42: =I42-H42 -> 60
C43: Total
C46: Hassan Kashoob | E46: Hassan Ghaly
C47: HR | E47: Cost Account
D50: Hassan Ghaly Leave Salary 2025
C52: National ID | D52: NAME | E52: POSITION | F52: Nationality | G52: Gross Salary 2025
C53: 99955793 | D53: Hassan Hamdi Ebrahim | E53: Cost accountant | F53: Expat | G53: 964.9996
F54: Salary Per Day | G54: =G53/30 -> 32.166653
F55: No Leave Days | G55: =7+28 -> 35
G56: =G54*G55 -> 1125.8329
C60: Naga | F60: Said Al Bahanta
C61: Finance Manager | F61: DGM
B72: Date | C72: NAME | D72: ID No | E72: POSITION | F72: Nationality | G72: Gross Fees
B73: 45292 | C73: Abdullah Omar Salim Al Marhoun | D73: 22029746 | E73: Inventory | F73: Omani | G73: 325
B74: 45323 | C74: Abdullah Omar Salim Al Marhoun | D74: 22029746 | E74: Inventory | F74: Omani | G74: 325
B75: 45352 | C75: Abdullah Omar Salim Al Marhoun | D75: 22029746 | E75: Inventory | F75: Omani | G75: 325
B76: 45383 | C76: Abdullah Omar Salim Al Marhoun | D76: 22029746 | E76: Inventory | F76: Omani | G76: 325
B77: 45413 | C77: Abdullah Omar Salim Al Marhoun | D77: 22029746 | E77: Inventory | F77: Omani | G77: 325
B78: 45444 | C78: Abdullah Omar Salim Al Marhoun | D78: 22029746 | E78: Inventory | F78: Omani | G78: 325
B79: 45474 | C79: Abdullah Omar Salim Al Marhoun | D79: 22029746 | E79: Inventory | F79: Omani | G79: 325
B80: 45505 | C80: Abdullah Omar Salim Al Marhoun | D80: 22029746 | E80: Inventory | F80: Omani | G80: 325
B81: 45536 | C81: Abdullah Omar Salim Al Marhoun | D81: 22029746 | E81: Inventory | F81: Omani | G81: 400
B82: 45566 | C82: Abdullah Omar Salim Al Marhoun | D82: 22029746 | E82: Inventory | F82: Omani | G82: 400
B83: 45597 | C83: Abdullah Omar Salim Al Marhoun | D83: 22029746 | E83: Inventory | F83: Omani | G83: 400
B84: 45627 | C84: Abdullah Omar Salim Al Marhoun | D84: 22029746 | E84: Inventory | F84: Omani | G84: 400
...

Sheet Sheet1
D4: Mohammed ahmed Salim Qatan | G4: Total Feb Salary
D5: Salary | E5: 501.54832 | F5: 692
D6: Addition | E6: 50.155 | F6: 0
D7: Total | E7: =SUM(E5:E6) -> 551.70332 | F7: =SUM(F5:F6) -> 692
D8: PASI | E8: =-E5*0.08 -> -40.123866 | F8: -55.36
D9: Salary / Day | E9: =E7/30 -> 18.390111 | F9: 23.066667
D10: Total 15 Day | E10: =E9*15 -> 275.85166 | F10: =F9*15 -> 346 | G10: =E10+F10 -> 621.85166
D11: Pasi for 15 Day | E11: =E8*0.5 -> -20.061933 | F11: -27.68 | G11: =E11+F11 -> -47.741933
D12: Net salary | E12: =SUM(E10:E11) -> 255.78973 | F12: =SUM(F10:F11) -> 318.32 | G12: =SUM(G10:G11) -> 574.10973
A17: Mohammed Al marhoon | E17: Hassan Ghaly | G17: Said AL Bahananata
A18: HR | E18: Finance | G18: DGM
